5:return {{["x"] = 0, ["y"] = 0, ["param1"] = 15, ["z"] = 1, ["name"] = "default:grass_2"}, {["x"] = 0, ["y"] = 0, ["param1"] = 15, ["z"] = 4, ["name"] = "default:grass_4"}, {["x"] = 0, ["y"] = 0, ["param1"] = 15, ["z"] = 5, ["name"] = "default:grass_4"}, {["x"] = 0, ["y"] = 0, ["param1"] = 15, ["z"] = 14, ["name"] = "default:wood"}, {["x"] = 0, ["y"] = 0, ["param1"] = 15, ["z"] = 15, ["name"] = "default:wood"}, {["x"] = 0, ["y"] = 1, ["param1"] = 15, ["z"] = 14, ["name"] = "default:wood"}, {["x"] = 0, ["y"] = 1, ["param1"] = 15, ["z"] = 15, ["name"] = "default:wood"}, {["x"] = 0, ["y"] = 2, ["param1"] = 15, ["z"] = 14, ["name"] = "default:wood"}, {["x"] = 0, ["y"] = 2, ["param1"] = 15, ["z"] = 15, ["name"] = "default:wood"}, {["x"] = 0, ["y"] = 3, ["param1"] = 15, ["z"] = 14, ["name"] = "default:wood"}, {["x"] = 0, ["y"] = 3, ["param1"] = 15, ["z"] = 15, ["name"] = "default:wood"}, {["x"] = 0, ["y"] = 4, ["param1"] = 15, ["z"] = 14, ["name"] = "default:wood"}, {["x"] = 0, ["y"] = 4, ["param1"] = 15, ["z"] = 15, ["name"] = "default:wood"}, {["x"] = 1, ["y"] = 0, ["param1"] = 15, ["z"] = 14, ["name"] = "default:wood"}, {["x"] = 1, ["y"] = 0, ["param1"] = 15, ["z"] = 15, ["name"] = "default:wood"}, {["x"] = 1, ["y"] = 1, ["param1"] = 15, ["z"] = 14, ["name"] = "default:wood"}, {["x"] = 1, ["y"] = 1, ["param1"] = 15, ["z"] = 15, ["name"] = "default:wood"}, {["x"] = 1, ["y"] = 2, ["param1"] = 15, ["z"] = 14, ["name"] = "default:wood"}, {["x"] = 1, ["y"] = 2, ["param1"] = 15, ["z"] = 15, ["name"] = "default:wood"}, {["x"] = 1, ["y"] = 3, ["param1"] = 15, ["z"] = 14, ["name"] = "default:wood"}, {["x"] = 1, ["y"] = 3, ["param1"] = 15, ["z"] = 15, ["name"] = "default:wood"}, {["x"] = 1, ["y"] = 4, ["param1"] = 15, ["z"] = 14, ["name"] = "default:wood"}, {["x"] = 1, ["y"] = 4, ["param1"] = 15, ["z"] = 15, ["name"] = "default:wood"}, {["x"] = 2, ["y"] = 0, ["param1"] = 15, ["z"] = 1, ["name"] = "default:grass_1"}, {["x"] = 2, ["y"] = 0, ["param1"] = 15, ["z"] = 5, ["name"] = "default:grass_2"}, {["x"] = 2, ["y"] = 0, ["param1"] = 15, ["z"] = 11, ["name"] = "default:grass_1"}, {["x"] = 2, ["y"] = 0, ["param1"] = 15, ["z"] = 14, ["name"] = "default:wood"}, {["x"] = 2, ["y"] = 0, ["param1"] = 15, ["z"] = 15, ["name"] = "default:wood"}, {["x"] = 2, ["y"] = 1, ["param1"] = 15, ["z"] = 14, ["name"] = "default:wood"}, {["x"] = 2, ["y"] = 1, ["param1"] = 15, ["z"] = 15, ["name"] = "default:wood"}, {["x"] = 2, ["y"] = 2, ["param1"] = 15, ["z"] = 14, ["name"] = "default:wood"}, {["x"] = 2, ["y"] = 2, ["param1"] = 15, ["z"] = 15, ["name"] = "default:wood"}, {["x"] = 2, ["y"] = 3, ["param1"] = 15, ["z"] = 14, ["name"] = "default:wood"}, {["x"] = 2, ["y"] = 3, ["param1"] = 15, ["z"] = 15, ["name"] = "default:wood"}, {["x"] = 2, ["y"] = 4, ["param1"] = 15, ["z"] = 14, ["name"] = "default:wood"}, {["x"] = 2, ["y"] = 4, ["param1"] = 15, ["z"] = 15, ["name"] = "default:wood"}, {["x"] = 3, ["y"] = 0, ["param1"] = 14, ["z"] = 3, ["name"] = "default:grass_1"}, {["x"] = 3, ["y"] = 0, ["param1"] = 14, ["z"] = 8, ["name"] = "default:grass_3"}, {["x"] = 3, ["y"] = 0, ["param1"] = 15, ["z"] = 14, ["name"] = "default:wood"}, {["x"] = 3, ["y"] = 0, ["param1"] = 15, ["z"] = 15, ["name"] = "default:wood"}, {["x"] = 3, ["y"] = 1, ["param1"] = 15, ["z"] = 14, ["name"] = "default:wood"}, {["x"] = 3, ["y"] = 1, ["param1"] = 15, ["z"] = 15, ["name"] = "default:wood"}, {["x"] = 3, ["y"] = 2, ["param1"] = 15, ["z"] = 14, ["name"] = "default:wood"}, {["x"] = 3, ["y"] = 2, ["param1"] = 15, ["z"] = 15, ["name"] = "default:wood"}, {["x"] = 3, ["y"] = 3, ["param1"] = 15, ["z"] = 14, ["name"] = "default:wood"}, {["x"] = 3, ["y"] = 3, ["param1"] = 15, ["z"] = 15, ["name"] = "default:wood"}, {["x"] = 3, ["y"] = 4, ["param1"] = 15, ["z"] = 14, ["name"] = "default:wood"}, {["x"] = 3, ["y"] = 4, ["param1"] = 15, ["z"] = 15, ["name"] = "default:wood"}, {["x"] = 4, ["y"] = 0, ["param1"] = 14, ["z"] = 5, ["name"] = "default:grass_2"}, {["x"] = 4, ["y"] = 0, ["param1"] = 15, ["z"] = 14, ["name"] = "default:wood"}, {["x"] = 4, ["y"] = 0, ["param1"] = 15, ["z"] = 15, ["name"] = "default:wood"}, {["x"] = 4, ["y"] = 1, ["param1"] = 15, ["z"] = 14, ["name"] = "default:wood"}, {["x"] = 4, ["y"] = 1, ["param1"] = 15, ["z"] = 15, ["name"] = "default:wood"}, {["x"] = 4, ["y"] = 2, ["param1"] = 15, ["z"] = 14, ["name"] = "default:wood"}, {["x"] = 4, ["y"] = 2, ["param1"] = 15, ["z"] = 15, ["name"] = "default:wood"}, {["x"] = 4, ["y"] = 3, ["param1"] = 15, ["z"] = 14, ["name"] = "default:wood"}, {["x"] = 4, ["y"] = 3, ["param1"] = 15, ["z"] = 15, ["name"] = "default:wood"}, {["x"] = 4, ["y"] = 4, ["param1"] = 15, ["z"] = 14, ["name"] = "default:wood"}, {["x"] = 4, ["y"] = 4, ["param1"] = 15, ["z"] = 15, ["name"] = "default:wood"}, {["x"] = 5, ["y"] = 0, ["param1"] = 15, ["z"] = 0, ["name"] = "default:grass_2"}, {["x"] = 5, ["y"] = 0, ["param1"] = 14, ["z"] = 2, ["name"] = "default:grass_3"}, {["x"] = 6, ["y"] = 0, ["param1"] = 15, ["z"] = 4, ["name"] = "default:grass_2"}, {["x"] = 6, ["y"] = 0, ["param1"] = 15, ["z"] = 5, ["name"] = "default:grass_3"}, {["x"] = 7, ["y"] = 0, ["param1"] = 15, ["z"] = 0, ["name"] = "default:grass_5"}, {["x"] = 7, ["y"] = 0, ["param1"] = 15, ["z"] = 8, ["name"] = "default:grass_1"}, {["x"] = 8, ["y"] = 0, ["param1"] = 15, ["z"] = 5, ["name"] = "default:grass_2"}, {["x"] = 8, ["y"] = 0, ["param1"] = 15, ["z"] = 12, ["name"] = "default:grass_4"}, {["x"] = 9, ["y"] = 0, ["param1"] = 15, ["z"] = 9, ["name"] = "default:grass_3"}, {["x"] = 9, ["y"] = 0, ["param1"] = 15, ["z"] = 15, ["name"] = "default:grass_1"}, {["x"] = 10, ["y"] = 0, ["z"] = 0, ["name"] = "building_blocks:Marble"}, {["x"] = 10, ["y"] = 1, ["z"] = 0, ["name"] = "building_blocks:Marble"}, {["x"] = 10, ["y"] = 2, ["z"] = 0, ["name"] = "building_blocks:Marble"}, {["x"] = 10, ["y"] = 3, ["z"] = 0, ["name"] = "building_blocks:Marble"}, {["x"] = 10, ["y"] = 4, ["z"] = 0, ["name"] = "building_blocks:Marble"}}