5:return {{["x"] = 0, ["y"] = 0, ["z"] = 0, ["name"] = "default:dirt_with_grass"}, {["x"] = 0, ["y"] = 0, ["z"] = 1, ["name"] = "default:dirt_with_grass"}, {["x"] = 0, ["y"] = 0, ["z"] = 2, ["name"] = "default:stone"}, {["x"] = 0, ["y"] = 0, ["z"] = 3, ["name"] = "default:stone"}, {["x"] = 0, ["y"] = 0, ["z"] = 4, ["name"] = "default:stone"}, {["x"] = 0, ["y"] = 0, ["z"] = 5, ["name"] = "default:stone"}, {["x"] = 0, ["y"] = 0, ["z"] = 6, ["name"] = "default:stone"}, {["x"] = 0, ["y"] = 0, ["z"] = 7, ["name"] = "default:stone"}, {["x"] = 0, ["y"] = 0, ["z"] = 8, ["name"] = "default:stone"}, {["x"] = 0, ["y"] = 0, ["z"] = 9, ["name"] = "default:stone"}, {["x"] = 0, ["y"] = 0, ["z"] = 10, ["name"] = "default:stone"}, {["x"] = 0, ["y"] = 0, ["z"] = 11, ["name"] = "default:stone"}, {["x"] = 0, ["y"] = 0, ["z"] = 12, ["name"] = "default:silver_sand"}, {["x"] = 0, ["y"] = 0, ["z"] = 13, ["name"] = "default:silver_sand"}, {["x"] = 0, ["y"] = 0, ["z"] = 14, ["name"] = "default:silver_sand"}, {["x"] = 0, ["y"] = 0, ["z"] = 15, ["name"] = "default:stone"}, {["x"] = 0, ["y"] = 0, ["z"] = 16, ["name"] = "default:stone"}, {["x"] = 0, ["y"] = 0, ["z"] = 17, ["name"] = "default:stone"}, {["x"] = 0, ["y"] = 0, ["z"] = 18, ["name"] = "default:stone"}, {["x"] = 0, ["y"] = 0, ["z"] = 19, ["name"] = "default:stone"}, {["x"] = 0, ["y"] = 0, ["z"] = 20, ["name"] = "default:stone"}, {["x"] = 0, ["y"] = 0, ["z"] = 21, ["name"] = "default:stone"}, {["x"] = 0, ["y"] = 0, ["z"] = 22, ["name"] = "default:stone"}, {["x"] = 0, ["y"] = 0, ["z"] = 23, ["name"] = "default:silver_sand"}, {["x"] = 0, ["y"] = 0, ["z"] = 24, ["name"] = "default:silver_sand"}, {["x"] = 0, ["y"] = 0, ["z"] = 25, ["name"] = "default:stone"}, {["x"] = 0, ["y"] = 0, ["z"] = 26, ["name"] = "default:stone"}, {["x"] = 0, ["y"] = 0, ["z"] = 27, ["name"] = "default:stone"}, {["x"] = 0, ["y"] = 0, ["z"] = 28, ["name"] = "default:stone"}, {["x"] = 0, ["y"] = 0, ["z"] = 29, ["name"] = "default:stone"}, {["x"] = 0, ["y"] = 0, ["z"] = 30, ["name"] = "default:stone"}, {["x"] = 0, ["y"] = 0, ["z"] = 31, ["name"] = "default:stone"}, {["x"] = 0, ["y"] = 0, ["z"] = 32, ["name"] = "default:stone"}, {["x"] = 0, ["y"] = 0, ["z"] = 33, ["name"] = "default:stone"}, {["x"] = 0, ["y"] = 0, ["z"] = 34, ["name"] = "default:stone"}, {["x"] = 0, ["y"] = 0, ["z"] = 35, ["name"] = "default:dirt_with_grass"}, {["x"] = 0, ["y"] = 1, ["z"] = 2, ["name"] = "default:dirt_with_grass"}, {["x"] = 0, ["y"] = 1, ["z"] = 3, ["name"] = "default:dirt_with_grass"}, {["x"] = 0, ["y"] = 1, ["z"] = 4, ["name"] = "default:dirt_with_grass"}, {["x"] = 0, ["y"] = 1, ["z"] = 5, ["name"] = "default:dirt_with_grass"}, {["x"] = 0, ["y"] = 1, ["z"] = 6, ["name"] = "default:dirt_with_grass"}, {["x"] = 0, ["y"] = 1, ["z"] = 7, ["name"] = "default:dirt_with_grass"}, {["x"] = 0, ["y"] = 1, ["z"] = 8, ["name"] = "default:dirt_with_grass"}, {["x"] = 0, ["y"] = 1, ["z"] = 9, ["name"] = "default:dirt_with_grass"}, {["x"] = 0, ["y"] = 1, ["z"] = 10, ["name"] = "default:dirt_with_grass"}, {["x"] = 0, ["y"] = 1, ["z"] = 11, ["name"] = "default:dirt_with_grass"}, {["x"] = 0, ["y"] = 1, ["z"] = 12, ["name"] = "default:dirt_with_grass"}, {["x"] = 0, ["y"] = 1, ["z"] = 13, ["name"] = "default:dirt_with_grass"}, {["x"] = 0, ["y"] = 1, ["z"] = 14, ["name"] = "default:dirt_with_grass"}, {["x"] = 0, ["y"] = 1, ["z"] = 15, ["name"] = "default:dirt_with_grass"}, {["x"] = 0, ["y"] = 1, ["z"] = 16, ["name"] = "default:dirt_with_grass"}, {["x"] = 0, ["y"] = 1, ["z"] = 17, ["name"] = "default:dirt_with_grass"}, {["x"] = 0, ["y"] = 1, ["z"] = 18, ["name"] = "default:stone"}, {["x"] = 0, ["y"] = 1, ["z"] = 19, ["name"] = "default:stone"}, {["x"] = 0, ["y"] = 1, ["z"] = 20, ["name"] = "default:stone"}, {["x"] = 0, ["y"] = 1, ["z"] = 21, ["name"] = "default:stone"}, {["x"] = 0, ["y"] = 1, ["z"] = 22, ["name"] = "default:stone"}, {["x"] = 0, ["y"] = 1, ["z"] = 23, ["name"] = "default:stone"}, {["x"] = 0, ["y"] = 1, ["z"] = 24, ["name"] = "default:stone"}, {["x"] = 0, ["y"] = 1, ["z"] = 25, ["name"] = "default:dirt_with_grass"}, {["x"] = 0, ["y"] = 1, ["z"] = 26, ["name"] = "default:dirt_with_grass"}, {["x"] = 0, ["y"] = 1, ["z"] = 27, ["name"] = "default:dirt_with_grass"}, {["x"] = 0, ["y"] = 1, ["z"] = 28, ["name"] = "default:dirt_with_grass"}, {["x"] = 0, ["y"] = 1, ["z"] = 29, ["name"] = "default:dirt_with_grass"}, {["x"] = 0, ["y"] = 1, ["z"] = 30, ["name"] = "default:dirt_with_grass"}, {["x"] = 0, ["y"] = 1, ["z"] = 31, ["name"] = "default:dirt_with_grass"}, {["x"] = 0, ["y"] = 1, ["z"] = 32, ["name"] = "default:dirt_with_grass"}, {["x"] = 0, ["y"] = 1, ["z"] = 33, ["name"] = "default:dirt_with_grass"}, {["x"] = 0, ["y"] = 1, ["z"] = 34, ["name"] = "default:dirt_with_grass"}, {["x"] = 0, ["y"] = 2, ["param1"] = 15, ["z"] = 6, ["name"] = "flowers:viola"}, {["x"] = 0, ["y"] = 2, ["param1"] = 14, ["z"] = 13, ["name"] = "default:blueberry_bush_leaves_with_berries"}, {["x"] = 0, ["y"] = 2, ["param1"] = 15, ["z"] = 15, ["name"] = "flowers:dandelion_yellow"}, {["x"] = 0, ["y"] = 2, ["param1"] = 15, ["z"] = 16, ["name"] = "default:grass_5"}, {["x"] = 0, ["y"] = 2, ["param1"] = 15, ["z"] = 17, ["name"] = "bakedclay:lazarus"}, {["x"] = 0, ["y"] = 2, ["z"] = 18, ["name"] = "default:dirt_with_grass"}, {["x"] = 0, ["y"] = 2, ["z"] = 19, ["name"] = "default:dirt_with_grass"}, {["x"] = 0, ["y"] = 2, ["z"] = 20, ["name"] = "default:dirt_with_grass"}, {["x"] = 0, ["y"] = 2, ["z"] = 21, ["name"] = "default:dirt_with_grass"}, {["x"] = 0, ["y"] = 2, ["z"] = 22, ["name"] = "default:dirt_with_grass"}, {["x"] = 0, ["y"] = 2, ["z"] = 23, ["name"] = "default:dirt_with_grass"}, {["x"] = 0, ["y"] = 2, ["z"] = 24, ["name"] = "default:dirt_with_grass"}, {["x"] = 0, ["y"] = 2, ["param1"] = 15, ["z"] = 34, ["name"] = "flowers:dandelion_yellow"}, {["x"] = 0, ["y"] = 3, ["param1"] = 15, ["z"] = 18, ["name"] = "mobs:fence_wood"}, {["x"] = 0, ["y"] = 3, ["param1"] = 15, ["z"] = 19, ["name"] = "mobs:fence_wood"}, {["x"] = 0, ["y"] = 3, ["param1"] = 15, ["z"] = 20, ["name"] = "mobs:fence_wood"}, {["x"] = 0, ["y"] = 3, ["param1"] = 15, ["z"] = 21, ["name"] = "mobs:fence_wood"}, {["x"] = 0, ["y"] = 3, ["param1"] = 15, ["z"] = 22, ["name"] = "mobs:fence_wood"}, {["x"] = 0, ["y"] = 3, ["param1"] = 15, ["z"] = 23, ["name"] = "mobs:fence_wood"}, {["x"] = 0, ["y"] = 3, ["param1"] = 15, ["z"] = 24, ["name"] = "mobs:fence_wood"}, {["x"] = 1, ["y"] = 0, ["z"] = 0, ["name"] = "default:dirt_with_grass"}, {["x"] = 1, ["y"] = 0, ["z"] = 1, ["name"] = "default:stone"}, {["x"] = 1, ["y"] = 0, ["z"] = 2, ["name"] = "default:stone"}, {["x"] = 1, ["y"] = 0, ["z"] = 3, ["name"] = "default:stone"}, {["x"] = 1, ["y"] = 0, ["z"] = 4, ["name"] = "default:stone"}, {["x"] = 1, ["y"] = 0, ["z"] = 5, ["name"] = "default:stone"}, {["x"] = 1, ["y"] = 0, ["z"] = 6, ["name"] = "default:stone"}, {["x"] = 1, ["y"] = 0, ["z"] = 7, ["name"] = "default:stone"}, {["x"] = 1, ["y"] = 0, ["z"] = 8, ["name"] = "default:stone"}, {["x"] = 1, ["y"] = 0, ["z"] = 9, ["name"] = "default:stone"}, {["x"] = 1, ["y"] = 0, ["z"] = 10, ["name"] = "default:stone"}, {["x"] = 1, ["y"] = 0, ["z"] = 11, ["name"] = "default:stone"}, {["x"] = 1, ["y"] = 0, ["z"] = 12, ["name"] = "default:stone"}, {["x"] = 1, ["y"] = 0, ["z"] = 13, ["name"] = "default:stone"}, {["x"] = 1, ["y"] = 0, ["z"] = 14, ["name"] = "default:stone"}, {["x"] = 1, ["y"] = 0, ["z"] = 15, ["name"] = "default:stone"}, {["x"] = 1, ["y"] = 0, ["param1"] = 4, ["z"] = 16, ["name"] = "default:stone"}, {["x"] = 1, ["y"] = 0, ["param1"] = 4, ["z"] = 17, ["name"] = "default:stone"}, {["x"] = 1, ["y"] = 0, ["param1"] = 4, ["z"] = 18, ["name"] = "default:stone"}, {["x"] = 1, ["y"] = 0, ["param1"] = 4, ["z"] = 19, ["name"] = "default:stone"}, {["x"] = 1, ["y"] = 0, ["param1"] = 4, ["z"] = 20, ["name"] = "default:stone"}, {["x"] = 1, ["y"] = 0, ["param1"] = 4, ["z"] = 21, ["name"] = "default:stone"}, {["x"] = 1, ["y"] = 0, ["param1"] = 4, ["z"] = 22, ["name"] = "default:stone"}, {["x"] = 1, ["y"] = 0, ["param1"] = 4, ["z"] = 23, ["name"] = "default:stone"}, {["x"] = 1, ["y"] = 0, ["param1"] = 4, ["z"] = 24, ["name"] = "default:stone"}, {["x"] = 1, ["y"] = 0, ["param1"] = 4, ["z"] = 25, ["name"] = "default:stone"}, {["x"] = 1, ["y"] = 0, ["param1"] = 4, ["z"] = 26, ["name"] = "default:stone"}, {["x"] = 1, ["y"] = 0, ["param1"] = 4, ["z"] = 27, ["name"] = "default:stone"}, {["x"] = 1, ["y"] = 0, ["param1"] = 4, ["z"] = 28, ["name"] = "default:stone"}, {["x"] = 1, ["y"] = 0, ["param1"] = 4, ["z"] = 29, ["name"] = "default:stone"}, {["x"] = 1, ["y"] = 0, ["param1"] = 4, ["z"] = 30, ["name"] = "default:stone"}, {["x"] = 1, ["y"] = 0, ["param1"] = 4, ["z"] = 31, ["name"] = "default:stone"}, {["x"] = 1, ["y"] = 0, ["z"] = 32, ["name"] = "default:stone"}, {["x"] = 1, ["y"] = 0, ["z"] = 33, ["name"] = "default:stone"}, {["x"] = 1, ["y"] = 0, ["z"] = 34, ["name"] = "default:stone"}, {["x"] = 1, ["y"] = 0, ["z"] = 35, ["name"] = "default:stone"}, {["x"] = 1, ["y"] = 1, ["param1"] = 14, ["z"] = 0, ["name"] = "flowers:dandelion_white"}, {["x"] = 1, ["y"] = 1, ["z"] = 1, ["name"] = "default:dirt_with_grass"}, {["x"] = 1, ["y"] = 1, ["z"] = 2, ["name"] = "default:dirt_with_grass"}, {["x"] = 1, ["y"] = 1, ["z"] = 3, ["name"] = "default:dirt_with_grass"}, {["x"] = 1, ["y"] = 1, ["z"] = 4, ["name"] = "default:dirt_with_grass"}, {["x"] = 1, ["y"] = 1, ["z"] = 5, ["name"] = "default:dirt_with_grass"}, {["x"] = 1, ["y"] = 1, ["z"] = 6, ["name"] = "default:dirt_with_grass"}, {["x"] = 1, ["y"] = 1, ["z"] = 7, ["name"] = "default:dirt_with_grass"}, {["x"] = 1, ["y"] = 1, ["z"] = 8, ["name"] = "default:dirt_with_grass"}, {["x"] = 1, ["y"] = 1, ["z"] = 9, ["name"] = "default:dirt_with_grass"}, {["x"] = 1, ["y"] = 1, ["z"] = 10, ["name"] = "default:dirt_with_grass"}, {["x"] = 1, ["y"] = 1, ["z"] = 11, ["name"] = "default:dirt_with_grass"}, {["x"] = 1, ["y"] = 1, ["z"] = 12, ["name"] = "default:dirt_with_grass"}, {["x"] = 1, ["y"] = 1, ["z"] = 13, ["name"] = "default:dirt_with_grass"}, {["x"] = 1, ["y"] = 1, ["z"] = 14, ["name"] = "default:stone"}, {["x"] = 1, ["y"] = 1, ["z"] = 15, ["name"] = "default:stone"}, {["x"] = 1, ["y"] = 1, ["param1"] = 69, ["z"] = 16, ["name"] = "default:stone_with_coal"}, {["x"] = 1, ["y"] = 1, ["param1"] = 4, ["z"] = 17, ["name"] = "default:stone"}, {["x"] = 1, ["y"] = 1, ["param1"] = 4, ["z"] = 18, ["name"] = "default:stone"}, {["x"] = 1, ["y"] = 1, ["param1"] = 4, ["z"] = 19, ["name"] = "default:stone"}, {["x"] = 1, ["y"] = 1, ["param1"] = 4, ["z"] = 20, ["name"] = "default:stone"}, {["x"] = 1, ["y"] = 1, ["param1"] = 4, ["z"] = 21, ["name"] = "default:stone"}, {["x"] = 1, ["y"] = 1, ["param1"] = 4, ["z"] = 22, ["name"] = "default:stone"}, {["x"] = 1, ["y"] = 1, ["param1"] = 4, ["z"] = 23, ["name"] = "default:stone"}, {["x"] = 1, ["y"] = 1, ["param1"] = 4, ["z"] = 24, ["name"] = "default:stone"}, {["x"] = 1, ["y"] = 1, ["param1"] = 4, ["z"] = 25, ["name"] = "default:stone"}, {["x"] = 1, ["y"] = 1, ["param1"] = 4, ["z"] = 26, ["name"] = "default:stone"}, {["x"] = 1, ["y"] = 1, ["param1"] = 4, ["z"] = 27, ["name"] = "default:stone"}, {["x"] = 1, ["y"] = 1, ["param1"] = 26, ["z"] = 28, ["name"] = "default:dirt_with_grass"}, {["x"] = 1, ["y"] = 1, ["param1"] = 26, ["z"] = 29, ["name"] = "default:dirt_with_grass"}, {["x"] = 1, ["y"] = 1, ["param1"] = 26, ["z"] = 30, ["name"] = "default:dirt_with_grass"}, {["x"] = 1, ["y"] = 1, ["param1"] = 26, ["z"] = 31, ["name"] = "default:dirt_with_grass"}, {["x"] = 1, ["y"] = 1, ["z"] = 32, ["name"] = "default:dirt_with_grass"}, {["x"] = 1, ["y"] = 1, ["z"] = 33, ["name"] = "default:dirt_with_grass"}, {["x"] = 1, ["y"] = 1, ["z"] = 34, ["name"] = "default:dirt_with_grass"}, {["x"] = 1, ["y"] = 1, ["z"] = 35, ["name"] = "default:dirt_with_grass"}, {["x"] = 1, ["y"] = 2, ["param1"] = 14, ["z"] = 12, ["name"] = "default:blueberry_bush_leaves_with_berries"}, {["x"] = 1, ["y"] = 2, ["param1"] = 13, ["z"] = 13, ["name"] = "default:blueberry_bush_leaves_with_berries"}, {["x"] = 1, ["y"] = 2, ["z"] = 14, ["name"] = "default:dirt_with_grass"}, {["x"] = 1, ["y"] = 2, ["z"] = 15, ["name"] = "default:dirt_with_grass"}, {["x"] = 1, ["y"] = 2, ["param1"] = 26, ["z"] = 16, ["name"] = "default:dirt_with_grass"}, {["x"] = 1, ["y"] = 2, ["param1"] = 26, ["z"] = 17, ["name"] = "default:dirt_with_grass"}, {["x"] = 1, ["y"] = 2, ["param1"] = 26, ["z"] = 18, ["name"] = "default:dirt_with_grass"}, {["x"] = 1, ["y"] = 2, ["param1"] = 26, ["z"] = 19, ["name"] = "default:dirt_with_grass"}, {["x"] = 1, ["y"] = 2, ["param1"] = 26, ["z"] = 20, ["name"] = "default:dirt_with_grass"}, {["x"] = 1, ["y"] = 2, ["param1"] = 26, ["z"] = 21, ["name"] = "default:dirt_with_grass"}, {["x"] = 1, ["y"] = 2, ["z"] = 22, ["name"] = "default:dirt_with_grass"}, {["x"] = 1, ["y"] = 2, ["z"] = 23, ["name"] = "default:dirt_with_grass"}, {["x"] = 1, ["y"] = 2, ["param1"] = 26, ["z"] = 24, ["name"] = "default:dirt_with_grass"}, {["x"] = 1, ["y"] = 2, ["param1"] = 26, ["z"] = 25, ["name"] = "default:dirt_with_grass"}, {["x"] = 1, ["y"] = 2, ["param1"] = 26, ["z"] = 26, ["name"] = "default:dirt_with_grass"}, {["x"] = 1, ["y"] = 2, ["param1"] = 26, ["z"] = 27, ["name"] = "default:dirt_with_grass"}, {["x"] = 1, ["y"] = 2, ["param1"] = 14, ["z"] = 29, ["name"] = "flowers:dandelion_white"}, {["x"] = 1, ["y"] = 3, ["param1"] = 14, ["z"] = 14, ["name"] = "mobs:fence_wood"}, {["x"] = 1, ["y"] = 3, ["param1"] = 14, ["z"] = 15, ["name"] = "mobs:fence_wood"}, {["x"] = 1, ["y"] = 3, ["param1"] = 14, ["z"] = 16, ["name"] = "mobs:fence_wood"}, {["x"] = 1, ["y"] = 3, ["param1"] = 14, ["z"] = 17, ["name"] = "mobs:fence_wood"}, {["x"] = 1, ["y"] = 3, ["param1"] = 14, ["z"] = 18, ["name"] = "mobs:fence_wood"}, {["x"] = 1, ["y"] = 3, ["param1"] = 14, ["z"] = 24, ["name"] = "mobs:fence_wood"}, {["x"] = 1, ["y"] = 3, ["param1"] = 14, ["z"] = 25, ["name"] = "mobs:fence_wood"}, {["x"] = 1, ["y"] = 3, ["param1"] = 14, ["z"] = 26, ["name"] = "mobs:fence_wood"}, {["x"] = 1, ["y"] = 3, ["param1"] = 14, ["z"] = 27, ["name"] = "mobs:fence_wood"}, {["x"] = 1, ["y"] = 5, ["param1"] = 14, ["z"] = 19, ["name"] = "butterflies:butterfly_violet"}, {["x"] = 2, ["y"] = 0, ["z"] = 0, ["name"] = "default:stone"}, {["x"] = 2, ["y"] = 0, ["z"] = 1, ["name"] = "default:stone"}, {["x"] = 2, ["y"] = 0, ["z"] = 2, ["name"] = "default:stone"}, {["x"] = 2, ["y"] = 0, ["z"] = 3, ["name"] = "default:stone"}, {["x"] = 2, ["y"] = 0, ["z"] = 4, ["name"] = "default:stone"}, {["x"] = 2, ["y"] = 0, ["z"] = 5, ["name"] = "default:stone"}, {["x"] = 2, ["y"] = 0, ["z"] = 6, ["name"] = "default:stone"}, {["x"] = 2, ["y"] = 0, ["z"] = 7, ["name"] = "default:stone"}, {["x"] = 2, ["y"] = 0, ["z"] = 8, ["name"] = "default:stone"}, {["x"] = 2, ["y"] = 0, ["z"] = 9, ["name"] = "default:stone"}, {["x"] = 2, ["y"] = 0, ["z"] = 10, ["name"] = "default:stone"}, {["x"] = 2, ["y"] = 0, ["z"] = 11, ["name"] = "default:stone"}, {["x"] = 2, ["y"] = 0, ["z"] = 12, ["name"] = "default:stone"}, {["x"] = 2, ["y"] = 0, ["z"] = 13, ["name"] = "default:stone"}, {["x"] = 2, ["y"] = 0, ["z"] = 14, ["name"] = "default:stone"}, {["x"] = 2, ["y"] = 0, ["z"] = 15, ["name"] = "default:stone"}, {["x"] = 2, ["y"] = 0, ["param1"] = 4, ["z"] = 16, ["name"] = "default:stone"}, {["x"] = 2, ["y"] = 0, ["param1"] = 4, ["z"] = 17, ["name"] = "default:stone"}, {["x"] = 2, ["y"] = 0, ["param1"] = 4, ["z"] = 18, ["name"] = "default:stone"}, {["x"] = 2, ["y"] = 0, ["param1"] = 4, ["z"] = 19, ["name"] = "default:stone"}, {["x"] = 2, ["y"] = 0, ["param1"] = 4, ["z"] = 20, ["name"] = "default:stone"}, {["x"] = 2, ["y"] = 0, ["param1"] = 4, ["z"] = 21, ["name"] = "default:stone"}, {["x"] = 2, ["y"] = 0, ["param1"] = 4, ["z"] = 22, ["name"] = "default:stone"}, {["x"] = 2, ["y"] = 0, ["param1"] = 4, ["z"] = 23, ["name"] = "default:stone"}, {["x"] = 2, ["y"] = 0, ["param1"] = 4, ["z"] = 24, ["name"] = "default:stone"}, {["x"] = 2, ["y"] = 0, ["param1"] = 4, ["z"] = 25, ["name"] = "default:stone"}, {["x"] = 2, ["y"] = 0, ["param1"] = 4, ["z"] = 26, ["name"] = "default:stone"}, {["x"] = 2, ["y"] = 0, ["param1"] = 4, ["z"] = 27, ["name"] = "default:stone"}, {["x"] = 2, ["y"] = 0, ["param1"] = 4, ["z"] = 28, ["name"] = "default:stone"}, {["x"] = 2, ["y"] = 0, ["param1"] = 4, ["z"] = 29, ["name"] = "default:stone"}, {["x"] = 2, ["y"] = 0, ["param1"] = 4, ["z"] = 30, ["name"] = "default:stone"}, {["x"] = 2, ["y"] = 0, ["param1"] = 4, ["z"] = 31, ["name"] = "default:stone"}, {["x"] = 2, ["y"] = 0, ["z"] = 32, ["name"] = "default:stone"}, {["x"] = 2, ["y"] = 0, ["z"] = 33, ["name"] = "default:stone"}, {["x"] = 2, ["y"] = 0, ["z"] = 34, ["name"] = "default:stone"}, {["x"] = 2, ["y"] = 0, ["z"] = 35, ["name"] = "default:stone"}, {["x"] = 2, ["y"] = 1, ["z"] = 0, ["name"] = "default:dirt_with_grass"}, {["x"] = 2, ["y"] = 1, ["z"] = 1, ["name"] = "default:dirt_with_grass"}, {["x"] = 2, ["y"] = 1, ["z"] = 2, ["name"] = "default:dirt_with_grass"}, {["x"] = 2, ["y"] = 1, ["z"] = 3, ["name"] = "default:dirt_with_grass"}, {["x"] = 2, ["y"] = 1, ["z"] = 4, ["name"] = "default:dirt_with_grass"}, {["x"] = 2, ["y"] = 1, ["z"] = 5, ["name"] = "default:dirt_with_grass"}, {["x"] = 2, ["y"] = 1, ["z"] = 6, ["name"] = "default:dirt_with_grass"}, {["x"] = 2, ["y"] = 1, ["z"] = 7, ["name"] = "default:dirt_with_grass"}, {["x"] = 2, ["y"] = 1, ["z"] = 8, ["name"] = "default:dirt_with_grass"}, {["x"] = 2, ["y"] = 1, ["z"] = 9, ["name"] = "default:dirt_with_grass"}, {["x"] = 2, ["y"] = 1, ["z"] = 10, ["name"] = "default:dirt_with_grass"}, {["x"] = 2, ["y"] = 1, ["z"] = 11, ["name"] = "default:stone"}, {["x"] = 2, ["y"] = 1, ["z"] = 12, ["name"] = "default:stone"}, {["x"] = 2, ["y"] = 1, ["z"] = 13, ["name"] = "default:stone"}, {["x"] = 2, ["y"] = 1, ["z"] = 14, ["name"] = "default:stone"}, {["x"] = 2, ["y"] = 1, ["z"] = 15, ["name"] = "default:stone"}, {["x"] = 2, ["y"] = 1, ["param1"] = 69, ["z"] = 16, ["name"] = "default:stone_with_coal"}, {["x"] = 2, ["y"] = 1, ["param1"] = 4, ["z"] = 17, ["name"] = "default:stone"}, {["x"] = 2, ["y"] = 1, ["param1"] = 4, ["z"] = 18, ["name"] = "default:stone"}, {["x"] = 2, ["y"] = 1, ["param1"] = 4, ["z"] = 19, ["name"] = "default:stone"}, {["x"] = 2, ["y"] = 1, ["param1"] = 4, ["z"] = 20, ["name"] = "default:stone"}, {["x"] = 2, ["y"] = 1, ["param1"] = 4, ["z"] = 21, ["name"] = "default:stone"}, {["x"] = 2, ["y"] = 1, ["param1"] = 4, ["z"] = 22, ["name"] = "default:stone"}, {["x"] = 2, ["y"] = 1, ["param1"] = 4, ["z"] = 23, ["name"] = "default:stone"}, {["x"] = 2, ["y"] = 1, ["param1"] = 4, ["z"] = 24, ["name"] = "default:stone"}, {["x"] = 2, ["y"] = 1, ["param1"] = 4, ["z"] = 25, ["name"] = "default:stone"}, {["x"] = 2, ["y"] = 1, ["param1"] = 4, ["z"] = 26, ["name"] = "default:stone"}, {["x"] = 2, ["y"] = 1, ["param1"] = 4, ["z"] = 27, ["name"] = "default:stone"}, {["x"] = 2, ["y"] = 1, ["param1"] = 4, ["z"] = 28, ["name"] = "default:stone"}, {["x"] = 2, ["y"] = 1, ["param1"] = 26, ["z"] = 29, ["name"] = "default:dirt_with_grass"}, {["x"] = 2, ["y"] = 1, ["param1"] = 26, ["z"] = 30, ["name"] = "default:dirt_with_grass"}, {["x"] = 2, ["y"] = 1, ["param1"] = 26, ["z"] = 31, ["name"] = "default:dirt_with_grass"}, {["x"] = 2, ["y"] = 1, ["z"] = 32, ["name"] = "default:dirt_with_grass"}, {["x"] = 2, ["y"] = 1, ["z"] = 33, ["name"] = "default:dirt_with_grass"}, {["x"] = 2, ["y"] = 1, ["z"] = 34, ["name"] = "default:dirt_with_grass"}, {["x"] = 2, ["y"] = 1, ["z"] = 35, ["name"] = "default:dirt_with_grass"}, {["x"] = 2, ["y"] = 2, ["param1"] = 15, ["z"] = 6, ["name"] = "flowers:viola"}, {["x"] = 2, ["y"] = 2, ["param1"] = 15, ["z"] = 9, ["name"] = "bakedclay:thistle"}, {["x"] = 2, ["y"] = 2, ["param1"] = 15, ["z"] = 10, ["name"] = "flowers:viola"}, {["x"] = 2, ["y"] = 2, ["z"] = 11, ["name"] = "default:dirt_with_grass"}, {["x"] = 2, ["y"] = 2, ["z"] = 12, ["name"] = "default:dirt_with_grass"}, {["x"] = 2, ["y"] = 2, ["z"] = 13, ["name"] = "default:dirt_with_grass"}, {["x"] = 2, ["y"] = 2, ["z"] = 14, ["name"] = "default:dirt_with_grass"}, {["x"] = 2, ["y"] = 2, ["z"] = 15, ["name"] = "default:dirt_with_grass"}, {["x"] = 2, ["y"] = 2, ["param1"] = 26, ["z"] = 16, ["name"] = "default:dirt_with_grass"}, {["x"] = 2, ["y"] = 2, ["param1"] = 26, ["z"] = 17, ["name"] = "default:dirt_with_grass"}, {["x"] = 2, ["y"] = 2, ["param1"] = 26, ["z"] = 18, ["name"] = "default:dirt_with_grass"}, {["x"] = 2, ["y"] = 2, ["param1"] = 26, ["z"] = 19, ["name"] = "default:dirt_with_grass"}, {["x"] = 2, ["y"] = 2, ["param1"] = 26, ["z"] = 20, ["name"] = "default:dirt_with_grass"}, {["x"] = 2, ["y"] = 2, ["param1"] = 26, ["z"] = 21, ["name"] = "default:dirt_with_grass"}, {["x"] = 2, ["y"] = 2, ["param1"] = 26, ["z"] = 22, ["name"] = "default:dirt_with_grass"}, {["x"] = 2, ["y"] = 2, ["param1"] = 26, ["z"] = 23, ["name"] = "default:dirt_with_grass"}, {["x"] = 2, ["y"] = 2, ["param1"] = 26, ["z"] = 24, ["name"] = "default:dirt_with_grass"}, {["x"] = 2, ["y"] = 2, ["param1"] = 26, ["z"] = 25, ["name"] = "default:dirt_with_grass"}, {["x"] = 2, ["y"] = 2, ["param1"] = 26, ["z"] = 26, ["name"] = "default:dirt_with_grass"}, {["x"] = 2, ["y"] = 2, ["param1"] = 26, ["z"] = 27, ["name"] = "default:dirt_with_grass"}, {["x"] = 2, ["y"] = 2, ["param1"] = 26, ["z"] = 28, ["name"] = "default:dirt_with_grass"}, {["x"] = 2, ["y"] = 2, ["param1"] = 14, ["z"] = 31, ["name"] = "flowers:viola"}, {["x"] = 2, ["y"] = 3, ["param1"] = 15, ["z"] = 11, ["name"] = "mobs:fence_wood"}, {["x"] = 2, ["y"] = 3, ["param1"] = 15, ["z"] = 12, ["name"] = "mobs:fence_wood"}, {["x"] = 2, ["y"] = 3, ["param1"] = 15, ["z"] = 13, ["name"] = "mobs:fence_wood"}, {["x"] = 2, ["y"] = 3, ["param1"] = 15, ["z"] = 14, ["name"] = "mobs:fence_wood"}, {["x"] = 2, ["y"] = 3, ["param1"] = 15, ["z"] = 27, ["name"] = "mobs:fence_wood"}, {["x"] = 2, ["y"] = 3, ["param1"] = 15, ["z"] = 28, ["name"] = "mobs:fence_wood"}, {["x"] = 3, ["y"] = 0, ["z"] = 0, ["name"] = "default:stone"}, {["x"] = 3, ["y"] = 0, ["z"] = 1, ["name"] = "default:stone"}, {["x"] = 3, ["y"] = 0, ["z"] = 2, ["name"] = "default:stone"}, {["x"] = 3, ["y"] = 0, ["z"] = 3, ["name"] = "default:stone"}, {["x"] = 3, ["y"] = 0, ["z"] = 4, ["name"] = "default:stone"}, {["x"] = 3, ["y"] = 0, ["z"] = 5, ["name"] = "default:stone"}, {["x"] = 3, ["y"] = 0, ["z"] = 6, ["name"] = "default:stone"}, {["x"] = 3, ["y"] = 0, ["z"] = 7, ["name"] = "default:stone"}, {["x"] = 3, ["y"] = 0, ["z"] = 8, ["name"] = "default:stone"}, {["x"] = 3, ["y"] = 0, ["z"] = 9, ["name"] = "default:stone"}, {["x"] = 3, ["y"] = 0, ["z"] = 10, ["name"] = "default:stone"}, {["x"] = 3, ["y"] = 0, ["z"] = 11, ["name"] = "default:stone"}, {["x"] = 3, ["y"] = 0, ["z"] = 12, ["name"] = "default:stone"}, {["x"] = 3, ["y"] = 0, ["z"] = 13, ["name"] = "default:stone"}, {["x"] = 3, ["y"] = 0, ["z"] = 14, ["name"] = "default:stone"}, {["x"] = 3, ["y"] = 0, ["z"] = 15, ["name"] = "default:stone"}, {["x"] = 3, ["y"] = 0, ["param1"] = 4, ["z"] = 16, ["name"] = "default:stone"}, {["x"] = 3, ["y"] = 0, ["param1"] = 4, ["z"] = 17, ["name"] = "default:stone"}, {["x"] = 3, ["y"] = 0, ["param1"] = 4, ["z"] = 18, ["name"] = "default:stone"}, {["x"] = 3, ["y"] = 0, ["param1"] = 4, ["z"] = 19, ["name"] = "default:stone"}, {["x"] = 3, ["y"] = 0, ["param1"] = 4, ["z"] = 20, ["name"] = "default:stone"}, {["x"] = 3, ["y"] = 0, ["param1"] = 4, ["z"] = 21, ["name"] = "default:stone"}, {["x"] = 3, ["y"] = 0, ["param1"] = 4, ["z"] = 22, ["name"] = "default:stone"}, {["x"] = 3, ["y"] = 0, ["param1"] = 4, ["z"] = 23, ["name"] = "default:stone"}, {["x"] = 3, ["y"] = 0, ["param1"] = 4, ["z"] = 24, ["name"] = "default:stone"}, {["x"] = 3, ["y"] = 0, ["param1"] = 4, ["z"] = 25, ["name"] = "default:stone"}, {["x"] = 3, ["y"] = 0, ["param1"] = 4, ["z"] = 26, ["name"] = "default:stone"}, {["x"] = 3, ["y"] = 0, ["param1"] = 4, ["z"] = 27, ["name"] = "default:stone"}, {["x"] = 3, ["y"] = 0, ["param1"] = 4, ["z"] = 28, ["name"] = "default:stone"}, {["x"] = 3, ["y"] = 0, ["param1"] = 4, ["z"] = 29, ["name"] = "default:stone"}, {["x"] = 3, ["y"] = 0, ["param1"] = 4, ["z"] = 30, ["name"] = "default:stone"}, {["x"] = 3, ["y"] = 0, ["param1"] = 4, ["z"] = 31, ["name"] = "default:stone"}, {["x"] = 3, ["y"] = 0, ["z"] = 32, ["name"] = "default:stone"}, {["x"] = 3, ["y"] = 0, ["z"] = 33, ["name"] = "default:stone"}, {["x"] = 3, ["y"] = 0, ["z"] = 34, ["name"] = "default:stone"}, {["x"] = 3, ["y"] = 0, ["z"] = 35, ["name"] = "default:stone"}, {["x"] = 3, ["y"] = 1, ["z"] = 0, ["name"] = "default:dirt_with_grass"}, {["x"] = 3, ["y"] = 1, ["z"] = 1, ["name"] = "default:dirt_with_grass"}, {["x"] = 3, ["y"] = 1, ["z"] = 2, ["name"] = "default:dirt_with_grass"}, {["x"] = 3, ["y"] = 1, ["z"] = 3, ["name"] = "default:dirt_with_grass"}, {["x"] = 3, ["y"] = 1, ["z"] = 4, ["name"] = "default:dirt_with_grass"}, {["x"] = 3, ["y"] = 1, ["z"] = 5, ["name"] = "default:dirt_with_grass"}, {["x"] = 3, ["y"] = 1, ["z"] = 6, ["name"] = "default:dirt_with_grass"}, {["x"] = 3, ["y"] = 1, ["z"] = 7, ["name"] = "default:dirt_with_grass"}, {["x"] = 3, ["y"] = 1, ["z"] = 8, ["name"] = "default:dirt_with_grass"}, {["x"] = 3, ["y"] = 1, ["z"] = 9, ["name"] = "default:stone"}, {["x"] = 3, ["y"] = 1, ["z"] = 10, ["name"] = "default:stone"}, {["x"] = 3, ["y"] = 1, ["z"] = 11, ["name"] = "default:stone"}, {["x"] = 3, ["y"] = 1, ["z"] = 12, ["name"] = "default:stone"}, {["x"] = 3, ["y"] = 1, ["z"] = 13, ["name"] = "default:stone"}, {["x"] = 3, ["y"] = 1, ["z"] = 14, ["name"] = "default:stone"}, {["x"] = 3, ["y"] = 1, ["z"] = 15, ["name"] = "default:stone"}, {["x"] = 3, ["y"] = 1, ["param1"] = 4, ["z"] = 16, ["name"] = "default:stone"}, {["x"] = 3, ["y"] = 1, ["param1"] = 4, ["z"] = 17, ["name"] = "default:stone"}, {["x"] = 3, ["y"] = 1, ["param1"] = 4, ["z"] = 18, ["name"] = "default:stone"}, {["x"] = 3, ["y"] = 1, ["param1"] = 4, ["z"] = 19, ["name"] = "default:stone"}, {["x"] = 3, ["y"] = 1, ["param1"] = 4, ["z"] = 20, ["name"] = "default:stone"}, {["x"] = 3, ["y"] = 1, ["param1"] = 4, ["z"] = 21, ["name"] = "default:stone"}, {["x"] = 3, ["y"] = 1, ["param1"] = 4, ["z"] = 22, ["name"] = "default:stone"}, {["x"] = 3, ["y"] = 1, ["param1"] = 4, ["z"] = 23, ["name"] = "default:stone"}, {["x"] = 3, ["y"] = 1, ["param1"] = 4, ["z"] = 24, ["name"] = "default:stone"}, {["x"] = 3, ["y"] = 1, ["param1"] = 4, ["z"] = 25, ["name"] = "default:stone"}, {["x"] = 3, ["y"] = 1, ["param1"] = 4, ["z"] = 26, ["name"] = "default:stone"}, {["x"] = 3, ["y"] = 1, ["param1"] = 4, ["z"] = 27, ["name"] = "default:stone"}, {["x"] = 3, ["y"] = 1, ["param1"] = 4, ["z"] = 28, ["name"] = "default:stone"}, {["x"] = 3, ["y"] = 1, ["param1"] = 4, ["z"] = 29, ["name"] = "default:stone"}, {["x"] = 3, ["y"] = 1, ["param1"] = 26, ["z"] = 30, ["name"] = "default:dirt_with_grass"}, {["x"] = 3, ["y"] = 1, ["param1"] = 26, ["z"] = 31, ["name"] = "default:dirt_with_grass"}, {["x"] = 3, ["y"] = 1, ["z"] = 32, ["name"] = "default:dirt_with_grass"}, {["x"] = 3, ["y"] = 1, ["z"] = 33, ["name"] = "default:dirt_with_grass"}, {["x"] = 3, ["y"] = 1, ["z"] = 34, ["name"] = "default:dirt_with_grass"}, {["x"] = 3, ["y"] = 1, ["z"] = 35, ["name"] = "default:dirt_with_grass"}, {["x"] = 3, ["y"] = 2, ["z"] = 9, ["name"] = "default:dirt_with_grass"}, {["x"] = 3, ["y"] = 2, ["z"] = 10, ["name"] = "default:dirt_with_grass"}, {["x"] = 3, ["y"] = 2, ["z"] = 11, ["name"] = "default:dirt_with_grass"}, {["x"] = 3, ["y"] = 2, ["z"] = 12, ["name"] = "default:dirt_with_grass"}, {["x"] = 3, ["y"] = 2, ["z"] = 13, ["name"] = "default:dirt_with_grass"}, {["x"] = 3, ["y"] = 2, ["z"] = 14, ["name"] = "default:dirt_with_grass"}, {["x"] = 3, ["y"] = 2, ["z"] = 15, ["name"] = "default:dirt_with_grass"}, {["x"] = 3, ["y"] = 2, ["param1"] = 26, ["z"] = 16, ["name"] = "default:dirt_with_grass"}, {["x"] = 3, ["y"] = 2, ["param1"] = 26, ["z"] = 17, ["name"] = "default:dirt_with_grass"}, {["x"] = 3, ["y"] = 2, ["param1"] = 26, ["z"] = 18, ["name"] = "default:dirt_with_grass"}, {["x"] = 3, ["y"] = 2, ["param1"] = 26, ["z"] = 19, ["name"] = "default:dirt_with_grass"}, {["x"] = 3, ["y"] = 2, ["param1"] = 26, ["z"] = 20, ["name"] = "default:dirt_with_grass"}, {["x"] = 3, ["y"] = 2, ["param1"] = 26, ["z"] = 21, ["name"] = "default:dirt_with_grass"}, {["x"] = 3, ["y"] = 2, ["param1"] = 26, ["z"] = 22, ["name"] = "default:dirt_with_grass"}, {["x"] = 3, ["y"] = 2, ["param1"] = 26, ["z"] = 23, ["name"] = "default:dirt_with_grass"}, {["x"] = 3, ["y"] = 2, ["param1"] = 26, ["z"] = 24, ["name"] = "default:dirt_with_grass"}, {["x"] = 3, ["y"] = 2, ["param1"] = 26, ["z"] = 25, ["name"] = "default:dirt_with_grass"}, {["x"] = 3, ["y"] = 2, ["param1"] = 26, ["z"] = 26, ["name"] = "default:dirt_with_grass"}, {["x"] = 3, ["y"] = 2, ["z"] = 27, ["name"] = "default:dirt_with_grass"}, {["x"] = 3, ["y"] = 2, ["param1"] = 26, ["z"] = 28, ["name"] = "default:dirt_with_grass"}, {["x"] = 3, ["y"] = 2, ["param1"] = 26, ["z"] = 29, ["name"] = "default:dirt_with_grass"}, {["x"] = 3, ["y"] = 2, ["param1"] = 15, ["z"] = 35, ["name"] = "default:grass_1"}, {["x"] = 3, ["y"] = 3, ["param1"] = 14, ["z"] = 9, ["name"] = "mobs:fence_wood"}, {["x"] = 3, ["y"] = 3, ["param1"] = 14, ["z"] = 10, ["name"] = "mobs:fence_wood"}, {["x"] = 3, ["y"] = 3, ["param1"] = 14, ["z"] = 11, ["name"] = "mobs:fence_wood"}, {["x"] = 3, ["y"] = 3, ["param1"] = 15, ["z"] = 28, ["name"] = "mobs:fence_wood"}, {["x"] = 3, ["y"] = 3, ["param1"] = 15, ["z"] = 29, ["name"] = "mobs:fence_wood"}, {["x"] = 3, ["param2"] = 19, ["y"] = 9, ["param1"] = 14, ["z"] = 9, ["name"] = "bakedclay:stair_baked_clay_white"}, {["x"] = 3, ["param2"] = 19, ["y"] = 9, ["param1"] = 14, ["z"] = 10, ["name"] = "bakedclay:stair_baked_clay_white"}, {["x"] = 3, ["param2"] = 19, ["y"] = 9, ["param1"] = 14, ["z"] = 11, ["name"] = "bakedclay:stair_baked_clay_white"}, {["x"] = 3, ["param2"] = 19, ["y"] = 9, ["param1"] = 14, ["z"] = 12, ["name"] = "bakedclay:stair_baked_clay_white"}, {["x"] = 3, ["param2"] = 19, ["y"] = 9, ["param1"] = 14, ["z"] = 13, ["name"] = "bakedclay:stair_baked_clay_white"}, {["x"] = 3, ["param2"] = 19, ["y"] = 9, ["param1"] = 14, ["z"] = 14, ["name"] = "bakedclay:stair_baked_clay_white"}, {["x"] = 3, ["param2"] = 19, ["y"] = 9, ["param1"] = 13, ["z"] = 15, ["name"] = "bakedclay:stair_baked_clay_white"}, {["x"] = 3, ["param2"] = 19, ["y"] = 9, ["param1"] = 14, ["z"] = 16, ["name"] = "bakedclay:stair_baked_clay_white"}, {["x"] = 3, ["param2"] = 19, ["y"] = 9, ["param1"] = 14, ["z"] = 17, ["name"] = "bakedclay:stair_baked_clay_white"}, {["x"] = 3, ["param2"] = 19, ["y"] = 9, ["param1"] = 14, ["z"] = 18, ["name"] = "bakedclay:stair_baked_clay_white"}, {["x"] = 3, ["param2"] = 19, ["y"] = 9, ["param1"] = 14, ["z"] = 19, ["name"] = "bakedclay:stair_baked_clay_white"}, {["x"] = 3, ["param2"] = 19, ["y"] = 9, ["param1"] = 14, ["z"] = 20, ["name"] = "bakedclay:stair_baked_clay_white"}, {["x"] = 3, ["param2"] = 19, ["y"] = 9, ["param1"] = 14, ["z"] = 21, ["name"] = "bakedclay:stair_baked_clay_white"}, {["x"] = 3, ["param2"] = 19, ["y"] = 9, ["param1"] = 14, ["z"] = 22, ["name"] = "bakedclay:stair_baked_clay_white"}, {["x"] = 3, ["param2"] = 19, ["y"] = 9, ["param1"] = 14, ["z"] = 23, ["name"] = "bakedclay:stair_baked_clay_white"}, {["x"] = 3, ["param2"] = 19, ["y"] = 9, ["param1"] = 14, ["z"] = 24, ["name"] = "bakedclay:stair_baked_clay_white"}, {["x"] = 3, ["param2"] = 19, ["y"] = 9, ["param1"] = 14, ["z"] = 25, ["name"] = "bakedclay:stair_baked_clay_white"}, {["x"] = 3, ["param2"] = 19, ["y"] = 9, ["param1"] = 14, ["z"] = 26, ["name"] = "bakedclay:stair_baked_clay_white"}, {["x"] = 3, ["param2"] = 2, ["y"] = 9, ["param1"] = 14, ["z"] = 27, ["name"] = "bakedclay:stair_baked_clay_white_outer"}, {["x"] = 4, ["y"] = 0, ["z"] = 0, ["name"] = "default:stone"}, {["x"] = 4, ["y"] = 0, ["z"] = 1, ["name"] = "default:stone"}, {["x"] = 4, ["y"] = 0, ["z"] = 2, ["name"] = "default:stone"}, {["x"] = 4, ["y"] = 0, ["z"] = 3, ["name"] = "default:stone"}, {["x"] = 4, ["y"] = 0, ["z"] = 4, ["name"] = "default:stone"}, {["x"] = 4, ["y"] = 0, ["z"] = 5, ["name"] = "default:stone"}, {["x"] = 4, ["y"] = 0, ["z"] = 6, ["name"] = "default:stone_with_coal"}, {["x"] = 4, ["y"] = 0, ["z"] = 7, ["name"] = "default:stone"}, {["x"] = 4, ["y"] = 0, ["z"] = 8, ["name"] = "default:stone"}, {["x"] = 4, ["y"] = 0, ["z"] = 9, ["name"] = "default:stone"}, {["x"] = 4, ["y"] = 0, ["z"] = 10, ["name"] = "default:stone"}, {["x"] = 4, ["y"] = 0, ["z"] = 11, ["name"] = "default:stone"}, {["x"] = 4, ["y"] = 0, ["z"] = 12, ["name"] = "default:stone"}, {["x"] = 4, ["y"] = 0, ["z"] = 13, ["name"] = "default:stone_with_coal"}, {["x"] = 4, ["y"] = 0, ["z"] = 14, ["name"] = "default:stone"}, {["x"] = 4, ["y"] = 0, ["z"] = 15, ["name"] = "default:stone"}, {["x"] = 4, ["y"] = 0, ["param1"] = 4, ["z"] = 16, ["name"] = "default:stone"}, {["x"] = 4, ["y"] = 0, ["param1"] = 4, ["z"] = 17, ["name"] = "default:stone"}, {["x"] = 4, ["y"] = 0, ["param1"] = 4, ["z"] = 18, ["name"] = "default:stone"}, {["x"] = 4, ["y"] = 0, ["param1"] = 4, ["z"] = 19, ["name"] = "default:stone"}, {["x"] = 4, ["y"] = 0, ["param1"] = 4, ["z"] = 20, ["name"] = "default:stone"}, {["x"] = 4, ["y"] = 0, ["param1"] = 4, ["z"] = 21, ["name"] = "default:stone"}, {["x"] = 4, ["y"] = 0, ["param1"] = 4, ["z"] = 22, ["name"] = "default:stone"}, {["x"] = 4, ["y"] = 0, ["param1"] = 4, ["z"] = 23, ["name"] = "default:stone"}, {["x"] = 4, ["y"] = 0, ["param1"] = 4, ["z"] = 24, ["name"] = "default:stone"}, {["x"] = 4, ["y"] = 0, ["param1"] = 4, ["z"] = 25, ["name"] = "default:stone"}, {["x"] = 4, ["y"] = 0, ["param1"] = 4, ["z"] = 26, ["name"] = "default:stone"}, {["x"] = 4, ["y"] = 0, ["param1"] = 4, ["z"] = 27, ["name"] = "default:stone"}, {["x"] = 4, ["y"] = 0, ["param1"] = 4, ["z"] = 28, ["name"] = "default:stone"}, {["x"] = 4, ["y"] = 0, ["param1"] = 4, ["z"] = 29, ["name"] = "default:stone"}, {["x"] = 4, ["y"] = 0, ["param1"] = 4, ["z"] = 30, ["name"] = "default:stone"}, {["x"] = 4, ["y"] = 0, ["param1"] = 4, ["z"] = 31, ["name"] = "default:stone"}, {["x"] = 4, ["y"] = 0, ["z"] = 32, ["name"] = "default:stone"}, {["x"] = 4, ["y"] = 0, ["z"] = 33, ["name"] = "default:stone"}, {["x"] = 4, ["y"] = 0, ["z"] = 34, ["name"] = "default:stone"}, {["x"] = 4, ["y"] = 0, ["z"] = 35, ["name"] = "default:stone"}, {["x"] = 4, ["y"] = 1, ["z"] = 0, ["name"] = "default:dirt_with_grass"}, {["x"] = 4, ["y"] = 1, ["z"] = 1, ["name"] = "default:dirt_with_grass"}, {["x"] = 4, ["y"] = 1, ["z"] = 2, ["name"] = "default:dirt_with_grass"}, {["x"] = 4, ["y"] = 1, ["z"] = 3, ["name"] = "default:dirt_with_grass"}, {["x"] = 4, ["y"] = 1, ["z"] = 4, ["name"] = "default:dirt_with_grass"}, {["x"] = 4, ["y"] = 1, ["z"] = 5, ["name"] = "default:dirt_with_grass"}, {["x"] = 4, ["y"] = 1, ["z"] = 6, ["name"] = "default:dirt_with_grass"}, {["x"] = 4, ["y"] = 1, ["z"] = 7, ["name"] = "default:dirt_with_grass"}, {["x"] = 4, ["y"] = 1, ["z"] = 8, ["name"] = "default:stone"}, {["x"] = 4, ["y"] = 1, ["z"] = 9, ["name"] = "default:stone"}, {["x"] = 4, ["y"] = 1, ["z"] = 10, ["name"] = "default:stone"}, {["x"] = 4, ["y"] = 1, ["z"] = 11, ["name"] = "default:stone"}, {["x"] = 4, ["y"] = 1, ["z"] = 12, ["name"] = "default:stone"}, {["x"] = 4, ["y"] = 1, ["z"] = 13, ["name"] = "default:stone"}, {["x"] = 4, ["y"] = 1, ["z"] = 14, ["name"] = "default:stone"}, {["x"] = 4, ["y"] = 1, ["z"] = 15, ["name"] = "default:stone"}, {["x"] = 4, ["y"] = 1, ["param1"] = 4, ["z"] = 16, ["name"] = "default:stone"}, {["x"] = 4, ["y"] = 1, ["param1"] = 4, ["z"] = 17, ["name"] = "default:stone"}, {["x"] = 4, ["y"] = 1, ["param1"] = 4, ["z"] = 18, ["name"] = "default:stone"}, {["x"] = 4, ["y"] = 1, ["param1"] = 4, ["z"] = 19, ["name"] = "default:stone"}, {["x"] = 4, ["y"] = 1, ["param1"] = 4, ["z"] = 20, ["name"] = "default:stone"}, {["x"] = 4, ["y"] = 1, ["param1"] = 4, ["z"] = 21, ["name"] = "default:stone"}, {["x"] = 4, ["y"] = 1, ["param1"] = 4, ["z"] = 22, ["name"] = "default:stone"}, {["x"] = 4, ["y"] = 1, ["param1"] = 4, ["z"] = 23, ["name"] = "default:stone"}, {["x"] = 4, ["y"] = 1, ["param1"] = 4, ["z"] = 24, ["name"] = "default:stone"}, {["x"] = 4, ["y"] = 1, ["param1"] = 4, ["z"] = 25, ["name"] = "default:stone"}, {["x"] = 4, ["y"] = 1, ["param1"] = 4, ["z"] = 26, ["name"] = "default:stone"}, {["x"] = 4, ["y"] = 1, ["param1"] = 4, ["z"] = 27, ["name"] = "default:stone"}, {["x"] = 4, ["y"] = 1, ["param1"] = 4, ["z"] = 28, ["name"] = "default:stone"}, {["x"] = 4, ["y"] = 1, ["param1"] = 4, ["z"] = 29, ["name"] = "default:stone"}, {["x"] = 4, ["y"] = 1, ["param1"] = 4, ["z"] = 30, ["name"] = "default:stone"}, {["x"] = 4, ["y"] = 1, ["z"] = 31, ["name"] = "default:dirt_with_grass"}, {["x"] = 4, ["y"] = 1, ["z"] = 32, ["name"] = "default:dirt_with_grass"}, {["x"] = 4, ["y"] = 1, ["z"] = 33, ["name"] = "default:dirt_with_grass"}, {["x"] = 4, ["y"] = 1, ["z"] = 34, ["name"] = "default:dirt_with_grass"}, {["x"] = 4, ["y"] = 1, ["z"] = 35, ["name"] = "default:dirt_with_grass"}, {["x"] = 4, ["y"] = 2, ["param1"] = 15, ["z"] = 1, ["name"] = "flowers:viola"}, {["x"] = 4, ["y"] = 2, ["param1"] = 15, ["z"] = 4, ["name"] = "flowers:dandelion_white"}, {["x"] = 4, ["y"] = 2, ["z"] = 8, ["name"] = "default:dirt_with_grass"}, {["x"] = 4, ["y"] = 2, ["z"] = 9, ["name"] = "default:dirt_with_grass"}, {["x"] = 4, ["y"] = 2, ["z"] = 10, ["name"] = "default:dirt_with_grass"}, {["x"] = 4, ["y"] = 2, ["z"] = 11, ["name"] = "default:dirt_with_grass"}, {["x"] = 4, ["y"] = 2, ["z"] = 12, ["name"] = "default:dirt_with_grass"}, {["x"] = 4, ["y"] = 2, ["z"] = 13, ["name"] = "default:dirt_with_grass"}, {["x"] = 4, ["y"] = 2, ["z"] = 14, ["name"] = "default:dirt_with_grass"}, {["x"] = 4, ["y"] = 2, ["z"] = 15, ["name"] = "default:dirt_with_grass"}, {["x"] = 4, ["y"] = 2, ["param1"] = 26, ["z"] = 16, ["name"] = "default:dirt_with_grass"}, {["x"] = 4, ["y"] = 2, ["param1"] = 26, ["z"] = 17, ["name"] = "default:dirt_with_grass"}, {["x"] = 4, ["y"] = 2, ["param1"] = 26, ["z"] = 18, ["name"] = "default:dirt_with_grass"}, {["x"] = 4, ["y"] = 2, ["param1"] = 26, ["z"] = 19, ["name"] = "default:dirt_with_grass"}, {["x"] = 4, ["y"] = 2, ["z"] = 20, ["name"] = "default:dirt"}, {["x"] = 4, ["y"] = 2, ["param1"] = 26, ["z"] = 21, ["name"] = "default:dirt_with_grass"}, {["x"] = 4, ["y"] = 2, ["param1"] = 26, ["z"] = 22, ["name"] = "default:dirt_with_grass"}, {["x"] = 4, ["y"] = 2, ["param1"] = 26, ["z"] = 23, ["name"] = "default:dirt_with_grass"}, {["x"] = 4, ["y"] = 2, ["param1"] = 26, ["z"] = 24, ["name"] = "default:dirt_with_grass"}, {["x"] = 4, ["y"] = 2, ["param1"] = 26, ["z"] = 25, ["name"] = "default:dirt_with_grass"}, {["x"] = 4, ["y"] = 2, ["z"] = 26, ["name"] = "default:dirt_with_grass"}, {["x"] = 4, ["y"] = 2, ["param1"] = 26, ["z"] = 27, ["name"] = "default:dirt_with_grass"}, {["x"] = 4, ["y"] = 2, ["z"] = 28, ["name"] = "default:dirt_with_grass"}, {["x"] = 4, ["y"] = 2, ["param1"] = 26, ["z"] = 29, ["name"] = "default:dirt_with_grass"}, {["x"] = 4, ["y"] = 2, ["param1"] = 26, ["z"] = 30, ["name"] = "default:dirt_with_grass"}, {["x"] = 4, ["y"] = 3, ["param1"] = 15, ["z"] = 8, ["name"] = "mobs:fence_wood"}, {["x"] = 4, ["y"] = 3, ["param1"] = 14, ["z"] = 9, ["name"] = "mobs:fence_wood"}, {["x"] = 4, ["y"] = 3, ["param1"] = 13, ["z"] = 10, ["name"] = "default:blueberry_bush_leaves_with_berries"}, {["x"] = 4, ["y"] = 3, ["param1"] = 13, ["z"] = 11, ["name"] = "default:blueberry_bush_leaves_with_berries"}, {["x"] = 4, ["y"] = 3, ["param1"] = 13, ["z"] = 12, ["name"] = "default:blueberry_bush_leaves_with_berries"}, {["x"] = 4, ["y"] = 3, ["param1"] = 13, ["z"] = 13, ["name"] = "default:blueberry_bush_leaves_with_berries"}, {["x"] = 4, ["y"] = 3, ["param1"] = 13, ["z"] = 14, ["name"] = "default:blueberry_bush_leaves_with_berries"}, {["x"] = 4, ["y"] = 3, ["param1"] = 12, ["z"] = 15, ["name"] = "default:blueberry_bush_leaves_with_berries"}, {["x"] = 4, ["y"] = 3, ["param1"] = 12, ["z"] = 16, ["name"] = "default:blueberry_bush_leaves_with_berries"}, {["x"] = 4, ["y"] = 3, ["param1"] = 13, ["z"] = 17, ["name"] = "default:blueberry_bush_leaves_with_berries"}, {["x"] = 4, ["y"] = 3, ["param1"] = 13, ["z"] = 18, ["name"] = "default:blueberry_bush_leaves_with_berries"}, {["x"] = 4, ["y"] = 3, ["param1"] = 13, ["z"] = 19, ["name"] = "default:blueberry_bush_leaves_with_berries"}, {["x"] = 4, ["y"] = 3, ["param1"] = 13, ["z"] = 20, ["name"] = "default:blueberry_bush_leaves_with_berries"}, {["x"] = 4, ["y"] = 3, ["param1"] = 13, ["z"] = 21, ["name"] = "default:blueberry_bush_leaves_with_berries"}, {["x"] = 4, ["y"] = 3, ["param1"] = 13, ["z"] = 22, ["name"] = "default:blueberry_bush_leaves_with_berries"}, {["x"] = 4, ["y"] = 3, ["param1"] = 13, ["z"] = 23, ["name"] = "default:blueberry_bush_leaves_with_berries"}, {["x"] = 4, ["y"] = 3, ["param1"] = 13, ["z"] = 24, ["name"] = "default:blueberry_bush_leaves_with_berries"}, {["x"] = 4, ["y"] = 3, ["param1"] = 13, ["z"] = 25, ["name"] = "default:blueberry_bush_leaves_with_berries"}, {["x"] = 4, ["y"] = 3, ["param1"] = 13, ["z"] = 26, ["name"] = "default:blueberry_bush_leaves_with_berries"}, {["x"] = 4, ["y"] = 3, ["param1"] = 15, ["z"] = 29, ["name"] = "mobs:fence_wood"}, {["x"] = 4, ["y"] = 3, ["param1"] = 15, ["z"] = 30, ["name"] = "mobs:fence_wood"}, {["x"] = 4, ["y"] = 5, ["param1"] = 14, ["z"] = 23, ["name"] = "butterflies:butterfly_red"}, {["x"] = 4, ["param2"] = 2, ["y"] = 9, ["param1"] = 14, ["z"] = 27, ["name"] = "bakedclay:stair_baked_clay_white"}, {["x"] = 4, ["param2"] = 19, ["y"] = 10, ["param1"] = 14, ["z"] = 9, ["name"] = "bakedclay:stair_baked_clay_white"}, {["x"] = 4, ["param2"] = 19, ["y"] = 10, ["param1"] = 14, ["z"] = 10, ["name"] = "bakedclay:stair_baked_clay_white"}, {["x"] = 4, ["param2"] = 19, ["y"] = 10, ["param1"] = 14, ["z"] = 11, ["name"] = "bakedclay:stair_baked_clay_white"}, {["x"] = 4, ["param2"] = 19, ["y"] = 10, ["param1"] = 14, ["z"] = 12, ["name"] = "bakedclay:stair_baked_clay_white"}, {["x"] = 4, ["param2"] = 19, ["y"] = 10, ["param1"] = 14, ["z"] = 13, ["name"] = "bakedclay:stair_baked_clay_white"}, {["x"] = 4, ["param2"] = 19, ["y"] = 10, ["param1"] = 14, ["z"] = 14, ["name"] = "bakedclay:stair_baked_clay_white"}, {["x"] = 4, ["param2"] = 19, ["y"] = 10, ["param1"] = 13, ["z"] = 15, ["name"] = "bakedclay:stair_baked_clay_white"}, {["x"] = 4, ["param2"] = 19, ["y"] = 10, ["param1"] = 13, ["z"] = 16, ["name"] = "bakedclay:stair_baked_clay_white"}, {["x"] = 4, ["param2"] = 19, ["y"] = 10, ["param1"] = 14, ["z"] = 17, ["name"] = "bakedclay:stair_baked_clay_white"}, {["x"] = 4, ["param2"] = 19, ["y"] = 10, ["param1"] = 14, ["z"] = 18, ["name"] = "bakedclay:stair_baked_clay_white"}, {["x"] = 4, ["param2"] = 19, ["y"] = 10, ["param1"] = 14, ["z"] = 19, ["name"] = "bakedclay:stair_baked_clay_white"}, {["x"] = 4, ["param2"] = 19, ["y"] = 10, ["param1"] = 14, ["z"] = 20, ["name"] = "bakedclay:stair_baked_clay_white"}, {["x"] = 4, ["param2"] = 19, ["y"] = 10, ["param1"] = 14, ["z"] = 21, ["name"] = "bakedclay:stair_baked_clay_white"}, {["x"] = 4, ["param2"] = 19, ["y"] = 10, ["param1"] = 14, ["z"] = 22, ["name"] = "bakedclay:stair_baked_clay_white"}, {["x"] = 4, ["param2"] = 19, ["y"] = 10, ["param1"] = 14, ["z"] = 23, ["name"] = "bakedclay:stair_baked_clay_white"}, {["x"] = 4, ["param2"] = 19, ["y"] = 10, ["param1"] = 14, ["z"] = 24, ["name"] = "bakedclay:stair_baked_clay_white"}, {["x"] = 4, ["param2"] = 19, ["y"] = 10, ["param1"] = 14, ["z"] = 25, ["name"] = "bakedclay:stair_baked_clay_white"}, {["x"] = 4, ["param2"] = 2, ["y"] = 10, ["param1"] = 14, ["z"] = 26, ["name"] = "bakedclay:stair_baked_clay_white_outer"}, {["x"] = 4, ["param2"] = 19, ["y"] = 14, ["param1"] = 14, ["z"] = 13, ["name"] = "bakedclay:stair_baked_clay_white"}, {["x"] = 4, ["param2"] = 19, ["y"] = 14, ["param1"] = 14, ["z"] = 14, ["name"] = "bakedclay:stair_baked_clay_white"}, {["x"] = 4, ["param2"] = 19, ["y"] = 14, ["param1"] = 13, ["z"] = 15, ["name"] = "bakedclay:stair_baked_clay_white"}, {["x"] = 4, ["param2"] = 19, ["y"] = 14, ["param1"] = 13, ["z"] = 16, ["name"] = "bakedclay:stair_baked_clay_white"}, {["x"] = 4, ["param2"] = 1, ["y"] = 14, ["param1"] = 14, ["z"] = 17, ["name"] = "bakedclay:stair_baked_clay_white"}, {["x"] = 4, ["param2"] = 1, ["y"] = 14, ["param1"] = 14, ["z"] = 18, ["name"] = "bakedclay:stair_baked_clay_white"}, {["x"] = 4, ["param2"] = 1, ["y"] = 14, ["param1"] = 14, ["z"] = 19, ["name"] = "bakedclay:stair_baked_clay_white"}, {["x"] = 4, ["param2"] = 1, ["y"] = 14, ["param1"] = 14, ["z"] = 20, ["name"] = "bakedclay:stair_baked_clay_white"}, {["x"] = 4, ["param2"] = 1, ["y"] = 14, ["param1"] = 14, ["z"] = 21, ["name"] = "bakedclay:stair_baked_clay_white"}, {["x"] = 4, ["param2"] = 1, ["y"] = 14, ["param1"] = 14, ["z"] = 22, ["name"] = "bakedclay:stair_baked_clay_white"}, {["x"] = 4, ["param2"] = 1, ["y"] = 14, ["param1"] = 14, ["z"] = 23, ["name"] = "bakedclay:stair_baked_clay_white"}, {["x"] = 4, ["param2"] = 1, ["y"] = 14, ["param1"] = 14, ["z"] = 24, ["name"] = "bakedclay:stair_baked_clay_white"}, {["x"] = 4, ["param2"] = 1, ["y"] = 14, ["param1"] = 14, ["z"] = 25, ["name"] = "bakedclay:stair_baked_clay_white"}, {["x"] = 5, ["y"] = 0, ["z"] = 0, ["name"] = "default:stone"}, {["x"] = 5, ["y"] = 0, ["z"] = 1, ["name"] = "default:stone"}, {["x"] = 5, ["y"] = 0, ["z"] = 2, ["name"] = "default:stone"}, {["x"] = 5, ["y"] = 0, ["z"] = 3, ["name"] = "default:stone"}, {["x"] = 5, ["y"] = 0, ["z"] = 4, ["name"] = "default:stone"}, {["x"] = 5, ["y"] = 0, ["z"] = 5, ["name"] = "default:stone"}, {["x"] = 5, ["y"] = 0, ["z"] = 6, ["name"] = "default:stone_with_coal"}, {["x"] = 5, ["y"] = 0, ["z"] = 7, ["name"] = "default:stone"}, {["x"] = 5, ["y"] = 0, ["z"] = 8, ["name"] = "default:stone"}, {["x"] = 5, ["y"] = 0, ["z"] = 9, ["name"] = "default:stone"}, {["x"] = 5, ["y"] = 0, ["z"] = 10, ["name"] = "default:stone"}, {["x"] = 5, ["y"] = 0, ["z"] = 11, ["name"] = "default:stone"}, {["x"] = 5, ["y"] = 0, ["z"] = 12, ["name"] = "default:stone"}, {["x"] = 5, ["y"] = 0, ["z"] = 13, ["name"] = "default:stone"}, {["x"] = 5, ["y"] = 0, ["z"] = 14, ["name"] = "default:stone"}, {["x"] = 5, ["y"] = 0, ["z"] = 15, ["name"] = "default:stone"}, {["x"] = 5, ["y"] = 0, ["param1"] = 4, ["z"] = 16, ["name"] = "default:stone"}, {["x"] = 5, ["y"] = 0, ["param1"] = 4, ["z"] = 17, ["name"] = "default:stone"}, {["x"] = 5, ["y"] = 0, ["param1"] = 4, ["z"] = 18, ["name"] = "default:stone"}, {["x"] = 5, ["y"] = 0, ["param1"] = 4, ["z"] = 19, ["name"] = "default:stone"}, {["x"] = 5, ["y"] = 0, ["param1"] = 4, ["z"] = 20, ["name"] = "default:stone"}, {["x"] = 5, ["y"] = 0, ["param1"] = 4, ["z"] = 21, ["name"] = "default:stone"}, {["x"] = 5, ["y"] = 0, ["param1"] = 4, ["z"] = 22, ["name"] = "default:stone"}, {["x"] = 5, ["y"] = 0, ["param1"] = 4, ["z"] = 23, ["name"] = "default:stone"}, {["x"] = 5, ["y"] = 0, ["param1"] = 4, ["z"] = 24, ["name"] = "default:stone"}, {["x"] = 5, ["y"] = 0, ["param1"] = 4, ["z"] = 25, ["name"] = "default:stone"}, {["x"] = 5, ["y"] = 0, ["param1"] = 4, ["z"] = 26, ["name"] = "default:stone"}, {["x"] = 5, ["y"] = 0, ["param1"] = 4, ["z"] = 27, ["name"] = "default:stone"}, {["x"] = 5, ["y"] = 0, ["param1"] = 4, ["z"] = 28, ["name"] = "default:stone"}, {["x"] = 5, ["y"] = 0, ["param1"] = 4, ["z"] = 29, ["name"] = "default:stone"}, {["x"] = 5, ["y"] = 0, ["param1"] = 4, ["z"] = 30, ["name"] = "default:stone"}, {["x"] = 5, ["y"] = 0, ["param1"] = 4, ["z"] = 31, ["name"] = "default:stone"}, {["x"] = 5, ["y"] = 0, ["z"] = 32, ["name"] = "default:stone"}, {["x"] = 5, ["y"] = 0, ["z"] = 33, ["name"] = "default:stone"}, {["x"] = 5, ["y"] = 0, ["z"] = 34, ["name"] = "default:stone"}, {["x"] = 5, ["y"] = 0, ["z"] = 35, ["name"] = "default:stone"}, {["x"] = 5, ["y"] = 1, ["z"] = 0, ["name"] = "default:dirt_with_grass"}, {["x"] = 5, ["y"] = 1, ["z"] = 1, ["name"] = "default:dirt_with_grass"}, {["x"] = 5, ["y"] = 1, ["z"] = 2, ["name"] = "default:dirt_with_grass"}, {["x"] = 5, ["y"] = 1, ["z"] = 3, ["name"] = "default:dirt_with_grass"}, {["x"] = 5, ["y"] = 1, ["z"] = 4, ["name"] = "default:dirt_with_grass"}, {["x"] = 5, ["y"] = 1, ["z"] = 5, ["name"] = "default:dirt_with_grass"}, {["x"] = 5, ["y"] = 1, ["z"] = 6, ["name"] = "default:stone"}, {["x"] = 5, ["y"] = 1, ["z"] = 7, ["name"] = "default:stone"}, {["x"] = 5, ["y"] = 1, ["z"] = 8, ["name"] = "default:stone"}, {["x"] = 5, ["y"] = 1, ["z"] = 9, ["name"] = "default:stone"}, {["x"] = 5, ["y"] = 1, ["z"] = 10, ["name"] = "default:stone"}, {["x"] = 5, ["y"] = 1, ["z"] = 11, ["name"] = "default:stone"}, {["x"] = 5, ["y"] = 1, ["z"] = 12, ["name"] = "default:stone"}, {["x"] = 5, ["y"] = 1, ["z"] = 13, ["name"] = "default:stone"}, {["x"] = 5, ["y"] = 1, ["z"] = 14, ["name"] = "default:stone"}, {["x"] = 5, ["y"] = 1, ["z"] = 15, ["name"] = "default:stone"}, {["x"] = 5, ["y"] = 1, ["param1"] = 4, ["z"] = 16, ["name"] = "default:stone"}, {["x"] = 5, ["y"] = 1, ["param1"] = 4, ["z"] = 17, ["name"] = "default:stone"}, {["x"] = 5, ["y"] = 1, ["param1"] = 4, ["z"] = 18, ["name"] = "default:stone"}, {["x"] = 5, ["y"] = 1, ["param1"] = 4, ["z"] = 19, ["name"] = "default:stone"}, {["x"] = 5, ["y"] = 1, ["param1"] = 4, ["z"] = 20, ["name"] = "default:stone"}, {["x"] = 5, ["y"] = 1, ["param1"] = 4, ["z"] = 21, ["name"] = "default:stone"}, {["x"] = 5, ["y"] = 1, ["param1"] = 4, ["z"] = 22, ["name"] = "default:stone"}, {["x"] = 5, ["y"] = 1, ["param1"] = 4, ["z"] = 23, ["name"] = "default:stone"}, {["x"] = 5, ["y"] = 1, ["param1"] = 4, ["z"] = 24, ["name"] = "default:stone"}, {["x"] = 5, ["y"] = 1, ["param1"] = 4, ["z"] = 25, ["name"] = "default:stone"}, {["x"] = 5, ["y"] = 1, ["param1"] = 4, ["z"] = 26, ["name"] = "default:stone"}, {["x"] = 5, ["y"] = 1, ["param1"] = 4, ["z"] = 27, ["name"] = "default:stone"}, {["x"] = 5, ["y"] = 1, ["param1"] = 4, ["z"] = 28, ["name"] = "default:stone"}, {["x"] = 5, ["y"] = 1, ["param1"] = 4, ["z"] = 29, ["name"] = "default:stone"}, {["x"] = 5, ["y"] = 1, ["param1"] = 4, ["z"] = 30, ["name"] = "default:stone"}, {["x"] = 5, ["y"] = 1, ["param1"] = 4, ["z"] = 31, ["name"] = "default:stone"}, {["x"] = 5, ["y"] = 1, ["z"] = 32, ["name"] = "default:dirt_with_grass"}, {["x"] = 5, ["y"] = 1, ["z"] = 33, ["name"] = "default:dirt_with_grass"}, {["x"] = 5, ["y"] = 1, ["z"] = 34, ["name"] = "default:dirt_with_grass"}, {["x"] = 5, ["y"] = 1, ["z"] = 35, ["name"] = "default:dirt_with_grass"}, {["x"] = 5, ["y"] = 2, ["param1"] = 15, ["z"] = 5, ["name"] = "flowers:viola"}, {["x"] = 5, ["y"] = 2, ["z"] = 6, ["name"] = "default:dirt_with_grass"}, {["x"] = 5, ["y"] = 2, ["z"] = 7, ["name"] = "default:dirt_with_grass"}, {["x"] = 5, ["y"] = 2, ["z"] = 8, ["name"] = "default:dirt_with_grass"}, {["x"] = 5, ["y"] = 2, ["z"] = 9, ["name"] = "default:dirt_with_grass"}, {["x"] = 5, ["y"] = 2, ["z"] = 10, ["name"] = "mesecons_lightstone:lightstone_violet_off"}, {["x"] = 5, ["y"] = 2, ["z"] = 11, ["name"] = "default:acacia_wood"}, {["x"] = 5, ["y"] = 2, ["z"] = 12, ["name"] = "default:acacia_wood"}, {["x"] = 5, ["y"] = 2, ["z"] = 13, ["name"] = "default:acacia_wood"}, {["x"] = 5, ["y"] = 2, ["z"] = 14, ["name"] = "default:acacia_wood"}, {["x"] = 5, ["y"] = 2, ["z"] = 15, ["name"] = "default:acacia_wood"}, {["x"] = 5, ["y"] = 2, ["param1"] = 62, ["z"] = 16, ["name"] = "default:acacia_wood"}, {["x"] = 5, ["y"] = 2, ["param1"] = 62, ["z"] = 17, ["name"] = "default:acacia_wood"}, {["x"] = 5, ["y"] = 2, ["param1"] = 62, ["z"] = 18, ["name"] = "default:acacia_wood"}, {["x"] = 5, ["y"] = 2, ["param1"] = 62, ["z"] = 19, ["name"] = "default:acacia_wood"}, {["x"] = 5, ["y"] = 2, ["param1"] = 62, ["z"] = 20, ["name"] = "default:acacia_wood"}, {["x"] = 5, ["y"] = 2, ["param1"] = 62, ["z"] = 21, ["name"] = "default:acacia_wood"}, {["x"] = 5, ["y"] = 2, ["param1"] = 62, ["z"] = 22, ["name"] = "default:acacia_wood"}, {["x"] = 5, ["y"] = 2, ["param1"] = 62, ["z"] = 23, ["name"] = "default:acacia_wood"}, {["x"] = 5, ["y"] = 2, ["param1"] = 62, ["z"] = 24, ["name"] = "default:acacia_wood"}, {["x"] = 5, ["y"] = 2, ["param1"] = 62, ["z"] = 25, ["name"] = "default:acacia_wood"}, {["x"] = 5, ["y"] = 2, ["param1"] = 26, ["z"] = 26, ["name"] = "default:dirt_with_grass"}, {["x"] = 5, ["y"] = 2, ["param1"] = 26, ["z"] = 27, ["name"] = "default:dirt_with_grass"}, {["x"] = 5, ["y"] = 2, ["param1"] = 26, ["z"] = 28, ["name"] = "default:dirt_with_grass"}, {["x"] = 5, ["y"] = 2, ["param1"] = 26, ["z"] = 29, ["name"] = "default:dirt_with_grass"}, {["x"] = 5, ["y"] = 2, ["param1"] = 26, ["z"] = 30, ["name"] = "default:dirt_with_grass"}, {["x"] = 5, ["y"] = 2, ["param1"] = 26, ["z"] = 31, ["name"] = "default:dirt_with_grass"}, {["x"] = 5, ["y"] = 2, ["param1"] = 14, ["z"] = 34, ["name"] = "default:blueberry_bush_leaves_with_berries"}, {["x"] = 5, ["y"] = 2, ["param1"] = 14, ["z"] = 35, ["name"] = "default:blueberry_bush_leaves_with_berries"}, {["x"] = 5, ["y"] = 3, ["param1"] = 15, ["z"] = 6, ["name"] = "mobs:fence_wood"}, {["x"] = 5, ["y"] = 3, ["param1"] = 15, ["z"] = 7, ["name"] = "mobs:fence_wood"}, {["x"] = 5, ["y"] = 3, ["param1"] = 15, ["z"] = 8, ["name"] = "mobs:fence_wood"}, {["x"] = 5, ["y"] = 3, ["param1"] = 14, ["z"] = 9, ["name"] = "default:blueberry_bush_leaves_with_berries"}, {["x"] = 5, ["y"] = 3, ["z"] = 10, ["name"] = "mesecons_lightstone:lightstone_violet_off"}, {["x"] = 5, ["y"] = 3, ["z"] = 11, ["name"] = "mesecons_lightstone:lightstone_violet_off"}, {["x"] = 5, ["y"] = 3, ["z"] = 12, ["name"] = "mesecons_lightstone:lightstone_violet_off"}, {["x"] = 5, ["y"] = 3, ["z"] = 13, ["name"] = "mesecons_lightstone:lightstone_violet_off"}, {["x"] = 5, ["y"] = 3, ["z"] = 14, ["name"] = "mesecons_lightstone:lightstone_violet_off"}, {["x"] = 5, ["y"] = 3, ["z"] = 15, ["name"] = "mesecons_lightstone:lightstone_violet_off"}, {["x"] = 5, ["y"] = 3, ["z"] = 16, ["name"] = "mesecons_lightstone:lightstone_violet_off"}, {["x"] = 5, ["y"] = 3, ["z"] = 17, ["name"] = "mesecons_lightstone:lightstone_violet_off"}, {["x"] = 5, ["y"] = 3, ["z"] = 18, ["name"] = "mesecons_lightstone:lightstone_violet_off"}, {["x"] = 5, ["y"] = 3, ["z"] = 19, ["name"] = "mesecons_lightstone:lightstone_violet_off"}, {["x"] = 5, ["y"] = 3, ["z"] = 20, ["name"] = "mesecons_lightstone:lightstone_violet_off"}, {["x"] = 5, ["y"] = 3, ["z"] = 21, ["name"] = "mesecons_lightstone:lightstone_violet_off"}, {["x"] = 5, ["y"] = 3, ["z"] = 22, ["name"] = "mesecons_lightstone:lightstone_violet_off"}, {["x"] = 5, ["y"] = 3, ["z"] = 23, ["name"] = "mesecons_lightstone:lightstone_violet_off"}, {["x"] = 5, ["y"] = 3, ["z"] = 24, ["name"] = "mesecons_lightstone:lightstone_violet_off"}, {["x"] = 5, ["y"] = 3, ["param1"] = 246, ["z"] = 25, ["name"] = "mesecons_lightstone:lightstone_violet_off"}, {["x"] = 5, ["y"] = 3, ["param1"] = 29, ["z"] = 26, ["name"] = "default:blueberry_bush_leaves_with_berries"}, {["x"] = 5, ["y"] = 3, ["param1"] = 15, ["z"] = 30, ["name"] = "mobs:fence_wood"}, {["x"] = 5, ["y"] = 3, ["param1"] = 14, ["z"] = 31, ["name"] = "mobs:fence_wood"}, {["x"] = 5, ["y"] = 4, ["param1"] = 15, ["z"] = 10, ["name"] = "mesecons_lightstone:lightstone_violet_off"}, {["x"] = 5, ["y"] = 4, ["param1"] = 15, ["z"] = 11, ["name"] = "mesecons_lightstone:lightstone_violet_off"}, {["x"] = 5, ["y"] = 4, ["param1"] = 15, ["z"] = 12, ["name"] = "mesecons_lightstone:lightstone_violet_off"}, {["x"] = 5, ["y"] = 4, ["param1"] = 15, ["z"] = 13, ["name"] = "mesecons_lightstone:lightstone_violet_off"}, {["x"] = 5, ["y"] = 4, ["param1"] = 15, ["z"] = 14, ["name"] = "mesecons_lightstone:lightstone_violet_off"}, {["x"] = 5, ["y"] = 4, ["param1"] = 14, ["z"] = 15, ["name"] = "mesecons_lightstone:lightstone_violet_off"}, {["x"] = 5, ["y"] = 4, ["param1"] = 14, ["z"] = 16, ["name"] = "mesecons_lightstone:lightstone_violet_off"}, {["x"] = 5, ["y"] = 4, ["param1"] = 15, ["z"] = 17, ["name"] = "mesecons_lightstone:lightstone_violet_off"}, {["x"] = 5, ["y"] = 4, ["param1"] = 15, ["z"] = 18, ["name"] = "mesecons_lightstone:lightstone_violet_off"}, {["x"] = 5, ["y"] = 4, ["param1"] = 15, ["z"] = 19, ["name"] = "mesecons_lightstone:lightstone_violet_off"}, {["x"] = 5, ["y"] = 4, ["param1"] = 15, ["z"] = 20, ["name"] = "mesecons_lightstone:lightstone_violet_off"}, {["x"] = 5, ["y"] = 4, ["param1"] = 15, ["z"] = 21, ["name"] = "mesecons_lightstone:lightstone_violet_off"}, {["x"] = 5, ["y"] = 4, ["param1"] = 15, ["z"] = 22, ["name"] = "mesecons_lightstone:lightstone_violet_off"}, {["x"] = 5, ["y"] = 4, ["param1"] = 15, ["z"] = 23, ["name"] = "mesecons_lightstone:lightstone_violet_off"}, {["x"] = 5, ["y"] = 4, ["param1"] = 15, ["z"] = 24, ["name"] = "mesecons_lightstone:lightstone_violet_off"}, {["x"] = 5, ["y"] = 4, ["param1"] = 246, ["z"] = 25, ["name"] = "mesecons_lightstone:lightstone_violet_off"}, {["x"] = 5, ["y"] = 5, ["param1"] = 15, ["z"] = 10, ["name"] = "mesecons_lightstone:lightstone_violet_off"}, {["x"] = 5, ["y"] = 5, ["param1"] = 15, ["z"] = 11, ["name"] = "mesecons_lightstone:lightstone_violet_off"}, {["x"] = 5, ["y"] = 5, ["param1"] = 15, ["z"] = 12, ["name"] = "mesecons_lightstone:lightstone_violet_off"}, {["x"] = 5, ["y"] = 5, ["param1"] = 15, ["z"] = 13, ["name"] = "mesecons_lightstone:lightstone_violet_off"}, {["x"] = 5, ["y"] = 5, ["param1"] = 15, ["z"] = 14, ["name"] = "mesecons_lightstone:lightstone_violet_off"}, {["x"] = 5, ["y"] = 5, ["param1"] = 14, ["z"] = 15, ["name"] = "mesecons_lightstone:lightstone_violet_off"}, {["x"] = 5, ["y"] = 5, ["param1"] = 14, ["z"] = 16, ["name"] = "mesecons_lightstone:lightstone_violet_off"}, {["x"] = 5, ["y"] = 5, ["param1"] = 15, ["z"] = 17, ["name"] = "mesecons_lightstone:lightstone_violet_off"}, {["x"] = 5, ["y"] = 5, ["param1"] = 15, ["z"] = 18, ["name"] = "mesecons_lightstone:lightstone_violet_off"}, {["x"] = 5, ["y"] = 5, ["param1"] = 15, ["z"] = 19, ["name"] = "mesecons_lightstone:lightstone_violet_off"}, {["x"] = 5, ["y"] = 5, ["param1"] = 15, ["z"] = 20, ["name"] = "mesecons_lightstone:lightstone_violet_off"}, {["x"] = 5, ["y"] = 5, ["param1"] = 15, ["z"] = 21, ["name"] = "mesecons_lightstone:lightstone_violet_off"}, {["x"] = 5, ["y"] = 5, ["param1"] = 15, ["z"] = 22, ["name"] = "mesecons_lightstone:lightstone_violet_off"}, {["x"] = 5, ["y"] = 5, ["param1"] = 15, ["z"] = 23, ["name"] = "mesecons_lightstone:lightstone_violet_off"}, {["x"] = 5, ["y"] = 5, ["param1"] = 15, ["z"] = 24, ["name"] = "mesecons_lightstone:lightstone_violet_off"}, {["x"] = 5, ["y"] = 5, ["param1"] = 246, ["z"] = 25, ["name"] = "mesecons_lightstone:lightstone_violet_off"}, {["x"] = 5, ["y"] = 6, ["param1"] = 15, ["z"] = 10, ["name"] = "mesecons_lightstone:lightstone_violet_off"}, {["x"] = 5, ["y"] = 6, ["param1"] = 15, ["z"] = 11, ["name"] = "mesecons_lightstone:lightstone_violet_off"}, {["x"] = 5, ["y"] = 6, ["param1"] = 15, ["z"] = 12, ["name"] = "mesecons_lightstone:lightstone_violet_off"}, {["x"] = 5, ["y"] = 6, ["param1"] = 15, ["z"] = 13, ["name"] = "mesecons_lightstone:lightstone_violet_off"}, {["x"] = 5, ["y"] = 6, ["param1"] = 15, ["z"] = 14, ["name"] = "mesecons_lightstone:lightstone_violet_off"}, {["x"] = 5, ["y"] = 6, ["param1"] = 14, ["z"] = 15, ["name"] = "mesecons_lightstone:lightstone_violet_off"}, {["x"] = 5, ["y"] = 6, ["param1"] = 14, ["z"] = 16, ["name"] = "mesecons_lightstone:lightstone_violet_off"}, {["x"] = 5, ["y"] = 6, ["param1"] = 15, ["z"] = 17, ["name"] = "mesecons_lightstone:lightstone_violet_off"}, {["x"] = 5, ["y"] = 6, ["param1"] = 15, ["z"] = 18, ["name"] = "mesecons_lightstone:lightstone_violet_off"}, {["x"] = 5, ["y"] = 6, ["param1"] = 15, ["z"] = 19, ["name"] = "mesecons_lightstone:lightstone_violet_off"}, {["x"] = 5, ["y"] = 6, ["param1"] = 15, ["z"] = 20, ["name"] = "mesecons_lightstone:lightstone_violet_off"}, {["x"] = 5, ["y"] = 6, ["param1"] = 15, ["z"] = 21, ["name"] = "mesecons_lightstone:lightstone_violet_off"}, {["x"] = 5, ["y"] = 6, ["param1"] = 15, ["z"] = 22, ["name"] = "mesecons_lightstone:lightstone_violet_off"}, {["x"] = 5, ["y"] = 6, ["param1"] = 15, ["z"] = 23, ["name"] = "mesecons_lightstone:lightstone_violet_off"}, {["x"] = 5, ["y"] = 6, ["param1"] = 15, ["z"] = 24, ["name"] = "mesecons_lightstone:lightstone_violet_off"}, {["x"] = 5, ["y"] = 6, ["param1"] = 246, ["z"] = 25, ["name"] = "mesecons_lightstone:lightstone_violet_off"}, {["x"] = 5, ["y"] = 7, ["param1"] = 15, ["z"] = 10, ["name"] = "mesecons_lightstone:lightstone_violet_off"}, {["x"] = 5, ["y"] = 7, ["param1"] = 15, ["z"] = 11, ["name"] = "mesecons_lightstone:lightstone_violet_off"}, {["x"] = 5, ["y"] = 7, ["param1"] = 15, ["z"] = 12, ["name"] = "mesecons_lightstone:lightstone_violet_off"}, {["x"] = 5, ["y"] = 7, ["param1"] = 15, ["z"] = 13, ["name"] = "mesecons_lightstone:lightstone_violet_off"}, {["x"] = 5, ["y"] = 7, ["param1"] = 15, ["z"] = 14, ["name"] = "mesecons_lightstone:lightstone_violet_off"}, {["x"] = 5, ["y"] = 7, ["param1"] = 14, ["z"] = 15, ["name"] = "mesecons_lightstone:lightstone_violet_off"}, {["x"] = 5, ["y"] = 7, ["param1"] = 14, ["z"] = 16, ["name"] = "mesecons_lightstone:lightstone_violet_off"}, {["x"] = 5, ["y"] = 7, ["param1"] = 15, ["z"] = 17, ["name"] = "mesecons_lightstone:lightstone_violet_off"}, {["x"] = 5, ["y"] = 7, ["param1"] = 15, ["z"] = 18, ["name"] = "mesecons_lightstone:lightstone_violet_off"}, {["x"] = 5, ["y"] = 7, ["param1"] = 15, ["z"] = 19, ["name"] = "mesecons_lightstone:lightstone_violet_off"}, {["x"] = 5, ["y"] = 7, ["param1"] = 15, ["z"] = 20, ["name"] = "mesecons_lightstone:lightstone_violet_off"}, {["x"] = 5, ["y"] = 7, ["param1"] = 15, ["z"] = 21, ["name"] = "mesecons_lightstone:lightstone_violet_off"}, {["x"] = 5, ["y"] = 7, ["param1"] = 15, ["z"] = 22, ["name"] = "mesecons_lightstone:lightstone_violet_off"}, {["x"] = 5, ["y"] = 7, ["param1"] = 15, ["z"] = 23, ["name"] = "mesecons_lightstone:lightstone_violet_off"}, {["x"] = 5, ["y"] = 7, ["param1"] = 15, ["z"] = 24, ["name"] = "mesecons_lightstone:lightstone_violet_off"}, {["x"] = 5, ["y"] = 7, ["param1"] = 246, ["z"] = 25, ["name"] = "mesecons_lightstone:lightstone_violet_off"}, {["x"] = 5, ["y"] = 8, ["param1"] = 15, ["z"] = 10, ["name"] = "mesecons_lightstone:lightstone_violet_off"}, {["x"] = 5, ["y"] = 8, ["param1"] = 15, ["z"] = 11, ["name"] = "mesecons_lightstone:lightstone_violet_off"}, {["x"] = 5, ["y"] = 8, ["param1"] = 15, ["z"] = 12, ["name"] = "mesecons_lightstone:lightstone_violet_off"}, {["x"] = 5, ["y"] = 8, ["param1"] = 15, ["z"] = 13, ["name"] = "mesecons_lightstone:lightstone_violet_off"}, {["x"] = 5, ["y"] = 8, ["param1"] = 15, ["z"] = 14, ["name"] = "mesecons_lightstone:lightstone_violet_off"}, {["x"] = 5, ["y"] = 8, ["param1"] = 14, ["z"] = 15, ["name"] = "mesecons_lightstone:lightstone_violet_off"}, {["x"] = 5, ["y"] = 8, ["param1"] = 14, ["z"] = 16, ["name"] = "mesecons_lightstone:lightstone_violet_off"}, {["x"] = 5, ["y"] = 8, ["param1"] = 15, ["z"] = 17, ["name"] = "mesecons_lightstone:lightstone_violet_off"}, {["x"] = 5, ["y"] = 8, ["param1"] = 15, ["z"] = 18, ["name"] = "mesecons_lightstone:lightstone_violet_off"}, {["x"] = 5, ["y"] = 8, ["param1"] = 15, ["z"] = 19, ["name"] = "mesecons_lightstone:lightstone_violet_off"}, {["x"] = 5, ["y"] = 8, ["param1"] = 15, ["z"] = 20, ["name"] = "mesecons_lightstone:lightstone_violet_off"}, {["x"] = 5, ["y"] = 8, ["param1"] = 15, ["z"] = 21, ["name"] = "mesecons_lightstone:lightstone_violet_off"}, {["x"] = 5, ["y"] = 8, ["param1"] = 15, ["z"] = 22, ["name"] = "mesecons_lightstone:lightstone_violet_off"}, {["x"] = 5, ["y"] = 8, ["param1"] = 15, ["z"] = 23, ["name"] = "mesecons_lightstone:lightstone_violet_off"}, {["x"] = 5, ["y"] = 8, ["param1"] = 15, ["z"] = 24, ["name"] = "mesecons_lightstone:lightstone_violet_off"}, {["x"] = 5, ["y"] = 8, ["z"] = 25, ["name"] = "mesecons_lightstone:lightstone_violet_off"}, {["x"] = 5, ["y"] = 9, ["param1"] = 15, ["z"] = 10, ["name"] = "mesecons_lightstone:lightstone_violet_off"}, {["x"] = 5, ["y"] = 9, ["param1"] = 15, ["z"] = 11, ["name"] = "mesecons_lightstone:lightstone_violet_off"}, {["x"] = 5, ["y"] = 9, ["param1"] = 15, ["z"] = 12, ["name"] = "mesecons_lightstone:lightstone_violet_off"}, {["x"] = 5, ["y"] = 9, ["param1"] = 15, ["z"] = 13, ["name"] = "mesecons_lightstone:lightstone_violet_off"}, {["x"] = 5, ["y"] = 9, ["param1"] = 15, ["z"] = 14, ["name"] = "mesecons_lightstone:lightstone_violet_off"}, {["x"] = 5, ["y"] = 9, ["param1"] = 14, ["z"] = 15, ["name"] = "mesecons_lightstone:lightstone_violet_off"}, {["x"] = 5, ["y"] = 9, ["param1"] = 14, ["z"] = 16, ["name"] = "mesecons_lightstone:lightstone_violet_off"}, {["x"] = 5, ["y"] = 9, ["param1"] = 15, ["z"] = 17, ["name"] = "mesecons_lightstone:lightstone_violet_off"}, {["x"] = 5, ["y"] = 9, ["param1"] = 15, ["z"] = 18, ["name"] = "mesecons_lightstone:lightstone_violet_off"}, {["x"] = 5, ["y"] = 9, ["param1"] = 15, ["z"] = 19, ["name"] = "mesecons_lightstone:lightstone_violet_off"}, {["x"] = 5, ["y"] = 9, ["param1"] = 15, ["z"] = 20, ["name"] = "mesecons_lightstone:lightstone_violet_off"}, {["x"] = 5, ["y"] = 9, ["param1"] = 15, ["z"] = 21, ["name"] = "mesecons_lightstone:lightstone_violet_off"}, {["x"] = 5, ["y"] = 9, ["param1"] = 15, ["z"] = 22, ["name"] = "mesecons_lightstone:lightstone_violet_off"}, {["x"] = 5, ["y"] = 9, ["param1"] = 15, ["z"] = 23, ["name"] = "mesecons_lightstone:lightstone_violet_off"}, {["x"] = 5, ["y"] = 9, ["param1"] = 15, ["z"] = 24, ["name"] = "mesecons_lightstone:lightstone_violet_off"}, {["x"] = 5, ["y"] = 9, ["z"] = 25, ["name"] = "mesecons_lightstone:lightstone_violet_off"}, {["x"] = 5, ["param2"] = 4, ["y"] = 9, ["param1"] = 14, ["z"] = 27, ["name"] = "bakedclay:stair_baked_clay_white"}, {["x"] = 5, ["param2"] = 3, ["y"] = 10, ["param1"] = 14, ["z"] = 9, ["name"] = "bakedclay:white"}, {["x"] = 5, ["y"] = 10, ["param1"] = 15, ["z"] = 10, ["name"] = "mesecons_lightstone:lightstone_violet_off"}, {["x"] = 5, ["y"] = 10, ["param1"] = 15, ["z"] = 11, ["name"] = "mesecons_lightstone:lightstone_violet_off"}, {["x"] = 5, ["y"] = 10, ["param1"] = 15, ["z"] = 12, ["name"] = "mesecons_lightstone:lightstone_violet_off"}, {["x"] = 5, ["y"] = 10, ["param1"] = 15, ["z"] = 13, ["name"] = "mesecons_lightstone:lightstone_violet_off"}, {["x"] = 5, ["y"] = 10, ["param1"] = 15, ["z"] = 14, ["name"] = "mesecons_lightstone:lightstone_violet_off"}, {["x"] = 5, ["y"] = 10, ["param1"] = 14, ["z"] = 15, ["name"] = "mesecons_lightstone:lightstone_violet_off"}, {["x"] = 5, ["y"] = 10, ["param1"] = 14, ["z"] = 16, ["name"] = "mesecons_lightstone:lightstone_violet_off"}, {["x"] = 5, ["y"] = 10, ["param1"] = 15, ["z"] = 17, ["name"] = "mesecons_lightstone:lightstone_violet_off"}, {["x"] = 5, ["y"] = 10, ["param1"] = 15, ["z"] = 18, ["name"] = "mesecons_lightstone:lightstone_violet_off"}, {["x"] = 5, ["y"] = 10, ["param1"] = 15, ["z"] = 19, ["name"] = "mesecons_lightstone:lightstone_violet_off"}, {["x"] = 5, ["y"] = 10, ["param1"] = 15, ["z"] = 20, ["name"] = "mesecons_lightstone:lightstone_violet_off"}, {["x"] = 5, ["y"] = 10, ["param1"] = 15, ["z"] = 21, ["name"] = "mesecons_lightstone:lightstone_violet_off"}, {["x"] = 5, ["y"] = 10, ["param1"] = 15, ["z"] = 22, ["name"] = "mesecons_lightstone:lightstone_violet_off"}, {["x"] = 5, ["y"] = 10, ["param1"] = 15, ["z"] = 23, ["name"] = "mesecons_lightstone:lightstone_violet_off"}, {["x"] = 5, ["y"] = 10, ["param1"] = 15, ["z"] = 24, ["name"] = "mesecons_lightstone:lightstone_violet_off"}, {["x"] = 5, ["y"] = 10, ["z"] = 25, ["name"] = "mesecons_lightstone:lightstone_violet_off"}, {["x"] = 5, ["param2"] = 4, ["y"] = 10, ["param1"] = 14, ["z"] = 26, ["name"] = "bakedclay:stair_baked_clay_white"}, {["x"] = 5, ["param2"] = 3, ["y"] = 11, ["param1"] = 14, ["z"] = 10, ["name"] = "homedecor:fence_wrought_iron"}, {["x"] = 5, ["param2"] = 3, ["y"] = 11, ["param1"] = 14, ["z"] = 11, ["name"] = "homedecor:fence_wrought_iron"}, {["x"] = 5, ["y"] = 11, ["param1"] = 14, ["z"] = 12, ["name"] = "homedecor:fence_wrought_iron"}, {["x"] = 5, ["y"] = 11, ["param1"] = 15, ["z"] = 13, ["name"] = "mesecons_lightstone:lightstone_violet_off"}, {["x"] = 5, ["y"] = 11, ["param1"] = 15, ["z"] = 14, ["name"] = "mesecons_lightstone:lightstone_violet_off"}, {["x"] = 5, ["y"] = 11, ["param1"] = 14, ["z"] = 15, ["name"] = "mesecons_lightstone:lightstone_violet_off"}, {["x"] = 5, ["y"] = 11, ["param1"] = 13, ["z"] = 16, ["name"] = "mesecons_lightstone:lightstone_violet_off"}, {["x"] = 5, ["y"] = 11, ["param1"] = 15, ["z"] = 17, ["name"] = "mesecons_lightstone:lightstone_violet_off"}, {["x"] = 5, ["y"] = 11, ["param1"] = 15, ["z"] = 18, ["name"] = "mesecons_lightstone:lightstone_violet_off"}, {["x"] = 5, ["y"] = 11, ["param1"] = 15, ["z"] = 19, ["name"] = "mesecons_lightstone:lightstone_violet_off"}, {["x"] = 5, ["y"] = 11, ["param1"] = 15, ["z"] = 20, ["name"] = "mesecons_lightstone:lightstone_violet_off"}, {["x"] = 5, ["y"] = 11, ["param1"] = 15, ["z"] = 21, ["name"] = "mesecons_lightstone:lightstone_violet_off"}, {["x"] = 5, ["y"] = 11, ["param1"] = 15, ["z"] = 22, ["name"] = "mesecons_lightstone:lightstone_violet_off"}, {["x"] = 5, ["y"] = 11, ["param1"] = 15, ["z"] = 23, ["name"] = "mesecons_lightstone:lightstone_violet_off"}, {["x"] = 5, ["y"] = 11, ["param1"] = 15, ["z"] = 24, ["name"] = "mesecons_lightstone:lightstone_violet_off"}, {["x"] = 5, ["y"] = 11, ["z"] = 25, ["name"] = "mesecons_lightstone:lightstone_violet_off"}, {["x"] = 5, ["y"] = 12, ["param1"] = 15, ["z"] = 13, ["name"] = "mesecons_lightstone:lightstone_violet_off"}, {["x"] = 5, ["y"] = 12, ["param1"] = 15, ["z"] = 14, ["name"] = "mesecons_lightstone:lightstone_violet_off"}, {["x"] = 5, ["y"] = 12, ["param1"] = 14, ["z"] = 15, ["name"] = "mesecons_lightstone:lightstone_violet_off"}, {["x"] = 5, ["y"] = 12, ["param1"] = 14, ["z"] = 16, ["name"] = "mesecons_lightstone:lightstone_violet_off"}, {["x"] = 5, ["y"] = 12, ["param1"] = 15, ["z"] = 17, ["name"] = "mesecons_lightstone:lightstone_violet_off"}, {["x"] = 5, ["y"] = 12, ["param1"] = 15, ["z"] = 18, ["name"] = "mesecons_lightstone:lightstone_violet_off"}, {["x"] = 5, ["y"] = 12, ["param1"] = 15, ["z"] = 19, ["name"] = "mesecons_lightstone:lightstone_violet_off"}, {["x"] = 5, ["y"] = 12, ["param1"] = 15, ["z"] = 20, ["name"] = "mesecons_lightstone:lightstone_violet_off"}, {["x"] = 5, ["y"] = 12, ["param1"] = 15, ["z"] = 21, ["name"] = "mesecons_lightstone:lightstone_violet_off"}, {["x"] = 5, ["y"] = 12, ["param1"] = 15, ["z"] = 22, ["name"] = "mesecons_lightstone:lightstone_violet_off"}, {["x"] = 5, ["y"] = 12, ["param1"] = 15, ["z"] = 23, ["name"] = "mesecons_lightstone:lightstone_violet_off"}, {["x"] = 5, ["y"] = 12, ["param1"] = 15, ["z"] = 24, ["name"] = "mesecons_lightstone:lightstone_violet_off"}, {["x"] = 5, ["y"] = 12, ["z"] = 25, ["name"] = "mesecons_lightstone:lightstone_violet_off"}, {["x"] = 5, ["y"] = 13, ["param1"] = 14, ["z"] = 13, ["name"] = "mesecons_lightstone:lightstone_violet_off"}, {["x"] = 5, ["y"] = 13, ["param1"] = 14, ["z"] = 14, ["name"] = "mesecons_lightstone:lightstone_violet_off"}, {["x"] = 5, ["y"] = 13, ["param1"] = 14, ["z"] = 15, ["name"] = "mesecons_lightstone:lightstone_violet_off"}, {["x"] = 5, ["y"] = 13, ["param1"] = 13, ["z"] = 16, ["name"] = "mesecons_lightstone:lightstone_violet_off"}, {["x"] = 5, ["y"] = 13, ["param1"] = 15, ["z"] = 17, ["name"] = "mesecons_lightstone:lightstone_violet_off"}, {["x"] = 5, ["y"] = 13, ["param1"] = 15, ["z"] = 18, ["name"] = "mesecons_lightstone:lightstone_violet_off"}, {["x"] = 5, ["y"] = 13, ["param1"] = 15, ["z"] = 19, ["name"] = "mesecons_lightstone:lightstone_violet_off"}, {["x"] = 5, ["y"] = 13, ["param1"] = 15, ["z"] = 20, ["name"] = "mesecons_lightstone:lightstone_violet_off"}, {["x"] = 5, ["y"] = 13, ["param1"] = 15, ["z"] = 21, ["name"] = "mesecons_lightstone:lightstone_violet_off"}, {["x"] = 5, ["y"] = 13, ["param1"] = 15, ["z"] = 22, ["name"] = "mesecons_lightstone:lightstone_violet_off"}, {["x"] = 5, ["y"] = 13, ["param1"] = 15, ["z"] = 23, ["name"] = "mesecons_lightstone:lightstone_violet_off"}, {["x"] = 5, ["y"] = 13, ["param1"] = 15, ["z"] = 24, ["name"] = "mesecons_lightstone:lightstone_violet_off"}, {["x"] = 5, ["y"] = 13, ["z"] = 25, ["name"] = "mesecons_lightstone:lightstone_violet_off"}, {["x"] = 5, ["y"] = 14, ["param1"] = 15, ["z"] = 13, ["name"] = "mesecons_lightstone:lightstone_violet_off"}, {["x"] = 5, ["y"] = 14, ["param1"] = 15, ["z"] = 14, ["name"] = "mesecons_lightstone:lightstone_violet_off"}, {["x"] = 5, ["y"] = 14, ["param1"] = 15, ["z"] = 15, ["name"] = "mesecons_lightstone:lightstone_violet_off"}, {["x"] = 5, ["y"] = 14, ["param1"] = 14, ["z"] = 16, ["name"] = "mesecons_lightstone:lightstone_violet_off"}, {["x"] = 5, ["y"] = 14, ["z"] = 17, ["name"] = "mesecons_lightstone:lightstone_violet_off"}, {["x"] = 5, ["y"] = 14, ["param1"] = 14, ["z"] = 18, ["name"] = "mesecons_lightstone:lightstone_violet_off"}, {["x"] = 5, ["y"] = 14, ["param1"] = 14, ["z"] = 19, ["name"] = "mesecons_lightstone:lightstone_violet_off"}, {["x"] = 5, ["y"] = 14, ["param1"] = 14, ["z"] = 20, ["name"] = "mesecons_lightstone:lightstone_violet_off"}, {["x"] = 5, ["y"] = 14, ["param1"] = 14, ["z"] = 21, ["name"] = "mesecons_lightstone:lightstone_violet_off"}, {["x"] = 5, ["y"] = 14, ["param1"] = 14, ["z"] = 22, ["name"] = "mesecons_lightstone:lightstone_violet_off"}, {["x"] = 5, ["y"] = 14, ["param1"] = 14, ["z"] = 23, ["name"] = "mesecons_lightstone:lightstone_violet_off"}, {["x"] = 5, ["y"] = 14, ["param1"] = 14, ["z"] = 24, ["name"] = "mesecons_lightstone:lightstone_violet_off"}, {["x"] = 5, ["y"] = 14, ["z"] = 25, ["name"] = "mesecons_lightstone:lightstone_violet_off"}, {["x"] = 5, ["param2"] = 1, ["y"] = 15, ["param1"] = 14, ["z"] = 13, ["name"] = "bakedclay:stair_baked_clay_white"}, {["x"] = 5, ["param2"] = 1, ["y"] = 15, ["param1"] = 14, ["z"] = 14, ["name"] = "bakedclay:stair_baked_clay_white"}, {["x"] = 5, ["param2"] = 1, ["y"] = 15, ["param1"] = 13, ["z"] = 15, ["name"] = "bakedclay:stair_baked_clay_white"}, {["x"] = 5, ["param2"] = 1, ["y"] = 15, ["param1"] = 13, ["z"] = 16, ["name"] = "bakedclay:stair_baked_clay_white"}, {["x"] = 5, ["param2"] = 19, ["y"] = 15, ["param1"] = 14, ["z"] = 17, ["name"] = "bakedclay:stair_baked_clay_white"}, {["x"] = 5, ["param2"] = 19, ["y"] = 15, ["param1"] = 14, ["z"] = 18, ["name"] = "bakedclay:stair_baked_clay_white"}, {["x"] = 5, ["param2"] = 19, ["y"] = 15, ["param1"] = 14, ["z"] = 19, ["name"] = "bakedclay:stair_baked_clay_white"}, {["x"] = 5, ["param2"] = 19, ["y"] = 15, ["param1"] = 14, ["z"] = 20, ["name"] = "bakedclay:stair_baked_clay_white"}, {["x"] = 5, ["param2"] = 19, ["y"] = 15, ["param1"] = 14, ["z"] = 21, ["name"] = "bakedclay:stair_baked_clay_white"}, {["x"] = 5, ["param2"] = 19, ["y"] = 15, ["param1"] = 14, ["z"] = 22, ["name"] = "bakedclay:stair_baked_clay_white"}, {["x"] = 5, ["param2"] = 19, ["y"] = 15, ["param1"] = 14, ["z"] = 23, ["name"] = "bakedclay:stair_baked_clay_white"}, {["x"] = 5, ["param2"] = 19, ["y"] = 15, ["param1"] = 14, ["z"] = 24, ["name"] = "bakedclay:stair_baked_clay_white"}, {["x"] = 5, ["param2"] = 1, ["y"] = 15, ["param1"] = 14, ["z"] = 25, ["name"] = "bakedclay:stair_baked_clay_white"}, {["x"] = 6, ["y"] = 0, ["z"] = 0, ["name"] = "default:stone"}, {["x"] = 6, ["y"] = 0, ["z"] = 1, ["name"] = "default:stone"}, {["x"] = 6, ["y"] = 0, ["z"] = 2, ["name"] = "default:stone"}, {["x"] = 6, ["y"] = 0, ["z"] = 3, ["name"] = "default:stone"}, {["x"] = 6, ["y"] = 0, ["z"] = 4, ["name"] = "default:stone"}, {["x"] = 6, ["y"] = 0, ["z"] = 5, ["name"] = "default:stone"}, {["x"] = 6, ["y"] = 0, ["z"] = 6, ["name"] = "default:stone_with_coal"}, {["x"] = 6, ["y"] = 0, ["z"] = 7, ["name"] = "default:stone"}, {["x"] = 6, ["y"] = 0, ["z"] = 8, ["name"] = "default:stone"}, {["x"] = 6, ["y"] = 0, ["z"] = 9, ["name"] = "default:stone"}, {["x"] = 6, ["y"] = 0, ["z"] = 10, ["name"] = "default:stone"}, {["x"] = 6, ["y"] = 0, ["z"] = 11, ["name"] = "default:stone"}, {["x"] = 6, ["y"] = 0, ["z"] = 12, ["name"] = "default:stone"}, {["x"] = 6, ["y"] = 0, ["z"] = 13, ["name"] = "default:stone"}, {["x"] = 6, ["y"] = 0, ["z"] = 14, ["name"] = "default:stone"}, {["x"] = 6, ["y"] = 0, ["z"] = 15, ["name"] = "default:stone"}, {["x"] = 6, ["y"] = 0, ["param1"] = 4, ["z"] = 16, ["name"] = "default:stone"}, {["x"] = 6, ["y"] = 0, ["param1"] = 4, ["z"] = 17, ["name"] = "default:stone"}, {["x"] = 6, ["y"] = 0, ["param1"] = 4, ["z"] = 18, ["name"] = "default:stone"}, {["x"] = 6, ["y"] = 0, ["param1"] = 4, ["z"] = 19, ["name"] = "default:stone"}, {["x"] = 6, ["y"] = 0, ["param1"] = 4, ["z"] = 20, ["name"] = "default:stone"}, {["x"] = 6, ["y"] = 0, ["param1"] = 4, ["z"] = 21, ["name"] = "default:stone"}, {["x"] = 6, ["y"] = 0, ["param1"] = 4, ["z"] = 22, ["name"] = "default:stone"}, {["x"] = 6, ["y"] = 0, ["param1"] = 4, ["z"] = 23, ["name"] = "default:stone"}, {["x"] = 6, ["y"] = 0, ["param1"] = 4, ["z"] = 24, ["name"] = "default:stone"}, {["x"] = 6, ["y"] = 0, ["param1"] = 4, ["z"] = 25, ["name"] = "default:stone"}, {["x"] = 6, ["y"] = 0, ["param1"] = 4, ["z"] = 26, ["name"] = "default:stone"}, {["x"] = 6, ["y"] = 0, ["param1"] = 4, ["z"] = 27, ["name"] = "default:stone"}, {["x"] = 6, ["y"] = 0, ["param1"] = 4, ["z"] = 28, ["name"] = "default:stone"}, {["x"] = 6, ["y"] = 0, ["param1"] = 4, ["z"] = 29, ["name"] = "default:stone"}, {["x"] = 6, ["y"] = 0, ["param1"] = 4, ["z"] = 30, ["name"] = "default:stone"}, {["x"] = 6, ["y"] = 0, ["param1"] = 4, ["z"] = 31, ["name"] = "default:stone"}, {["x"] = 6, ["y"] = 0, ["z"] = 32, ["name"] = "default:stone"}, {["x"] = 6, ["y"] = 0, ["z"] = 33, ["name"] = "default:stone"}, {["x"] = 6, ["y"] = 0, ["z"] = 34, ["name"] = "default:stone"}, {["x"] = 6, ["y"] = 0, ["z"] = 35, ["name"] = "default:stone"}, {["x"] = 6, ["y"] = 1, ["z"] = 0, ["name"] = "default:dirt_with_grass"}, {["x"] = 6, ["y"] = 1, ["z"] = 1, ["name"] = "default:dirt_with_grass"}, {["x"] = 6, ["y"] = 1, ["z"] = 2, ["name"] = "default:dirt_with_grass"}, {["x"] = 6, ["y"] = 1, ["z"] = 3, ["name"] = "default:dirt_with_grass"}, {["x"] = 6, ["y"] = 1, ["z"] = 4, ["name"] = "default:dirt_with_grass"}, {["x"] = 6, ["y"] = 1, ["z"] = 5, ["name"] = "default:stone"}, {["x"] = 6, ["y"] = 1, ["z"] = 6, ["name"] = "default:stone"}, {["x"] = 6, ["y"] = 1, ["z"] = 7, ["name"] = "default:stone"}, {["x"] = 6, ["y"] = 1, ["z"] = 8, ["name"] = "default:stone"}, {["x"] = 6, ["y"] = 1, ["z"] = 9, ["name"] = "default:stone"}, {["x"] = 6, ["y"] = 1, ["z"] = 10, ["name"] = "default:stone"}, {["x"] = 6, ["y"] = 1, ["z"] = 11, ["name"] = "default:stone"}, {["x"] = 6, ["y"] = 1, ["z"] = 12, ["name"] = "default:stone"}, {["x"] = 6, ["y"] = 1, ["z"] = 13, ["name"] = "default:stone"}, {["x"] = 6, ["y"] = 1, ["z"] = 14, ["name"] = "default:stone"}, {["x"] = 6, ["y"] = 1, ["z"] = 15, ["name"] = "default:stone"}, {["x"] = 6, ["y"] = 1, ["param1"] = 4, ["z"] = 16, ["name"] = "default:stone"}, {["x"] = 6, ["y"] = 1, ["param1"] = 4, ["z"] = 17, ["name"] = "default:stone"}, {["x"] = 6, ["y"] = 1, ["param1"] = 4, ["z"] = 18, ["name"] = "default:stone"}, {["x"] = 6, ["y"] = 1, ["param1"] = 4, ["z"] = 19, ["name"] = "default:stone"}, {["x"] = 6, ["y"] = 1, ["param1"] = 4, ["z"] = 20, ["name"] = "default:stone"}, {["x"] = 6, ["y"] = 1, ["param1"] = 4, ["z"] = 21, ["name"] = "default:stone"}, {["x"] = 6, ["y"] = 1, ["param1"] = 4, ["z"] = 22, ["name"] = "default:stone"}, {["x"] = 6, ["y"] = 1, ["param1"] = 4, ["z"] = 23, ["name"] = "default:stone"}, {["x"] = 6, ["y"] = 1, ["param1"] = 4, ["z"] = 24, ["name"] = "default:stone"}, {["x"] = 6, ["y"] = 1, ["param1"] = 4, ["z"] = 25, ["name"] = "default:stone"}, {["x"] = 6, ["y"] = 1, ["param1"] = 4, ["z"] = 26, ["name"] = "default:stone"}, {["x"] = 6, ["y"] = 1, ["param1"] = 4, ["z"] = 27, ["name"] = "default:stone"}, {["x"] = 6, ["y"] = 1, ["param1"] = 4, ["z"] = 28, ["name"] = "default:stone"}, {["x"] = 6, ["y"] = 1, ["param1"] = 4, ["z"] = 29, ["name"] = "default:stone"}, {["x"] = 6, ["y"] = 1, ["param1"] = 4, ["z"] = 30, ["name"] = "default:stone"}, {["x"] = 6, ["y"] = 1, ["param1"] = 4, ["z"] = 31, ["name"] = "default:stone"}, {["x"] = 6, ["y"] = 1, ["z"] = 32, ["name"] = "default:dirt_with_grass"}, {["x"] = 6, ["y"] = 1, ["z"] = 33, ["name"] = "default:dirt_with_grass"}, {["x"] = 6, ["y"] = 1, ["z"] = 34, ["name"] = "default:dirt_with_grass"}, {["x"] = 6, ["y"] = 1, ["z"] = 35, ["name"] = "default:dirt_with_grass"}, {["x"] = 6, ["y"] = 2, ["param1"] = 15, ["z"] = 1, ["name"] = "flowers:viola"}, {["x"] = 6, ["y"] = 2, ["z"] = 5, ["name"] = "default:dirt_with_grass"}, {["x"] = 6, ["y"] = 2, ["z"] = 6, ["name"] = "default:dirt_with_grass"}, {["x"] = 6, ["y"] = 2, ["z"] = 7, ["name"] = "default:dirt_with_grass"}, {["x"] = 6, ["y"] = 2, ["z"] = 8, ["name"] = "default:dirt_with_grass"}, {["x"] = 6, ["y"] = 2, ["z"] = 9, ["name"] = "default:dirt_with_grass"}, {["x"] = 6, ["y"] = 2, ["z"] = 10, ["name"] = "default:dirt"}, {["x"] = 6, ["y"] = 2, ["z"] = 11, ["name"] = "bakedclay:white"}, {["x"] = 6, ["y"] = 2, ["z"] = 12, ["name"] = "bakedclay:white"}, {["x"] = 6, ["y"] = 2, ["z"] = 13, ["name"] = "bakedclay:white"}, {["x"] = 6, ["y"] = 2, ["z"] = 14, ["name"] = "bakedclay:white"}, {["x"] = 6, ["y"] = 2, ["z"] = 15, ["name"] = "bakedclay:white"}, {["x"] = 6, ["y"] = 2, ["param1"] = 26, ["z"] = 16, ["name"] = "bakedclay:white"}, {["x"] = 6, ["y"] = 2, ["param1"] = 26, ["z"] = 17, ["name"] = "bakedclay:white"}, {["x"] = 6, ["y"] = 2, ["param1"] = 26, ["z"] = 18, ["name"] = "bakedclay:white"}, {["x"] = 6, ["y"] = 2, ["param1"] = 26, ["z"] = 19, ["name"] = "bakedclay:white"}, {["x"] = 6, ["y"] = 2, ["param1"] = 26, ["z"] = 20, ["name"] = "bakedclay:white"}, {["x"] = 6, ["y"] = 2, ["param1"] = 26, ["z"] = 21, ["name"] = "bakedclay:white"}, {["x"] = 6, ["y"] = 2, ["param1"] = 26, ["z"] = 22, ["name"] = "bakedclay:white"}, {["x"] = 6, ["y"] = 2, ["param1"] = 26, ["z"] = 23, ["name"] = "bakedclay:white"}, {["x"] = 6, ["y"] = 2, ["param1"] = 25, ["z"] = 24, ["name"] = "default:dirt"}, {["x"] = 6, ["y"] = 2, ["param1"] = 26, ["z"] = 25, ["name"] = "default:dirt_with_grass"}, {["x"] = 6, ["y"] = 2, ["param1"] = 26, ["z"] = 26, ["name"] = "default:dirt_with_grass"}, {["x"] = 6, ["y"] = 2, ["param1"] = 26, ["z"] = 27, ["name"] = "default:dirt_with_grass"}, {["x"] = 6, ["y"] = 2, ["param1"] = 26, ["z"] = 28, ["name"] = "default:dirt_with_grass"}, {["x"] = 6, ["y"] = 2, ["param1"] = 26, ["z"] = 29, ["name"] = "default:dirt_with_grass"}, {["x"] = 6, ["y"] = 2, ["z"] = 30, ["name"] = "default:dirt_with_grass"}, {["x"] = 6, ["y"] = 2, ["param1"] = 26, ["z"] = 31, ["name"] = "default:dirt_with_grass"}, {["x"] = 6, ["y"] = 2, ["param1"] = 14, ["z"] = 33, ["name"] = "default:blueberry_bush_leaves_with_berries"}, {["x"] = 6, ["y"] = 2, ["param1"] = 14, ["z"] = 34, ["name"] = "default:blueberry_bush_leaves_with_berries"}, {["x"] = 6, ["y"] = 2, ["param1"] = 14, ["z"] = 35, ["name"] = "default:blueberry_bush_leaves_with_berries"}, {["x"] = 6, ["y"] = 3, ["param1"] = 15, ["z"] = 5, ["name"] = "mobs:fence_wood"}, {["x"] = 6, ["y"] = 3, ["param1"] = 15, ["z"] = 6, ["name"] = "mobs:fence_wood"}, {["x"] = 6, ["y"] = 3, ["param1"] = 14, ["z"] = 9, ["name"] = "default:blueberry_bush_leaves_with_berries"}, {["x"] = 6, ["y"] = 3, ["z"] = 10, ["name"] = "mesecons_lightstone:lightstone_violet_off"}, {["x"] = 6, ["y"] = 3, ["z"] = 24, ["name"] = "moreblocks:iron_stone"}, {["x"] = 6, ["y"] = 3, ["param1"] = 14, ["z"] = 31, ["name"] = "mobs:fence_wood"}, {["x"] = 6, ["y"] = 4, ["z"] = 10, ["name"] = "mesecons_lightstone:lightstone_violet_off"}, {["x"] = 6, ["y"] = 4, ["z"] = 24, ["name"] = "moreblocks:iron_stone"}, {["x"] = 6, ["y"] = 5, ["z"] = 10, ["name"] = "mesecons_lightstone:lightstone_violet_off"}, {["x"] = 6, ["y"] = 5, ["z"] = 24, ["name"] = "moreblocks:iron_stone"}, {["x"] = 6, ["y"] = 6, ["z"] = 10, ["name"] = "mesecons_lightstone:lightstone_violet_off"}, {["x"] = 6, ["y"] = 6, ["z"] = 24, ["name"] = "moreblocks:iron_stone"}, {["x"] = 6, ["param2"] = 21, ["y"] = 6, ["param1"] = 108, ["z"] = 25, ["name"] = "stairs:stair_con_violet"}, {["x"] = 6, ["y"] = 7, ["z"] = 10, ["name"] = "mesecons_lightstone:lightstone_violet_off"}, {["x"] = 6, ["y"] = 7, ["param1"] = 246, ["z"] = 25, ["name"] = "mesecons_lightstone:lightstone_violet_off"}, {["x"] = 6, ["y"] = 8, ["z"] = 10, ["name"] = "mesecons_lightstone:lightstone_violet_off"}, {["x"] = 6, ["y"] = 8, ["z"] = 25, ["name"] = "mesecons_lightstone:lightstone_violet_off"}, {["x"] = 6, ["y"] = 9, ["z"] = 10, ["name"] = "mesecons_lightstone:lightstone_violet_off"}, {["x"] = 6, ["y"] = 9, ["z"] = 25, ["name"] = "mesecons_lightstone:lightstone_violet_off"}, {["x"] = 6, ["param2"] = 4, ["y"] = 9, ["param1"] = 30, ["z"] = 27, ["name"] = "bakedclay:stair_baked_clay_white"}, {["x"] = 6, ["y"] = 10, ["param1"] = 15, ["z"] = 9, ["name"] = "bakedclay:white"}, {["x"] = 6, ["y"] = 10, ["param1"] = 15, ["z"] = 10, ["name"] = "mesecons_lightstone:lightstone_violet_off"}, {["x"] = 6, ["y"] = 10, ["param1"] = 15, ["z"] = 11, ["name"] = "bakedclay:white"}, {["x"] = 6, ["y"] = 10, ["param1"] = 15, ["z"] = 12, ["name"] = "bakedclay:white"}, {["x"] = 6, ["y"] = 10, ["param1"] = 15, ["z"] = 13, ["name"] = "bakedclay:white"}, {["x"] = 6, ["y"] = 10, ["param1"] = 15, ["z"] = 14, ["name"] = "bakedclay:white"}, {["x"] = 6, ["y"] = 10, ["param1"] = 14, ["z"] = 15, ["name"] = "bakedclay:white"}, {["x"] = 6, ["y"] = 10, ["param1"] = 14, ["z"] = 16, ["name"] = "bakedclay:white"}, {["x"] = 6, ["y"] = 10, ["param1"] = 15, ["z"] = 17, ["name"] = "bakedclay:white"}, {["x"] = 6, ["y"] = 10, ["param1"] = 15, ["z"] = 18, ["name"] = "bakedclay:white"}, {["x"] = 6, ["y"] = 10, ["param1"] = 15, ["z"] = 19, ["name"] = "bakedclay:white"}, {["x"] = 6, ["y"] = 10, ["param1"] = 15, ["z"] = 20, ["name"] = "bakedclay:white"}, {["x"] = 6, ["y"] = 10, ["param1"] = 15, ["z"] = 21, ["name"] = "bakedclay:white"}, {["x"] = 6, ["y"] = 10, ["param1"] = 15, ["z"] = 22, ["name"] = "bakedclay:white"}, {["x"] = 6, ["y"] = 10, ["param1"] = 15, ["z"] = 23, ["name"] = "bakedclay:white"}, {["x"] = 6, ["y"] = 10, ["param1"] = 15, ["z"] = 24, ["name"] = "bakedclay:white"}, {["x"] = 6, ["y"] = 10, ["z"] = 25, ["name"] = "mesecons_lightstone:lightstone_violet_off"}, {["x"] = 6, ["param2"] = 4, ["y"] = 10, ["param1"] = 30, ["z"] = 26, ["name"] = "bakedclay:stair_baked_clay_white"}, {["x"] = 6, ["param2"] = 3, ["y"] = 11, ["param1"] = 14, ["z"] = 10, ["name"] = "homedecor:fence_wrought_iron"}, {["x"] = 6, ["y"] = 11, ["z"] = 14, ["name"] = "mesecons_lightstone:lightstone_white_off"}, {["x"] = 6, ["y"] = 11, ["z"] = 24, ["name"] = "mesecons_lightstone:lightstone_white_off"}, {["x"] = 6, ["y"] = 12, ["z"] = 14, ["name"] = "mesecons_lightstone:lightstone_white_off"}, {["x"] = 6, ["y"] = 12, ["z"] = 24, ["name"] = "mesecons_lightstone:lightstone_white_off"}, {["x"] = 6, ["y"] = 13, ["z"] = 14, ["name"] = "mesecons_lightstone:lightstone_white_off"}, {["x"] = 6, ["y"] = 13, ["z"] = 24, ["name"] = "mesecons_lightstone:lightstone_white_off"}, {["x"] = 6, ["y"] = 14, ["z"] = 14, ["name"] = "mesecons_lightstone:lightstone_white_off"}, {["x"] = 6, ["y"] = 14, ["z"] = 24, ["name"] = "mesecons_lightstone:lightstone_white_off"}, {["x"] = 6, ["y"] = 15, ["z"] = 14, ["name"] = "mesecons_lightstone:lightstone_white_off"}, {["x"] = 6, ["y"] = 15, ["z"] = 24, ["name"] = "mesecons_lightstone:lightstone_white_off"}, {["x"] = 6, ["param2"] = 1, ["y"] = 16, ["param1"] = 14, ["z"] = 13, ["name"] = "bakedclay:stair_baked_clay_white"}, {["x"] = 6, ["param2"] = 1, ["y"] = 16, ["param1"] = 14, ["z"] = 14, ["name"] = "bakedclay:stair_baked_clay_white"}, {["x"] = 6, ["param2"] = 1, ["y"] = 16, ["param1"] = 13, ["z"] = 15, ["name"] = "bakedclay:stair_baked_clay_white"}, {["x"] = 6, ["param2"] = 1, ["y"] = 16, ["param1"] = 13, ["z"] = 16, ["name"] = "bakedclay:stair_baked_clay_white"}, {["x"] = 6, ["param2"] = 1, ["y"] = 16, ["param1"] = 14, ["z"] = 17, ["name"] = "bakedclay:stair_baked_clay_white"}, {["x"] = 6, ["param2"] = 1, ["y"] = 16, ["param1"] = 14, ["z"] = 18, ["name"] = "bakedclay:stair_baked_clay_white"}, {["x"] = 6, ["param2"] = 1, ["y"] = 16, ["param1"] = 14, ["z"] = 19, ["name"] = "bakedclay:stair_baked_clay_white"}, {["x"] = 6, ["param2"] = 1, ["y"] = 16, ["param1"] = 14, ["z"] = 20, ["name"] = "bakedclay:stair_baked_clay_white"}, {["x"] = 6, ["param2"] = 1, ["y"] = 16, ["param1"] = 14, ["z"] = 21, ["name"] = "bakedclay:stair_baked_clay_white"}, {["x"] = 6, ["param2"] = 1, ["y"] = 16, ["param1"] = 14, ["z"] = 22, ["name"] = "bakedclay:stair_baked_clay_white"}, {["x"] = 6, ["param2"] = 19, ["y"] = 16, ["param1"] = 14, ["z"] = 23, ["name"] = "bakedclay:stair_baked_clay_white"}, {["x"] = 6, ["param2"] = 1, ["y"] = 16, ["param1"] = 14, ["z"] = 24, ["name"] = "bakedclay:stair_baked_clay_white"}, {["x"] = 6, ["param2"] = 1, ["y"] = 16, ["param1"] = 14, ["z"] = 25, ["name"] = "bakedclay:stair_baked_clay_white"}, {["x"] = 7, ["y"] = 0, ["z"] = 0, ["name"] = "default:stone"}, {["x"] = 7, ["y"] = 0, ["z"] = 1, ["name"] = "default:stone"}, {["x"] = 7, ["y"] = 0, ["z"] = 2, ["name"] = "default:stone"}, {["x"] = 7, ["y"] = 0, ["z"] = 3, ["name"] = "default:stone"}, {["x"] = 7, ["y"] = 0, ["z"] = 4, ["name"] = "default:stone"}, {["x"] = 7, ["y"] = 0, ["z"] = 5, ["name"] = "default:stone"}, {["x"] = 7, ["y"] = 0, ["z"] = 6, ["name"] = "default:stone"}, {["x"] = 7, ["y"] = 0, ["z"] = 7, ["name"] = "default:stone"}, {["x"] = 7, ["y"] = 0, ["z"] = 8, ["name"] = "default:stone"}, {["x"] = 7, ["y"] = 0, ["z"] = 9, ["name"] = "default:stone"}, {["x"] = 7, ["y"] = 0, ["z"] = 10, ["name"] = "default:stone"}, {["x"] = 7, ["y"] = 0, ["z"] = 11, ["name"] = "default:stone"}, {["x"] = 7, ["y"] = 0, ["z"] = 12, ["name"] = "default:stone"}, {["x"] = 7, ["y"] = 0, ["z"] = 13, ["name"] = "default:stone"}, {["x"] = 7, ["y"] = 0, ["z"] = 14, ["name"] = "default:stone"}, {["x"] = 7, ["y"] = 0, ["z"] = 15, ["name"] = "default:stone"}, {["x"] = 7, ["y"] = 0, ["param1"] = 4, ["z"] = 16, ["name"] = "default:stone"}, {["x"] = 7, ["y"] = 0, ["param1"] = 4, ["z"] = 17, ["name"] = "default:stone"}, {["x"] = 7, ["y"] = 0, ["param1"] = 4, ["z"] = 18, ["name"] = "default:stone"}, {["x"] = 7, ["y"] = 0, ["param1"] = 4, ["z"] = 19, ["name"] = "default:stone"}, {["x"] = 7, ["y"] = 0, ["param1"] = 4, ["z"] = 20, ["name"] = "default:stone"}, {["x"] = 7, ["y"] = 0, ["param1"] = 4, ["z"] = 21, ["name"] = "default:stone"}, {["x"] = 7, ["y"] = 0, ["param1"] = 4, ["z"] = 22, ["name"] = "default:stone"}, {["x"] = 7, ["y"] = 0, ["param1"] = 4, ["z"] = 23, ["name"] = "default:stone"}, {["x"] = 7, ["y"] = 0, ["param1"] = 4, ["z"] = 24, ["name"] = "default:stone"}, {["x"] = 7, ["y"] = 0, ["param1"] = 4, ["z"] = 25, ["name"] = "default:stone"}, {["x"] = 7, ["y"] = 0, ["param1"] = 4, ["z"] = 26, ["name"] = "default:stone"}, {["x"] = 7, ["y"] = 0, ["param1"] = 4, ["z"] = 27, ["name"] = "default:stone"}, {["x"] = 7, ["y"] = 0, ["param1"] = 4, ["z"] = 28, ["name"] = "default:stone"}, {["x"] = 7, ["y"] = 0, ["param1"] = 4, ["z"] = 29, ["name"] = "default:stone"}, {["x"] = 7, ["y"] = 0, ["param1"] = 4, ["z"] = 30, ["name"] = "default:stone"}, {["x"] = 7, ["y"] = 0, ["param1"] = 4, ["z"] = 31, ["name"] = "default:stone"}, {["x"] = 7, ["y"] = 0, ["z"] = 32, ["name"] = "default:stone"}, {["x"] = 7, ["y"] = 0, ["z"] = 33, ["name"] = "default:stone"}, {["x"] = 7, ["y"] = 0, ["z"] = 34, ["name"] = "default:stone"}, {["x"] = 7, ["y"] = 0, ["z"] = 35, ["name"] = "default:stone"}, {["x"] = 7, ["y"] = 1, ["z"] = 0, ["name"] = "default:dirt_with_grass"}, {["x"] = 7, ["y"] = 1, ["z"] = 1, ["name"] = "default:dirt_with_grass"}, {["x"] = 7, ["y"] = 1, ["z"] = 2, ["name"] = "default:dirt_with_grass"}, {["x"] = 7, ["y"] = 1, ["z"] = 3, ["name"] = "default:dirt_with_grass"}, {["x"] = 7, ["y"] = 1, ["z"] = 4, ["name"] = "default:stone"}, {["x"] = 7, ["y"] = 1, ["z"] = 5, ["name"] = "default:stone"}, {["x"] = 7, ["y"] = 1, ["z"] = 6, ["name"] = "default:stone"}, {["x"] = 7, ["y"] = 1, ["z"] = 7, ["name"] = "default:stone"}, {["x"] = 7, ["y"] = 1, ["z"] = 8, ["name"] = "default:stone"}, {["x"] = 7, ["y"] = 1, ["z"] = 9, ["name"] = "default:stone"}, {["x"] = 7, ["y"] = 1, ["z"] = 10, ["name"] = "default:stone"}, {["x"] = 7, ["y"] = 1, ["z"] = 11, ["name"] = "default:stone"}, {["x"] = 7, ["y"] = 1, ["z"] = 12, ["name"] = "default:stone"}, {["x"] = 7, ["y"] = 1, ["z"] = 13, ["name"] = "default:stone"}, {["x"] = 7, ["y"] = 1, ["z"] = 14, ["name"] = "default:stone"}, {["x"] = 7, ["y"] = 1, ["z"] = 15, ["name"] = "default:stone"}, {["x"] = 7, ["y"] = 1, ["param1"] = 4, ["z"] = 16, ["name"] = "default:stone"}, {["x"] = 7, ["y"] = 1, ["param1"] = 4, ["z"] = 17, ["name"] = "default:stone"}, {["x"] = 7, ["y"] = 1, ["param1"] = 4, ["z"] = 18, ["name"] = "default:stone"}, {["x"] = 7, ["y"] = 1, ["param1"] = 4, ["z"] = 19, ["name"] = "default:stone"}, {["x"] = 7, ["y"] = 1, ["param1"] = 4, ["z"] = 20, ["name"] = "default:stone"}, {["x"] = 7, ["y"] = 1, ["param1"] = 4, ["z"] = 21, ["name"] = "default:stone"}, {["x"] = 7, ["y"] = 1, ["param1"] = 4, ["z"] = 22, ["name"] = "default:stone"}, {["x"] = 7, ["y"] = 1, ["param1"] = 4, ["z"] = 23, ["name"] = "default:stone"}, {["x"] = 7, ["y"] = 1, ["param1"] = 4, ["z"] = 24, ["name"] = "default:stone"}, {["x"] = 7, ["y"] = 1, ["param1"] = 4, ["z"] = 25, ["name"] = "default:stone"}, {["x"] = 7, ["y"] = 1, ["param1"] = 4, ["z"] = 26, ["name"] = "default:stone"}, {["x"] = 7, ["y"] = 1, ["param1"] = 4, ["z"] = 27, ["name"] = "default:stone"}, {["x"] = 7, ["y"] = 1, ["param1"] = 4, ["z"] = 28, ["name"] = "default:stone"}, {["x"] = 7, ["y"] = 1, ["param1"] = 4, ["z"] = 29, ["name"] = "default:stone"}, {["x"] = 7, ["y"] = 1, ["param1"] = 4, ["z"] = 30, ["name"] = "default:stone"}, {["x"] = 7, ["y"] = 1, ["param1"] = 4, ["z"] = 31, ["name"] = "default:stone"}, {["x"] = 7, ["y"] = 1, ["z"] = 32, ["name"] = "default:stone"}, {["x"] = 7, ["y"] = 1, ["z"] = 33, ["name"] = "default:dirt_with_grass"}, {["x"] = 7, ["y"] = 1, ["z"] = 34, ["name"] = "default:dirt_with_grass"}, {["x"] = 7, ["y"] = 1, ["z"] = 35, ["name"] = "default:dirt_with_grass"}, {["x"] = 7, ["y"] = 2, ["param1"] = 14, ["z"] = 0, ["name"] = "flowers:dandelion_white"}, {["x"] = 7, ["y"] = 2, ["z"] = 4, ["name"] = "default:dirt_with_grass"}, {["x"] = 7, ["y"] = 2, ["z"] = 5, ["name"] = "default:dirt_with_grass"}, {["x"] = 7, ["y"] = 2, ["z"] = 6, ["name"] = "maptools:grass"}, {["x"] = 7, ["y"] = 2, ["z"] = 7, ["name"] = "maptools:grass"}, {["x"] = 7, ["y"] = 2, ["z"] = 8, ["name"] = "maptools:grass"}, {["x"] = 7, ["y"] = 2, ["z"] = 9, ["name"] = "maptools:grass"}, {["x"] = 7, ["y"] = 2, ["z"] = 10, ["name"] = "maptools:grass"}, {["x"] = 7, ["y"] = 2, ["z"] = 11, ["name"] = "bakedclay:white"}, {["x"] = 7, ["y"] = 2, ["z"] = 12, ["name"] = "bakedclay:white"}, {["x"] = 7, ["y"] = 2, ["z"] = 13, ["name"] = "bakedclay:white"}, {["x"] = 7, ["y"] = 2, ["z"] = 14, ["name"] = "bakedclay:white"}, {["x"] = 7, ["y"] = 2, ["z"] = 15, ["name"] = "bakedclay:white"}, {["x"] = 7, ["y"] = 2, ["param1"] = 255, ["z"] = 16, ["name"] = "bakedclay:white"}, {["x"] = 7, ["y"] = 2, ["param1"] = 255, ["z"] = 17, ["name"] = "bakedclay:white"}, {["x"] = 7, ["y"] = 2, ["param1"] = 255, ["z"] = 18, ["name"] = "bakedclay:white"}, {["x"] = 7, ["y"] = 2, ["param1"] = 255, ["z"] = 19, ["name"] = "bakedclay:white"}, {["x"] = 7, ["y"] = 2, ["param1"] = 255, ["z"] = 20, ["name"] = "bakedclay:white"}, {["x"] = 7, ["y"] = 2, ["param1"] = 255, ["z"] = 21, ["name"] = "bakedclay:white"}, {["x"] = 7, ["y"] = 2, ["param1"] = 255, ["z"] = 22, ["name"] = "bakedclay:white"}, {["x"] = 7, ["y"] = 2, ["param1"] = 255, ["z"] = 23, ["name"] = "bakedclay:white"}, {["x"] = 7, ["y"] = 2, ["param1"] = 255, ["z"] = 24, ["name"] = "maptools:grass"}, {["x"] = 7, ["y"] = 2, ["param1"] = 255, ["z"] = 25, ["name"] = "maptools:grass"}, {["x"] = 7, ["y"] = 2, ["param1"] = 255, ["z"] = 26, ["name"] = "maptools:grass"}, {["x"] = 7, ["y"] = 2, ["param1"] = 255, ["z"] = 27, ["name"] = "maptools:grass"}, {["x"] = 7, ["y"] = 2, ["param1"] = 255, ["z"] = 28, ["name"] = "maptools:grass"}, {["x"] = 7, ["y"] = 2, ["param1"] = 255, ["z"] = 29, ["name"] = "maptools:grass"}, {["x"] = 7, ["y"] = 2, ["param1"] = 255, ["z"] = 30, ["name"] = "maptools:grass"}, {["x"] = 7, ["y"] = 2, ["param1"] = 255, ["z"] = 31, ["name"] = "maptools:grass"}, {["x"] = 7, ["y"] = 2, ["z"] = 32, ["name"] = "default:dirt_with_grass"}, {["x"] = 7, ["y"] = 2, ["param1"] = 14, ["z"] = 33, ["name"] = "default:blueberry_bush_leaves_with_berries"}, {["x"] = 7, ["y"] = 3, ["param1"] = 15, ["z"] = 4, ["name"] = "mobs:fence_wood"}, {["x"] = 7, ["y"] = 3, ["param1"] = 15, ["z"] = 5, ["name"] = "mobs:fence_wood"}, {["x"] = 7, ["y"] = 3, ["param1"] = 14, ["z"] = 9, ["name"] = "default:blueberry_bush_leaves_with_berries"}, {["x"] = 7, ["y"] = 3, ["z"] = 10, ["name"] = "mesecons_lightstone:lightstone_violet_off"}, {["x"] = 7, ["y"] = 3, ["z"] = 24, ["name"] = "moreblocks:iron_stone"}, {["x"] = 7, ["y"] = 3, ["param1"] = 14, ["z"] = 31, ["name"] = "mobs:fence_wood"}, {["x"] = 7, ["y"] = 3, ["param1"] = 15, ["z"] = 32, ["name"] = "mobs:fence_wood"}, {["x"] = 7, ["y"] = 4, ["z"] = 10, ["name"] = "mesecons_lightstone:lightstone_violet_off"}, {["x"] = 7, ["y"] = 4, ["z"] = 24, ["name"] = "moreblocks:iron_stone"}, {["x"] = 7, ["y"] = 5, ["z"] = 10, ["name"] = "mesecons_lightstone:lightstone_violet_off"}, {["x"] = 7, ["y"] = 5, ["z"] = 24, ["name"] = "moreblocks:iron_stone"}, {["x"] = 7, ["y"] = 6, ["z"] = 10, ["name"] = "mesecons_lightstone:lightstone_violet_off"}, {["x"] = 7, ["y"] = 6, ["param1"] = 142, ["z"] = 24, ["name"] = "default:glass"}, {["x"] = 7, ["y"] = 7, ["z"] = 10, ["name"] = "mesecons_lightstone:lightstone_violet_off"}, {["x"] = 7, ["y"] = 7, ["z"] = 24, ["name"] = "moreblocks:iron_stone"}, {["x"] = 7, ["param2"] = 21, ["y"] = 7, ["param1"] = 108, ["z"] = 25, ["name"] = "stairs:stair_con_violet"}, {["x"] = 7, ["y"] = 8, ["z"] = 10, ["name"] = "mesecons_lightstone:lightstone_violet_off"}, {["x"] = 7, ["y"] = 8, ["param1"] = 246, ["z"] = 25, ["name"] = "mesecons_lightstone:lightstone_violet_off"}, {["x"] = 7, ["y"] = 9, ["z"] = 10, ["name"] = "mesecons_lightstone:lightstone_violet_off"}, {["x"] = 7, ["y"] = 9, ["param1"] = 238, ["z"] = 14, ["name"] = "homedecor:glowlight_quarter_14"}, {["x"] = 7, ["y"] = 9, ["param1"] = 238, ["z"] = 18, ["name"] = "homedecor:glowlight_quarter_14"}, {["x"] = 7, ["y"] = 9, ["param1"] = 238, ["z"] = 21, ["name"] = "homedecor:glowlight_quarter_14"}, {["x"] = 7, ["y"] = 9, ["z"] = 25, ["name"] = "mesecons_lightstone:lightstone_violet_off"}, {["x"] = 7, ["param2"] = 4, ["y"] = 9, ["param1"] = 46, ["z"] = 27, ["name"] = "bakedclay:stair_baked_clay_white"}, {["x"] = 7, ["y"] = 10, ["param1"] = 15, ["z"] = 9, ["name"] = "bakedclay:white"}, {["x"] = 7, ["y"] = 10, ["param1"] = 15, ["z"] = 10, ["name"] = "mesecons_lightstone:lightstone_violet_off"}, {["x"] = 7, ["y"] = 10, ["param1"] = 15, ["z"] = 11, ["name"] = "bakedclay:white"}, {["x"] = 7, ["y"] = 10, ["param1"] = 15, ["z"] = 12, ["name"] = "bakedclay:white"}, {["x"] = 7, ["y"] = 10, ["param1"] = 15, ["z"] = 13, ["name"] = "bakedclay:white"}, {["x"] = 7, ["y"] = 10, ["z"] = 14, ["name"] = "bakedclay:white"}, {["x"] = 7, ["y"] = 10, ["param1"] = 14, ["z"] = 15, ["name"] = "bakedclay:white"}, {["x"] = 7, ["y"] = 10, ["param1"] = 14, ["z"] = 16, ["name"] = "bakedclay:white"}, {["x"] = 7, ["y"] = 10, ["param1"] = 15, ["z"] = 17, ["name"] = "bakedclay:white"}, {["x"] = 7, ["y"] = 10, ["param1"] = 15, ["z"] = 18, ["name"] = "bakedclay:white"}, {["x"] = 7, ["y"] = 10, ["param1"] = 15, ["z"] = 19, ["name"] = "bakedclay:white"}, {["x"] = 7, ["y"] = 10, ["param1"] = 15, ["z"] = 20, ["name"] = "bakedclay:white"}, {["x"] = 7, ["y"] = 10, ["param1"] = 15, ["z"] = 21, ["name"] = "bakedclay:white"}, {["x"] = 7, ["y"] = 10, ["param1"] = 15, ["z"] = 22, ["name"] = "bakedclay:white"}, {["x"] = 7, ["y"] = 10, ["param1"] = 15, ["z"] = 23, ["name"] = "bakedclay:white"}, {["x"] = 7, ["y"] = 10, ["param1"] = 15, ["z"] = 24, ["name"] = "bakedclay:white"}, {["x"] = 7, ["y"] = 10, ["z"] = 25, ["name"] = "mesecons_lightstone:lightstone_violet_off"}, {["x"] = 7, ["param2"] = 4, ["y"] = 10, ["param1"] = 46, ["z"] = 26, ["name"] = "bakedclay:stair_baked_clay_white"}, {["x"] = 7, ["param2"] = 3, ["y"] = 11, ["param1"] = 14, ["z"] = 10, ["name"] = "homedecor:fence_wrought_iron"}, {["x"] = 7, ["y"] = 11, ["param1"] = 13, ["z"] = 14, ["name"] = "homedecor:window_plain"}, {["x"] = 7, ["y"] = 11, ["z"] = 25, ["name"] = "bakedclay:white"}, {["x"] = 7, ["y"] = 12, ["param1"] = 13, ["z"] = 14, ["name"] = "homedecor:window_plain"},