5:return {{["y"] = 0, ["x"] = 0, ["name"] = "default:dry_dirt", ["z"] = 9}, {["y"] = 0, ["x"] = 0, ["name"] = "default:desert_sand", ["z"] = 10, ["param1"] = 35}, {["y"] = 0, ["x"] = 0, ["name"] = "default:desert_sand", ["z"] = 11, ["param1"] = 35}, {["y"] = 0, ["x"] = 0, ["name"] = "default:desert_sand", ["z"] = 12, ["param1"] = 35}, {["y"] = 0, ["x"] = 0, ["name"] = "default:desert_sand", ["z"] = 13, ["param1"] = 35}, {["y"] = 0, ["x"] = 0, ["name"] = "default:desert_sand", ["z"] = 25, ["param1"] = 35}, {["y"] = 0, ["x"] = 0, ["name"] = "default:desert_sand", ["z"] = 26, ["param1"] = 35}, {["y"] = 0, ["x"] = 0, ["name"] = "default:desert_sand", ["z"] = 27, ["param1"] = 35}, {["y"] = 0, ["x"] = 0, ["name"] = "default:desert_sand", ["z"] = 28, ["param1"] = 35}, {["y"] = 0, ["x"] = 0, ["name"] = "default:desert_sand", ["z"] = 29, ["param1"] = 35}, {["y"] = 0, ["x"] = 0, ["name"] = "default:desert_sand", ["z"] = 30, ["param1"] = 35}, {["y"] = 0, ["x"] = 0, ["name"] = "default:desert_sand", ["z"] = 31, ["param1"] = 35}, {["y"] = 0, ["x"] = 0, ["name"] = "default:desert_sand", ["z"] = 32, ["param1"] = 35}, {["y"] = 0, ["x"] = 0, ["name"] = "default:desert_sand", ["z"] = 33, ["param1"] = 35}, {["y"] = 0, ["x"] = 0, ["name"] = "default:desert_sand", ["z"] = 34, ["param1"] = 35}, {["y"] = 0, ["x"] = 0, ["name"] = "default:desert_sand", ["z"] = 35, ["param1"] = 35}, {["y"] = 0, ["x"] = 0, ["name"] = "default:desert_sand", ["z"] = 36, ["param1"] = 35}, {["y"] = 0, ["x"] = 0, ["name"] = "default:desert_sand", ["z"] = 37, ["param1"] = 35}, {["y"] = 0, ["x"] = 0, ["name"] = "default:desert_sand", ["z"] = 38, ["param1"] = 35}, {["y"] = 0, ["x"] = 0, ["name"] = "default:desert_sand", ["z"] = 39, ["param1"] = 35}, {["y"] = 0, ["x"] = 0, ["name"] = "default:desert_sand", ["z"] = 40, ["param1"] = 35}, {["y"] = 0, ["x"] = 0, ["name"] = "default:desert_sand", ["z"] = 41, ["param1"] = 35}, {["y"] = 0, ["x"] = 0, ["name"] = "default:desert_sand", ["z"] = 42, ["param1"] = 35}, {["y"] = 0, ["x"] = 0, ["name"] = "default:desert_sand", ["z"] = 43, ["param1"] = 35}, {["y"] = 0, ["x"] = 0, ["name"] = "default:desert_sand", ["z"] = 44, ["param1"] = 35}, {["y"] = 0, ["x"] = 0, ["name"] = "default:desert_sand", ["z"] = 45, ["param1"] = 35}, {["y"] = 0, ["x"] = 0, ["name"] = "default:desert_sand", ["z"] = 46, ["param1"] = 35}, {["y"] = 0, ["x"] = 0, ["name"] = "default:desert_sand", ["z"] = 47, ["param1"] = 35}, {["y"] = 0, ["x"] = 0, ["name"] = "default:desert_sand", ["z"] = 48, ["param1"] = 35}, {["y"] = 0, ["x"] = 0, ["name"] = "default:desert_sand", ["z"] = 49, ["param1"] = 35}, {["y"] = 0, ["x"] = 0, ["name"] = "default:desert_sand", ["z"] = 50, ["param1"] = 35}, {["y"] = 0, ["x"] = 0, ["name"] = "default:desert_sand", ["z"] = 51, ["param1"] = 35}, {["y"] = 0, ["x"] = 0, ["name"] = "default:desert_sand", ["z"] = 52, ["param1"] = 35}, {["y"] = 0, ["x"] = 0, ["name"] = "default:desert_sand", ["z"] = 53, ["param1"] = 35}, {["y"] = 0, ["x"] = 0, ["name"] = "default:desert_sand", ["z"] = 54, ["param1"] = 35}, {["y"] = 0, ["x"] = 0, ["name"] = "default:desert_sand", ["z"] = 55, ["param1"] = 35}, {["y"] = 0, ["x"] = 0, ["name"] = "default:desert_sand", ["z"] = 56, ["param1"] = 35}, {["y"] = 0, ["x"] = 0, ["name"] = "default:desert_sand", ["z"] = 57, ["param1"] = 35}, {["y"] = 0, ["x"] = 0, ["name"] = "default:desert_sand", ["z"] = 58, ["param1"] = 35}, {["y"] = 0, ["x"] = 0, ["name"] = "default:desert_sand", ["z"] = 59, ["param1"] = 35}, {["y"] = 0, ["x"] = 0, ["name"] = "default:desert_sand", ["z"] = 60, ["param1"] = 35}, {["y"] = 0, ["x"] = 0, ["name"] = "default:desert_sand", ["z"] = 61, ["param1"] = 35}, {["y"] = 0, ["x"] = 0, ["name"] = "default:desert_sand", ["z"] = 62, ["param1"] = 35}, {["y"] = 0, ["x"] = 0, ["name"] = "default:desert_sand", ["z"] = 63, ["param1"] = 35}, {["y"] = 0, ["x"] = 0, ["name"] = "default:desert_sand", ["z"] = 64, ["param1"] = 35}, {["y"] = 0, ["x"] = 0, ["name"] = "default:desert_sand", ["z"] = 65, ["param1"] = 35}, {["y"] = 0, ["x"] = 0, ["name"] = "default:desert_sand", ["z"] = 66, ["param1"] = 35}, {["y"] = 0, ["x"] = 0, ["name"] = "default:desert_sand", ["z"] = 67, ["param1"] = 35}, {["y"] = 0, ["x"] = 0, ["name"] = "default:desert_sand", ["z"] = 68, ["param1"] = 35}, {["y"] = 0, ["x"] = 0, ["name"] = "default:desert_sand", ["z"] = 69, ["param1"] = 35}, {["y"] = 0, ["x"] = 0, ["name"] = "default:desert_sand", ["z"] = 70, ["param1"] = 35}, {["y"] = 0, ["x"] = 0, ["name"] = "default:desert_sand", ["z"] = 71, ["param1"] = 35}, {["y"] = 0, ["x"] = 0, ["name"] = "default:desert_sand", ["z"] = 72, ["param1"] = 35}, {["y"] = 0, ["x"] = 0, ["name"] = "default:desert_sand", ["z"] = 73, ["param1"] = 35}, {["y"] = 0, ["x"] = 0, ["name"] = "default:desert_sand", ["z"] = 74, ["param1"] = 35}, {["y"] = 0, ["x"] = 0, ["name"] = "default:desert_sand", ["z"] = 75, ["param1"] = 35}, {["y"] = 0, ["x"] = 0, ["name"] = "default:desert_sand", ["z"] = 76, ["param1"] = 35}, {["y"] = 0, ["x"] = 0, ["name"] = "default:desert_sand", ["z"] = 77, ["param1"] = 35}, {["y"] = 0, ["x"] = 0, ["name"] = "default:desert_sand", ["z"] = 78, ["param1"] = 35}, {["y"] = 0, ["x"] = 0, ["name"] = "default:desert_sand", ["z"] = 79, ["param1"] = 35}, {["y"] = 0, ["x"] = 0, ["name"] = "default:desert_sand", ["z"] = 80, ["param1"] = 35}, {["y"] = 0, ["x"] = 0, ["name"] = "default:desert_sand", ["z"] = 81, ["param1"] = 35}, {["y"] = 0, ["x"] = 0, ["name"] = "default:desert_sand", ["z"] = 82, ["param1"] = 35}, {["y"] = 0, ["x"] = 0, ["name"] = "default:desert_sand", ["z"] = 83, ["param1"] = 35}, {["y"] = 0, ["x"] = 0, ["name"] = "default:desert_sand", ["z"] = 84, ["param1"] = 35}, {["y"] = 0, ["x"] = 0, ["name"] = "default:desert_sand", ["z"] = 85, ["param1"] = 35}, {["y"] = 0, ["x"] = 0, ["name"] = "default:desert_sand", ["z"] = 86, ["param1"] = 35}, {["y"] = 0, ["x"] = 0, ["name"] = "default:desert_sand", ["z"] = 87, ["param1"] = 35}, {["y"] = 0, ["x"] = 0, ["name"] = "default:desert_sand", ["z"] = 88, ["param1"] = 35}, {["y"] = 0, ["x"] = 0, ["name"] = "default:desert_sand", ["z"] = 89, ["param1"] = 35}, {["y"] = 0, ["x"] = 0, ["name"] = "default:desert_sand", ["z"] = 90, ["param1"] = 35}, {["y"] = 0, ["x"] = 0, ["name"] = "default:desert_sand", ["z"] = 91, ["param1"] = 35}, {["y"] = 0, ["x"] = 0, ["name"] = "default:desert_sand", ["z"] = 92, ["param1"] = 35}, {["y"] = 0, ["x"] = 0, ["name"] = "default:desert_sand", ["z"] = 93, ["param1"] = 35}, {["y"] = 0, ["x"] = 0, ["name"] = "default:desert_sand", ["z"] = 94, ["param1"] = 35}, {["y"] = 0, ["x"] = 0, ["name"] = "default:desert_sand", ["z"] = 95, ["param1"] = 35}, {["y"] = 0, ["x"] = 0, ["name"] = "default:desert_sand", ["z"] = 96, ["param1"] = 35}, {["y"] = 0, ["x"] = 0, ["name"] = "default:desert_sand", ["z"] = 97, ["param1"] = 35}, {["y"] = 0, ["x"] = 0, ["name"] = "default:desert_sand", ["z"] = 98, ["param1"] = 35}, {["y"] = 0, ["x"] = 0, ["name"] = "default:desert_sand", ["z"] = 99, ["param1"] = 35}, {["y"] = 0, ["x"] = 0, ["name"] = "default:desert_sand", ["z"] = 100, ["param1"] = 35}, {["y"] = 0, ["x"] = 0, ["name"] = "default:desert_sand", ["z"] = 101, ["param1"] = 35}, {["y"] = 0, ["x"] = 0, ["name"] = "default:desert_sand", ["z"] = 102, ["param1"] = 35}, {["y"] = 0, ["x"] = 0, ["name"] = "default:desert_sand", ["z"] = 103, ["param1"] = 35}, {["y"] = 0, ["x"] = 0, ["name"] = "default:desert_sand", ["z"] = 104, ["param1"] = 35}, {["y"] = 0, ["x"] = 0, ["name"] = "default:desert_sand", ["z"] = 105, ["param1"] = 35}, {["y"] = 0, ["x"] = 0, ["name"] = "default:desert_sand", ["z"] = 106, ["param1"] = 35}, {["y"] = 0, ["x"] = 0, ["name"] = "default:dry_dirt", ["z"] = 107}, {["y"] = 0, ["x"] = 0, ["name"] = "default:dry_dirt", ["z"] = 108}, {["y"] = 0, ["x"] = 0, ["name"] = "default:desert_sand", ["z"] = 109, ["param1"] = 35}, {["y"] = 0, ["x"] = 0, ["name"] = "default:desert_sand", ["z"] = 110, ["param1"] = 35}, {["y"] = 0, ["x"] = 0, ["name"] = "default:desert_sand", ["z"] = 111, ["param1"] = 35}, {["y"] = 0, ["x"] = 0, ["name"] = "default:desert_sand", ["z"] = 112, ["param1"] = 35}, {["y"] = 0, ["x"] = 0, ["name"] = "default:desert_sand", ["z"] = 113, ["param1"] = 35}, {["y"] = 0, ["x"] = 0, ["name"] = "default:desert_sand", ["z"] = 114, ["param1"] = 35}, {["y"] = 0, ["x"] = 0, ["name"] = "default:desert_sand", ["z"] = 115, ["param1"] = 35}, {["y"] = 0, ["x"] = 0, ["name"] = "default:dry_dirt", ["z"] = 116}, {["y"] = 10, ["x"] = 0, ["name"] = "default:silver_sandstone_brick", ["z"] = 0}, {["y"] = 10, ["x"] = 0, ["name"] = "default:silver_sandstone_brick", ["z"] = 1}, {["y"] = 10, ["x"] = 0, ["name"] = "default:silver_sandstone_brick", ["z"] = 2}, {["y"] = 11, ["x"] = 0, ["name"] = "default:silver_sandstone_brick", ["z"] = 0}, {["y"] = 12, ["x"] = 0, ["name"] = "default:silver_sandstone_brick", ["z"] = 0}, {["y"] = 13, ["x"] = 0, ["name"] = "default:silver_sandstone_brick", ["z"] = 0}, {["y"] = 14, ["x"] = 0, ["name"] = "default:silver_sandstone_brick", ["z"] = 0}, {["y"] = 15, ["x"] = 0, ["name"] = "default:silver_sandstone_brick", ["z"] = 0}, {["y"] = 16, ["x"] = 0, ["name"] = "default:silver_sandstone_brick", ["z"] = 0}, {["y"] = 17, ["x"] = 0, ["name"] = "default:silver_sandstone_brick", ["z"] = 0}, {["y"] = 0, ["x"] = 1, ["name"] = "default:silver_sandstone_brick", ["z"] = 5, ["param1"] = 17}, {["y"] = 0, ["x"] = 1, ["name"] = "default:silver_sandstone_brick", ["z"] = 6, ["param1"] = 17}, {["y"] = 0, ["x"] = 1, ["name"] = "default:silver_sandstone_brick", ["z"] = 7, ["param1"] = 17}, {["y"] = 0, ["x"] = 1, ["name"] = "default:silver_sandstone_brick", ["z"] = 8}, {["y"] = 0, ["x"] = 1, ["name"] = "default:dry_dirt", ["z"] = 9}, {["y"] = 0, ["x"] = 1, ["name"] = "default:dry_dirt", ["z"] = 10, ["param1"] = 35}, {["y"] = 0, ["x"] = 1, ["name"] = "default:dry_dirt", ["z"] = 11, ["param1"] = 35}, {["y"] = 0, ["x"] = 1, ["name"] = "default:dry_dirt", ["z"] = 12, ["param1"] = 15}, {["y"] = 0, ["x"] = 1, ["name"] = "default:dry_dirt", ["z"] = 13, ["param1"] = 15}, {["y"] = 0, ["x"] = 1, ["name"] = "default:dry_dirt", ["z"] = 14, ["param1"] = 15}, {["y"] = 0, ["x"] = 1, ["name"] = "default:dry_dirt", ["z"] = 15, ["param1"] = 15}, {["y"] = 0, ["x"] = 1, ["name"] = "default:dry_dirt", ["z"] = 16, ["param1"] = 15}, {["y"] = 0, ["x"] = 1, ["name"] = "default:dry_dirt", ["z"] = 17, ["param1"] = 15}, {["y"] = 0, ["x"] = 1, ["name"] = "default:dry_dirt", ["z"] = 18, ["param1"] = 15}, {["y"] = 0, ["x"] = 1, ["name"] = "default:dry_dirt", ["z"] = 19, ["param1"] = 15}, {["y"] = 0, ["x"] = 1, ["name"] = "default:dry_dirt", ["z"] = 20, ["param1"] = 15}, {["y"] = 0, ["x"] = 1, ["name"] = "default:dry_dirt", ["z"] = 21, ["param1"] = 15}, {["y"] = 0, ["x"] = 1, ["name"] = "default:dry_dirt", ["z"] = 22, ["param1"] = 15}, {["y"] = 0, ["x"] = 1, ["name"] = "default:dry_dirt", ["z"] = 23, ["param1"] = 14}, {["y"] = 0, ["x"] = 1, ["name"] = "default:dry_dirt", ["z"] = 24, ["param1"] = 13}, {["y"] = 0, ["x"] = 1, ["name"] = "default:dry_dirt", ["z"] = 25, ["param1"] = 35}, {["y"] = 0, ["x"] = 1, ["name"] = "default:dry_dirt", ["z"] = 26, ["param1"] = 35}, {["y"] = 0, ["x"] = 1, ["name"] = "default:dry_dirt", ["z"] = 27, ["param1"] = 35}, {["y"] = 0, ["x"] = 1, ["name"] = "default:dry_dirt", ["z"] = 28, ["param1"] = 35}, {["y"] = 0, ["x"] = 1, ["name"] = "default:dry_dirt", ["z"] = 29, ["param1"] = 35}, {["y"] = 0, ["x"] = 1, ["name"] = "default:dry_dirt", ["z"] = 30, ["param1"] = 35}, {["y"] = 0, ["x"] = 1, ["name"] = "default:dry_dirt", ["z"] = 31, ["param1"] = 35}, {["y"] = 0, ["x"] = 1, ["name"] = "default:dry_dirt", ["z"] = 32, ["param1"] = 35}, {["y"] = 0, ["x"] = 1, ["name"] = "default:dry_dirt", ["z"] = 33, ["param1"] = 35}, {["y"] = 0, ["x"] = 1, ["name"] = "default:dry_dirt", ["z"] = 34, ["param1"] = 35}, {["y"] = 0, ["x"] = 1, ["name"] = "default:dry_dirt", ["z"] = 35, ["param1"] = 35}, {["y"] = 0, ["x"] = 1, ["name"] = "default:dry_dirt", ["z"] = 36, ["param1"] = 35}, {["y"] = 0, ["x"] = 1, ["name"] = "default:dry_dirt", ["z"] = 37, ["param1"] = 35}, {["y"] = 0, ["x"] = 1, ["name"] = "default:dry_dirt", ["z"] = 38, ["param1"] = 35}, {["y"] = 0, ["x"] = 1, ["name"] = "default:dry_dirt", ["z"] = 39, ["param1"] = 35}, {["y"] = 0, ["x"] = 1, ["name"] = "default:dry_dirt", ["z"] = 40, ["param1"] = 35}, {["y"] = 0, ["x"] = 1, ["name"] = "default:dry_dirt", ["z"] = 41, ["param1"] = 35}, {["y"] = 0, ["x"] = 1, ["name"] = "default:dry_dirt", ["z"] = 42, ["param1"] = 35}, {["y"] = 0, ["x"] = 1, ["name"] = "default:dry_dirt", ["z"] = 43, ["param1"] = 35}, {["y"] = 0, ["x"] = 1, ["name"] = "default:dry_dirt", ["z"] = 44, ["param1"] = 35}, {["y"] = 0, ["x"] = 1, ["name"] = "default:dry_dirt", ["z"] = 45, ["param1"] = 35}, {["y"] = 0, ["x"] = 1, ["name"] = "default:dry_dirt", ["z"] = 46, ["param1"] = 35}, {["y"] = 0, ["x"] = 1, ["name"] = "default:dry_dirt", ["z"] = 47, ["param1"] = 35}, {["y"] = 0, ["x"] = 1, ["name"] = "default:dry_dirt", ["z"] = 48, ["param1"] = 35}, {["y"] = 0, ["x"] = 1, ["name"] = "default:dry_dirt", ["z"] = 49, ["param1"] = 35}, {["y"] = 0, ["x"] = 1, ["name"] = "default:dry_dirt", ["z"] = 50, ["param1"] = 35}, {["y"] = 0, ["x"] = 1, ["name"] = "default:dry_dirt", ["z"] = 51, ["param1"] = 35}, {["y"] = 0, ["x"] = 1, ["name"] = "default:dry_dirt", ["z"] = 52, ["param1"] = 35}, {["y"] = 0, ["x"] = 1, ["name"] = "default:dry_dirt", ["z"] = 53, ["param1"] = 35}, {["y"] = 0, ["x"] = 1, ["name"] = "default:dry_dirt", ["z"] = 54, ["param1"] = 35}, {["y"] = 0, ["x"] = 1, ["name"] = "default:dry_dirt", ["z"] = 55, ["param1"] = 35}, {["y"] = 0, ["x"] = 1, ["name"] = "default:dry_dirt", ["z"] = 56, ["param1"] = 35}, {["y"] = 0, ["x"] = 1, ["name"] = "default:dry_dirt", ["z"] = 57, ["param1"] = 35}, {["y"] = 0, ["x"] = 1, ["name"] = "default:dry_dirt", ["z"] = 58, ["param1"] = 35}, {["y"] = 0, ["x"] = 1, ["name"] = "default:dry_dirt", ["z"] = 59, ["param1"] = 35}, {["y"] = 0, ["x"] = 1, ["name"] = "default:dry_dirt", ["z"] = 60, ["param1"] = 35}, {["y"] = 0, ["x"] = 1, ["name"] = "default:dry_dirt", ["z"] = 61, ["param1"] = 35}, {["y"] = 0, ["x"] = 1, ["name"] = "default:dry_dirt", ["z"] = 62, ["param1"] = 35}, {["y"] = 0, ["x"] = 1, ["name"] = "default:dry_dirt", ["z"] = 63, ["param1"] = 35}, {["y"] = 0, ["x"] = 1, ["name"] = "default:dry_dirt", ["z"] = 64, ["param1"] = 35}, {["y"] = 0, ["x"] = 1, ["name"] = "default:dry_dirt", ["z"] = 65, ["param1"] = 35}, {["y"] = 0, ["x"] = 1, ["name"] = "default:dry_dirt", ["z"] = 66, ["param1"] = 35}, {["y"] = 0, ["x"] = 1, ["name"] = "default:dry_dirt", ["z"] = 67, ["param1"] = 35}, {["y"] = 0, ["x"] = 1, ["name"] = "default:dry_dirt", ["z"] = 68, ["param1"] = 35}, {["y"] = 0, ["x"] = 1, ["name"] = "default:dry_dirt", ["z"] = 69, ["param1"] = 35}, {["y"] = 0, ["x"] = 1, ["name"] = "default:dry_dirt", ["z"] = 70, ["param1"] = 35}, {["y"] = 0, ["x"] = 1, ["name"] = "default:dry_dirt", ["z"] = 71, ["param1"] = 35}, {["y"] = 0, ["x"] = 1, ["name"] = "default:dry_dirt", ["z"] = 72, ["param1"] = 35}, {["y"] = 0, ["x"] = 1, ["name"] = "default:dry_dirt", ["z"] = 73, ["param1"] = 35}, {["y"] = 0, ["x"] = 1, ["name"] = "default:dry_dirt", ["z"] = 74, ["param1"] = 35}, {["y"] = 0, ["x"] = 1, ["name"] = "default:dry_dirt", ["z"] = 75, ["param1"] = 35}, {["y"] = 0, ["x"] = 1, ["name"] = "default:dry_dirt", ["z"] = 76, ["param1"] = 35}, {["y"] = 0, ["x"] = 1, ["name"] = "default:dry_dirt", ["z"] = 77, ["param1"] = 35}, {["y"] = 0, ["x"] = 1, ["name"] = "default:dry_dirt", ["z"] = 78, ["param1"] = 35}, {["y"] = 0, ["x"] = 1, ["name"] = "default:dry_dirt", ["z"] = 79, ["param1"] = 35}, {["y"] = 0, ["x"] = 1, ["name"] = "default:dry_dirt", ["z"] = 80, ["param1"] = 35}, {["y"] = 0, ["x"] = 1, ["name"] = "default:dry_dirt", ["z"] = 81, ["param1"] = 35}, {["y"] = 0, ["x"] = 1, ["name"] = "default:dry_dirt", ["z"] = 82, ["param1"] = 35}, {["y"] = 0, ["x"] = 1, ["name"] = "default:dry_dirt", ["z"] = 83, ["param1"] = 35}, {["y"] = 0, ["x"] = 1, ["name"] = "default:dry_dirt", ["z"] = 84, ["param1"] = 35}, {["y"] = 0, ["x"] = 1, ["name"] = "default:dry_dirt", ["z"] = 85, ["param1"] = 35}, {["y"] = 0, ["x"] = 1, ["name"] = "default:dry_dirt", ["z"] = 86, ["param1"] = 35}, {["y"] = 0, ["x"] = 1, ["name"] = "default:dry_dirt", ["z"] = 87, ["param1"] = 35}, {["y"] = 0, ["x"] = 1, ["name"] = "default:dry_dirt", ["z"] = 88, ["param1"] = 35}, {["y"] = 0, ["x"] = 1, ["name"] = "default:dry_dirt", ["z"] = 89, ["param1"] = 35}, {["y"] = 0, ["x"] = 1, ["name"] = "default:dry_dirt", ["z"] = 90, ["param1"] = 35}, {["y"] = 0, ["x"] = 1, ["name"] = "default:dry_dirt", ["z"] = 91, ["param1"] = 35}, {["y"] = 0, ["x"] = 1, ["name"] = "default:dry_dirt", ["z"] = 92, ["param1"] = 35}, {["y"] = 0, ["x"] = 1, ["name"] = "default:dry_dirt", ["z"] = 93, ["param1"] = 35}, {["y"] = 0, ["x"] = 1, ["name"] = "default:dry_dirt", ["z"] = 94, ["param1"] = 35}, {["y"] = 0, ["x"] = 1, ["name"] = "default:dry_dirt", ["z"] = 95, ["param1"] = 35}, {["y"] = 0, ["x"] = 1, ["name"] = "default:dry_dirt", ["z"] = 96, ["param1"] = 35}, {["y"] = 0, ["x"] = 1, ["name"] = "default:dry_dirt", ["z"] = 97, ["param1"] = 35}, {["y"] = 0, ["x"] = 1, ["name"] = "default:dry_dirt", ["z"] = 98, ["param1"] = 35}, {["y"] = 0, ["x"] = 1, ["name"] = "default:dry_dirt", ["z"] = 99, ["param1"] = 35}, {["y"] = 0, ["x"] = 1, ["name"] = "default:dry_dirt", ["z"] = 100, ["param1"] = 35}, {["y"] = 0, ["x"] = 1, ["name"] = "default:dry_dirt", ["z"] = 101, ["param1"] = 35}, {["y"] = 0, ["x"] = 1, ["name"] = "default:dry_dirt", ["z"] = 102, ["param1"] = 35}, {["y"] = 0, ["x"] = 1, ["name"] = "default:dry_dirt", ["z"] = 103, ["param1"] = 35}, {["y"] = 0, ["x"] = 1, ["name"] = "default:dry_dirt", ["z"] = 104, ["param1"] = 35}, {["y"] = 0, ["x"] = 1, ["name"] = "default:dry_dirt", ["z"] = 105, ["param1"] = 35}, {["y"] = 0, ["x"] = 1, ["name"] = "default:dry_dirt", ["z"] = 106, ["param1"] = 35}, {["y"] = 0, ["x"] = 1, ["name"] = "default:dry_dirt", ["z"] = 107}, {["y"] = 0, ["x"] = 1, ["name"] = "default:silver_sandstone_brick", ["z"] = 108, ["param1"] = 35}, {["y"] = 0, ["x"] = 1, ["name"] = "default:silver_sandstone_brick", ["z"] = 109, ["param1"] = 35}, {["y"] = 0, ["x"] = 1, ["name"] = "default:silver_sandstone_brick", ["z"] = 110, ["param1"] = 35}, {["y"] = 0, ["x"] = 1, ["name"] = "default:silver_sandstone_brick", ["z"] = 111, ["param1"] = 35}, {["y"] = 0, ["x"] = 1, ["name"] = "default:dry_dirt", ["z"] = 112}, {["y"] = 0, ["x"] = 1, ["name"] = "default:desert_sand", ["z"] = 113, ["param1"] = 35}, {["y"] = 0, ["x"] = 1, ["name"] = "default:desert_sand", ["z"] = 114, ["param1"] = 35}, {["y"] = 0, ["x"] = 1, ["name"] = "default:desert_sand", ["z"] = 115, ["param1"] = 35}, {["y"] = 0, ["x"] = 1, ["name"] = "default:desert_sand", ["z"] = 116, ["param1"] = 35}, {["y"] = 1, ["x"] = 1, ["name"] = "default:silver_sandstone_brick", ["z"] = 5, ["param1"] = 15}, {["y"] = 1, ["x"] = 1, ["name"] = "default:silver_sandstone_brick", ["z"] = 6, ["param1"] = 15}, {["y"] = 1, ["x"] = 1, ["name"] = "default:silver_sandstone_brick", ["z"] = 7, ["param1"] = 15}, {["y"] = 1, ["x"] = 1, ["name"] = "default:silver_sandstone_brick", ["z"] = 8}, {["y"] = 1, ["x"] = 1, ["name"] = "default:silver_sandstone_brick", ["z"] = 108}, {["y"] = 1, ["x"] = 1, ["name"] = "default:silver_sandstone_brick", ["z"] = 109}, {["y"] = 1, ["x"] = 1, ["name"] = "default:silver_sandstone_brick", ["z"] = 110}, {["y"] = 1, ["x"] = 1, ["name"] = "default:silver_sandstone_brick", ["z"] = 111}, {["y"] = 2, ["x"] = 1, ["name"] = "default:silver_sandstone_brick", ["z"] = 5, ["param1"] = 15}, {["y"] = 2, ["x"] = 1, ["name"] = "default:silver_sandstone_brick", ["z"] = 6, ["param1"] = 15}, {["y"] = 2, ["x"] = 1, ["name"] = "default:silver_sandstone_brick", ["z"] = 7, ["param1"] = 15}, {["y"] = 2, ["x"] = 1, ["name"] = "default:silver_sandstone_brick", ["z"] = 8, ["param1"] = 14}, {["y"] = 2, ["x"] = 1, ["name"] = "default:silver_sandstone_brick", ["z"] = 108}, {["y"] = 2, ["x"] = 1, ["name"] = "default:silver_sandstone_brick", ["z"] = 109}, {["y"] = 2, ["x"] = 1, ["name"] = "default:silver_sandstone_brick", ["z"] = 110}, {["y"] = 2, ["x"] = 1, ["name"] = "default:silver_sandstone_brick", ["z"] = 111}, {["y"] = 3, ["x"] = 1, ["name"] = "default:silver_sandstone_brick", ["z"] = 5, ["param1"] = 15}, {["y"] = 3, ["x"] = 1, ["name"] = "default:silver_sandstone_brick", ["z"] = 6, ["param1"] = 15}, {["y"] = 3, ["x"] = 1, ["name"] = "default:silver_sandstone_brick", ["z"] = 7, ["param1"] = 15}, {["y"] = 3, ["x"] = 1, ["name"] = "default:silver_sandstone_brick", ["z"] = 8, ["param1"] = 14}, {["y"] = 3, ["x"] = 1, ["name"] = "default:silver_sandstone_brick", ["z"] = 108}, {["y"] = 3, ["x"] = 1, ["name"] = "default:silver_sandstone_brick", ["z"] = 109}, {["y"] = 3, ["x"] = 1, ["name"] = "default:silver_sandstone_brick", ["z"] = 110}, {["y"] = 3, ["x"] = 1, ["name"] = "default:silver_sandstone_brick", ["z"] = 111}, {["y"] = 4, ["x"] = 1, ["name"] = "default:silver_sandstone_brick", ["z"] = 5, ["param1"] = 15}, {["y"] = 4, ["x"] = 1, ["name"] = "default:silver_sandstone_brick", ["z"] = 6, ["param1"] = 15}, {["y"] = 4, ["x"] = 1, ["name"] = "default:silver_sandstone_brick", ["z"] = 7, ["param1"] = 15}, {["y"] = 4, ["x"] = 1, ["name"] = "default:silver_sandstone_brick", ["z"] = 8, ["param1"] = 14}, {["y"] = 4, ["x"] = 1, ["name"] = "default:silver_sandstone_brick", ["z"] = 108}, {["y"] = 4, ["x"] = 1, ["name"] = "default:silver_sandstone_brick", ["z"] = 109}, {["y"] = 4, ["x"] = 1, ["name"] = "default:silver_sandstone_brick", ["z"] = 110}, {["y"] = 4, ["x"] = 1, ["name"] = "default:silver_sandstone_brick", ["z"] = 111}, {["y"] = 5, ["x"] = 1, ["name"] = "default:silver_sandstone_brick", ["z"] = 5, ["param1"] = 15}, {["y"] = 5, ["x"] = 1, ["name"] = "default:silver_sandstone_brick", ["z"] = 6, ["param1"] = 15}, {["y"] = 5, ["x"] = 1, ["name"] = "default:silver_sandstone_brick", ["z"] = 7, ["param1"] = 15}, {["y"] = 5, ["x"] = 1, ["name"] = "default:silver_sandstone_brick", ["z"] = 8, ["param1"] = 14}, {["y"] = 5, ["x"] = 1, ["name"] = "default:silver_sandstone_brick", ["z"] = 108}, {["y"] = 5, ["x"] = 1, ["name"] = "default:silver_sandstone_brick", ["z"] = 109}, {["y"] = 5, ["x"] = 1, ["name"] = "default:silver_sandstone_brick", ["z"] = 110}, {["y"] = 5, ["x"] = 1, ["name"] = "default:silver_sandstone_brick", ["z"] = 111}, {["y"] = 6, ["x"] = 1, ["name"] = "default:silver_sandstone_brick", ["z"] = 5, ["param1"] = 15}, {["y"] = 6, ["x"] = 1, ["name"] = "default:silver_sandstone_brick", ["z"] = 6, ["param1"] = 15}, {["y"] = 6, ["x"] = 1, ["name"] = "default:silver_sandstone_brick", ["z"] = 7, ["param1"] = 15}, {["y"] = 6, ["x"] = 1, ["name"] = "default:silver_sandstone_brick", ["z"] = 8, ["param1"] = 14}, {["y"] = 6, ["x"] = 1, ["name"] = "default:silver_sandstone_brick", ["z"] = 108, ["param1"] = 15}, {["y"] = 6, ["x"] = 1, ["name"] = "default:silver_sandstone_brick", ["z"] = 109, ["param1"] = 15}, {["y"] = 6, ["x"] = 1, ["name"] = "default:silver_sandstone_brick", ["z"] = 110, ["param1"] = 15}, {["y"] = 6, ["x"] = 1, ["name"] = "default:silver_sandstone_brick", ["z"] = 111, ["param1"] = 15}, {["y"] = 7, ["x"] = 1, ["name"] = "default:silver_sandstone_brick", ["z"] = 5, ["param1"] = 15}, {["y"] = 7, ["x"] = 1, ["name"] = "default:silver_sandstone_brick", ["z"] = 6, ["param1"] = 15}, {["y"] = 7, ["x"] = 1, ["name"] = "default:silver_sandstone_brick", ["z"] = 7, ["param1"] = 15}, {["y"] = 7, ["x"] = 1, ["name"] = "default:silver_sandstone_brick", ["z"] = 8, ["param1"] = 14}, {["y"] = 7, ["x"] = 1, ["name"] = "default:silver_sandstone_brick", ["z"] = 108, ["param1"] = 15}, {["y"] = 7, ["x"] = 1, ["name"] = "default:silver_sandstone_brick", ["z"] = 109, ["param1"] = 15}, {["y"] = 7, ["x"] = 1, ["name"] = "default:silver_sandstone_brick", ["z"] = 110, ["param1"] = 15}, {["y"] = 7, ["x"] = 1, ["name"] = "default:silver_sandstone_brick", ["z"] = 111, ["param1"] = 15}, {["y"] = 8, ["x"] = 1, ["name"] = "default:silver_sandstone_brick", ["z"] = 5, ["param1"] = 15}, {["y"] = 8, ["x"] = 1, ["name"] = "default:silver_sandstone_brick", ["z"] = 6, ["param1"] = 15}, {["y"] = 8, ["x"] = 1, ["name"] = "default:silver_sandstone_brick", ["z"] = 7, ["param1"] = 15}, {["y"] = 8, ["x"] = 1, ["name"] = "default:silver_sandstone_brick", ["z"] = 8, ["param1"] = 14}, {["y"] = 8, ["x"] = 1, ["name"] = "default:silver_sandstone_brick", ["z"] = 108, ["param1"] = 15}, {["y"] = 8, ["x"] = 1, ["name"] = "default:silver_sandstone_brick", ["z"] = 109, ["param1"] = 15}, {["y"] = 8, ["x"] = 1, ["name"] = "default:silver_sandstone_brick", ["z"] = 110, ["param1"] = 15}, {["y"] = 8, ["x"] = 1, ["name"] = "default:silver_sandstone_brick", ["z"] = 111, ["param1"] = 15}, {["y"] = 9, ["x"] = 1, ["name"] = "default:silver_sandstone_brick", ["z"] = 5, ["param1"] = 15}, {["y"] = 9, ["x"] = 1, ["name"] = "default:silver_sandstone_brick", ["z"] = 6, ["param1"] = 15}, {["y"] = 9, ["x"] = 1, ["name"] = "default:silver_sandstone_brick", ["z"] = 7, ["param1"] = 15}, {["y"] = 9, ["x"] = 1, ["name"] = "default:silver_sandstone_brick", ["z"] = 8, ["param1"] = 14}, {["y"] = 9, ["x"] = 1, ["name"] = "default:silver_sandstone_brick", ["z"] = 108, ["param1"] = 15}, {["y"] = 9, ["x"] = 1, ["name"] = "default:silver_sandstone_brick", ["z"] = 109, ["param1"] = 15}, {["y"] = 9, ["x"] = 1, ["name"] = "default:silver_sandstone_brick", ["z"] = 110, ["param1"] = 15}, {["y"] = 9, ["x"] = 1, ["name"] = "default:silver_sandstone_brick", ["z"] = 111, ["param1"] = 15}, {["y"] = 10, ["x"] = 1, ["name"] = "default:silver_sandstone_brick", ["z"] = 2}, {["y"] = 10, ["x"] = 1, ["name"] = "default:silver_sandstone_brick", ["z"] = 5, ["param1"] = 15}, {["y"] = 10, ["x"] = 1, ["name"] = "default:silver_sandstone_brick", ["z"] = 6, ["param1"] = 15}, {["y"] = 10, ["x"] = 1, ["name"] = "default:silver_sandstone_brick", ["z"] = 7, ["param1"] = 15}, {["y"] = 10, ["x"] = 1, ["name"] = "default:silver_sandstone_brick", ["z"] = 8, ["param1"] = 14}, {["y"] = 10, ["x"] = 1, ["name"] = "default:silver_sandstone_brick", ["z"] = 108, ["param1"] = 15}, {["y"] = 10, ["x"] = 1, ["name"] = "default:silver_sandstone_brick", ["z"] = 109, ["param1"] = 15}, {["y"] = 10, ["x"] = 1, ["name"] = "default:silver_sandstone_brick", ["z"] = 110, ["param1"] = 15}, {["y"] = 10, ["x"] = 1, ["name"] = "default:silver_sandstone_brick", ["z"] = 111, ["param1"] = 15}, {["y"] = 11, ["x"] = 1, ["name"] = "default:silver_sandstone_brick", ["z"] = 5, ["param1"] = 15}, {["y"] = 11, ["x"] = 1, ["name"] = "default:silver_sandstone_brick", ["z"] = 6, ["param1"] = 15}, {["y"] = 11, ["x"] = 1, ["name"] = "default:silver_sandstone_brick", ["z"] = 7, ["param1"] = 15}, {["y"] = 11, ["x"] = 1, ["name"] = "default:silver_sandstone_brick", ["z"] = 8, ["param1"] = 14}, {["y"] = 11, ["x"] = 1, ["name"] = "default:silver_sandstone_brick", ["z"] = 108, ["param1"] = 15}, {["y"] = 11, ["x"] = 1, ["name"] = "default:silver_sandstone_brick", ["z"] = 109, ["param1"] = 15}, {["y"] = 11, ["x"] = 1, ["name"] = "default:silver_sandstone_brick", ["z"] = 110, ["param1"] = 15}, {["y"] = 11, ["x"] = 1, ["name"] = "default:silver_sandstone_brick", ["z"] = 111, ["param1"] = 15}, {["y"] = 12, ["x"] = 1, ["name"] = "default:silver_sandstone_brick", ["z"] = 5, ["param1"] = 15}, {["y"] = 12, ["x"] = 1, ["name"] = "default:silver_sandstone_brick", ["z"] = 6, ["param1"] = 15}, {["y"] = 12, ["x"] = 1, ["name"] = "default:silver_sandstone_brick", ["z"] = 7, ["param1"] = 15}, {["y"] = 12, ["x"] = 1, ["name"] = "default:silver_sandstone_brick", ["z"] = 8, ["param1"] = 14}, {["y"] = 12, ["x"] = 1, ["name"] = "default:silver_sandstone_brick", ["z"] = 108, ["param1"] = 15}, {["y"] = 12, ["x"] = 1, ["name"] = "default:silver_sandstone_brick", ["z"] = 109, ["param1"] = 15}, {["y"] = 12, ["x"] = 1, ["name"] = "default:silver_sandstone_brick", ["z"] = 110, ["param1"] = 15}, {["y"] = 12, ["x"] = 1, ["name"] = "default:silver_sandstone_brick", ["z"] = 111, ["param1"] = 15}, {["y"] = 13, ["x"] = 1, ["name"] = "default:silver_sandstone_brick", ["z"] = 5, ["param1"] = 15}, {["y"] = 13, ["x"] = 1, ["name"] = "default:silver_sandstone_brick", ["z"] = 6, ["param1"] = 15}, {["y"] = 13, ["x"] = 1, ["name"] = "default:silver_sandstone_brick", ["z"] = 7, ["param1"] = 15}, {["y"] = 13, ["x"] = 1, ["name"] = "default:silver_sandstone_brick", ["z"] = 8, ["param1"] = 14}, {["y"] = 13, ["x"] = 1, ["name"] = "default:silver_sandstone_brick", ["z"] = 108, ["param1"] = 15}, {["y"] = 13, ["x"] = 1, ["name"] = "default:silver_sandstone_brick", ["z"] = 109, ["param1"] = 15}, {["y"] = 13, ["x"] = 1, ["name"] = "default:silver_sandstone_brick", ["z"] = 110, ["param1"] = 15}, {["y"] = 13, ["x"] = 1, ["name"] = "default:silver_sandstone_brick", ["z"] = 111, ["param1"] = 15}, {["y"] = 14, ["x"] = 1, ["name"] = "default:silver_sandstone_brick", ["z"] = 5, ["param1"] = 15}, {["y"] = 14, ["x"] = 1, ["name"] = "default:silver_sandstone_brick", ["z"] = 6, ["param1"] = 15}, {["y"] = 14, ["x"] = 1, ["name"] = "default:silver_sandstone_brick", ["z"] = 7, ["param1"] = 15}, {["y"] = 14, ["x"] = 1, ["name"] = "default:silver_sandstone_brick", ["z"] = 8, ["param1"] = 14}, {["y"] = 14, ["x"] = 1, ["name"] = "default:silver_sandstone_brick", ["z"] = 108, ["param1"] = 15}, {["y"] = 14, ["x"] = 1, ["name"] = "default:silver_sandstone_brick", ["z"] = 109, ["param1"] = 15}, {["y"] = 14, ["x"] = 1, ["name"] = "default:silver_sandstone_brick", ["z"] = 110, ["param1"] = 15}, {["y"] = 14, ["x"] = 1, ["name"] = "default:silver_sandstone_brick", ["z"] = 111, ["param1"] = 15}, {["y"] = 15, ["x"] = 1, ["name"] = "default:silver_sandstone_brick", ["z"] = 5, ["param1"] = 15}, {["y"] = 15, ["x"] = 1, ["name"] = "default:silver_sandstone_brick", ["z"] = 6, ["param1"] = 15}, {["y"] = 15, ["x"] = 1, ["name"] = "default:silver_sandstone_brick", ["z"] = 7, ["param1"] = 15}, {["y"] = 15, ["x"] = 1, ["name"] = "default:silver_sandstone_brick", ["z"] = 8, ["param1"] = 14}, {["y"] = 15, ["x"] = 1, ["name"] = "default:silver_sandstone_brick", ["z"] = 108, ["param1"] = 15}, {["y"] = 15, ["x"] = 1, ["name"] = "default:silver_sandstone_brick", ["z"] = 109, ["param1"] = 15}, {["y"] = 15, ["x"] = 1, ["name"] = "default:silver_sandstone_brick", ["z"] = 110, ["param1"] = 15}, {["y"] = 15, ["x"] = 1, ["name"] = "default:silver_sandstone_brick", ["z"] = 111, ["param1"] = 15}, {["y"] = 0, ["x"] = 2, ["name"] = "default:silver_sandstone_brick", ["z"] = 4}, {["y"] = 0, ["x"] = 2, ["name"] = "default:silver_sandstone_brick", ["z"] = 5, ["param1"] = 17}, {["y"] = 0, ["x"] = 2, ["name"] = "default:silver_sandstone_brick", ["z"] = 6, ["param1"] = 17}, {["y"] = 0, ["x"] = 2, ["name"] = "default:silver_sandstone_brick", ["z"] = 7, ["param1"] = 17}, {["y"] = 0, ["x"] = 2, ["name"] = "default:silver_sandstone_brick", ["z"] = 8, ["param1"] = 35}, {["y"] = 0, ["x"] = 2, ["name"] = "default:silver_sandstone_brick", ["z"] = 9, ["param1"] = 35}, {["y"] = 0, ["x"] = 2, ["name"] = "default:dry_dirt", ["z"] = 10, ["param1"] = 35}, {["y"] = 0, ["x"] = 2, ["name"] = "default:dry_dirt", ["z"] = 11, ["param1"] = 35}, {["y"] = 0, ["x"] = 2, ["name"] = "default:dry_dirt", ["z"] = 12, ["param1"] = 15}, {["y"] = 0, ["x"] = 2, ["name"] = "default:dry_dirt", ["z"] = 13, ["param1"] = 15}, {["y"] = 0, ["x"] = 2, ["name"] = "default:dry_dirt", ["z"] = 14, ["param1"] = 15}, {["y"] = 0, ["x"] = 2, ["name"] = "default:dry_dirt", ["z"] = 15, ["param1"] = 15}, {["y"] = 0, ["x"] = 2, ["name"] = "default:dry_dirt", ["z"] = 16, ["param1"] = 15}, {["y"] = 0, ["x"] = 2, ["name"] = "default:dry_dirt", ["z"] = 17, ["param1"] = 15}, {["y"] = 0, ["x"] = 2, ["name"] = "default:dry_dirt", ["z"] = 18, ["param1"] = 15}, {["y"] = 0, ["x"] = 2, ["name"] = "default:dry_dirt", ["z"] = 19, ["param1"] = 15}, {["y"] = 0, ["x"] = 2, ["name"] = "default:dry_dirt", ["z"] = 20, ["param1"] = 15}, {["y"] = 0, ["x"] = 2, ["name"] = "default:dry_dirt", ["z"] = 21, ["param1"] = 15}, {["y"] = 0, ["x"] = 2, ["name"] = "default:dry_dirt", ["z"] = 22, ["param1"] = 15}, {["y"] = 0, ["x"] = 2, ["name"] = "default:dry_dirt", ["z"] = 23, ["param1"] = 14}, {["y"] = 0, ["x"] = 2, ["name"] = "default:dry_dirt", ["z"] = 24, ["param1"] = 13}, {["y"] = 0, ["x"] = 2, ["name"] = "default:dry_dirt", ["z"] = 25, ["param1"] = 17}, {["y"] = 0, ["x"] = 2, ["name"] = "default:dry_dirt", ["z"] = 26, ["param1"] = 17}, {["y"] = 0, ["x"] = 2, ["name"] = "default:dry_dirt", ["z"] = 27, ["param1"] = 17}, {["y"] = 0, ["x"] = 2, ["name"] = "default:dry_dirt", ["z"] = 28, ["param1"] = 17}, {["y"] = 0, ["x"] = 2, ["name"] = "default:dry_dirt", ["z"] = 29, ["param1"] = 17}, {["y"] = 0, ["x"] = 2, ["name"] = "default:dry_dirt", ["z"] = 30, ["param1"] = 17}, {["y"] = 0, ["x"] = 2, ["name"] = "default:dry_dirt", ["z"] = 31, ["param1"] = 17}, {["y"] = 0, ["x"] = 2, ["name"] = "default:dry_dirt", ["z"] = 32, ["param1"] = 17}, {["y"] = 0, ["x"] = 2, ["name"] = "default:dry_dirt", ["z"] = 33, ["param1"] = 17}, {["y"] = 0, ["x"] = 2, ["name"] = "default:dry_dirt", ["z"] = 34, ["param1"] = 17}, {["y"] = 0, ["x"] = 2, ["name"] = "default:dry_dirt", ["z"] = 35, ["param1"] = 17}, {["y"] = 0, ["x"] = 2, ["name"] = "default:dry_dirt", ["z"] = 36, ["param1"] = 17}, {["y"] = 0, ["x"] = 2, ["name"] = "default:dry_dirt", ["z"] = 37, ["param1"] = 17}, {["y"] = 0, ["x"] = 2, ["name"] = "default:dry_dirt", ["z"] = 38, ["param1"] = 17}, {["y"] = 0, ["x"] = 2, ["name"] = "default:dry_dirt", ["z"] = 39, ["param1"] = 17}, {["y"] = 0, ["x"] = 2, ["name"] = "default:dry_dirt", ["z"] = 40, ["param1"] = 17}, {["y"] = 0, ["x"] = 2, ["name"] = "default:dry_dirt", ["z"] = 41, ["param1"] = 17}, {["y"] = 0, ["x"] = 2, ["name"] = "default:dry_dirt", ["z"] = 42, ["param1"] = 17}, {["y"] = 0, ["x"] = 2, ["name"] = "default:dry_dirt", ["z"] = 43, ["param1"] = 17}, {["y"] = 0, ["x"] = 2, ["name"] = "default:dry_dirt", ["z"] = 44, ["param1"] = 17}, {["y"] = 0, ["x"] = 2, ["name"] = "default:dry_dirt", ["z"] = 45, ["param1"] = 17}, {["y"] = 0, ["x"] = 2, ["name"] = "default:dry_dirt", ["z"] = 46, ["param1"] = 17}, {["y"] = 0, ["x"] = 2, ["name"] = "default:dry_dirt", ["z"] = 47, ["param1"] = 17}, {["y"] = 0, ["x"] = 2, ["name"] = "default:dry_dirt", ["z"] = 48, ["param1"] = 17}, {["y"] = 0, ["x"] = 2, ["name"] = "default:dry_dirt", ["z"] = 49, ["param1"] = 17}, {["y"] = 0, ["x"] = 2, ["name"] = "default:dry_dirt", ["z"] = 50, ["param1"] = 17}, {["y"] = 0, ["x"] = 2, ["name"] = "default:dry_dirt", ["z"] = 51, ["param1"] = 17}, {["y"] = 0, ["x"] = 2, ["name"] = "default:dry_dirt", ["z"] = 52, ["param1"] = 17}, {["y"] = 0, ["x"] = 2, ["name"] = "default:dry_dirt", ["z"] = 53, ["param1"] = 17}, {["y"] = 0, ["x"] = 2, ["name"] = "default:dry_dirt", ["z"] = 54, ["param1"] = 17}, {["y"] = 0, ["x"] = 2, ["name"] = "default:dry_dirt", ["z"] = 55, ["param1"] = 17}, {["y"] = 0, ["x"] = 2, ["name"] = "default:dry_dirt", ["z"] = 56, ["param1"] = 17}, {["y"] = 0, ["x"] = 2, ["name"] = "default:dry_dirt", ["z"] = 57, ["param1"] = 17}, {["y"] = 0, ["x"] = 2, ["name"] = "default:dry_dirt", ["z"] = 58, ["param1"] = 17}, {["y"] = 0, ["x"] = 2, ["name"] = "default:dry_dirt", ["z"] = 59, ["param1"] = 17}, {["y"] = 0, ["x"] = 2, ["name"] = "default:dry_dirt", ["z"] = 60, ["param1"] = 17}, {["y"] = 0, ["x"] = 2, ["name"] = "default:dry_dirt", ["z"] = 61, ["param1"] = 17}, {["y"] = 0, ["x"] = 2, ["name"] = "default:dry_dirt", ["z"] = 62, ["param1"] = 17}, {["y"] = 0, ["x"] = 2, ["name"] = "default:dry_dirt", ["z"] = 63, ["param1"] = 17}, {["y"] = 0, ["x"] = 2, ["name"] = "default:dry_dirt", ["z"] = 64, ["param1"] = 17}, {["y"] = 0, ["x"] = 2, ["name"] = "default:dry_dirt", ["z"] = 65, ["param1"] = 17}, {["y"] = 0, ["x"] = 2, ["name"] = "default:dry_dirt", ["z"] = 66, ["param1"] = 17}, {["y"] = 0, ["x"] = 2, ["name"] = "default:dry_dirt", ["z"] = 67, ["param1"] = 17}, {["y"] = 0, ["x"] = 2, ["name"] = "default:dry_dirt", ["z"] = 68, ["param1"] = 17}, {["y"] = 0, ["x"] = 2, ["name"] = "default:dry_dirt", ["z"] = 69, ["param1"] = 17}, {["y"] = 0, ["x"] = 2, ["name"] = "default:dry_dirt", ["z"] = 70, ["param1"] = 17}, {["y"] = 0, ["x"] = 2, ["name"] = "default:dry_dirt", ["z"] = 71, ["param1"] = 17}, {["y"] = 0, ["x"] = 2, ["name"] = "default:dry_dirt", ["z"] = 72, ["param1"] = 17}, {["y"] = 0, ["x"] = 2, ["name"] = "default:dry_dirt", ["z"] = 73, ["param1"] = 17}, {["y"] = 0, ["x"] = 2, ["name"] = "default:dry_dirt", ["z"] = 74, ["param1"] = 17}, {["y"] = 0, ["x"] = 2, ["name"] = "default:dry_dirt", ["z"] = 75, ["param1"] = 17}, {["y"] = 0, ["x"] = 2, ["name"] = "default:dry_dirt", ["z"] = 76, ["param1"] = 17}, {["y"] = 0, ["x"] = 2, ["name"] = "default:dry_dirt", ["z"] = 77, ["param1"] = 17}, {["y"] = 0, ["x"] = 2, ["name"] = "default:dry_dirt", ["z"] = 78, ["param1"] = 17}, {["y"] = 0, ["x"] = 2, ["name"] = "default:dry_dirt", ["z"] = 79, ["param1"] = 17}, {["y"] = 0, ["x"] = 2, ["name"] = "default:dry_dirt", ["z"] = 80, ["param1"] = 17}, {["y"] = 0, ["x"] = 2, ["name"] = "default:dry_dirt", ["z"] = 81, ["param1"] = 17}, {["y"] = 0, ["x"] = 2, ["name"] = "default:dry_dirt", ["z"] = 82, ["param1"] = 17}, {["y"] = 0, ["x"] = 2, ["name"] = "default:dry_dirt", ["z"] = 83, ["param1"] = 17}, {["y"] = 0, ["x"] = 2, ["name"] = "default:dry_dirt", ["z"] = 84, ["param1"] = 17}, {["y"] = 0, ["x"] = 2, ["name"] = "default:dry_dirt", ["z"] = 85, ["param1"] = 17}, {["y"] = 0, ["x"] = 2, ["name"] = "default:dry_dirt", ["z"] = 86, ["param1"] = 17}, {["y"] = 0, ["x"] = 2, ["name"] = "default:dry_dirt", ["z"] = 87, ["param1"] = 17}, {["y"] = 0, ["x"] = 2, ["name"] = "default:dry_dirt", ["z"] = 88, ["param1"] = 17}, {["y"] = 0, ["x"] = 2, ["name"] = "default:dry_dirt", ["z"] = 89, ["param1"] = 17}, {["y"] = 0, ["x"] = 2, ["name"] = "default:dry_dirt", ["z"] = 90, ["param1"] = 17}, {["y"] = 0, ["x"] = 2, ["name"] = "default:dry_dirt", ["z"] = 91, ["param1"] = 17}, {["y"] = 0, ["x"] = 2, ["name"] = "default:dry_dirt", ["z"] = 92, ["param1"] = 17}, {["y"] = 0, ["x"] = 2, ["name"] = "default:dry_dirt", ["z"] = 93, ["param1"] = 17}, {["y"] = 0, ["x"] = 2, ["name"] = "default:dry_dirt", ["z"] = 94, ["param1"] = 17}, {["y"] = 0, ["x"] = 2, ["name"] = "default:dry_dirt", ["z"] = 95, ["param1"] = 17}, {["y"] = 0, ["x"] = 2, ["name"] = "default:dry_dirt", ["z"] = 96, ["param1"] = 17}, {["y"] = 0, ["x"] = 2, ["name"] = "default:dry_dirt", ["z"] = 97, ["param1"] = 17}, {["y"] = 0, ["x"] = 2, ["name"] = "default:dry_dirt", ["z"] = 98, ["param1"] = 17}, {["y"] = 0, ["x"] = 2, ["name"] = "default:dry_dirt", ["z"] = 99, ["param1"] = 17}, {["y"] = 0, ["x"] = 2, ["name"] = "default:dry_dirt", ["z"] = 100, ["param1"] = 17}, {["y"] = 0, ["x"] = 2, ["name"] = "default:dry_dirt", ["z"] = 101, ["param1"] = 17}, {["y"] = 0, ["x"] = 2, ["name"] = "default:dry_dirt", ["z"] = 102, ["param1"] = 17}, {["y"] = 0, ["x"] = 2, ["name"] = "default:dry_dirt", ["z"] = 103, ["param1"] = 17}, {["y"] = 0, ["x"] = 2, ["name"] = "default:dry_dirt", ["z"] = 104, ["param1"] = 17}, {["y"] = 0, ["x"] = 2, ["name"] = "default:dry_dirt", ["z"] = 105, ["param1"] = 17}, {["y"] = 0, ["x"] = 2, ["name"] = "default:dry_dirt", ["z"] = 106, ["param1"] = 17}, {["y"] = 0, ["x"] = 2, ["name"] = "default:silver_sandstone_brick", ["z"] = 107}, {["y"] = 0, ["x"] = 2, ["name"] = "default:silver_sandstone_brick", ["z"] = 108, ["param1"] = 17}, {["y"] = 0, ["x"] = 2, ["name"] = "default:silver_sandstone_brick", ["z"] = 109, ["param1"] = 17}, {["y"] = 0, ["x"] = 2, ["name"] = "default:silver_sandstone_brick", ["z"] = 110, ["param1"] = 17}, {["y"] = 0, ["x"] = 2, ["name"] = "default:silver_sandstone_brick", ["z"] = 111}, {["y"] = 0, ["x"] = 2, ["name"] = "default:silver_sandstone_brick", ["z"] = 112, ["param1"] = 35}, {["y"] = 0, ["x"] = 2, ["name"] = "default:desert_sand", ["z"] = 113, ["param1"] = 35}, {["y"] = 0, ["x"] = 2, ["name"] = "default:desert_sand", ["z"] = 114, ["param1"] = 35}, {["y"] = 0, ["x"] = 2, ["name"] = "default:desert_sand", ["z"] = 115, ["param1"] = 35}, {["y"] = 0, ["x"] = 2, ["name"] = "default:desert_sand", ["z"] = 116, ["param1"] = 35}, {["y"] = 1, ["x"] = 2, ["name"] = "default:silver_sandstone_brick", ["z"] = 4, ["param1"] = 15}, {["y"] = 1, ["x"] = 2, ["name"] = "default:silver_sandstone_brick", ["z"] = 9, ["param1"] = 15}, {["y"] = 1, ["x"] = 2, ["name"] = "default:silver_sandstone_brick", ["z"] = 107}, {["y"] = 1, ["x"] = 2, ["name"] = "default:silver_sandstone_brick", ["z"] = 112}, {["y"] = 2, ["x"] = 2, ["name"] = "default:silver_sandstone_brick", ["z"] = 4, ["param1"] = 15}, {["y"] = 2, ["x"] = 2, ["name"] = "default:silver_sandstone_brick", ["z"] = 9, ["param1"] = 15}, {["y"] = 2, ["x"] = 2, ["name"] = "default:silver_sandstone_brick", ["z"] = 107}, {["y"] = 2, ["x"] = 2, ["name"] = "default:silver_sandstone_brick", ["z"] = 112}, {["y"] = 3, ["x"] = 2, ["name"] = "default:silver_sandstone_brick", ["z"] = 4, ["param1"] = 15}, {["y"] = 3, ["x"] = 2, ["name"] = "default:silver_sandstone_brick", ["z"] = 9, ["param1"] = 15}, {["y"] = 3, ["x"] = 2, ["name"] = "default:silver_sandstone_brick", ["z"] = 107}, {["y"] = 3, ["x"] = 2, ["name"] = "default:silver_sandstone_brick", ["z"] = 112}, {["y"] = 4, ["x"] = 2, ["name"] = "default:silver_sandstone_brick", ["z"] = 4, ["param1"] = 15}, {["y"] = 4, ["x"] = 2, ["name"] = "default:silver_sandstone_brick", ["z"] = 9, ["param1"] = 15}, {["y"] = 4, ["x"] = 2, ["name"] = "default:silver_sandstone_brick", ["z"] = 107}, {["y"] = 4, ["x"] = 2, ["name"] = "default:silver_sandstone_brick", ["z"] = 112}, {["y"] = 5, ["x"] = 2, ["name"] = "default:silver_sandstone_brick", ["z"] = 4, ["param1"] = 15}, {["y"] = 5, ["x"] = 2, ["name"] = "default:acacia_wood", ["z"] = 5}, {["y"] = 5, ["x"] = 2, ["name"] = "default:acacia_wood", ["z"] = 6}, {["y"] = 5, ["x"] = 2, ["name"] = "default:acacia_wood", ["z"] = 7}, {["y"] = 5, ["x"] = 2, ["name"] = "default:acacia_wood", ["z"] = 8}, {["y"] = 5, ["x"] = 2, ["name"] = "default:silver_sandstone_brick", ["z"] = 9, ["param1"] = 15}, {["y"] = 5, ["x"] = 2, ["name"] = "default:silver_sandstone_brick", ["z"] = 107}, {["y"] = 5, ["x"] = 2, ["name"] = "default:acacia_wood", ["z"] = 108}, {["y"] = 5, ["x"] = 2, ["name"] = "default:acacia_wood", ["z"] = 109, ["param1"] = 15}, {["y"] = 5, ["x"] = 2, ["name"] = "default:acacia_wood", ["z"] = 110, ["param1"] = 15}, {["y"] = 5, ["x"] = 2, ["name"] = "default:acacia_wood", ["z"] = 111, ["param1"] = 15}, {["y"] = 5, ["x"] = 2, ["name"] = "default:silver_sandstone_brick", ["z"] = 112}, {["y"] = 6, ["x"] = 2, ["name"] = "default:silver_sandstone_brick", ["z"] = 4, ["param1"] = 15}, {["y"] = 6, ["x"] = 2, ["name"] = "default:silver_sandstone_brick", ["z"] = 9, ["param1"] = 15}, {["y"] = 6, ["x"] = 2, ["name"] = "default:silver_sandstone_brick", ["z"] = 107}, {["y"] = 6, ["x"] = 2, ["name"] = "default:silver_sandstone_brick", ["z"] = 112, ["param1"] = 15}, {["y"] = 7, ["x"] = 2, ["name"] = "default:silver_sandstone_brick", ["z"] = 4, ["param1"] = 14}, {["y"] = 7, ["x"] = 2, ["name"] = "default:silver_sandstone_brick", ["z"] = 9, ["param1"] = 14}, {["y"] = 7, ["x"] = 2, ["name"] = "default:silver_sandstone_brick", ["z"] = 107}, {["y"] = 7, ["x"] = 2, ["name"] = "default:silver_sandstone_brick", ["z"] = 112, ["param1"] = 15}, {["y"] = 8, ["x"] = 2, ["name"] = "default:silver_sandstone_brick", ["z"] = 4, ["param1"] = 14}, {["y"] = 8, ["x"] = 2, ["name"] = "default:silver_sandstone_brick", ["z"] = 9, ["param1"] = 14}, {["y"] = 8, ["x"] = 2, ["name"] = "default:silver_sandstone_brick", ["z"] = 107}, {["y"] = 8, ["x"] = 2, ["name"] = "default:silver_sandstone_brick", ["z"] = 112, ["param1"] = 15}, {["y"] = 9, ["x"] = 2, ["name"] = "default:silver_sandstone_brick", ["z"] = 4, ["param1"] = 14}, {["y"] = 9, ["x"] = 2, ["name"] = "default:silver_sandstone_brick", ["z"] = 9, ["param1"] = 15}, {["y"] = 9, ["x"] = 2, ["name"] = "default:silver_sandstone_brick", ["z"] = 107}, {["y"] = 9, ["x"] = 2, ["name"] = "default:silver_sandstone_brick", ["z"] = 112, ["param1"] = 15}, {["y"] = 10, ["x"] = 2, ["name"] = "default:silver_sandstone_brick", ["z"] = 2, ["param1"] = 15}, {["y"] = 10, ["x"] = 2, ["name"] = "default:silver_sandstone_brick", ["z"] = 4, ["param1"] = 14}, {["y"] = 10, ["x"] = 2, ["name"] = "default:silver_sandstone_brick", ["z"] = 9, ["param1"] = 15}, {["y"] = 10, ["x"] = 2, ["name"] = "default:silver_sandstone_brick", ["z"] = 107}, {["y"] = 10, ["x"] = 2, ["name"] = "default:silver_sandstone_brick", ["z"] = 112, ["param1"] = 15}, {["y"] = 11, ["x"] = 2, ["name"] = "default:silver_sandstone_brick", ["z"] = 4, ["param1"] = 14}, {["y"] = 11, ["x"] = 2, ["name"] = "default:silver_sandstone_brick", ["z"] = 9, ["param1"] = 15}, {["y"] = 11, ["x"] = 2, ["name"] = "default:silver_sandstone_brick", ["z"] = 107}, {["y"] = 11, ["x"] = 2, ["name"] = "default:silver_sandstone_brick", ["z"] = 112, ["param1"] = 15}, {["y"] = 12, ["x"] = 2, ["name"] = "default:silver_sandstone_brick", ["z"] = 4, ["param1"] = 14}, {["y"] = 12, ["x"] = 2, ["name"] = "default:silver_sandstone_brick", ["z"] = 9, ["param1"] = 15}, {["y"] = 12, ["x"] = 2, ["name"] = "default:silver_sandstone_brick", ["z"] = 107}, {["y"] = 12, ["x"] = 2, ["name"] = "default:silver_sandstone_brick", ["z"] = 112, ["param1"] = 15}, {["y"] = 13, ["x"] = 2, ["name"] = "default:silver_sandstone_brick", ["z"] = 4, ["param1"] = 14}, {["y"] = 13, ["x"] = 2, ["name"] = "default:silver_sandstone_brick", ["z"] = 9, ["param1"] = 15}, {["y"] = 13, ["x"] = 2, ["name"] = "default:silver_sandstone_brick", ["z"] = 107}, {["y"] = 13, ["x"] = 2, ["name"] = "default:silver_sandstone_brick", ["z"] = 112, ["param1"] = 15}, {["y"] = 14, ["x"] = 2, ["name"] = "default:silver_sandstone_brick", ["z"] = 4, ["param1"] = 14}, {["y"] = 14, ["x"] = 2, ["name"] = "default:silver_sandstone_brick", ["z"] = 9, ["param1"] = 15}, {["y"] = 14, ["x"] = 2, ["name"] = "default:silver_sandstone_brick", ["z"] = 107}, {["y"] = 14, ["x"] = 2, ["name"] = "default:silver_sandstone_brick", ["z"] = 112, ["param1"] = 15}, {["y"] = 15, ["x"] = 2, ["name"] = "default:silver_sandstone_brick", ["z"] = 4}, {["y"] = 15, ["x"] = 2, ["name"] = "default:acacia_wood", ["z"] = 5, ["param1"] = 79}, {["y"] = 15, ["x"] = 2, ["name"] = "default:acacia_wood", ["z"] = 6, ["param1"] = 63}, {["y"] = 15, ["x"] = 2, ["name"] = "default:acacia_wood", ["z"] = 7, ["param1"] = 62}, {["y"] = 15, ["x"] = 2, ["name"] = "default:acacia_wood", ["z"] = 8}, {["y"] = 15, ["x"] = 2, ["name"] = "default:silver_sandstone_brick", ["z"] = 9, ["param1"] = 15}, {["y"] = 15, ["x"] = 2, ["name"] = "default:silver_sandstone_brick", ["z"] = 107}, {["y"] = 15, ["x"] = 2, ["name"] = "default:acacia_wood", ["z"] = 108}, {["y"] = 15, ["x"] = 2, ["name"] = "default:acacia_wood", ["z"] = 109}, {["y"] = 15, ["x"] = 2, ["name"] = "default:acacia_wood", ["z"] = 110}, {["y"] = 15, ["x"] = 2, ["name"] = "default:acacia_wood", ["z"] = 111}, {["y"] = 15, ["x"] = 2, ["name"] = "default:silver_sandstone_brick", ["z"] = 112, ["param1"] = 15}, {["y"] = 0, ["x"] = 3, ["name"] = "default:silver_sandstone_brick", ["z"] = 3, ["param1"] = 17}, {["y"] = 0, ["x"] = 3, ["name"] = "default:silver_sandstone_brick", ["z"] = 4}, {["y"] = 0, ["x"] = 3, ["name"] = "default:silver_sandstone_brick", ["z"] = 5}, {["y"] = 0, ["x"] = 3, ["name"] = "default:silver_sandstone_brick", ["z"] = 6, ["param1"] = 17}, {["y"] = 0, ["x"] = 3, ["name"] = "default:silver_sandstone_brick", ["z"] = 7, ["param1"] = 17}, {["y"] = 0, ["x"] = 3, ["name"] = "default:silver_sandstone_brick", ["z"] = 8, ["param1"] = 35}, {["y"] = 0, ["x"] = 3, ["name"] = "default:silver_sandstone_brick", ["z"] = 9, ["param1"] = 35}, {["y"] = 0, ["x"] = 3, ["name"] = "default:silver_sandstone_brick", ["z"] = 10, ["param1"] = 35}, {["y"] = 0, ["x"] = 3, ["name"] = "default:silver_sandstone_brick", ["z"] = 11, ["param1"] = 35}, {["y"] = 0, ["x"] = 3, ["name"] = "default:silver_sandstone_brick", ["z"] = 12, ["param1"] = 15}, {["y"] = 0, ["x"] = 3, ["name"] = "default:silver_sandstone_brick", ["z"] = 13, ["param1"] = 15}, {["y"] = 0, ["x"] = 3, ["name"] = "default:silver_sandstone_brick", ["z"] = 14, ["param1"] = 15}, {["y"] = 0, ["x"] = 3, ["name"] = "default:silver_sandstone_brick", ["z"] = 15, ["param1"] = 15}, {["y"] = 0, ["x"] = 3, ["name"] = "default:silver_sandstone_brick", ["z"] = 16, ["param1"] = 15}, {["y"] = 0, ["x"] = 3, ["name"] = "default:silver_sandstone_brick", ["z"] = 17, ["param1"] = 15}, {["y"] = 0, ["x"] = 3, ["name"] = "default:silver_sandstone_brick", ["z"] = 18, ["param1"] = 15}, {["y"] = 0, ["x"] = 3, ["name"] = "default:silver_sandstone_brick", ["z"] = 19, ["param1"] = 15}, {["y"] = 0, ["x"] = 3, ["name"] = "default:silver_sandstone_brick", ["z"] = 20, ["param1"] = 15}, {["y"] = 0, ["x"] = 3, ["name"] = "default:silver_sandstone_brick", ["z"] = 21, ["param1"] = 15}, {["y"] = 0, ["x"] = 3, ["name"] = "default:silver_sandstone_brick", ["z"] = 22, ["param1"] = 15}, {["y"] = 0, ["x"] = 3, ["name"] = "default:silver_sandstone_brick", ["z"] = 23, ["param1"] = 14}, {["y"] = 0, ["x"] = 3, ["name"] = "default:silver_sandstone_brick", ["z"] = 24, ["param1"] = 13}, {["y"] = 0, ["x"] = 3, ["name"] = "default:silver_sandstone_brick", ["z"] = 25, ["param1"] = 17}, {["y"] = 0, ["x"] = 3, ["name"] = "default:silver_sandstone_brick", ["z"] = 26, ["param1"] = 17}, {["y"] = 0, ["x"] = 3, ["name"] = "default:silver_sandstone_brick", ["z"] = 27, ["param1"] = 17}, {["y"] = 0, ["x"] = 3, ["name"] = "default:silver_sandstone_brick", ["z"] = 28, ["param1"] = 17}, {["y"] = 0, ["x"] = 3, ["name"] = "default:silver_sandstone_brick", ["z"] = 29, ["param1"] = 17}, {["y"] = 0, ["x"] = 3, ["name"] = "default:silver_sandstone_brick", ["z"] = 30, ["param1"] = 17}, {["y"] = 0, ["x"] = 3, ["name"] = "default:silver_sandstone_brick", ["z"] = 31, ["param1"] = 17}, {["y"] = 0, ["x"] = 3, ["name"] = "default:silver_sandstone_brick", ["z"] = 32, ["param1"] = 17}, {["y"] = 0, ["x"] = 3, ["name"] = "default:silver_sandstone_brick", ["z"] = 33, ["param1"] = 17}, {["y"] = 0, ["x"] = 3, ["name"] = "default:silver_sandstone_brick", ["z"] = 34, ["param1"] = 17}, {["y"] = 0, ["x"] = 3, ["name"] = "default:silver_sandstone_brick", ["z"] = 35, ["param1"] = 17}, {["y"] = 0, ["x"] = 3, ["name"] = "default:silver_sandstone_brick", ["z"] = 36, ["param1"] = 17}, {["y"] = 0, ["x"] = 3, ["name"] = "default:silver_sandstone_brick", ["z"] = 37, ["param1"] = 17}, {["y"] = 0, ["x"] = 3, ["name"] = "default:silver_sandstone_brick", ["z"] = 38, ["param1"] = 17}, {["y"] = 0, ["x"] = 3, ["name"] = "default:silver_sandstone_brick", ["z"] = 39, ["param1"] = 17}, {["y"] = 0, ["x"] = 3, ["name"] = "default:silver_sandstone_brick", ["z"] = 40, ["param1"] = 17}, {["y"] = 0, ["x"] = 3, ["name"] = "default:silver_sandstone_brick", ["z"] = 41, ["param1"] = 17}, {["y"] = 0, ["x"] = 3, ["name"] = "default:silver_sandstone_brick", ["z"] = 42, ["param1"] = 17}, {["y"] = 0, ["x"] = 3, ["name"] = "default:silver_sandstone_brick", ["z"] = 43, ["param1"] = 17}, {["y"] = 0, ["x"] = 3, ["name"] = "default:silver_sandstone_brick", ["z"] = 44, ["param1"] = 17}, {["y"] = 0, ["x"] = 3, ["name"] = "default:silver_sandstone_brick", ["z"] = 45, ["param1"] = 17}, {["y"] = 0, ["x"] = 3, ["name"] = "default:silver_sandstone_brick", ["z"] = 46, ["param1"] = 17}, {["y"] = 0, ["x"] = 3, ["name"] = "default:silver_sandstone_brick", ["z"] = 47, ["param1"] = 17}, {["y"] = 0, ["x"] = 3, ["name"] = "default:silver_sandstone_brick", ["z"] = 48, ["param1"] = 17}, {["y"] = 0, ["x"] = 3, ["name"] = "default:silver_sandstone_brick", ["z"] = 49, ["param1"] = 17}, {["y"] = 0, ["x"] = 3, ["name"] = "default:silver_sandstone_brick", ["z"] = 50, ["param1"] = 17}, {["y"] = 0, ["x"] = 3, ["name"] = "default:silver_sandstone_brick", ["z"] = 51, ["param1"] = 17}, {["y"] = 0, ["x"] = 3, ["name"] = "default:silver_sandstone_brick", ["z"] = 52, ["param1"] = 17}, {["y"] = 0, ["x"] = 3, ["name"] = "default:silver_sandstone_brick", ["z"] = 53, ["param1"] = 17}, {["y"] = 0, ["x"] = 3, ["name"] = "default:silver_sandstone_brick", ["z"] = 54, ["param1"] = 17}, {["y"] = 0, ["x"] = 3, ["name"] = "default:silver_sandstone_brick", ["z"] = 55, ["param1"] = 17}, {["y"] = 0, ["x"] = 3, ["name"] = "default:silver_sandstone_brick", ["z"] = 56, ["param1"] = 17}, {["y"] = 0, ["x"] = 3, ["name"] = "default:silver_sandstone_brick", ["z"] = 57, ["param1"] = 17}, {["y"] = 0, ["x"] = 3, ["name"] = "default:silver_sandstone_brick", ["z"] = 58, ["param1"] = 17}, {["y"] = 0, ["x"] = 3, ["name"] = "default:silver_sandstone_brick", ["z"] = 59, ["param1"] = 17}, {["y"] = 0, ["x"] = 3, ["name"] = "default:silver_sandstone_brick", ["z"] = 60, ["param1"] = 17}, {["y"] = 0, ["x"] = 3, ["name"] = "default:silver_sandstone_brick", ["z"] = 61, ["param1"] = 17}, {["y"] = 0, ["x"] = 3, ["name"] = "default:silver_sandstone_brick", ["z"] = 62, ["param1"] = 17}, {["y"] = 0, ["x"] = 3, ["name"] = "default:silver_sandstone_brick", ["z"] = 63, ["param1"] = 17}, {["y"] = 0, ["x"] = 3, ["name"] = "default:silver_sandstone_brick", ["z"] = 64, ["param1"] = 17}, {["y"] = 0, ["x"] = 3, ["name"] = "default:silver_sandstone_brick", ["z"] = 65, ["param1"] = 17}, {["y"] = 0, ["x"] = 3, ["name"] = "default:silver_sandstone_brick", ["z"] = 66, ["param1"] = 17}, {["y"] = 0, ["x"] = 3, ["name"] = "default:silver_sandstone_brick", ["z"] = 67, ["param1"] = 17}, {["y"] = 0, ["x"] = 3, ["name"] = "default:silver_sandstone_brick", ["z"] = 68, ["param1"] = 17}, {["y"] = 0, ["x"] = 3, ["name"] = "default:silver_sandstone_brick", ["z"] = 69, ["param1"] = 17}, {["y"] = 0, ["x"] = 3, ["name"] = "default:silver_sandstone_brick", ["z"] = 70, ["param1"] = 17}, {["y"] = 0, ["x"] = 3, ["name"] = "default:silver_sandstone_brick", ["z"] = 71, ["param1"] = 17}, {["y"] = 0, ["x"] = 3, ["name"] = "default:silver_sandstone_brick", ["z"] = 72, ["param1"] = 17}, {["y"] = 0, ["x"] = 3, ["name"] = "default:silver_sandstone_brick", ["z"] = 73, ["param1"] = 17}, {["y"] = 0, ["x"] = 3, ["name"] = "default:silver_sandstone_brick", ["z"] = 74, ["param1"] = 17}, {["y"] = 0, ["x"] = 3, ["name"] = "default:silver_sandstone_brick", ["z"] = 75, ["param1"] = 17}, {["y"] = 0, ["x"] = 3, ["name"] = "default:silver_sandstone_brick", ["z"] = 76, ["param1"] = 17}, {["y"] = 0, ["x"] = 3, ["name"] = "default:silver_sandstone_brick", ["z"] = 77, ["param1"] = 17}, {["y"] = 0, ["x"] = 3, ["name"] = "default:silver_sandstone_brick", ["z"] = 78, ["param1"] = 17}, {["y"] = 0, ["x"] = 3, ["name"] = "default:silver_sandstone_brick", ["z"] = 79, ["param1"] = 17}, {["y"] = 0, ["x"] = 3, ["name"] = "default:silver_sandstone_brick", ["z"] = 80, ["param1"] = 17}, {["y"] = 0, ["x"] = 3, ["name"] = "default:silver_sandstone_brick", ["z"] = 81, ["param1"] = 17}, {["y"] = 0, ["x"] = 3, ["name"] = "default:silver_sandstone_brick", ["z"] = 82, ["param1"] = 17}, {["y"] = 0, ["x"] = 3, ["name"] = "default:silver_sandstone_brick", ["z"] = 83, ["param1"] = 17}, {["y"] = 0, ["x"] = 3, ["name"] = "default:silver_sandstone_brick", ["z"] = 84, ["param1"] = 17}, {["y"] = 0, ["x"] = 3, ["name"] = "default:silver_sandstone_brick", ["z"] = 85, ["param1"] = 17}, {["y"] = 0, ["x"] = 3, ["name"] = "default:silver_sandstone_brick", ["z"] = 86, ["param1"] = 17}, {["y"] = 0, ["x"] = 3, ["name"] = "default:silver_sandstone_brick", ["z"] = 87, ["param1"] = 17}, {["y"] = 0, ["x"] = 3, ["name"] = "default:silver_sandstone_brick", ["z"] = 88, ["param1"] = 17}, {["y"] = 0, ["x"] = 3, ["name"] = "default:silver_sandstone_brick", ["z"] = 89, ["param1"] = 17}, {["y"] = 0, ["x"] = 3, ["name"] = "default:silver_sandstone_brick", ["z"] = 90, ["param1"] = 17}, {["y"] = 0, ["x"] = 3, ["name"] = "default:silver_sandstone_brick", ["z"] = 91, ["param1"] = 17}, {["y"] = 0, ["x"] = 3, ["name"] = "default:silver_sandstone_brick", ["z"] = 92, ["param1"] = 17}, {["y"] = 0, ["x"] = 3, ["name"] = "default:silver_sandstone_brick", ["z"] = 93, ["param1"] = 17}, {["y"] = 0, ["x"] = 3, ["name"] = "default:silver_sandstone_brick", ["z"] = 94, ["param1"] = 17}, {["y"] = 0, ["x"] = 3, ["name"] = "default:silver_sandstone_brick", ["z"] = 95, ["param1"] = 17}, {["y"] = 0, ["x"] = 3, ["name"] = "default:silver_sandstone_brick", ["z"] = 96, ["param1"] = 17}, {["y"] = 0, ["x"] = 3, ["name"] = "default:silver_sandstone_brick", ["z"] = 97, ["param1"] = 17}, {["y"] = 0, ["x"] = 3, ["name"] = "default:silver_sandstone_brick", ["z"] = 98, ["param1"] = 17}, {["y"] = 0, ["x"] = 3, ["name"] = "default:silver_sandstone_brick", ["z"] = 99, ["param1"] = 17}, {["y"] = 0, ["x"] = 3, ["name"] = "default:silver_sandstone_brick", ["z"] = 100, ["param1"] = 17}, {["y"] = 0, ["x"] = 3, ["name"] = "default:silver_sandstone_brick", ["z"] = 101, ["param1"] = 17}, {["y"] = 0, ["x"] = 3, ["name"] = "default:silver_sandstone_brick", ["z"] = 102, ["param1"] = 17}, {["y"] = 0, ["x"] = 3, ["name"] = "default:silver_sandstone_brick", ["z"] = 103, ["param1"] = 17}, {["y"] = 0, ["x"] = 3, ["name"] = "default:silver_sandstone_brick", ["z"] = 104, ["param1"] = 17}, {["y"] = 0, ["x"] = 3, ["name"] = "default:silver_sandstone_brick", ["z"] = 105, ["param1"] = 17}, {["y"] = 0, ["x"] = 3, ["name"] = "default:silver_sandstone_brick", ["z"] = 106, ["param1"] = 17}, {["y"] = 0, ["x"] = 3, ["name"] = "default:silver_sandstone_brick", ["z"] = 107}, {["y"] = 0, ["x"] = 3, ["name"] = "default:silver_sandstone_brick", ["z"] = 108, ["param1"] = 17}, {["y"] = 0, ["x"] = 3, ["name"] = "default:silver_sandstone_brick", ["z"] = 109, ["param1"] = 17}, {["y"] = 0, ["x"] = 3, ["name"] = "default:silver_sandstone_brick", ["z"] = 110, ["param1"] = 17}, {["y"] = 0, ["x"] = 3, ["name"] = "default:silver_sandstone_brick", ["z"] = 111, ["param1"] = 35}, {["y"] = 0, ["x"] = 3, ["name"] = "default:silver_sandstone_brick", ["z"] = 112, ["param1"] = 35}, {["y"] = 0, ["x"] = 3, ["name"] = "default:silver_sandstone_brick", ["z"] = 113, ["param1"] = 35}, {["y"] = 0, ["x"] = 3, ["name"] = "default:desert_sand", ["z"] = 114, ["param1"] = 35}, {["y"] = 0, ["x"] = 3, ["name"] = "default:desert_sand", ["z"] = 115, ["param1"] = 35}, {["y"] = 0, ["x"] = 3, ["name"] = "default:desert_sand", ["z"] = 116, ["param1"] = 35}, {["y"] = 1, ["x"] = 3, ["name"] = "default:silver_sandstone_brick", ["z"] = 3}, {["y"] = 1, ["x"] = 3, ["name"] = "default:silver_sandstone_brick", ["z"] = 10, ["param1"] = 15}, {["y"] = 1, ["x"] = 3, ["name"] = "default:silver_sandstone_brick", ["z"] = 11, ["param1"] = 15}, {["y"] = 1, ["x"] = 3, ["name"] = "default:silver_sandstone_brick", ["z"] = 12, ["param1"] = 15}, {["y"] = 1, ["x"] = 3, ["name"] = "default:silver_sandstone_brick", ["z"] = 13, ["param1"] = 15}, {["y"] = 1, ["x"] = 3, ["name"] = "default:silver_sandstone_brick", ["z"] = 14, ["param1"] = 15}, {["y"] = 1, ["x"] = 3, ["name"] = "default:silver_sandstone_brick", ["z"] = 15, ["param1"] = 15}, {["y"] = 1, ["x"] = 3, ["name"] = "default:silver_sandstone_brick", ["z"] = 16, ["param1"] = 15}, {["y"] = 1, ["x"] = 3, ["name"] = "default:silver_sandstone_brick", ["z"] = 17, ["param1"] = 15}, {["y"] = 1, ["x"] = 3, ["name"] = "default:silver_sandstone_brick", ["z"] = 18, ["param1"] = 15}, {["y"] = 1, ["x"] = 3, ["name"] = "default:silver_sandstone_brick", ["z"] = 19, ["param1"] = 15}, {["y"] = 1, ["x"] = 3, ["name"] = "default:silver_sandstone_brick", ["z"] = 20, ["param1"] = 15}, {["y"] = 1, ["x"] = 3, ["name"] = "default:silver_sandstone_brick", ["z"] = 21, ["param1"] = 15}, {["y"] = 1, ["x"] = 3, ["name"] = "default:silver_sandstone_brick", ["z"] = 22, ["param1"] = 15}, {["y"] = 1, ["x"] = 3, ["name"] = "default:silver_sandstone_brick", ["z"] = 23, ["param1"] = 14}, {["y"] = 1, ["x"] = 3, ["name"] = "default:silver_sandstone_brick", ["z"] = 24, ["param1"] = 15}, {["y"] = 1, ["x"] = 3, ["name"] = "default:silver_sandstone_brick", ["z"] = 25, ["param2"] = 4, ["param1"] = 15}, {["y"] = 1, ["x"] = 3, ["name"] = "default:silver_sandstone_brick", ["z"] = 26, ["param1"] = 15}, {["y"] = 1, ["x"] = 3, ["name"] = "default:silver_sandstone_brick", ["z"] = 27, ["param1"] = 15}, {["y"] = 1, ["x"] = 3, ["name"] = "default:silver_sandstone_brick", ["z"] = 28, ["param1"] = 15}, {["y"] = 1, ["x"] = 3, ["name"] = "default:silver_sandstone_brick", ["z"] = 29, ["param1"] = 15}, {["y"] = 1, ["x"] = 3, ["name"] = "default:silver_sandstone_brick", ["z"] = 30, ["param1"] = 15}, {["y"] = 1, ["x"] = 3, ["name"] = "default:silver_sandstone_brick", ["z"] = 31, ["param1"] = 15}, {["y"] = 1, ["x"] = 3, ["name"] = "default:silver_sandstone_brick", ["z"] = 32, ["param1"] = 15}, {["y"] = 1, ["x"] = 3, ["name"] = "default:silver_sandstone_brick", ["z"] = 33, ["param1"] = 15}, {["y"] = 1, ["x"] = 3, ["name"] = "default:silver_sandstone_brick", ["z"] = 34, ["param1"] = 15}, {["y"] = 1, ["x"] = 3, ["name"] = "default:silver_sandstone_brick", ["z"] = 35, ["param1"] = 15}, {["y"] = 1, ["x"] = 3, ["name"] = "default:silver_sandstone_brick", ["z"] = 36, ["param1"] = 15}, {["y"] = 1, ["x"] = 3, ["name"] = "default:silver_sandstone_brick", ["z"] = 37, ["param1"] = 15}, {["y"] = 1, ["x"] = 3, ["name"] = "default:silver_sandstone_brick", ["z"] = 38, ["param1"] = 15}, {["y"] = 1, ["x"] = 3, ["name"] = "default:silver_sandstone_brick", ["z"] = 39, ["param1"] = 14}, {["y"] = 1, ["x"] = 3, ["name"] = "default:silver_sandstone_brick", ["z"] = 40, ["param1"] = 14}, {["y"] = 1, ["x"] = 3, ["name"] = "default:silver_sandstone_brick", ["z"] = 41, ["param1"] = 15}, {["y"] = 1, ["x"] = 3, ["name"] = "default:silver_sandstone_brick", ["z"] = 42, ["param1"] = 15}, {["y"] = 1, ["x"] = 3, ["name"] = "default:silver_sandstone_brick", ["z"] = 43, ["param1"] = 15}, {["y"] = 1, ["x"] = 3, ["name"] = "default:silver_sandstone_brick", ["z"] = 44, ["param1"] = 15}, {["y"] = 1, ["x"] = 3, ["name"] = "default:silver_sandstone_brick", ["z"] = 45, ["param1"] = 15}, {["y"] = 1, ["x"] = 3, ["name"] = "default:silver_sandstone_brick", ["z"] = 46, ["param1"] = 15}, {["y"] = 1, ["x"] = 3, ["name"] = "default:silver_sandstone_brick", ["z"] = 47, ["param1"] = 15}, {["y"] = 1, ["x"] = 3, ["name"] = "default:silver_sandstone_brick", ["z"] = 48, ["param1"] = 15}, {["y"] = 1, ["x"] = 3, ["name"] = "default:silver_sandstone_brick", ["z"] = 49, ["param1"] = 15}, {["y"] = 1, ["x"] = 3, ["name"] = "default:silver_sandstone_brick", ["z"] = 50, ["param1"] = 15}, {["y"] = 1, ["x"] = 3, ["name"] = "default:silver_sandstone_brick", ["z"] = 51, ["param1"] = 15}, {["y"] = 1, ["x"] = 3, ["name"] = "default:silver_sandstone_brick", ["z"] = 52, ["param1"] = 15}, {["y"] = 1, ["x"] = 3, ["name"] = "default:silver_sandstone_brick", ["z"] = 53, ["param1"] = 15}, {["y"] = 1, ["x"] = 3, ["name"] = "default:silver_sandstone_brick", ["z"] = 54, ["param1"] = 15}, {["y"] = 1, ["x"] = 3, ["name"] = "default:silver_sandstone_brick", ["z"] = 55, ["param1"] = 14}, {["y"] = 1, ["x"] = 3, ["name"] = "default:silver_sandstone_brick", ["z"] = 56, ["param1"] = 14}, {["y"] = 1, ["x"] = 3, ["name"] = "default:silver_sandstone_brick", ["z"] = 57, ["param1"] = 15}, {["y"] = 1, ["x"] = 3, ["name"] = "default:silver_sandstone_brick", ["z"] = 58, ["param1"] = 15}, {["y"] = 1, ["x"] = 3, ["name"] = "default:silver_sandstone_brick", ["z"] = 59, ["param1"] = 15}, {["y"] = 1, ["x"] = 3, ["name"] = "default:silver_sandstone_brick", ["z"] = 60, ["param1"] = 15}, {["y"] = 1, ["x"] = 3, ["name"] = "default:silver_sandstone_brick", ["z"] = 61, ["param1"] = 15}, {["y"] = 1, ["x"] = 3, ["name"] = "default:silver_sandstone_brick", ["z"] = 62, ["param1"] = 15}, {["y"] = 1, ["x"] = 3, ["name"] = "default:silver_sandstone_brick", ["z"] = 63, ["param1"] = 15}, {["y"] = 1, ["x"] = 3, ["name"] = "default:silver_sandstone_brick", ["z"] = 64, ["param1"] = 15}, {["y"] = 1, ["x"] = 3, ["name"] = "default:silver_sandstone_brick", ["z"] = 65, ["param1"] = 15}, {["y"] = 1, ["x"] = 3, ["name"] = "default:silver_sandstone_brick", ["z"] = 66, ["param1"] = 15}, {["y"] = 1, ["x"] = 3, ["name"] = "default:silver_sandstone_brick", ["z"] = 67, ["param1"] = 15}, {["y"] = 1, ["x"] = 3, ["name"] = "default:silver_sandstone_brick", ["z"] = 68, ["param1"] = 15}, {["y"] = 1, ["x"] = 3, ["name"] = "default:silver_sandstone_brick", ["z"] = 69, ["param1"] = 15}, {["y"] = 1, ["x"] = 3, ["name"] = "default:silver_sandstone_brick", ["z"] = 70, ["param1"] = 15}, {["y"] = 1, ["x"] = 3, ["name"] = "default:silver_sandstone_brick", ["z"] = 71, ["param1"] = 14}, {["y"] = 1, ["x"] = 3, ["name"] = "default:silver_sandstone_brick", ["z"] = 72, ["param1"] = 14}, {["y"] = 1, ["x"] = 3, ["name"] = "default:silver_sandstone_brick", ["z"] = 73, ["param1"] = 15}, {["y"] = 1, ["x"] = 3, ["name"] = "default:silver_sandstone_brick", ["z"] = 74, ["param1"] = 15}, {["y"] = 1, ["x"] = 3, ["name"] = "default:silver_sandstone_brick", ["z"] = 75, ["param1"] = 15}, {["y"] = 1, ["x"] = 3, ["name"] = "default:silver_sandstone_brick", ["z"] = 76, ["param1"] = 15}, {["y"] = 1, ["x"] = 3, ["name"] = "default:silver_sandstone_brick", ["z"] = 77, ["param1"] = 15}, {["y"] = 1, ["x"] = 3, ["name"] = "default:silver_sandstone_brick", ["z"] = 78, ["param1"] = 15}, {["y"] = 1, ["x"] = 3, ["name"] = "default:silver_sandstone_brick", ["z"] = 79, ["param1"] = 15}, {["y"] = 1, ["x"] = 3, ["name"] = "default:silver_sandstone_brick", ["z"] = 80, ["param1"] = 15}, {["y"] = 1, ["x"] = 3, ["name"] = "default:silver_sandstone_brick", ["z"] = 81, ["param1"] = 15}, {["y"] = 1, ["x"] = 3, ["name"] = "default:silver_sandstone_brick", ["z"] = 82, ["param1"] = 15}, {["y"] = 1, ["x"] = 3, ["name"] = "default:silver_sandstone_brick", ["z"] = 83, ["param1"] = 15}, {["y"] = 1, ["x"] = 3, ["name"] = "default:silver_sandstone_brick", ["z"] = 84, ["param1"] = 15}, {["y"] = 1, ["x"] = 3, ["name"] = "default:silver_sandstone_brick", ["z"] = 85, ["param1"] = 15}, {["y"] = 1, ["x"] = 3, ["name"] = "default:silver_sandstone_brick", ["z"] = 86, ["param1"] = 15}, {["y"] = 1, ["x"] = 3, ["name"] = "default:silver_sandstone_brick", ["z"] = 87, ["param1"] = 14}, {["y"] = 1, ["x"] = 3, ["name"] = "default:silver_sandstone_brick", ["z"] = 88, ["param1"] = 14}, {["y"] = 1, ["x"] = 3, ["name"] = "default:silver_sandstone_brick", ["z"] = 89, ["param1"] = 15}, {["y"] = 1, ["x"] = 3, ["name"] = "default:silver_sandstone_brick", ["z"] = 90, ["param1"] = 15}, {["y"] = 1, ["x"] = 3, ["name"] = "default:silver_sandstone_brick", ["z"] = 91, ["param1"] = 15}, {["y"] = 1, ["x"] = 3, ["name"] = "default:silver_sandstone_brick", ["z"] = 92, ["param1"] = 15}, {["y"] = 1, ["x"] = 3, ["name"] = "default:silver_sandstone_brick", ["z"] = 93, ["param1"] = 15}, {["y"] = 1, ["x"] = 3, ["name"] = "default:silver_sandstone_brick", ["z"] = 94, ["param1"] = 15}, {["y"] = 1, ["x"] = 3, ["name"] = "default:silver_sandstone_brick", ["z"] = 95, ["param1"] = 15}, {["y"] = 1, ["x"] = 3, ["name"] = "default:silver_sandstone_brick", ["z"] = 96, ["param1"] = 15}, {["y"] = 1, ["x"] = 3, ["name"] = "default:silver_sandstone_brick", ["z"] = 97, ["param1"] = 15}, {["y"] = 1, ["x"] = 3, ["name"] = "default:silver_sandstone_brick", ["z"] = 98, ["param1"] = 15}, {["y"] = 1, ["x"] = 3, ["name"] = "default:silver_sandstone_brick", ["z"] = 99, ["param1"] = 15}, {["y"] = 1, ["x"] = 3, ["name"] = "default:silver_sandstone_brick", ["z"] = 100, ["param1"] = 15}, {["y"] = 1, ["x"] = 3, ["name"] = "default:silver_sandstone_brick", ["z"] = 101, ["param1"] = 15}, {["y"] = 1, ["x"] = 3, ["name"] = "default:silver_sandstone_brick", ["z"] = 102, ["param1"] = 15}, {["y"] = 1, ["x"] = 3, ["name"] = "default:silver_sandstone_brick", ["z"] = 103, ["param1"] = 14}, {["y"] = 1, ["x"] = 3, ["name"] = "default:silver_sandstone_brick", ["z"] = 104, ["param1"] = 13}, {["y"] = 1, ["x"] = 3, ["name"] = "default:silver_sandstone_brick", ["z"] = 105, ["param1"] = 15}, {["y"] = 1, ["x"] = 3, ["name"] = "default:silver_sandstone_brick", ["z"] = 106}, {["y"] = 1, ["x"] = 3, ["name"] = "default:silver_sandstone_brick", ["z"] = 113, ["param1"] = 15}, {["y"] = 2, ["x"] = 3, ["name"] = "default:silver_sandstone_brick", ["z"] = 3, ["param1"] = 15}, {["y"] = 2, ["x"] = 3, ["name"] = "default:silver_sandstone_brick", ["z"] = 10, ["param1"] = 15}, {["y"] = 2, ["x"] = 3, ["name"] = "default:silver_sandstone_brick", ["z"] = 11, ["param1"] = 15}, {["y"] = 2, ["x"] = 3, ["name"] = "default:silver_sandstone_brick", ["z"] = 12, ["param1"] = 15}, {["y"] = 2, ["x"] = 3, ["name"] = "default:silver_sandstone_brick", ["z"] = 13, ["param1"] = 15}, {["y"] = 2, ["x"] = 3, ["name"] = "default:silver_sandstone_brick", ["z"] = 14, ["param1"] = 15}, {["y"] = 2, ["x"] = 3, ["name"] = "default:silver_sandstone_brick", ["z"] = 15, ["param1"] = 15}, {["y"] = 2, ["x"] = 3, ["name"] = "default:silver_sandstone_brick", ["z"] = 16, ["param1"] = 15}, {["y"] = 2, ["x"] = 3, ["name"] = "default:silver_sandstone_brick", ["z"] = 17, ["param1"] = 15}, {["y"] = 2, ["x"] = 3, ["name"] = "default:silver_sandstone_brick", ["z"] = 18, ["param1"] = 15}, {["y"] = 2, ["x"] = 3, ["name"] = "default:silver_sandstone_brick", ["z"] = 19, ["param1"] = 15}, {["y"] = 2, ["x"] = 3, ["name"] = "default:silver_sandstone_brick", ["z"] = 20, ["param1"] = 15}, {["y"] = 2, ["x"] = 3, ["name"] = "default:silver_sandstone_brick", ["z"] = 21, ["param1"] = 15}, {["y"] = 2, ["x"] = 3, ["name"] = "default:silver_sandstone_brick", ["z"] = 22, ["param1"] = 15}, {["y"] = 2, ["x"] = 3, ["name"] = "default:silver_sandstone_brick", ["z"] = 23, ["param1"] = 14}, {["y"] = 2, ["x"] = 3, ["name"] = "default:silver_sandstone_brick", ["z"] = 24, ["param1"] = 15}, {["y"] = 2, ["x"] = 3, ["name"] = "default:silver_sandstone_brick", ["z"] = 25, ["param1"] = 15}, {["y"] = 2, ["x"] = 3, ["name"] = "default:silver_sandstone_brick", ["z"] = 26, ["param1"] = 15}, {["y"] = 2, ["x"] = 3, ["name"] = "default:silver_sandstone_brick", ["z"] = 27, ["param1"] = 15}, {["y"] = 2, ["x"] = 3, ["name"] = "default:silver_sandstone_brick", ["z"] = 28, ["param1"] = 15}, {["y"] = 2, ["x"] = 3, ["name"] = "default:silver_sandstone_brick", ["z"] = 29, ["param1"] = 15}, {["y"] = 2, ["x"] = 3, ["name"] = "default:silver_sandstone_brick", ["z"] = 30, ["param1"] = 15}, {["y"] = 2, ["x"] = 3, ["name"] = "default:silver_sandstone_brick", ["z"] = 31, ["param1"] = 15}, {["y"] = 2, ["x"] = 3, ["name"] = "default:silver_sandstone_brick", ["z"] = 32, ["param1"] = 15}, {["y"] = 2, ["x"] = 3, ["name"] = "default:silver_sandstone_brick", ["z"] = 33, ["param1"] = 15}, {["y"] = 2, ["x"] = 3, ["name"] = "default:silver_sandstone_brick", ["z"] = 34, ["param1"] = 15}, {["y"] = 2, ["x"] = 3, ["name"] = "default:silver_sandstone_brick", ["z"] = 35, ["param1"] = 15}, {["y"] = 2, ["x"] = 3, ["name"] = "default:silver_sandstone_brick", ["z"] = 36, ["param1"] = 15}, {["y"] = 2, ["x"] = 3, ["name"] = "default:silver_sandstone_brick", ["z"] = 37, ["param1"] = 15}, {["y"] = 2, ["x"] = 3, ["name"] = "default:silver_sandstone_brick", ["z"] = 38, ["param1"] = 15}, {["y"] = 2, ["x"] = 3, ["name"] = "default:silver_sandstone_brick", ["z"] = 39, ["param1"] = 14}, {["y"] = 2, ["x"] = 3, ["name"] = "default:silver_sandstone_brick", ["z"] = 40, ["param1"] = 14}, {["y"] = 2, ["x"] = 3, ["name"] = "default:silver_sandstone_brick", ["z"] = 41, ["param1"] = 15}, {["y"] = 2, ["x"] = 3, ["name"] = "default:silver_sandstone_brick", ["z"] = 42, ["param1"] = 15}, {["y"] = 2, ["x"] = 3, ["name"] = "default:silver_sandstone_brick", ["z"] = 43, ["param1"] = 15}, {["y"] = 2, ["x"] = 3, ["name"] = "default:silver_sandstone_brick", ["z"] = 44, ["param1"] = 15}, {["y"] = 2, ["x"] = 3, ["name"] = "default:silver_sandstone_brick", ["z"] = 45, ["param1"] = 15}, {["y"] = 2, ["x"] = 3, ["name"] = "default:silver_sandstone_brick", ["z"] = 46, ["param1"] = 15}, {["y"] = 2, ["x"] = 3, ["name"] = "default:silver_sandstone_brick", ["z"] = 47, ["param1"] = 15}, {["y"] = 2, ["x"] = 3, ["name"] = "default:silver_sandstone_brick", ["z"] = 48, ["param1"] = 15}, {["y"] = 2, ["x"] = 3, ["name"] = "default:silver_sandstone_brick", ["z"] = 49, ["param1"] = 15}, {["y"] = 2, ["x"] = 3, ["name"] = "default:silver_sandstone_brick", ["z"] = 50, ["param1"] = 15}, {["y"] = 2, ["x"] = 3, ["name"] = "default:silver_sandstone_brick", ["z"] = 51, ["param1"] = 15}, {["y"] = 2, ["x"] = 3, ["name"] = "default:silver_sandstone_brick", ["z"] = 52, ["param1"] = 15}, {["y"] = 2, ["x"] = 3, ["name"] = "default:silver_sandstone_brick", ["z"] = 53, ["param1"] = 15}, {["y"] = 2, ["x"] = 3, ["name"] = "default:silver_sandstone_brick", ["z"] = 54, ["param1"] = 15}, {["y"] = 2, ["x"] = 3, ["name"] = "default:silver_sandstone_brick", ["z"] = 55, ["param1"] = 14}, {["y"] = 2, ["x"] = 3, ["name"] = "default:silver_sandstone_brick", ["z"] = 56, ["param1"] = 14}, {["y"] = 2, ["x"] = 3, ["name"] = "default:silver_sandstone_brick", ["z"] = 57, ["param1"] = 15}, {["y"] = 2, ["x"] = 3, ["name"] = "default:silver_sandstone_brick", ["z"] = 58, ["param1"] = 15}, {["y"] = 2, ["x"] = 3, ["name"] = "default:silver_sandstone_brick", ["z"] = 59, ["param1"] = 15}, {["y"] = 2, ["x"] = 3, ["name"] = "default:silver_sandstone_brick", ["z"] = 60, ["param1"] = 15}, {["y"] = 2, ["x"] = 3, ["name"] = "default:silver_sandstone_brick", ["z"] = 61, ["param1"] = 15}, {["y"] = 2, ["x"] = 3, ["name"] = "default:silver_sandstone_brick", ["z"] = 62, ["param1"] = 15}, {["y"] = 2, ["x"] = 3, ["name"] = "default:silver_sandstone_brick", ["z"] = 63, ["param1"] = 15}, {["y"] = 2, ["x"] = 3, ["name"] = "default:silver_sandstone_brick", ["z"] = 64, ["param1"] = 15}, {["y"] = 2, ["x"] = 3, ["name"] = "default:silver_sandstone_brick", ["z"] = 65, ["param1"] = 15}, {["y"] = 2, ["x"] = 3, ["name"] = "default:silver_sandstone_brick", ["z"] = 66, ["param1"] = 15}, {["y"] = 2, ["x"] = 3, ["name"] = "default:silver_sandstone_brick", ["z"] = 67, ["param1"] = 15}, {["y"] = 2, ["x"] = 3, ["name"] = "default:silver_sandstone_brick", ["z"] = 68, ["param1"] = 15}, {["y"] = 2, ["x"] = 3, ["name"] = "default:silver_sandstone_brick", ["z"] = 69, ["param1"] = 15}, {["y"] = 2, ["x"] = 3, ["name"] = "default:silver_sandstone_brick", ["z"] = 70, ["param1"] = 15}, {["y"] = 2, ["x"] = 3, ["name"] = "default:silver_sandstone_brick", ["z"] = 71, ["param1"] = 14}, {["y"] = 2, ["x"] = 3, ["name"] = "default:silver_sandstone_brick", ["z"] = 72, ["param1"] = 14}, {["y"] = 2, ["x"] = 3, ["name"] = "default:silver_sandstone_brick", ["z"] = 73, ["param1"] = 15}, {["y"] = 2, ["x"] = 3, ["name"] = "default:silver_sandstone_brick", ["z"] = 74, ["param1"] = 15}, {["y"] = 2, ["x"] = 3, ["name"] = "default:silver_sandstone_brick", ["z"] = 75, ["param1"] = 15}, {["y"] = 2, ["x"] = 3, ["name"] = "default:silver_sandstone_brick", ["z"] = 76, ["param1"] = 15}, {["y"] = 2, ["x"] = 3, ["name"] = "default:silver_sandstone_brick", ["z"] = 77, ["param1"] = 15}, {["y"] = 2, ["x"] = 3, ["name"] = "default:silver_sandstone_brick", ["z"] = 78, ["param1"] = 15}, {["y"] = 2, ["x"] = 3, ["name"] = "default:silver_sandstone_brick", ["z"] = 79, ["param1"] = 15}, {["y"] = 2, ["x"] = 3, ["name"] = "default:silver_sandstone_brick", ["z"] = 80, ["param1"] = 15}, {["y"] = 2, ["x"] = 3, ["name"] = "default:silver_sandstone_brick", ["z"] = 81, ["param1"] = 15}, {["y"] = 2, ["x"] = 3, ["name"] = "default:silver_sandstone_brick", ["z"] = 82, ["param1"] = 15}, {["y"] = 2, ["x"] = 3, ["name"] = "default:silver_sandstone_brick", ["z"] = 83, ["param1"] = 15}, {["y"] = 2, ["x"] = 3, ["name"] = "default:silver_sandstone_brick", ["z"] = 84, ["param1"] = 15}, {["y"] = 2, ["x"] = 3, ["name"] = "default:silver_sandstone_brick", ["z"] = 85, ["param1"] = 15}, {["y"] = 2, ["x"] = 3, ["name"] = "default:silver_sandstone_brick", ["z"] = 86, ["param1"] = 15}, {["y"] = 2, ["x"] = 3, ["name"] = "default:silver_sandstone_brick", ["z"] = 87, ["param1"] = 14}, {["y"] = 2, ["x"] = 3, ["name"] = "default:silver_sandstone_brick", ["z"] = 88, ["param1"] = 14}, {["y"] = 2, ["x"] = 3, ["name"] = "default:silver_sandstone_brick", ["z"] = 89, ["param1"] = 15}, {["y"] = 2, ["x"] = 3, ["name"] = "default:silver_sandstone_brick", ["z"] = 90, ["param1"] = 15}, {["y"] = 2, ["x"] = 3, ["name"] = "default:silver_sandstone_brick", ["z"] = 91, ["param1"] = 15}, {["y"] = 2, ["x"] = 3, ["name"] = "default:silver_sandstone_brick", ["z"] = 92, ["param1"] = 15}, {["y"] = 2, ["x"] = 3, ["name"] = "default:silver_sandstone_brick", ["z"] = 93, ["param1"] = 15}, {["y"] = 2, ["x"] = 3, ["name"] = "default:silver_sandstone_brick", ["z"] = 94, ["param1"] = 15}, {["y"] = 2, ["x"] = 3, ["name"] = "default:silver_sandstone_brick", ["z"] = 95, ["param1"] = 15}, {["y"] = 2, ["x"] = 3, ["name"] = "default:silver_sandstone_brick", ["z"] = 96, ["param1"] = 15}, {["y"] = 2, ["x"] = 3, ["name"] = "default:silver_sandstone_brick", ["z"] = 97, ["param1"] = 15}, {["y"] = 2, ["x"] = 3, ["name"] = "default:silver_sandstone_brick", ["z"] = 98, ["param1"] = 15}, {["y"] = 2, ["x"] = 3, ["name"] = "default:silver_sandstone_brick", ["z"] = 99, ["param1"] = 15}, {["y"] = 2, ["x"] = 3, ["name"] = "default:silver_sandstone_brick", ["z"] = 100, ["param1"] = 15}, {["y"] = 2, ["x"] = 3, ["name"] = "default:silver_sandstone_brick", ["z"] = 101, ["param1"] = 15}, {["y"] = 2, ["x"] = 3, ["name"] = "default:silver_sandstone_brick", ["z"] = 102, ["param1"] = 15}, {["y"] = 2, ["x"] = 3, ["name"] = "default:silver_sandstone_brick", ["z"] = 103, ["param1"] = 14}, {["y"] = 2, ["x"] = 3, ["name"] = "default:silver_sandstone_brick", ["z"] = 104, ["param1"] = 13}, {["y"] = 2, ["x"] = 3, ["name"] = "default:silver_sandstone_brick", ["z"] = 105, ["param1"] = 15}, {["y"] = 2, ["x"] = 3, ["name"] = "default:silver_sandstone_brick", ["z"] = 106}, {["y"] = 2, ["x"] = 3, ["name"] = "default:silver_sandstone_brick", ["z"] = 113, ["param1"] = 15}, {["y"] = 3, ["x"] = 3, ["name"] = "default:silver_sandstone_brick", ["z"] = 3, ["param1"] = 15}, {["y"] = 3, ["x"] = 3, ["name"] = "default:silver_sandstone_brick", ["z"] = 10, ["param1"] = 15}, {["y"] = 3, ["x"] = 3, ["name"] = "default:silver_sandstone_brick", ["z"] = 11, ["param1"] = 15}, {["y"] = 3, ["x"] = 3, ["name"] = "default:silver_sandstone_brick", ["z"] = 12, ["param1"] = 15}, {["y"] = 3, ["x"] = 3, ["name"] = "default:silver_sandstone_brick", ["z"] = 13, ["param1"] = 15}, {["y"] = 3, ["x"] = 3, ["name"] = "default:silver_sandstone_brick", ["z"] = 14, ["param1"] = 15}, {["y"] = 3, ["x"] = 3, ["name"] = "default:silver_sandstone_brick", ["z"] = 15, ["param1"] = 15}, {["y"] = 3, ["x"] = 3, ["name"] = "default:silver_sandstone_brick", ["z"] = 16, ["param1"] = 15}, {["y"] = 3, ["x"] = 3, ["name"] = "default:silver_sandstone_brick", ["z"] = 17, ["param1"] = 15}, {["y"] = 3, ["x"] = 3, ["name"] = "default:silver_sandstone_brick", ["z"] = 18, ["param1"] = 15}, {["y"] = 3, ["x"] = 3, ["name"] = "default:silver_sandstone_brick", ["z"] = 19, ["param1"] = 15}, {["y"] = 3, ["x"] = 3, ["name"] = "default:silver_sandstone_brick", ["z"] = 20, ["param1"] = 15}, {["y"] = 3, ["x"] = 3, ["name"] = "default:silver_sandstone_brick", ["z"] = 21, ["param1"] = 15}, {["y"] = 3, ["x"] = 3, ["name"] = "default:silver_sandstone_brick", ["z"] = 22, ["param1"] = 15}, {["y"] = 3, ["x"] = 3, ["name"] = "default:silver_sandstone_brick", ["z"] = 23, ["param1"] = 14}, {["y"] = 3, ["x"] = 3, ["name"] = "default:silver_sandstone_brick", ["z"] = 24, ["param1"] = 15}, {["y"] = 3, ["x"] = 3, ["name"] = "default:silver_sandstone_brick", ["z"] = 25, ["param1"] = 15}, {["y"] = 3, ["x"] = 3, ["name"] = "default:silver_sandstone_brick", ["z"] = 26, ["param1"] = 15}, {["y"] = 3, ["x"] = 3, ["name"] = "default:silver_sandstone_brick", ["z"] = 27, ["param1"] = 15}, {["y"] = 3, ["x"] = 3, ["name"] = "default:silver_sandstone_brick", ["z"] = 28, ["param1"] = 15}, {["y"] = 3, ["x"] = 3, ["name"] = "default:silver_sandstone_brick", ["z"] = 29, ["param1"] = 15}, {["y"] = 3, ["x"] = 3, ["name"] = "default:silver_sandstone_brick", ["z"] = 30, ["param1"] = 15}, {["y"] = 3, ["x"] = 3, ["name"] = "default:silver_sandstone_brick", ["z"] = 31, ["param1"] = 15}, {["y"] = 3, ["x"] = 3, ["name"] = "default:silver_sandstone_brick", ["z"] = 32, ["param1"] = 15}, {["y"] = 3, ["x"] = 3, ["name"] = "default:silver_sandstone_brick", ["z"] = 33, ["param1"] = 15}, {["y"] = 3, ["x"] = 3, ["name"] = "default:silver_sandstone_brick", ["z"] = 34, ["param1"] = 15}, {["y"] = 3, ["x"] = 3, ["name"] = "default:silver_sandstone_brick", ["z"] = 35, ["param1"] = 15}, {["y"] = 3, ["x"] = 3, ["name"] = "default:silver_sandstone_brick", ["z"] = 36, ["param1"] = 15}, {["y"] = 3, ["x"] = 3, ["name"] = "default:silver_sandstone_brick", ["z"] = 37, ["param1"] = 15}, {["y"] = 3, ["x"] = 3, ["name"] = "default:silver_sandstone_brick", ["z"] = 38, ["param1"] = 15}, {["y"] = 3, ["x"] = 3, ["name"] = "default:silver_sandstone_brick", ["z"] = 39, ["param1"] = 14}, {["y"] = 3, ["x"] = 3, ["name"] = "default:silver_sandstone_brick", ["z"] = 40, ["param1"] = 14}, {["y"] = 3, ["x"] = 3, ["name"] = "default:silver_sandstone_brick", ["z"] = 41, ["param1"] = 15}, {["y"] = 3, ["x"] = 3, ["name"] = "default:silver_sandstone_brick", ["z"] = 42, ["param1"] = 15}, {["y"] = 3, ["x"] = 3, ["name"] = "default:silver_sandstone_brick", ["z"] = 43, ["param1"] = 15}, {["y"] = 3, ["x"] = 3, ["name"] = "default:silver_sandstone_brick", ["z"] = 44, ["param1"] = 15}, {["y"] = 3, ["x"] = 3, ["name"] = "default:silver_sandstone_brick", ["z"] = 45, ["param1"] = 15}, {["y"] = 3, ["x"] = 3, ["name"] = "default:silver_sandstone_brick", ["z"] = 46, ["param1"] = 15}, {["y"] = 3, ["x"] = 3, ["name"] = "default:silver_sandstone_brick", ["z"] = 47, ["param1"] = 15}, {["y"] = 3, ["x"] = 3, ["name"] = "default:silver_sandstone_brick", ["z"] = 48, ["param1"] = 15}, {["y"] = 3, ["x"] = 3, ["name"] = "default:silver_sandstone_brick", ["z"] = 49, ["param1"] = 15}, {["y"] = 3, ["x"] = 3, ["name"] = "default:silver_sandstone_brick", ["z"] = 50, ["param1"] = 15}, {["y"] = 3, ["x"] = 3, ["name"] = "default:silver_sandstone_brick", ["z"] = 51, ["param1"] = 15}, {["y"] = 3, ["x"] = 3, ["name"] = "default:silver_sandstone_brick", ["z"] = 52, ["param1"] = 15}, {["y"] = 3, ["x"] = 3, ["name"] = "default:silver_sandstone_brick", ["z"] = 53, ["param1"] = 15}, {["y"] = 3, ["x"] = 3, ["name"] = "default:silver_sandstone_brick", ["z"] = 54, ["param1"] = 15}, {["y"] = 3, ["x"] = 3, ["name"] = "default:silver_sandstone_brick", ["z"] = 55, ["param1"] = 14}, {["y"] = 3, ["x"] = 3, ["name"] = "default:silver_sandstone_brick", ["z"] = 56, ["param1"] = 14}, {["y"] = 3, ["x"] = 3, ["name"] = "default:silver_sandstone_brick", ["z"] = 57, ["param1"] = 15}, {["y"] = 3, ["x"] = 3, ["name"] = "default:silver_sandstone_brick", ["z"] = 58, ["param1"] = 15}, {["y"] = 3, ["x"] = 3, ["name"] = "default:silver_sandstone_brick", ["z"] = 59, ["param1"] = 15}, {["y"] = 3, ["x"] = 3, ["name"] = "default:silver_sandstone_brick", ["z"] = 60, ["param1"] = 15}, {["y"] = 3, ["x"] = 3, ["name"] = "default:silver_sandstone_brick", ["z"] = 61, ["param1"] = 15}, {["y"] = 3, ["x"] = 3, ["name"] = "default:silver_sandstone_brick", ["z"] = 62, ["param1"] = 15}, {["y"] = 3, ["x"] = 3, ["name"] = "default:silver_sandstone_brick", ["z"] = 63, ["param1"] = 15}, {["y"] = 3, ["x"] = 3, ["name"] = "default:silver_sandstone_brick", ["z"] = 64, ["param1"] = 15}, {["y"] = 3, ["x"] = 3, ["name"] = "default:silver_sandstone_brick", ["z"] = 65, ["param1"] = 15}, {["y"] = 3, ["x"] = 3, ["name"] = "default:silver_sandstone_brick", ["z"] = 66, ["param1"] = 15}, {["y"] = 3, ["x"] = 3, ["name"] = "default:silver_sandstone_brick", ["z"] = 67, ["param1"] = 15}, {["y"] = 3, ["x"] = 3, ["name"] = "default:silver_sandstone_brick", ["z"] = 68, ["param1"] = 15}, {["y"] = 3, ["x"] = 3, ["name"] = "default:silver_sandstone_brick", ["z"] = 69, ["param1"] = 15}, {["y"] = 3, ["x"] = 3, ["name"] = "default:silver_sandstone_brick", ["z"] = 70, ["param1"] = 15}, {["y"] = 3, ["x"] = 3, ["name"] = "default:silver_sandstone_brick", ["z"] = 71, ["param1"] = 14}, {["y"] = 3, ["x"] = 3, ["name"] = "default:silver_sandstone_brick", ["z"] = 72, ["param1"] = 14}, {["y"] = 3, ["x"] = 3, ["name"] = "default:silver_sandstone_brick", ["z"] = 73, ["param1"] = 15}, {["y"] = 3, ["x"] = 3, ["name"] = "default:silver_sandstone_brick", ["z"] = 74, ["param1"] = 15}, {["y"] = 3, ["x"] = 3, ["name"] = "default:silver_sandstone_brick", ["z"] = 75, ["param1"] = 15}, {["y"] = 3, ["x"] = 3, ["name"] = "default:silver_sandstone_brick", ["z"] = 76, ["param1"] = 15}, {["y"] = 3, ["x"] = 3, ["name"] = "default:silver_sandstone_brick", ["z"] = 77, ["param1"] = 15}, {["y"] = 3, ["x"] = 3, ["name"] = "default:silver_sandstone_brick", ["z"] = 78, ["param1"] = 15}, {["y"] = 3, ["x"] = 3, ["name"] = "default:silver_sandstone_brick", ["z"] = 79, ["param1"] = 15}, {["y"] = 3, ["x"] = 3, ["name"] = "default:silver_sandstone_brick", ["z"] = 80, ["param1"] = 15}, {["y"] = 3, ["x"] = 3, ["name"] = "default:silver_sandstone_brick", ["z"] = 81, ["param1"] = 15}, {["y"] = 3, ["x"] = 3, ["name"] = "default:silver_sandstone_brick", ["z"] = 82, ["param1"] = 15}, {["y"] = 3, ["x"] = 3, ["name"] = "default:silver_sandstone_brick", ["z"] = 83, ["param1"] = 15}, {["y"] = 3, ["x"] = 3, ["name"] = "default:silver_sandstone_brick", ["z"] = 84, ["param1"] = 15}, {["y"] = 3, ["x"] = 3, ["name"] = "default:silver_sandstone_brick", ["z"] = 85, ["param1"] = 15}, {["y"] = 3, ["x"] = 3, ["name"] = "default:silver_sandstone_brick", ["z"] = 86, ["param1"] = 15}, {["y"] = 3, ["x"] = 3, ["name"] = "default:silver_sandstone_brick", ["z"] = 87, ["param1"] = 14}, {["y"] = 3, ["x"] = 3, ["name"] = "default:silver_sandstone_brick", ["z"] = 88, ["param1"] = 14}, {["y"] = 3, ["x"] = 3, ["name"] = "default:silver_sandstone_brick", ["z"] = 89, ["param1"] = 15}, {["y"] = 3, ["x"] = 3, ["name"] = "default:silver_sandstone_brick", ["z"] = 90, ["param1"] = 15}, {["y"] = 3, ["x"] = 3, ["name"] = "default:silver_sandstone_brick", ["z"] = 91, ["param1"] = 15}, {["y"] = 3, ["x"] = 3, ["name"] = "default:silver_sandstone_brick", ["z"] = 92, ["param1"] = 15}, {["y"] = 3, ["x"] = 3, ["name"] = "default:silver_sandstone_brick", ["z"] = 93, ["param1"] = 15}, {["y"] = 3, ["x"] = 3, ["name"] = "default:silver_sandstone_brick", ["z"] = 94, ["param1"] = 15}, {["y"] = 3, ["x"] = 3, ["name"] = "default:silver_sandstone_brick", ["z"] = 95, ["param1"] = 15}, {["y"] = 3, ["x"] = 3, ["name"] = "default:silver_sandstone_brick", ["z"] = 96, ["param1"] = 15}, {["y"] = 3, ["x"] = 3, ["name"] = "default:silver_sandstone_brick", ["z"] = 97, ["param1"] = 15}, {["y"] = 3, ["x"] = 3, ["name"] = "default:silver_sandstone_brick", ["z"] = 98, ["param1"] = 15}, {["y"] = 3, ["x"] = 3, ["name"] = "default:silver_sandstone_brick", ["z"] = 99, ["param1"] = 15}, {["y"] = 3, ["x"] = 3, ["name"] = "default:silver_sandstone_brick", ["z"] = 100, ["param1"] = 15}, {["y"] = 3, ["x"] = 3, ["name"] = "default:silver_sandstone_brick", ["z"] = 101, ["param1"] = 15}, {["y"] = 3, ["x"] = 3, ["name"] = "default:silver_sandstone_brick", ["z"] = 102, ["param1"] = 15}, {["y"] = 3, ["x"] = 3, ["name"] = "default:silver_sandstone_brick", ["z"] = 103, ["param1"] = 14}, {["y"] = 3, ["x"] = 3, ["name"] = "default:silver_sandstone_brick", ["z"] = 104, ["param1"] = 13}, {["y"] = 3, ["x"] = 3, ["name"] = "default:silver_sandstone_brick", ["z"] = 105, ["param1"] = 15}, {["y"] = 3, ["x"] = 3, ["name"] = "default:silver_sandstone_brick", ["z"] = 106}, {["y"] = 3, ["x"] = 3, ["name"] = "default:silver_sandstone_brick", ["z"] = 113, ["param1"] = 15}, {["y"] = 4, ["x"] = 3, ["name"] = "default:silver_sandstone_brick", ["z"] = 3, ["param1"] = 15}, {["y"] = 4, ["x"] = 3, ["name"] = "default:silver_sandstone_brick", ["z"] = 10, ["param1"] = 15}, {["y"] = 4, ["x"] = 3, ["name"] = "default:silver_sandstone_brick", ["z"] = 11, ["param1"] = 15}, {["y"] = 4, ["x"] = 3, ["name"] = "default:silver_sandstone_brick", ["z"] = 12, ["param1"] = 15}, {["y"] = 4, ["x"] = 3, ["name"] = "default:silver_sandstone_brick", ["z"] = 13, ["param1"] = 15}, {["y"] = 4, ["x"] = 3, ["name"] = "default:silver_sandstone_brick", ["z"] = 14, ["param1"] = 15}, {["y"] = 4, ["x"] = 3, ["name"] = "default:silver_sandstone_brick", ["z"] = 15, ["param1"] = 15}, {["y"] = 4, ["x"] = 3, ["name"] = "default:silver_sandstone_brick", ["z"] = 16, ["param1"] = 15}, {["y"] = 4, ["x"] = 3, ["name"] = "default:silver_sandstone_brick", ["z"] = 17, ["param1"] = 15}, {["y"] = 4, ["x"] = 3, ["name"] = "default:silver_sandstone_brick", ["z"] = 18, ["param1"] = 15}, {["y"] = 4, ["x"] = 3, ["name"] = "default:silver_sandstone_brick", ["z"] = 19, ["param1"] = 15}, {["y"] = 4, ["x"] = 3, ["name"] = "default:silver_sandstone_brick", ["z"] = 20, ["param1"] = 15}, {["y"] = 4, ["x"] = 3, ["name"] = "default:silver_sandstone_brick", ["z"] = 21, ["param1"] = 15}, {["y"] = 4, ["x"] = 3, ["name"] = "default:silver_sandstone_brick", ["z"] = 22, ["param1"] = 15}, {["y"] = 4, ["x"] = 3, ["name"] = "default:silver_sandstone_brick", ["z"] = 23, ["param1"] = 14}, {["y"] = 4, ["x"] = 3, ["name"] = "default:silver_sandstone_brick", ["z"] = 24, ["param1"] = 15}, {["y"] = 4, ["x"] = 3, ["name"] = "default:silver_sandstone_brick", ["z"] = 25, ["param1"] = 15}, {["y"] = 4, ["x"] = 3, ["name"] = "default:silver_sandstone_brick", ["z"] = 26, ["param1"] = 15}, {["y"] = 4, ["x"] = 3, ["name"] = "default:silver_sandstone_brick", ["z"] = 27, ["param1"] = 15}, {["y"] = 4, ["x"] = 3, ["name"] = "default:silver_sandstone_brick", ["z"] = 28, ["param1"] = 15}, {["y"] = 4, ["x"] = 3, ["name"] = "default:silver_sandstone_brick", ["z"] = 29, ["param1"] = 15}, {["y"] = 4, ["x"] = 3, ["name"] = "default:silver_sandstone_brick", ["z"] = 30, ["param1"] = 15}, {["y"] = 4, ["x"] = 3, ["name"] = "default:silver_sandstone_brick", ["z"] = 31, ["param1"] = 15}, {["y"] = 4, ["x"] = 3, ["name"] = "default:silver_sandstone_brick", ["z"] = 32, ["param1"] = 15}, {["y"] = 4, ["x"] = 3, ["name"] = "default:silver_sandstone_brick", ["z"] = 33, ["param1"] = 15}, {["y"] = 4, ["x"] = 3, ["name"] = "default:silver_sandstone_brick", ["z"] = 34, ["param1"] = 15}, {["y"] = 4, ["x"] = 3, ["name"] = "default:silver_sandstone_brick", ["z"] = 35, ["param1"] = 15}, {["y"] = 4, ["x"] = 3, ["name"] = "default:silver_sandstone_brick", ["z"] = 36, ["param1"] = 15}, {["y"] = 4, ["x"] = 3, ["name"] = "default:silver_sandstone_brick", ["z"] = 37, ["param1"] = 15}, {["y"] = 4, ["x"] = 3, ["name"] = "default:silver_sandstone_brick", ["z"] = 38, ["param1"] = 15}, {["y"] = 4, ["x"] = 3, ["name"] = "default:silver_sandstone_brick", ["z"] = 39, ["param1"] = 14}, {["y"] = 4, ["x"] = 3, ["name"] = "default:silver_sandstone_brick", ["z"] = 40, ["param1"] = 14}, {["y"] = 4, ["x"] = 3, ["name"] = "default:silver_sandstone_brick", ["z"] = 41, ["param1"] = 15}, {["y"] = 4, ["x"] = 3, ["name"] = "default:silver_sandstone_brick", ["z"] = 42, ["param1"] = 15}, {["y"] = 4, ["x"] = 3, ["name"] = "default:silver_sandstone_brick", ["z"] = 43, ["param1"] = 15}, {["y"] = 4, ["x"] = 3, ["name"] = "default:silver_sandstone_brick", ["z"] = 44, ["param1"] = 15}, {["y"] = 4, ["x"] = 3, ["name"] = "default:silver_sandstone_brick", ["z"] = 45, ["param1"] = 15}, {["y"] = 4, ["x"] = 3, ["name"] = "default:silver_sandstone_brick", ["z"] = 46, ["param1"] = 15}, {["y"] = 4, ["x"] = 3, ["name"] = "default:silver_sandstone_brick", ["z"] = 47, ["param1"] = 15}, {["y"] = 4, ["x"] = 3, ["name"] = "default:silver_sandstone_brick", ["z"] = 48, ["param1"] = 15}, {["y"] = 4, ["x"] = 3, ["name"] = "default:silver_sandstone_brick", ["z"] = 49, ["param1"] = 15}, {["y"] = 4, ["x"] = 3, ["name"] = "default:silver_sandstone_brick", ["z"] = 50, ["param1"] = 15}, {["y"] = 4, ["x"] = 3, ["name"] = "default:silver_sandstone_brick", ["z"] = 51, ["param1"] = 15}, {["y"] = 4, ["x"] = 3, ["name"] = "default:silver_sandstone_brick", ["z"] = 52, ["param1"] = 15}, {["y"] = 4, ["x"] = 3, ["name"] = "default:silver_sandstone_brick", ["z"] = 53, ["param1"] = 15}, {["y"] = 4, ["x"] = 3, ["name"] = "default:silver_sandstone_brick", ["z"] = 54, ["param1"] = 15}, {["y"] = 4, ["x"] = 3, ["name"] = "default:silver_sandstone_brick", ["z"] = 55, ["param1"] = 14}, {["y"] = 4, ["x"] = 3, ["name"] = "default:silver_sandstone_brick", ["z"] = 56, ["param1"] = 14}, {["y"] = 4, ["x"] = 3, ["name"] = "default:silver_sandstone_brick", ["z"] = 57, ["param1"] = 15}, {["y"] = 4, ["x"] = 3, ["name"] = "default:silver_sandstone_brick", ["z"] = 58, ["param1"] = 15}, {["y"] = 4, ["x"] = 3, ["name"] = "default:silver_sandstone_brick", ["z"] = 59, ["param1"] = 15}, {["y"] = 4, ["x"] = 3, ["name"] = "default:silver_sandstone_brick", ["z"] = 60, ["param1"] = 15}, {["y"] = 4, ["x"] = 3, ["name"] = "default:silver_sandstone_brick", ["z"] = 61, ["param1"] = 15}, {["y"] = 4, ["x"] = 3, ["name"] = "default:silver_sandstone_brick", ["z"] = 62, ["param1"] = 15}, {["y"] = 4, ["x"] = 3, ["name"] = "default:silver_sandstone_brick", ["z"] = 63, ["param1"] = 15}, {["y"] = 4, ["x"] = 3, ["name"] = "default:silver_sandstone_brick", ["z"] = 64, ["param1"] = 15}, {["y"] = 4, ["x"] = 3, ["name"] = "default:silver_sandstone_brick", ["z"] = 65, ["param1"] = 15}, {["y"] = 4, ["x"] = 3, ["name"] = "default:silver_sandstone_brick", ["z"] = 66, ["param1"] = 15}, {["y"] = 4, ["x"] = 3, ["name"] = "default:silver_sandstone_brick", ["z"] = 67, ["param1"] = 15}, {["y"] = 4, ["x"] = 3, ["name"] = "default:silver_sandstone_brick", ["z"] = 68, ["param1"] = 15}, {["y"] = 4, ["x"] = 3, ["name"] = "default:silver_sandstone_brick", ["z"] = 69, ["param1"] = 15}, {["y"] = 4, ["x"] = 3, ["name"] = "default:silver_sandstone_brick", ["z"] = 70, ["param1"] = 15}, {["y"] = 4, ["x"] = 3, ["name"] = "default:silver_sandstone_brick", ["z"] = 71, ["param1"] = 14}, {["y"] = 4, ["x"] = 3, ["name"] = "default:silver_sandstone_brick", ["z"] = 72, ["param1"] = 14}, {["y"] = 4, ["x"] = 3, ["name"] = "default:silver_sandstone_brick", ["z"] = 73, ["param1"] = 15}, {["y"] = 4, ["x"] = 3, ["name"] = "default:silver_sandstone_brick", ["z"] = 74, ["param1"] = 15}, {["y"] = 4, ["x"] = 3, ["name"] = "default:silver_sandstone_brick", ["z"] = 75, ["param1"] = 15}, {["y"] = 4, ["x"] = 3, ["name"] = "default:silver_sandstone_brick", ["z"] = 76, ["param1"] = 15}, {["y"] = 4, ["x"] = 3, ["name"] = "default:silver_sandstone_brick", ["z"] = 77, ["param1"] = 15}, {["y"] = 4, ["x"] = 3, ["name"] = "default:silver_sandstone_brick", ["z"] = 78, ["param1"] = 15}, {["y"] = 4, ["x"] = 3, ["name"] = "default:silver_sandstone_brick", ["z"] = 79, ["param1"] = 15}, {["y"] = 4, ["x"] = 3, ["name"] = "default:silver_sandstone_brick", ["z"] = 80, ["param1"] = 15}, {["y"] = 4, ["x"] = 3, ["name"] = "default:silver_sandstone_brick", ["z"] = 81, ["param1"] = 15}, {["y"] = 4, ["x"] = 3, ["name"] = "default:silver_sandstone_brick", ["z"] = 82, ["param1"] = 15}, {["y"] = 4, ["x"] = 3, ["name"] = "default:silver_sandstone_brick", ["z"] = 83, ["param1"] = 15}, {["y"] = 4, ["x"] = 3, ["name"] = "default:silver_sandstone_brick", ["z"] = 84, ["param1"] = 15}, {["y"] = 4, ["x"] = 3, ["name"] = "default:silver_sandstone_brick", ["z"] = 85, ["param1"] = 15}, {["y"] = 4, ["x"] = 3, ["name"] = "default:silver_sandstone_brick", ["z"] = 86, ["param1"] = 15}, {["y"] = 4, ["x"] = 3, ["name"] = "default:silver_sandstone_brick", ["z"] = 87, ["param1"] = 14}, {["y"] = 4, ["x"] = 3, ["name"] = "default:silver_sandstone_brick", ["z"] = 88, ["param1"] = 14}, {["y"] = 4, ["x"] = 3, ["name"] = "default:silver_sandstone_brick", ["z"] = 89, ["param1"] = 15}, {["y"] = 4, ["x"] = 3, ["name"] = "default:silver_sandstone_brick", ["z"] = 90, ["param1"] = 15}, {["y"] = 4, ["x"] = 3, ["name"] = "default:silver_sandstone_brick", ["z"] = 91, ["param1"] = 15}, {["y"] = 4, ["x"] = 3, ["name"] = "default:silver_sandstone_brick", ["z"] = 92, ["param1"] = 15}, {["y"] = 4, ["x"] = 3, ["name"] = "default:silver_sandstone_brick", ["z"] = 93, ["param1"] = 15}, {["y"] = 4, ["x"] = 3, ["name"] = "default:silver_sandstone_brick", ["z"] = 94, ["param1"] = 15}, {["y"] = 4, ["x"] = 3, ["name"] = "default:silver_sandstone_brick", ["z"] = 95, ["param1"] = 15}, {["y"] = 4, ["x"] = 3, ["name"] = "default:silver_sandstone_brick", ["z"] = 96, ["param1"] = 15}, {["y"] = 4, ["x"] = 3, ["name"] = "default:silver_sandstone_brick", ["z"] = 97, ["param1"] = 15}, {["y"] = 4, ["x"] = 3, ["name"] = "default:silver_sandstone_brick", ["z"] = 98, ["param1"] = 15}, {["y"] = 4, ["x"] = 3, ["name"] = "default:silver_sandstone_brick", ["z"] = 99, ["param1"] = 15}, {["y"] = 4, ["x"] = 3, ["name"] = "default:silver_sandstone_brick", ["z"] = 100, ["param1"] = 15}, {["y"] = 4, ["x"] = 3, ["name"] = "default:silver_sandstone_brick", ["z"] = 101, ["param1"] = 15}, {["y"] = 4, ["x"] = 3, ["name"] = "default:silver_sandstone_brick", ["z"] = 102, ["param1"] = 15}, {["y"] = 4, ["x"] = 3, ["name"] = "default:silver_sandstone_brick", ["z"] = 103, ["param1"] = 14}, {["y"] = 4, ["x"] = 3, ["name"] = "default:silver_sandstone_brick", ["z"] = 104, ["param1"] = 13}, {["y"] = 4, ["x"] = 3, ["name"] = "default:silver_sandstone_brick", ["z"] = 105, ["param1"] = 15}, {["y"] = 4, ["x"] = 3, ["name"] = "default:silver_sandstone_brick", ["z"] = 106}, {["y"] = 4, ["x"] = 3, ["name"] = "default:silver_sandstone_brick", ["z"] = 113, ["param1"] = 15}, {["y"] = 5, ["x"] = 3, ["name"] = "default:silver_sandstone_brick", ["z"] = 3, ["param1"] = 15}, {["y"] = 5, ["x"] = 3, ["name"] = "default:acacia_wood", ["z"] = 4}, {["y"] = 5, ["x"] = 3, ["name"] = "default:acacia_wood", ["z"] = 5}, {["y"] = 5, ["x"] = 3, ["name"] = "default:acacia_wood", ["z"] = 6}, {["y"] = 5, ["x"] = 3, ["name"] = "default:acacia_wood", ["z"] = 7}, {["y"] = 5, ["x"] = 3, ["name"] = "default:acacia_wood", ["z"] = 8}, {["y"] = 5, ["x"] = 3, ["name"] = "default:acacia_wood", ["z"] = 9}, {["y"] = 5, ["x"] = 3, ["name"] = "default:silver_sandstone_brick", ["z"] = 10, ["param1"] = 15}, {["y"] = 5, ["x"] = 3, ["name"] = "default:silver_sandstone_brick", ["z"] = 11, ["param1"] = 15}, {["y"] = 5, ["x"] = 3, ["name"] = "default:silver_sandstone_brick", ["z"] = 12, ["param1"] = 15}, {["y"] = 5, ["x"] = 3, ["name"] = "default:silver_sandstone_brick", ["z"] = 13, ["param1"] = 15}, {["y"] = 5, ["x"] = 3, ["name"] = "default:silver_sandstone_brick", ["z"] = 14, ["param1"] = 15}, {["y"] = 5, ["x"] = 3, ["name"] = "default:silver_sandstone_brick", ["z"] = 15, ["param1"] = 15}, {["y"] = 5, ["x"] = 3, ["name"] = "default:silver_sandstone_brick", ["z"] = 16, ["param1"] = 15}, {["y"] = 5, ["x"] = 3, ["name"] = "default:silver_sandstone_brick", ["z"] = 17, ["param1"] = 15}, {["y"] = 5, ["x"] = 3, ["name"] = "default:silver_sandstone_brick", ["z"] = 18, ["param1"] = 15}, {["y"] = 5, ["x"] = 3, ["name"] = "default:silver_sandstone_brick", ["z"] = 19, ["param1"] = 15}, {["y"] = 5, ["x"] = 3, ["name"] = "default:silver_sandstone_brick", ["z"] = 20, ["param1"] = 15}, {["y"] = 5, ["x"] = 3, ["name"] = "default:silver_sandstone_brick", ["z"] = 21, ["param1"] = 15}, {["y"] = 5, ["x"] = 3, ["name"] = "default:silver_sandstone_brick", ["z"] = 22, ["param1"] = 15}, {["y"] = 5, ["x"] = 3, ["name"] = "default:silver_sandstone_brick", ["z"] = 23, ["param1"] = 14}, {["y"] = 5, ["x"] = 3, ["name"] = "default:silver_sandstone_brick", ["z"] = 24, ["param1"] = 15}, {["y"] = 5, ["x"] = 3, ["name"] = "default:silver_sandstone_brick", ["z"] = 25, ["param1"] = 15}, {["y"] = 5, ["x"] = 3, ["name"] = "default:silver_sandstone_brick", ["z"] = 26, ["param1"] = 15}, {["y"] = 5, ["x"] = 3, ["name"] = "default:silver_sandstone_brick", ["z"] = 27, ["param1"] = 15}, {["y"] = 5, ["x"] = 3, ["name"] = "default:silver_sandstone_brick", ["z"] = 28, ["param1"] = 15}, {["y"] = 5, ["x"] = 3, ["name"] = "default:silver_sandstone_brick", ["z"] = 29, ["param1"] = 15}, {["y"] = 5, ["x"] = 3, ["name"] = "default:silver_sandstone_brick", ["z"] = 30, ["param1"] = 15}, {["y"] = 5, ["x"] = 3, ["name"] = "default:silver_sandstone_brick", ["z"] = 31, ["param1"] = 15}, {["y"] = 5, ["x"] = 3, ["name"] = "default:silver_sandstone_brick", ["z"] = 32, ["param1"] = 15}, {["y"] = 5, ["x"] = 3, ["name"] = "default:silver_sandstone_brick", ["z"] = 33, ["param1"] = 15}, {["y"] = 5, ["x"] = 3, ["name"] = "default:silver_sandstone_brick", ["z"] = 34, ["param1"] = 15}, {["y"] = 5, ["x"] = 3, ["name"] = "default:silver_sandstone_brick", ["z"] = 35, ["param1"] = 15}, {["y"] = 5, ["x"] = 3, ["name"] = "default:silver_sandstone_brick", ["z"] = 36, ["param1"] = 15}, {["y"] = 5, ["x"] = 3, ["name"] = "default:silver_sandstone_brick", ["z"] = 37, ["param1"] = 15}, {["y"] = 5, ["x"] = 3, ["name"] = "default:silver_sandstone_brick", ["z"] = 38, ["param1"] = 15},