5:return {{["x"] = 5, ["y"] = 5, ["z"] = 28, ["name"] = "wool:black"}, {["x"] = 5, ["y"] = 5, ["z"] = 29, ["name"] = "wool:black"}, {["x"] = 5, ["y"] = 5, ["z"] = 30, ["name"] = "wool:black"}, {["x"] = 5, ["y"] = 5, ["z"] = 31, ["name"] = "wool:black"}, {["x"] = 5, ["y"] = 5, ["z"] = 32, ["name"] = "wool:black"}, {["x"] = 5, ["y"] = 5, ["z"] = 33, ["name"] = "wool:black"}, {["x"] = 5, ["y"] = 5, ["z"] = 34, ["name"] = "wool:black"}, {["x"] = 5, ["y"] = 5, ["z"] = 35, ["name"] = "wool:black"}, {["x"] = 5, ["y"] = 5, ["z"] = 36, ["name"] = "wool:black"}, {["x"] = 5, ["y"] = 5, ["z"] = 37, ["name"] = "wool:black"}, {["x"] = 5, ["y"] = 5, ["z"] = 38, ["name"] = "wool:black"}, {["x"] = 5, ["y"] = 5, ["z"] = 39, ["name"] = "wool:black"}, {["x"] = 5, ["y"] = 5, ["z"] = 40, ["name"] = "wool:black"}, {["x"] = 5, ["y"] = 5, ["z"] = 41, ["name"] = "wool:black"}, {["x"] = 5, ["y"] = 5, ["z"] = 42, ["name"] = "wool:black"}, {["x"] = 5, ["y"] = 5, ["z"] = 43, ["name"] = "wool:black"}, {["x"] = 5, ["y"] = 5, ["z"] = 44, ["name"] = "wool:black"}, {["x"] = 5, ["y"] = 5, ["z"] = 45, ["name"] = "wool:black"}, {["x"] = 5, ["y"] = 5, ["z"] = 46, ["name"] = "wool:black"}, {["x"] = 5, ["y"] = 5, ["z"] = 47, ["name"] = "wool:black"}, {["x"] = 5, ["y"] = 5, ["z"] = 48, ["name"] = "wool:black"}, {["x"] = 5, ["y"] = 5, ["z"] = 49, ["name"] = "wool:black"}, {["x"] = 5, ["y"] = 5, ["z"] = 50, ["name"] = "wool:black"}, {["x"] = 5, ["y"] = 5, ["z"] = 51, ["name"] = "wool:black"}, {["x"] = 5, ["y"] = 5, ["z"] = 52, ["name"] = "wool:black"}, {["x"] = 5, ["y"] = 5, ["z"] = 53, ["name"] = "wool:black"}, {["x"] = 5, ["y"] = 5, ["z"] = 54, ["name"] = "wool:black"}, {["x"] = 5, ["y"] = 5, ["z"] = 55, ["name"] = "wool:black"}, {["x"] = 5, ["y"] = 5, ["z"] = 56, ["name"] = "wool:black"}, {["x"] = 5, ["y"] = 6, ["z"] = 28, ["name"] = "wool:black"}, {["x"] = 5, ["y"] = 6, ["z"] = 29, ["name"] = "wool:black"}, {["x"] = 5, ["y"] = 6, ["z"] = 30, ["name"] = "wool:black"}, {["x"] = 5, ["y"] = 6, ["z"] = 31, ["name"] = "wool:black"}, {["x"] = 5, ["y"] = 6, ["z"] = 32, ["name"] = "wool:black"}, {["x"] = 5, ["y"] = 6, ["z"] = 33, ["name"] = "wool:black"}, {["x"] = 5, ["y"] = 6, ["z"] = 34, ["name"] = "wool:black"}, {["x"] = 5, ["y"] = 6, ["z"] = 35, ["name"] = "wool:black"}, {["x"] = 5, ["y"] = 6, ["z"] = 36, ["name"] = "wool:black"}, {["x"] = 5, ["y"] = 6, ["z"] = 37, ["name"] = "wool:black"}, {["x"] = 5, ["y"] = 6, ["z"] = 38, ["name"] = "wool:black"}, {["x"] = 5, ["y"] = 6, ["z"] = 39, ["name"] = "wool:black"}, {["x"] = 5, ["y"] = 6, ["z"] = 40, ["name"] = "wool:black"}, {["x"] = 5, ["y"] = 6, ["z"] = 41, ["name"] = "wool:black"}, {["x"] = 5, ["y"] = 6, ["z"] = 42, ["name"] = "wool:black"}, {["x"] = 5, ["y"] = 6, ["z"] = 43, ["name"] = "wool:black"}, {["x"] = 5, ["y"] = 6, ["z"] = 44, ["name"] = "wool:black"}, {["x"] = 5, ["y"] = 6, ["z"] = 45, ["name"] = "wool:black"}, {["x"] = 5, ["y"] = 6, ["z"] = 46, ["name"] = "wool:black"}, {["x"] = 5, ["y"] = 6, ["z"] = 47, ["name"] = "wool:black"}, {["x"] = 5, ["y"] = 6, ["z"] = 48, ["name"] = "wool:black"}, {["x"] = 5, ["y"] = 6, ["z"] = 49, ["name"] = "wool:black"}, {["x"] = 5, ["y"] = 6, ["z"] = 50, ["name"] = "wool:black"}, {["x"] = 5, ["y"] = 6, ["z"] = 51, ["name"] = "wool:black"}, {["x"] = 5, ["y"] = 6, ["z"] = 52, ["name"] = "wool:black"}, {["x"] = 5, ["y"] = 6, ["z"] = 53, ["name"] = "wool:black"}, {["x"] = 5, ["y"] = 6, ["z"] = 54, ["name"] = "wool:black"}, {["x"] = 5, ["y"] = 6, ["z"] = 55, ["name"] = "wool:black"}, {["x"] = 5, ["y"] = 6, ["z"] = 56, ["name"] = "wool:black"}, {["x"] = 5, ["y"] = 7, ["z"] = 28, ["name"] = "wool:black"}, {["x"] = 5, ["y"] = 7, ["z"] = 29, ["name"] = "wool:black"}, {["x"] = 5, ["y"] = 7, ["z"] = 30, ["name"] = "wool:black"}, {["x"] = 5, ["y"] = 7, ["z"] = 31, ["name"] = "wool:black"}, {["x"] = 5, ["y"] = 7, ["z"] = 32, ["name"] = "wool:black"}, {["x"] = 5, ["y"] = 7, ["z"] = 33, ["name"] = "wool:black"}, {["x"] = 5, ["y"] = 7, ["z"] = 34, ["name"] = "wool:black"}, {["x"] = 5, ["y"] = 7, ["z"] = 35, ["name"] = "wool:black"}, {["x"] = 5, ["y"] = 7, ["z"] = 36, ["name"] = "wool:black"}, {["x"] = 5, ["y"] = 7, ["z"] = 37, ["name"] = "wool:black"}, {["x"] = 5, ["y"] = 7, ["z"] = 38, ["name"] = "wool:black"}, {["x"] = 5, ["y"] = 7, ["z"] = 39, ["name"] = "wool:black"}, {["x"] = 5, ["y"] = 7, ["z"] = 40, ["name"] = "wool:black"}, {["x"] = 5, ["y"] = 7, ["z"] = 41, ["name"] = "wool:black"}, {["x"] = 5, ["y"] = 7, ["z"] = 42, ["name"] = "wool:black"}, {["x"] = 5, ["y"] = 7, ["z"] = 43, ["name"] = "wool:black"}, {["x"] = 5, ["y"] = 7, ["z"] = 44, ["name"] = "wool:black"}, {["x"] = 5, ["y"] = 7, ["z"] = 45, ["name"] = "wool:black"}, {["x"] = 5, ["y"] = 7, ["z"] = 46, ["name"] = "wool:black"}, {["x"] = 5, ["y"] = 7, ["z"] = 47, ["name"] = "wool:black"}, {["x"] = 5, ["y"] = 7, ["z"] = 48, ["name"] = "wool:black"}, {["x"] = 5, ["y"] = 7, ["z"] = 49, ["name"] = "wool:black"}, {["x"] = 5, ["y"] = 7, ["z"] = 50, ["name"] = "wool:black"}, {["x"] = 5, ["y"] = 7, ["z"] = 51, ["name"] = "wool:black"}, {["x"] = 5, ["y"] = 7, ["z"] = 52, ["name"] = "wool:black"}, {["x"] = 5, ["y"] = 7, ["z"] = 53, ["name"] = "wool:black"}, {["x"] = 5, ["y"] = 7, ["z"] = 54, ["name"] = "wool:black"}, {["x"] = 5, ["y"] = 7, ["z"] = 55, ["name"] = "wool:black"}, {["x"] = 5, ["y"] = 7, ["z"] = 56, ["name"] = "wool:black"}, {["x"] = 5, ["y"] = 8, ["z"] = 28, ["name"] = "wool:black"}, {["x"] = 5, ["y"] = 8, ["z"] = 29, ["name"] = "wool:black"}, {["x"] = 5, ["y"] = 8, ["z"] = 30, ["name"] = "wool:black"}, {["x"] = 5, ["y"] = 8, ["z"] = 31, ["name"] = "wool:black"}, {["x"] = 5, ["y"] = 8, ["z"] = 32, ["name"] = "wool:black"}, {["x"] = 5, ["y"] = 8, ["z"] = 33, ["name"] = "wool:black"}, {["x"] = 5, ["y"] = 8, ["z"] = 34, ["name"] = "wool:black"}, {["x"] = 5, ["y"] = 8, ["z"] = 35, ["name"] = "wool:black"}, {["x"] = 5, ["y"] = 8, ["z"] = 36, ["name"] = "wool:black"}, {["x"] = 5, ["y"] = 8, ["z"] = 37, ["name"] = "wool:black"}, {["x"] = 5, ["y"] = 8, ["z"] = 38, ["name"] = "wool:black"}, {["x"] = 5, ["y"] = 8, ["z"] = 39, ["name"] = "wool:black"}, {["x"] = 5, ["y"] = 8, ["z"] = 40, ["name"] = "wool:black"}, {["x"] = 5, ["y"] = 8, ["z"] = 41, ["name"] = "wool:black"}, {["x"] = 5, ["y"] = 8, ["z"] = 42, ["name"] = "wool:black"}, {["x"] = 5, ["y"] = 8, ["z"] = 43, ["name"] = "wool:black"}, {["x"] = 5, ["y"] = 8, ["z"] = 44, ["name"] = "wool:black"}, {["x"] = 5, ["y"] = 8, ["z"] = 45, ["name"] = "wool:black"}, {["x"] = 5, ["y"] = 8, ["z"] = 46, ["name"] = "wool:black"}, {["x"] = 5, ["y"] = 8, ["z"] = 47, ["name"] = "wool:black"}, {["x"] = 5, ["y"] = 8, ["z"] = 48, ["name"] = "wool:black"}, {["x"] = 5, ["y"] = 8, ["z"] = 49, ["name"] = "wool:black"}, {["x"] = 5, ["y"] = 8, ["z"] = 50, ["name"] = "wool:black"}, {["x"] = 5, ["y"] = 8, ["z"] = 51, ["name"] = "wool:black"}, {["x"] = 5, ["y"] = 8, ["z"] = 52, ["name"] = "wool:black"}, {["x"] = 5, ["y"] = 8, ["z"] = 53, ["name"] = "wool:black"}, {["x"] = 5, ["y"] = 8, ["z"] = 54, ["name"] = "wool:black"}, {["x"] = 5, ["y"] = 8, ["z"] = 55, ["name"] = "wool:black"}, {["x"] = 5, ["y"] = 8, ["z"] = 56, ["name"] = "wool:black"}, {["x"] = 5, ["y"] = 9, ["z"] = 28, ["name"] = "wool:black"}, {["x"] = 5, ["y"] = 9, ["z"] = 29, ["name"] = "wool:black"}, {["x"] = 5, ["y"] = 9, ["z"] = 30, ["name"] = "wool:black"}, {["x"] = 5, ["y"] = 9, ["z"] = 31, ["name"] = "wool:black"}, {["x"] = 5, ["y"] = 9, ["z"] = 32, ["name"] = "wool:black"}, {["x"] = 5, ["y"] = 9, ["z"] = 33, ["name"] = "wool:black"}, {["x"] = 5, ["y"] = 9, ["z"] = 34, ["name"] = "wool:black"}, {["x"] = 5, ["y"] = 9, ["z"] = 35, ["name"] = "wool:black"}, {["x"] = 5, ["y"] = 9, ["z"] = 36, ["name"] = "wool:black"}, {["x"] = 5, ["y"] = 9, ["z"] = 37, ["name"] = "wool:black"}, {["x"] = 5, ["y"] = 9, ["z"] = 38, ["name"] = "wool:black"}, {["x"] = 5, ["y"] = 9, ["z"] = 39, ["name"] = "wool:black"}, {["x"] = 5, ["y"] = 9, ["z"] = 40, ["name"] = "wool:black"}, {["x"] = 5, ["y"] = 9, ["z"] = 41, ["name"] = "wool:black"}, {["x"] = 5, ["y"] = 9, ["z"] = 42, ["name"] = "wool:black"}, {["x"] = 5, ["y"] = 9, ["z"] = 43, ["name"] = "wool:black"}, {["x"] = 5, ["y"] = 9, ["z"] = 44, ["name"] = "wool:black"}, {["x"] = 5, ["y"] = 9, ["z"] = 45, ["name"] = "wool:black"}, {["x"] = 5, ["y"] = 9, ["z"] = 46, ["name"] = "wool:black"}, {["x"] = 5, ["y"] = 9, ["z"] = 47, ["name"] = "wool:black"}, {["x"] = 5, ["y"] = 9, ["z"] = 48, ["name"] = "wool:black"}, {["x"] = 5, ["y"] = 9, ["z"] = 49, ["name"] = "wool:black"}, {["x"] = 5, ["y"] = 9, ["z"] = 50, ["name"] = "wool:black"}, {["x"] = 5, ["y"] = 9, ["z"] = 51, ["name"] = "wool:black"}, {["x"] = 5, ["y"] = 9, ["z"] = 52, ["name"] = "wool:black"}, {["x"] = 5, ["y"] = 9, ["z"] = 53, ["name"] = "wool:black"}, {["x"] = 5, ["y"] = 9, ["z"] = 54, ["name"] = "wool:black"}, {["x"] = 5, ["y"] = 9, ["z"] = 55, ["name"] = "wool:black"}, {["x"] = 5, ["y"] = 9, ["z"] = 56, ["name"] = "wool:black"}, {["x"] = 5, ["y"] = 10, ["z"] = 28, ["name"] = "wool:black"}, {["x"] = 5, ["y"] = 10, ["z"] = 29, ["name"] = "wool:black"}, {["x"] = 5, ["y"] = 10, ["z"] = 30, ["name"] = "wool:black"}, {["x"] = 5, ["y"] = 10, ["z"] = 31, ["name"] = "wool:black"}, {["x"] = 5, ["y"] = 10, ["z"] = 32, ["name"] = "wool:black"}, {["x"] = 5, ["y"] = 10, ["z"] = 33, ["name"] = "wool:black"}, {["x"] = 5, ["y"] = 10, ["z"] = 34, ["name"] = "wool:black"}, {["x"] = 5, ["y"] = 10, ["z"] = 35, ["name"] = "wool:black"}, {["x"] = 5, ["y"] = 10, ["z"] = 36, ["name"] = "wool:black"}, {["x"] = 5, ["y"] = 10, ["z"] = 37, ["name"] = "wool:black"}, {["x"] = 5, ["y"] = 10, ["z"] = 38, ["name"] = "wool:black"}, {["x"] = 5, ["y"] = 10, ["z"] = 39, ["name"] = "wool:black"}, {["x"] = 5, ["y"] = 10, ["z"] = 40, ["name"] = "wool:black"}, {["x"] = 5, ["y"] = 10, ["z"] = 41, ["name"] = "wool:black"}, {["x"] = 5, ["y"] = 10, ["z"] = 42, ["name"] = "wool:black"}, {["x"] = 5, ["y"] = 10, ["z"] = 43, ["name"] = "wool:black"}, {["x"] = 5, ["y"] = 10, ["z"] = 44, ["name"] = "wool:black"}, {["x"] = 5, ["y"] = 10, ["z"] = 45, ["name"] = "wool:black"}, {["x"] = 5, ["y"] = 10, ["z"] = 46, ["name"] = "wool:black"}, {["x"] = 5, ["y"] = 10, ["z"] = 47, ["name"] = "wool:black"}, {["x"] = 5, ["y"] = 10, ["z"] = 48, ["name"] = "wool:black"}, {["x"] = 5, ["y"] = 10, ["z"] = 49, ["name"] = "wool:black"}, {["x"] = 5, ["y"] = 10, ["z"] = 50, ["name"] = "wool:black"}, {["x"] = 5, ["y"] = 10, ["z"] = 51, ["name"] = "wool:black"}, {["x"] = 5, ["y"] = 10, ["z"] = 52, ["name"] = "wool:black"}, {["x"] = 5, ["y"] = 10, ["z"] = 53, ["name"] = "wool:black"}, {["x"] = 5, ["y"] = 10, ["z"] = 54, ["name"] = "wool:black"}, {["x"] = 5, ["y"] = 10, ["z"] = 55, ["name"] = "wool:black"}, {["x"] = 5, ["y"] = 10, ["z"] = 56, ["name"] = "wool:black"}, {["x"] = 5, ["y"] = 11, ["z"] = 28, ["name"] = "wool:black"}, {["x"] = 5, ["y"] = 11, ["z"] = 29, ["name"] = "wool:black"}, {["x"] = 5, ["y"] = 11, ["z"] = 30, ["name"] = "wool:black"}, {["x"] = 5, ["y"] = 11, ["z"] = 31, ["name"] = "wool:black"}, {["x"] = 5, ["y"] = 11, ["z"] = 32, ["name"] = "wool:black"}, {["x"] = 5, ["y"] = 11, ["z"] = 33, ["name"] = "wool:black"}, {["x"] = 5, ["y"] = 11, ["z"] = 34, ["name"] = "wool:black"}, {["x"] = 5, ["y"] = 11, ["z"] = 35, ["name"] = "wool:black"}, {["x"] = 5, ["y"] = 11, ["z"] = 36, ["name"] = "wool:black"}, {["x"] = 5, ["y"] = 11, ["z"] = 37, ["name"] = "wool:black"}, {["x"] = 5, ["y"] = 11, ["z"] = 38, ["name"] = "wool:black"}, {["x"] = 5, ["y"] = 11, ["z"] = 39, ["name"] = "wool:black"}, {["x"] = 5, ["y"] = 11, ["z"] = 40, ["name"] = "wool:black"}, {["x"] = 5, ["y"] = 11, ["z"] = 41, ["name"] = "wool:black"}, {["x"] = 5, ["y"] = 11, ["z"] = 42, ["name"] = "wool:black"}, {["x"] = 5, ["y"] = 11, ["z"] = 43, ["name"] = "wool:black"}, {["x"] = 5, ["y"] = 11, ["z"] = 44, ["name"] = "wool:black"}, {["x"] = 5, ["y"] = 11, ["z"] = 45, ["name"] = "wool:black"}, {["x"] = 5, ["y"] = 11, ["z"] = 46, ["name"] = "wool:black"}, {["x"] = 5, ["y"] = 11, ["z"] = 47, ["name"] = "wool:black"}, {["x"] = 5, ["y"] = 11, ["z"] = 48, ["name"] = "wool:black"}, {["x"] = 5, ["y"] = 11, ["z"] = 49, ["name"] = "wool:black"}, {["x"] = 5, ["y"] = 11, ["z"] = 50, ["name"] = "wool:black"}, {["x"] = 5, ["y"] = 11, ["z"] = 51, ["name"] = "wool:black"}, {["x"] = 5, ["y"] = 11, ["z"] = 52, ["name"] = "wool:black"}, {["x"] = 5, ["y"] = 11, ["z"] = 53, ["name"] = "wool:black"}, {["x"] = 5, ["y"] = 11, ["z"] = 54, ["name"] = "wool:black"}, {["x"] = 5, ["y"] = 11, ["z"] = 55, ["name"] = "wool:black"}, {["x"] = 5, ["y"] = 11, ["z"] = 56, ["name"] = "wool:black"}, {["x"] = 6, ["y"] = 5, ["z"] = 28, ["name"] = "wool:black"}, {["x"] = 6, ["y"] = 5, ["z"] = 29, ["name"] = "wool:black"}, {["x"] = 6, ["y"] = 5, ["z"] = 30, ["name"] = "wool:black"}, {["x"] = 6, ["y"] = 5, ["z"] = 31, ["name"] = "wool:black"}, {["x"] = 6, ["y"] = 5, ["z"] = 32, ["name"] = "wool:black"}, {["x"] = 6, ["y"] = 5, ["z"] = 33, ["name"] = "wool:black"}, {["x"] = 6, ["y"] = 5, ["z"] = 34, ["name"] = "wool:black"}, {["x"] = 6, ["y"] = 5, ["z"] = 35, ["name"] = "wool:black"}, {["x"] = 6, ["y"] = 5, ["z"] = 36, ["name"] = "wool:black"}, {["x"] = 6, ["y"] = 5, ["z"] = 37, ["name"] = "wool:black"}, {["x"] = 6, ["y"] = 5, ["z"] = 38, ["name"] = "wool:black"}, {["x"] = 6, ["y"] = 5, ["z"] = 39, ["name"] = "wool:black"}, {["x"] = 6, ["y"] = 5, ["z"] = 40, ["name"] = "wool:black"}, {["x"] = 6, ["y"] = 5, ["z"] = 41, ["name"] = "wool:black"}, {["x"] = 6, ["y"] = 5, ["z"] = 42, ["name"] = "wool:black"}, {["x"] = 6, ["y"] = 5, ["z"] = 43, ["name"] = "wool:black"}, {["x"] = 6, ["y"] = 5, ["z"] = 44, ["name"] = "wool:black"}, {["x"] = 6, ["y"] = 5, ["z"] = 45, ["name"] = "wool:black"}, {["x"] = 6, ["y"] = 5, ["z"] = 46, ["name"] = "wool:black"}, {["x"] = 6, ["y"] = 5, ["z"] = 47, ["name"] = "wool:black"}, {["x"] = 6, ["y"] = 5, ["z"] = 48, ["name"] = "wool:black"}, {["x"] = 6, ["y"] = 5, ["z"] = 49, ["name"] = "wool:black"}, {["x"] = 6, ["y"] = 5, ["z"] = 50, ["name"] = "wool:black"}, {["x"] = 6, ["y"] = 5, ["z"] = 51, ["name"] = "wool:black"}, {["x"] = 6, ["y"] = 5, ["z"] = 52, ["name"] = "wool:black"}, {["x"] = 6, ["y"] = 5, ["z"] = 53, ["name"] = "wool:black"}, {["x"] = 6, ["y"] = 5, ["z"] = 54, ["name"] = "wool:black"}, {["x"] = 6, ["y"] = 5, ["z"] = 55, ["name"] = "wool:black"}, {["x"] = 6, ["y"] = 5, ["z"] = 56, ["name"] = "wool:black"}, {["x"] = 6, ["y"] = 6, ["z"] = 28, ["name"] = "wool:black"}, {["x"] = 6, ["y"] = 6, ["z"] = 56, ["name"] = "wool:black"}, {["x"] = 6, ["y"] = 7, ["z"] = 28, ["name"] = "wool:black"}, {["x"] = 6, ["y"] = 7, ["z"] = 56, ["name"] = "wool:black"}, {["x"] = 6, ["y"] = 8, ["z"] = 28, ["name"] = "wool:black"}, {["x"] = 6, ["y"] = 8, ["z"] = 56, ["name"] = "wool:black"}, {["x"] = 6, ["y"] = 9, ["z"] = 28, ["name"] = "wool:black"}, {["x"] = 6, ["y"] = 9, ["z"] = 56, ["name"] = "wool:black"}, {["x"] = 6, ["y"] = 10, ["z"] = 28, ["name"] = "wool:black"}, {["x"] = 6, ["y"] = 10, ["z"] = 56, ["name"] = "wool:black"}, {["x"] = 6, ["y"] = 11, ["z"] = 28, ["name"] = "wool:black"}, {["x"] = 6, ["y"] = 11, ["z"] = 29, ["name"] = "wool:black"}, {["x"] = 6, ["y"] = 11, ["z"] = 30, ["name"] = "wool:black"}, {["x"] = 6, ["y"] = 11, ["z"] = 31, ["name"] = "wool:black"}, {["x"] = 6, ["y"] = 11, ["z"] = 32, ["name"] = "wool:black"}, {["x"] = 6, ["y"] = 11, ["z"] = 33, ["name"] = "wool:black"}, {["x"] = 6, ["y"] = 11, ["z"] = 34, ["name"] = "wool:black"}, {["x"] = 6, ["y"] = 11, ["z"] = 35, ["name"] = "wool:black"}, {["x"] = 6, ["y"] = 11, ["z"] = 36, ["name"] = "wool:black"}, {["x"] = 6, ["y"] = 11, ["z"] = 37, ["name"] = "wool:black"}, {["x"] = 6, ["y"] = 11, ["z"] = 38, ["name"] = "wool:black"}, {["x"] = 6, ["y"] = 11, ["z"] = 39, ["name"] = "wool:black"}, {["x"] = 6, ["y"] = 11, ["z"] = 40, ["name"] = "wool:black"}, {["x"] = 6, ["y"] = 11, ["z"] = 41, ["name"] = "wool:black"}, {["x"] = 6, ["y"] = 11, ["z"] = 42, ["name"] = "wool:black"}, {["x"] = 6, ["y"] = 11, ["z"] = 43, ["name"] = "wool:black"}, {["x"] = 6, ["y"] = 11, ["z"] = 44, ["name"] = "wool:black"}, {["x"] = 6, ["y"] = 11, ["z"] = 45, ["name"] = "wool:black"}, {["x"] = 6, ["y"] = 11, ["z"] = 46, ["name"] = "wool:black"}, {["x"] = 6, ["y"] = 11, ["z"] = 47, ["name"] = "wool:black"}, {["x"] = 6, ["y"] = 11, ["z"] = 48, ["name"] = "wool:black"}, {["x"] = 6, ["y"] = 11, ["z"] = 49, ["name"] = "wool:black"}, {["x"] = 6, ["y"] = 11, ["z"] = 50, ["name"] = "wool:black"}, {["x"] = 6, ["y"] = 11, ["z"] = 51, ["name"] = "wool:black"}, {["x"] = 6, ["y"] = 11, ["z"] = 52, ["name"] = "wool:black"}, {["x"] = 6, ["y"] = 11, ["z"] = 53, ["name"] = "wool:black"}, {["x"] = 6, ["y"] = 11, ["z"] = 54, ["name"] = "wool:black"}, {["x"] = 6, ["y"] = 11, ["z"] = 55, ["name"] = "wool:black"}, {["x"] = 6, ["y"] = 11, ["z"] = 56, ["name"] = "wool:black"}, {["x"] = 7, ["y"] = 5, ["z"] = 28, ["name"] = "wool:black"}, {["x"] = 7, ["y"] = 5, ["z"] = 29, ["name"] = "wool:black"}, {["x"] = 7, ["y"] = 5, ["z"] = 30, ["name"] = "wool:black"}, {["x"] = 7, ["y"] = 5, ["z"] = 31, ["name"] = "wool:black"}, {["x"] = 7, ["y"] = 5, ["z"] = 32, ["name"] = "wool:black"}, {["x"] = 7, ["y"] = 5, ["z"] = 33, ["name"] = "wool:black"}, {["x"] = 7, ["y"] = 5, ["z"] = 34, ["name"] = "wool:black"}, {["x"] = 7, ["y"] = 5, ["z"] = 35, ["name"] = "wool:black"}, {["x"] = 7, ["y"] = 5, ["z"] = 36, ["name"] = "wool:black"}, {["x"] = 7, ["y"] = 5, ["z"] = 37, ["name"] = "wool:black"}, {["x"] = 7, ["y"] = 5, ["z"] = 38, ["name"] = "wool:black"}, {["x"] = 7, ["y"] = 5, ["z"] = 39, ["name"] = "wool:black"}, {["x"] = 7, ["y"] = 5, ["z"] = 40, ["name"] = "wool:black"}, {["x"] = 7, ["y"] = 5, ["z"] = 41, ["name"] = "wool:black"}, {["x"] = 7, ["y"] = 5, ["z"] = 42, ["name"] = "wool:black"}, {["x"] = 7, ["y"] = 5, ["z"] = 43, ["name"] = "wool:black"}, {["x"] = 7, ["y"] = 5, ["z"] = 44, ["name"] = "wool:black"}, {["x"] = 7, ["y"] = 5, ["z"] = 45, ["name"] = "wool:black"}, {["x"] = 7, ["y"] = 5, ["z"] = 46, ["name"] = "wool:black"}, {["x"] = 7, ["y"] = 5, ["z"] = 47, ["name"] = "wool:black"}, {["x"] = 7, ["y"] = 5, ["z"] = 48, ["name"] = "wool:black"}, {["x"] = 7, ["y"] = 5, ["z"] = 49, ["name"] = "wool:black"}, {["x"] = 7, ["y"] = 5, ["z"] = 50, ["name"] = "wool:black"}, {["x"] = 7, ["y"] = 5, ["z"] = 51, ["name"] = "wool:black"}, {["x"] = 7, ["y"] = 5, ["z"] = 52, ["name"] = "wool:black"}, {["x"] = 7, ["y"] = 5, ["z"] = 53, ["name"] = "wool:black"}, {["x"] = 7, ["y"] = 5, ["z"] = 54, ["name"] = "wool:black"}, {["x"] = 7, ["y"] = 5, ["z"] = 55, ["name"] = "wool:black"}, {["x"] = 7, ["y"] = 5, ["z"] = 56, ["name"] = "wool:black"}, {["x"] = 7, ["y"] = 6, ["z"] = 28, ["name"] = "wool:black"}, {["x"] = 7, ["y"] = 6, ["z"] = 56, ["name"] = "wool:black"}, {["x"] = 7, ["y"] = 7, ["z"] = 28, ["name"] = "wool:black"}, {["x"] = 7, ["y"] = 7, ["z"] = 56, ["name"] = "wool:black"}, {["x"] = 7, ["y"] = 8, ["z"] = 28, ["name"] = "wool:black"}, {["x"] = 7, ["y"] = 8, ["z"] = 56, ["name"] = "wool:black"}, {["x"] = 7, ["y"] = 9, ["z"] = 28, ["name"] = "wool:black"}, {["x"] = 7, ["y"] = 9, ["z"] = 56, ["name"] = "wool:black"}, {["x"] = 7, ["y"] = 10, ["z"] = 28, ["name"] = "wool:black"}, {["x"] = 7, ["y"] = 10, ["z"] = 56, ["name"] = "wool:black"}, {["x"] = 7, ["y"] = 11, ["z"] = 28, ["name"] = "wool:black"}, {["x"] = 7, ["y"] = 11, ["z"] = 29, ["name"] = "wool:black"}, {["x"] = 7, ["y"] = 11, ["z"] = 30, ["name"] = "wool:black"}, {["x"] = 7, ["y"] = 11, ["z"] = 31, ["name"] = "wool:black"}, {["x"] = 7, ["y"] = 11, ["z"] = 32, ["name"] = "wool:black"}, {["x"] = 7, ["y"] = 11, ["z"] = 33, ["name"] = "wool:black"}, {["x"] = 7, ["y"] = 11, ["z"] = 34, ["name"] = "wool:black"}, {["x"] = 7, ["y"] = 11, ["z"] = 35, ["name"] = "wool:black"}, {["x"] = 7, ["y"] = 11, ["z"] = 36, ["name"] = "wool:black"}, {["x"] = 7, ["y"] = 11, ["z"] = 37, ["name"] = "wool:black"}, {["x"] = 7, ["y"] = 11, ["z"] = 38, ["name"] = "wool:black"}, {["x"] = 7, ["y"] = 11, ["z"] = 39, ["name"] = "wool:black"}, {["x"] = 7, ["y"] = 11, ["z"] = 40, ["name"] = "wool:black"}, {["x"] = 7, ["y"] = 11, ["z"] = 41, ["name"] = "wool:black"}, {["x"] = 7, ["y"] = 11, ["z"] = 42, ["name"] = "wool:black"}, {["x"] = 7, ["y"] = 11, ["z"] = 43, ["name"] = "wool:black"}, {["x"] = 7, ["y"] = 11, ["z"] = 44, ["name"] = "wool:black"}, {["x"] = 7, ["y"] = 11, ["z"] = 45, ["name"] = "wool:black"}, {["x"] = 7, ["y"] = 11, ["z"] = 46, ["name"] = "wool:black"}, {["x"] = 7, ["y"] = 11, ["z"] = 47, ["name"] = "wool:black"}, {["x"] = 7, ["y"] = 11, ["z"] = 48, ["name"] = "wool:black"}, {["x"] = 7, ["y"] = 11, ["z"] = 49, ["name"] = "wool:black"}, {["x"] = 7, ["y"] = 11, ["z"] = 50, ["name"] = "wool:black"}, {["x"] = 7, ["y"] = 11, ["z"] = 51, ["name"] = "wool:black"}, {["x"] = 7, ["y"] = 11, ["z"] = 52, ["name"] = "wool:black"}, {["x"] = 7, ["y"] = 11, ["z"] = 53, ["name"] = "wool:black"}, {["x"] = 7, ["y"] = 11, ["z"] = 54, ["name"] = "wool:black"}, {["x"] = 7, ["y"] = 11, ["z"] = 55, ["name"] = "wool:black"}, {["x"] = 7, ["y"] = 11, ["z"] = 56, ["name"] = "wool:black"}, {["x"] = 8, ["y"] = 5, ["z"] = 28, ["name"] = "wool:black"}, {["x"] = 8, ["y"] = 5, ["z"] = 29, ["name"] = "wool:black"}, {["x"] = 8, ["y"] = 5, ["z"] = 30, ["name"] = "wool:black"}, {["x"] = 8, ["y"] = 5, ["z"] = 31, ["name"] = "wool:black"}, {["x"] = 8, ["y"] = 5, ["z"] = 32, ["name"] = "wool:black"}, {["x"] = 8, ["y"] = 5, ["z"] = 33, ["name"] = "wool:black"}, {["x"] = 8, ["y"] = 5, ["z"] = 34, ["name"] = "wool:black"}, {["x"] = 8, ["y"] = 5, ["z"] = 35, ["name"] = "wool:black"}, {["x"] = 8, ["y"] = 5, ["z"] = 36, ["name"] = "wool:black"}, {["x"] = 8, ["y"] = 5, ["z"] = 37, ["name"] = "wool:black"}, {["x"] = 8, ["y"] = 5, ["z"] = 38, ["name"] = "wool:black"}, {["x"] = 8, ["y"] = 5, ["z"] = 39, ["name"] = "wool:black"}, {["x"] = 8, ["y"] = 5, ["z"] = 40, ["name"] = "wool:black"}, {["x"] = 8, ["y"] = 5, ["z"] = 41, ["name"] = "wool:black"}, {["x"] = 8, ["y"] = 5, ["z"] = 42, ["name"] = "wool:black"}, {["x"] = 8, ["y"] = 5, ["z"] = 43, ["name"] = "wool:black"}, {["x"] = 8, ["y"] = 5, ["z"] = 44, ["name"] = "wool:black"}, {["x"] = 8, ["y"] = 5, ["z"] = 45, ["name"] = "wool:black"}, {["x"] = 8, ["y"] = 5, ["z"] = 46, ["name"] = "wool:black"}, {["x"] = 8, ["y"] = 5, ["z"] = 47, ["name"] = "wool:black"}, {["x"] = 8, ["y"] = 5, ["z"] = 48, ["name"] = "wool:black"}, {["x"] = 8, ["y"] = 5, ["z"] = 49, ["name"] = "wool:black"}, {["x"] = 8, ["y"] = 5, ["z"] = 50, ["name"] = "wool:black"}, {["x"] = 8, ["y"] = 5, ["z"] = 51, ["name"] = "wool:black"}, {["x"] = 8, ["y"] = 5, ["z"] = 52, ["name"] = "wool:black"}, {["x"] = 8, ["y"] = 5, ["z"] = 53, ["name"] = "wool:black"}, {["x"] = 8, ["y"] = 5, ["z"] = 54, ["name"] = "wool:black"}, {["x"] = 8, ["y"] = 5, ["z"] = 55, ["name"] = "wool:black"}, {["x"] = 8, ["y"] = 5, ["z"] = 56, ["name"] = "wool:black"}, {["x"] = 8, ["y"] = 6, ["z"] = 28, ["name"] = "wool:black"}, {["x"] = 8, ["y"] = 6, ["z"] = 56, ["name"] = "wool:black"}, {["x"] = 8, ["y"] = 7, ["z"] = 28, ["name"] = "wool:black"}, {["x"] = 8, ["y"] = 7, ["z"] = 56, ["name"] = "wool:black"}, {["x"] = 8, ["y"] = 8, ["z"] = 28, ["name"] = "wool:black"}, {["x"] = 8, ["y"] = 8, ["z"] = 56, ["name"] = "wool:black"}, {["x"] = 8, ["y"] = 9, ["z"] = 28, ["name"] = "wool:black"}, {["x"] = 8, ["y"] = 9, ["z"] = 56, ["name"] = "wool:black"}, {["x"] = 8, ["y"] = 10, ["z"] = 28, ["name"] = "wool:black"}, {["x"] = 8, ["y"] = 10, ["z"] = 56, ["name"] = "wool:black"}, {["x"] = 8, ["y"] = 11, ["z"] = 28, ["name"] = "wool:black"}, {["x"] = 8, ["y"] = 11, ["z"] = 29, ["name"] = "wool:black"}, {["x"] = 8, ["y"] = 11, ["z"] = 30, ["name"] = "wool:black"}, {["x"] = 8, ["y"] = 11, ["z"] = 31, ["name"] = "wool:black"}, {["x"] = 8, ["y"] = 11, ["z"] = 32, ["name"] = "wool:black"}, {["x"] = 8, ["y"] = 11, ["z"] = 33, ["name"] = "wool:black"}, {["x"] = 8, ["y"] = 11, ["z"] = 34, ["name"] = "wool:black"}, {["x"] = 8, ["y"] = 11, ["z"] = 35, ["name"] = "wool:black"}, {["x"] = 8, ["y"] = 11, ["z"] = 36, ["name"] = "wool:black"}, {["x"] = 8, ["y"] = 11, ["z"] = 37, ["name"] = "wool:black"}, {["x"] = 8, ["y"] = 11, ["z"] = 38, ["name"] = "wool:black"}, {["x"] = 8, ["y"] = 11, ["z"] = 39, ["name"] = "wool:black"}, {["x"] = 8, ["y"] = 11, ["z"] = 40, ["name"] = "wool:black"}, {["x"] = 8, ["y"] = 11, ["z"] = 41, ["name"] = "wool:black"}, {["x"] = 8, ["y"] = 11, ["z"] = 42, ["name"] = "wool:black"}, {["x"] = 8, ["y"] = 11, ["z"] = 43, ["name"] = "wool:black"}, {["x"] = 8, ["y"] = 11, ["z"] = 44, ["name"] = "wool:black"}, {["x"] = 8, ["y"] = 11, ["z"] = 45, ["name"] = "wool:black"}, {["x"] = 8, ["y"] = 11, ["z"] = 46, ["name"] = "wool:black"}, {["x"] = 8, ["y"] = 11, ["z"] = 47, ["name"] = "wool:black"}, {["x"] = 8, ["y"] = 11, ["z"] = 48, ["name"] = "wool:black"}, {["x"] = 8, ["y"] = 11, ["z"] = 49, ["name"] = "wool:black"}, {["x"] = 8, ["y"] = 11, ["z"] = 50, ["name"] = "wool:black"}, {["x"] = 8, ["y"] = 11, ["z"] = 51, ["name"] = "wool:black"}, {["x"] = 8, ["y"] = 11, ["z"] = 52, ["name"] = "wool:black"}, {["x"] = 8, ["y"] = 11, ["z"] = 53, ["name"] = "wool:black"}, {["x"] = 8, ["y"] = 11, ["z"] = 54, ["name"] = "wool:black"}, {["x"] = 8, ["y"] = 11, ["z"] = 55, ["name"] = "wool:black"}, {["x"] = 8, ["y"] = 11, ["z"] = 56, ["name"] = "wool:black"}, {["x"] = 9, ["y"] = 5, ["z"] = 28, ["name"] = "wool:black"}, {["x"] = 9, ["y"] = 5, ["z"] = 29, ["name"] = "wool:black"}, {["x"] = 9, ["y"] = 5, ["z"] = 30, ["name"] = "wool:black"}, {["x"] = 9, ["y"] = 5, ["z"] = 31, ["name"] = "wool:black"}, {["x"] = 9, ["y"] = 5, ["z"] = 32, ["name"] = "wool:black"}, {["x"] = 9, ["y"] = 5, ["z"] = 33, ["name"] = "wool:black"}, {["x"] = 9, ["y"] = 5, ["z"] = 34, ["name"] = "wool:black"}, {["x"] = 9, ["y"] = 5, ["z"] = 35, ["name"] = "wool:black"}, {["x"] = 9, ["y"] = 5, ["z"] = 36, ["name"] = "wool:black"}, {["x"] = 9, ["y"] = 5, ["z"] = 37, ["name"] = "wool:black"}, {["x"] = 9, ["y"] = 5, ["z"] = 38, ["name"] = "wool:black"}, {["x"] = 9, ["y"] = 5, ["z"] = 39, ["name"] = "wool:black"}, {["x"] = 9, ["y"] = 5, ["z"] = 40, ["name"] = "wool:black"}, {["x"] = 9, ["y"] = 5, ["z"] = 41, ["name"] = "wool:black"}, {["x"] = 9, ["y"] = 5, ["z"] = 42, ["name"] = "wool:black"}, {["x"] = 9, ["y"] = 5, ["z"] = 43, ["name"] = "wool:black"}, {["x"] = 9, ["y"] = 5, ["z"] = 44, ["name"] = "wool:black"}, {["x"] = 9, ["y"] = 5, ["z"] = 45, ["name"] = "wool:black"}, {["x"] = 9, ["y"] = 5, ["z"] = 46, ["name"] = "wool:black"}, {["x"] = 9, ["y"] = 5, ["z"] = 47, ["name"] = "wool:black"}, {["x"] = 9, ["y"] = 5, ["z"] = 48, ["name"] = "wool:black"}, {["x"] = 9, ["y"] = 5, ["z"] = 49, ["name"] = "wool:black"}, {["x"] = 9, ["y"] = 5, ["z"] = 50, ["name"] = "wool:black"}, {["x"] = 9, ["y"] = 5, ["z"] = 51, ["name"] = "wool:black"}, {["x"] = 9, ["y"] = 5, ["z"] = 52, ["name"] = "wool:black"}, {["x"] = 9, ["y"] = 5, ["z"] = 53, ["name"] = "wool:black"}, {["x"] = 9, ["y"] = 5, ["z"] = 54, ["name"] = "wool:black"}, {["x"] = 9, ["y"] = 5, ["z"] = 55, ["name"] = "wool:black"}, {["x"] = 9, ["y"] = 5, ["z"] = 56, ["name"] = "wool:black"}, {["x"] = 9, ["y"] = 6, ["z"] = 28, ["name"] = "wool:black"}, {["x"] = 9, ["y"] = 6, ["z"] = 56, ["name"] = "wool:black"}, {["x"] = 9, ["y"] = 7, ["z"] = 28, ["name"] = "wool:black"}, {["x"] = 9, ["y"] = 7, ["z"] = 56, ["name"] = "wool:black"}, {["x"] = 9, ["y"] = 8, ["z"] = 28, ["name"] = "wool:black"}, {["x"] = 9, ["y"] = 8, ["z"] = 56, ["name"] = "wool:black"}, {["x"] = 9, ["y"] = 9, ["z"] = 28, ["name"] = "wool:black"}, {["x"] = 9, ["y"] = 9, ["z"] = 56, ["name"] = "wool:black"}, {["x"] = 9, ["y"] = 10, ["z"] = 28, ["name"] = "wool:black"}, {["x"] = 9, ["y"] = 10, ["z"] = 56, ["name"] = "wool:black"}, {["x"] = 9, ["y"] = 11, ["z"] = 28, ["name"] = "wool:black"}, {["x"] = 9, ["y"] = 11, ["z"] = 29, ["name"] = "wool:black"}, {["x"] = 9, ["y"] = 11, ["z"] = 30, ["name"] = "wool:black"}, {["x"] = 9, ["y"] = 11, ["z"] = 31, ["name"] = "wool:black"}, {["x"] = 9, ["y"] = 11, ["z"] = 32, ["name"] = "wool:black"}, {["x"] = 9, ["y"] = 11, ["z"] = 33, ["name"] = "wool:black"}, {["x"] = 9, ["y"] = 11, ["z"] = 34, ["name"] = "wool:black"}, {["x"] = 9, ["y"] = 11, ["z"] = 35, ["name"] = "wool:black"}, {["x"] = 9, ["y"] = 11, ["z"] = 36, ["name"] = "wool:black"}, {["x"] = 9, ["y"] = 11, ["z"] = 37, ["name"] = "wool:black"}, {["x"] = 9, ["y"] = 11, ["z"] = 38, ["name"] = "wool:black"}, {["x"] = 9, ["y"] = 11, ["z"] = 39, ["name"] = "wool:black"}, {["x"] = 9, ["y"] = 11, ["z"] = 40, ["name"] = "wool:black"}, {["x"] = 9, ["y"] = 11, ["z"] = 41, ["name"] = "wool:black"}, {["x"] = 9, ["y"] = 11, ["z"] = 42, ["name"] = "wool:black"}, {["x"] = 9, ["y"] = 11, ["z"] = 43, ["name"] = "wool:black"}, {["x"] = 9, ["y"] = 11, ["z"] = 44, ["name"] = "wool:black"}, {["x"] = 9, ["y"] = 11, ["z"] = 45, ["name"] = "wool:black"}, {["x"] = 9, ["y"] = 11, ["z"] = 46, ["name"] = "wool:black"}, {["x"] = 9, ["y"] = 11, ["z"] = 47, ["name"] = "wool:black"}, {["x"] = 9, ["y"] = 11, ["z"] = 48, ["name"] = "wool:black"}, {["x"] = 9, ["y"] = 11, ["z"] = 49, ["name"] = "wool:black"}, {["x"] = 9, ["y"] = 11, ["z"] = 50, ["name"] = "wool:black"}, {["x"] = 9, ["y"] = 11, ["z"] = 51, ["name"] = "wool:black"}, {["x"] = 9, ["y"] = 11, ["z"] = 52, ["name"] = "wool:black"}, {["x"] = 9, ["y"] = 11, ["z"] = 53, ["name"] = "wool:black"}, {["x"] = 9, ["y"] = 11, ["z"] = 54, ["name"] = "wool:black"}, {["x"] = 9, ["y"] = 11, ["z"] = 55, ["name"] = "wool:black"}, {["x"] = 9, ["y"] = 11, ["z"] = 56, ["name"] = "wool:black"}, {["x"] = 10, ["y"] = 5, ["z"] = 28, ["name"] = "wool:black"}, {["x"] = 10, ["y"] = 5, ["z"] = 29, ["name"] = "wool:black"}, {["x"] = 10, ["y"] = 5, ["z"] = 30, ["name"] = "wool:black"}, {["x"] = 10, ["y"] = 5, ["z"] = 31, ["name"] = "wool:black"}, {["x"] = 10, ["y"] = 5, ["z"] = 32, ["name"] = "wool:black"}, {["x"] = 10, ["y"] = 5, ["z"] = 33, ["name"] = "wool:black"}, {["x"] = 10, ["y"] = 5, ["z"] = 34, ["name"] = "wool:black"}, {["x"] = 10, ["y"] = 5, ["z"] = 35, ["name"] = "wool:black"}, {["x"] = 10, ["y"] = 5, ["z"] = 36, ["name"] = "wool:black"}, {["x"] = 10, ["y"] = 5, ["z"] = 37, ["name"] = "wool:black"}, {["x"] = 10, ["y"] = 5, ["z"] = 38, ["name"] = "wool:black"}, {["x"] = 10, ["y"] = 5, ["z"] = 39, ["name"] = "wool:black"}, {["x"] = 10, ["y"] = 5, ["z"] = 40, ["name"] = "wool:black"}, {["x"] = 10, ["y"] = 5, ["z"] = 41, ["name"] = "wool:black"}, {["x"] = 10, ["y"] = 5, ["z"] = 42, ["name"] = "wool:black"}, {["x"] = 10, ["y"] = 5, ["z"] = 43, ["name"] = "wool:black"}, {["x"] = 10, ["y"] = 5, ["z"] = 44, ["name"] = "wool:black"}, {["x"] = 10, ["y"] = 5, ["z"] = 45, ["name"] = "wool:black"}, {["x"] = 10, ["y"] = 5, ["z"] = 46, ["name"] = "wool:black"}, {["x"] = 10, ["y"] = 5, ["z"] = 47, ["name"] = "wool:black"}, {["x"] = 10, ["y"] = 5, ["z"] = 48, ["name"] = "wool:black"}, {["x"] = 10, ["y"] = 5, ["z"] = 49, ["name"] = "wool:black"}, {["x"] = 10, ["y"] = 5, ["z"] = 50, ["name"] = "wool:black"}, {["x"] = 10, ["y"] = 5, ["z"] = 51, ["name"] = "wool:black"}, {["x"] = 10, ["y"] = 5, ["z"] = 52, ["name"] = "wool:black"}, {["x"] = 10, ["y"] = 5, ["z"] = 53, ["name"] = "wool:black"}, {["x"] = 10, ["y"] = 5, ["z"] = 54, ["name"] = "wool:black"}, {["x"] = 10, ["y"] = 5, ["z"] = 55, ["name"] = "wool:black"}, {["x"] = 10, ["y"] = 5, ["z"] = 56, ["name"] = "wool:black"}, {["x"] = 10, ["y"] = 6, ["z"] = 28, ["name"] = "wool:black"}, {["x"] = 10, ["y"] = 6, ["z"] = 56, ["name"] = "wool:black"}, {["x"] = 10, ["y"] = 7, ["z"] = 28, ["name"] = "wool:black"}, {["x"] = 10, ["y"] = 7, ["z"] = 56, ["name"] = "wool:black"}, {["x"] = 10, ["y"] = 8, ["z"] = 28, ["name"] = "wool:black"}, {["x"] = 10, ["y"] = 8, ["z"] = 56, ["name"] = "wool:black"}, {["x"] = 10, ["y"] = 9, ["z"] = 28, ["name"] = "wool:black"}, {["x"] = 10, ["y"] = 9, ["z"] = 56, ["name"] = "wool:black"}, {["x"] = 10, ["y"] = 10, ["z"] = 28, ["name"] = "wool:black"}, {["x"] = 10, ["y"] = 10, ["z"] = 56, ["name"] = "wool:black"}, {["x"] = 10, ["y"] = 11, ["z"] = 28, ["name"] = "wool:black"}, {["x"] = 10, ["y"] = 11, ["z"] = 29, ["name"] = "wool:black"}, {["x"] = 10, ["y"] = 11, ["z"] = 30, ["name"] = "wool:black"}, {["x"] = 10, ["y"] = 11, ["z"] = 31, ["name"] = "wool:black"}, {["x"] = 10, ["y"] = 11, ["z"] = 32, ["name"] = "wool:black"}, {["x"] = 10, ["y"] = 11, ["z"] = 33, ["name"] = "wool:black"}, {["x"] = 10, ["y"] = 11, ["z"] = 34, ["name"] = "wool:black"}, {["x"] = 10, ["y"] = 11, ["z"] = 35, ["name"] = "wool:black"}, {["x"] = 10, ["y"] = 11, ["z"] = 36, ["name"] = "wool:black"}, {["x"] = 10, ["y"] = 11, ["z"] = 37, ["name"] = "wool:black"}, {["x"] = 10, ["y"] = 11, ["z"] = 38, ["name"] = "wool:black"}, {["x"] = 10, ["y"] = 11, ["z"] = 39, ["name"] = "wool:black"}, {["x"] = 10, ["y"] = 11, ["z"] = 40, ["name"] = "wool:black"}, {["x"] = 10, ["y"] = 11, ["z"] = 41, ["name"] = "wool:black"}, {["x"] = 10, ["y"] = 11, ["z"] = 42, ["name"] = "wool:black"}, {["x"] = 10, ["y"] = 11, ["z"] = 43, ["name"] = "wool:black"}, {["x"] = 10, ["y"] = 11, ["z"] = 44, ["name"] = "wool:black"}, {["x"] = 10, ["y"] = 11, ["z"] = 45, ["name"] = "wool:black"}, {["x"] = 10, ["y"] = 11, ["z"] = 46, ["name"] = "wool:black"}, {["x"] = 10, ["y"] = 11, ["z"] = 47, ["name"] = "wool:black"}, {["x"] = 10, ["y"] = 11, ["z"] = 48, ["name"] = "wool:black"}, {["x"] = 10, ["y"] = 11, ["z"] = 49, ["name"] = "wool:black"}, {["x"] = 10, ["y"] = 11, ["z"] = 50, ["name"] = "wool:black"}, {["x"] = 10, ["y"] = 11, ["z"] = 51, ["name"] = "wool:black"}, {["x"] = 10, ["y"] = 11, ["z"] = 52, ["name"] = "wool:black"}, {["x"] = 10, ["y"] = 11, ["z"] = 53, ["name"] = "wool:black"}, {["x"] = 10, ["y"] = 11, ["z"] = 54, ["name"] = "wool:black"}, {["x"] = 10, ["y"] = 11, ["z"] = 55, ["name"] = "wool:black"}, {["x"] = 10, ["y"] = 11, ["z"] = 56, ["name"] = "wool:black"}, {["x"] = 11, ["y"] = 5, ["z"] = 28, ["name"] = "wool:black"}, {["x"] = 11, ["y"] = 5, ["z"] = 29, ["name"] = "wool:black"}, {["x"] = 11, ["y"] = 5, ["z"] = 30, ["name"] = "wool:black"}, {["x"] = 11, ["y"] = 5, ["z"] = 31, ["name"] = "wool:black"}, {["x"] = 11, ["y"] = 5, ["z"] = 32, ["name"] = "wool:black"}, {["x"] = 11, ["y"] = 5, ["z"] = 33, ["name"] = "wool:black"}, {["x"] = 11, ["y"] = 5, ["z"] = 34, ["name"] = "wool:black"}, {["x"] = 11, ["y"] = 5, ["z"] = 35, ["name"] = "wool:black"}, {["x"] = 11, ["y"] = 5, ["z"] = 36, ["name"] = "wool:black"}, {["x"] = 11, ["y"] = 5, ["z"] = 37, ["name"] = "wool:black"}, {["x"] = 11, ["y"] = 5, ["z"] = 38, ["name"] = "wool:black"}, {["x"] = 11, ["y"] = 5, ["z"] = 39, ["name"] = "wool:black"}, {["x"] = 11, ["y"] = 5, ["z"] = 40, ["name"] = "mesecons_lightstone:lightstone_gray_off"}, {["x"] = 11, ["y"] = 5, ["z"] = 41, ["name"] = "mesecons_lightstone:lightstone_gray_off"}, {["x"] = 11, ["y"] = 5, ["z"] = 42, ["name"] = "mesecons_lightstone:lightstone_gray_off"}, {["x"] = 11, ["y"] = 5, ["z"] = 43, ["name"] = "mesecons_lightstone:lightstone_gray_off"}, {["x"] = 11, ["y"] = 5, ["z"] = 44, ["name"] = "mesecons_lightstone:lightstone_gray_off"}, {["x"] = 11, ["y"] = 5, ["z"] = 45, ["name"] = "wool:black"}, {["x"] = 11, ["y"] = 5, ["z"] = 46, ["name"] = "wool:black"}, {["x"] = 11, ["y"] = 5, ["z"] = 47, ["name"] = "wool:black"}, {["x"] = 11, ["y"] = 5, ["z"] = 48, ["name"] = "wool:black"}, {["x"] = 11, ["y"] = 5, ["z"] = 49, ["name"] = "wool:black"}, {["x"] = 11, ["y"] = 5, ["z"] = 50, ["name"] = "wool:black"}, {["x"] = 11, ["y"] = 5, ["z"] = 51, ["name"] = "wool:black"}, {["x"] = 11, ["y"] = 5, ["z"] = 52, ["name"] = "wool:black"}, {["x"] = 11, ["y"] = 5, ["z"] = 53, ["name"] = "wool:black"}, {["x"] = 11, ["y"] = 5, ["z"] = 54, ["name"] = "wool:black"}, {["x"] = 11, ["y"] = 5, ["z"] = 55, ["name"] = "wool:black"}, {["x"] = 11, ["y"] = 5, ["z"] = 56, ["name"] = "wool:black"}, {["x"] = 11, ["y"] = 6, ["z"] = 28, ["name"] = "wool:black"}, {["x"] = 11, ["y"] = 6, ["z"] = 36, ["name"] = "wool:dark_grey"}, {["x"] = 11, ["y"] = 6, ["z"] = 37, ["name"] = "wool:dark_grey"}, {["x"] = 11, ["y"] = 6, ["z"] = 38, ["name"] = "wool:dark_grey"}, {["x"] = 11, ["y"] = 6, ["z"] = 39, ["name"] = "wool:dark_grey"}, {["x"] = 11, ["y"] = 6, ["param1"] = 68, ["z"] = 40, ["name"] = "default:obsidian_glass"}, {["x"] = 11, ["y"] = 6, ["param1"] = 85, ["z"] = 41, ["name"] = "default:obsidian_glass"}, {["x"] = 11, ["y"] = 6, ["param1"] = 102, ["z"] = 42, ["name"] = "default:obsidian_glass"}, {["x"] = 11, ["y"] = 6, ["param1"] = 85, ["z"] = 43, ["name"] = "default:obsidian_glass"}, {["x"] = 11, ["y"] = 6, ["param1"] = 68, ["z"] = 44, ["name"] = "default:obsidian_glass"}, {["x"] = 11, ["y"] = 6, ["z"] = 45, ["name"] = "wool:dark_grey"}, {["x"] = 11, ["y"] = 6, ["z"] = 46, ["name"] = "wool:dark_grey"}, {["x"] = 11, ["y"] = 6, ["z"] = 47, ["name"] = "wool:dark_grey"}, {["x"] = 11, ["y"] = 6, ["z"] = 48, ["name"] = "wool:dark_grey"}, {["x"] = 11, ["y"] = 6, ["z"] = 56, ["name"] = "wool:black"}, {["x"] = 11, ["y"] = 7, ["z"] = 28, ["name"] = "wool:black"}, {["x"] = 11, ["y"] = 7, ["param1"] = 68, ["z"] = 36, ["name"] = "default:obsidian_glass"}, {["x"] = 11, ["y"] = 7, ["param1"] = 85, ["z"] = 37, ["name"] = "default:obsidian_glass"}, {["x"] = 11, ["y"] = 7, ["param1"] = 85, ["z"] = 38, ["name"] = "default:obsidian_glass"}, {["x"] = 11, ["y"] = 7, ["z"] = 39, ["name"] = "mesecons_lightstone:lightstone_gray_off"}, {["x"] = 11, ["y"] = 7, ["param1"] = 85, ["z"] = 40, ["name"] = "default:obsidian_glass"}, {["x"] = 11, ["y"] = 7, ["param1"] = 102, ["z"] = 41, ["name"] = "default:obsidian_glass"}, {["x"] = 11, ["y"] = 7, ["param1"] = 119, ["z"] = 42, ["name"] = "default:obsidian_glass"}, {["x"] = 11, ["y"] = 7, ["param1"] = 102, ["z"] = 43, ["name"] = "default:obsidian_glass"}, {["x"] = 11, ["y"] = 7, ["param1"] = 85, ["z"] = 44, ["name"] = "default:obsidian_glass"}, {["x"] = 11, ["y"] = 7, ["z"] = 45, ["name"] = "mesecons_lightstone:lightstone_gray_off"}, {["x"] = 11, ["y"] = 7, ["param1"] = 85, ["z"] = 46, ["name"] = "default:obsidian_glass"}, {["x"] = 11, ["y"] = 7, ["param1"] = 85, ["z"] = 47, ["name"] = "default:obsidian_glass"}, {["x"] = 11, ["y"] = 7, ["param1"] = 85, ["z"] = 48, ["name"] = "default:obsidian_glass"}, {["x"] = 11, ["y"] = 7, ["z"] = 56, ["name"] = "wool:black"}, {["x"] = 11, ["y"] = 8, ["z"] = 28, ["name"] = "wool:black"}, {["x"] = 11, ["y"] = 8, ["param1"] = 85, ["z"] = 36, ["name"] = "default:obsidian_glass"}, {["x"] = 11, ["y"] = 8, ["param1"] = 102, ["z"] = 37, ["name"] = "default:obsidian_glass"}, {["x"] = 11, ["y"] = 8, ["param1"] = 102, ["z"] = 38, ["name"] = "default:obsidian_glass"}, {["x"] = 11, ["y"] = 8, ["z"] = 39, ["name"] = "mesecons_lightstone:lightstone_gray_off"}, {["x"] = 11, ["y"] = 8, ["param1"] = 102, ["z"] = 40, ["name"] = "default:obsidian_glass"}, {["x"] = 11, ["y"] = 8, ["param1"] = 119, ["z"] = 41, ["name"] = "default:obsidian_glass"}, {["x"] = 11, ["y"] = 8, ["param1"] = 136, ["z"] = 42, ["name"] = "default:obsidian_glass"}, {["x"] = 11, ["y"] = 8, ["param1"] = 119, ["z"] = 43, ["name"] = "default:obsidian_glass"}, {["x"] = 11, ["y"] = 8, ["param1"] = 102, ["z"] = 44, ["name"] = "default:obsidian_glass"}, {["x"] = 11, ["y"] = 8, ["z"] = 45, ["name"] = "mesecons_lightstone:lightstone_gray_off"}, {["x"] = 11, ["y"] = 8, ["param1"] = 102, ["z"] = 46, ["name"] = "default:obsidian_glass"}, {["x"] = 11, ["y"] = 8, ["param1"] = 102, ["z"] = 47, ["name"] = "default:obsidian_glass"}, {["x"] = 11, ["y"] = 8, ["param1"] = 102, ["z"] = 48, ["name"] = "default:obsidian_glass"}, {["x"] = 11, ["y"] = 8, ["z"] = 56, ["name"] = "wool:black"}, {["x"] = 11, ["y"] = 9, ["z"] = 28, ["name"] = "wool:black"}, {["x"] = 11, ["y"] = 9, ["param1"] = 102, ["z"] = 36, ["name"] = "default:obsidian_glass"}, {["x"] = 11, ["y"] = 9, ["param1"] = 119, ["z"] = 37, ["name"] = "default:obsidian_glass"}, {["x"] = 11, ["y"] = 9, ["param1"] = 119, ["z"] = 38, ["name"] = "default:obsidian_glass"}, {["x"] = 11, ["y"] = 9, ["z"] = 39, ["name"] = "mesecons_lightstone:lightstone_gray_off"}, {["x"] = 11, ["y"] = 9, ["param1"] = 119, ["z"] = 40, ["name"] = "default:obsidian_glass"}, {["x"] = 11, ["y"] = 9, ["param1"] = 136, ["z"] = 41, ["name"] = "default:obsidian_glass"}, {["x"] = 11, ["y"] = 9, ["param1"] = 153, ["z"] = 42, ["name"] = "default:obsidian_glass"}, {["x"] = 11, ["y"] = 9, ["param1"] = 136, ["z"] = 43, ["name"] = "default:obsidian_glass"}, {["x"] = 11, ["y"] = 9, ["param1"] = 119, ["z"] = 44, ["name"] = "default:obsidian_glass"}, {["x"] = 11, ["y"] = 9, ["z"] = 45, ["name"] = "mesecons_lightstone:lightstone_gray_off"}, {["x"] = 11, ["y"] = 9, ["param1"] = 119, ["z"] = 46, ["name"] = "default:obsidian_glass"}, {["x"] = 11, ["y"] = 9, ["param1"] = 119, ["z"] = 47, ["name"] = "default:obsidian_glass"}, {["x"] = 11, ["y"] = 9, ["param1"] = 119, ["z"] = 48, ["name"] = "default:obsidian_glass"}, {["x"] = 11, ["y"] = 9, ["z"] = 56, ["name"] = "wool:black"}, {["x"] = 11, ["y"] = 10, ["z"] = 28, ["name"] = "wool:black"}, {["x"] = 11, ["y"] = 10, ["z"] = 36, ["name"] = "wool:dark_grey"}, {["x"] = 11, ["y"] = 10, ["z"] = 37, ["name"] = "wool:dark_grey"}, {["x"] = 11, ["y"] = 10, ["z"] = 38, ["name"] = "wool:dark_grey"}, {["x"] = 11, ["y"] = 10, ["z"] = 39, ["name"] = "wool:dark_grey"}, {["x"] = 11, ["y"] = 10, ["z"] = 40, ["name"] = "wool:dark_grey"}, {["x"] = 11, ["y"] = 10, ["z"] = 41, ["name"] = "wool:dark_grey"}, {["x"] = 11, ["y"] = 10, ["z"] = 42, ["name"] = "wool:dark_grey"}, {["x"] = 11, ["y"] = 10, ["z"] = 43, ["name"] = "wool:dark_grey"}, {["x"] = 11, ["y"] = 10, ["z"] = 44, ["name"] = "wool:dark_grey"}, {["x"] = 11, ["y"] = 10, ["z"] = 45, ["name"] = "wool:dark_grey"}, {["x"] = 11, ["y"] = 10, ["z"] = 46, ["name"] = "wool:dark_grey"}, {["x"] = 11, ["y"] = 10, ["z"] = 47, ["name"] = "wool:dark_grey"}, {["x"] = 11, ["y"] = 10, ["z"] = 48, ["name"] = "wool:dark_grey"}, {["x"] = 11, ["y"] = 10, ["z"] = 56, ["name"] = "wool:black"}, {["x"] = 11, ["y"] = 11, ["z"] = 28, ["name"] = "wool:black"}, {["x"] = 11, ["y"] = 11, ["z"] = 29, ["name"] = "wool:black"}, {["x"] = 11, ["y"] = 11, ["z"] = 30, ["name"] = "wool:black"}, {["x"] = 11, ["y"] = 11, ["z"] = 31, ["name"] = "wool:black"}, {["x"] = 11, ["y"] = 11, ["z"] = 32, ["name"] = "wool:black"}, {["x"] = 11, ["y"] = 11, ["z"] = 33, ["name"] = "wool:black"}, {["x"] = 11, ["y"] = 11, ["z"] = 34, ["name"] = "wool:black"}, {["x"] = 11, ["y"] = 11, ["z"] = 35, ["name"] = "wool:black"}, {["x"] = 11, ["y"] = 11, ["z"] = 36, ["name"] = "wool:dark_grey"}, {["x"] = 11, ["y"] = 11, ["z"] = 37, ["name"] = "wool:dark_grey"}, {["x"] = 11, ["y"] = 11, ["z"] = 38, ["name"] = "wool:dark_grey"}, {["x"] = 11, ["y"] = 11, ["z"] = 39, ["name"] = "wool:dark_grey"}, {["x"] = 11, ["y"] = 11, ["z"] = 40, ["name"] = "wool:dark_grey"}, {["x"] = 11, ["y"] = 11, ["z"] = 41, ["name"] = "wool:dark_grey"}, {["x"] = 11, ["y"] = 11, ["z"] = 42, ["name"] = "wool:dark_grey"}, {["x"] = 11, ["y"] = 11, ["z"] = 43, ["name"] = "wool:dark_grey"}, {["x"] = 11, ["y"] = 11, ["z"] = 44, ["name"] = "wool:dark_grey"}, {["x"] = 11, ["y"] = 11, ["z"] = 45, ["name"] = "wool:dark_grey"}, {["x"] = 11, ["y"] = 11, ["z"] = 46, ["name"] = "wool:dark_grey"}, {["x"] = 11, ["y"] = 11, ["z"] = 47, ["name"] = "wool:dark_grey"}, {["x"] = 11, ["y"] = 11, ["z"] = 48, ["name"] = "wool:dark_grey"}, {["x"] = 11, ["y"] = 11, ["z"] = 49, ["name"] = "wool:black"}, {["x"] = 11, ["y"] = 11, ["z"] = 50, ["name"] = "wool:black"}, {["x"] = 11, ["y"] = 11, ["z"] = 51, ["name"] = "wool:black"}, {["x"] = 11, ["y"] = 11, ["z"] = 52, ["name"] = "wool:black"}, {["x"] = 11, ["y"] = 11, ["z"] = 53, ["name"] = "wool:black"}, {["x"] = 11, ["y"] = 11, ["z"] = 54, ["name"] = "wool:black"}, {["x"] = 11, ["y"] = 11, ["z"] = 55, ["name"] = "wool:black"}, {["x"] = 11, ["y"] = 11, ["z"] = 56, ["name"] = "wool:black"}, {["x"] = 12, ["y"] = 5, ["z"] = 28, ["name"] = "wool:black"}, {["x"] = 12, ["y"] = 5, ["z"] = 29, ["name"] = "wool:black"}, {["x"] = 12, ["y"] = 5, ["z"] = 30, ["name"] = "wool:black"}, {["x"] = 12, ["y"] = 5, ["z"] = 31, ["name"] = "wool:black"}, {["x"] = 12, ["y"] = 5, ["z"] = 32, ["name"] = "wool:black"}, {["x"] = 12, ["y"] = 5, ["z"] = 33, ["name"] = "wool:black"}, {["x"] = 12, ["y"] = 5, ["z"] = 34, ["name"] = "wool:black"}, {["x"] = 12, ["y"] = 5, ["z"] = 35, ["name"] = "wool:black"}, {["x"] = 12, ["y"] = 5, ["z"] = 36, ["name"] = "moreblocks:copperpatina"}, {["x"] = 12, ["y"] = 5, ["z"] = 37, ["name"] = "moreblocks:copperpatina"}, {["x"] = 12, ["y"] = 5, ["z"] = 38, ["name"] = "mesecons_lightstone:lightstone_white_off"}, {["x"] = 12, ["y"] = 5, ["z"] = 39, ["name"] = "mesecons_lightstone:lightstone_white_off"}, {["x"] = 12, ["y"] = 5, ["z"] = 40, ["name"] = "mesecons_lightstone:lightstone_white_off"}, {["x"] = 12, ["y"] = 5, ["z"] = 41, ["name"] = "mesecons_lightstone:lightstone_white_off"}, {["x"] = 12, ["y"] = 5, ["z"] = 42, ["name"] = "mesecons_lightstone:lightstone_white_off"}, {["x"] = 12, ["y"] = 5, ["z"] = 43, ["name"] = "mesecons_lightstone:lightstone_white_off"}, {["x"] = 12, ["y"] = 5, ["z"] = 44, ["name"] = "mesecons_lightstone:lightstone_white_off"}, {["x"] = 12, ["y"] = 5, ["z"] = 45, ["name"] = "mesecons_lightstone:lightstone_white_off"}, {["x"] = 12, ["y"] = 5, ["z"] = 46, ["name"] = "mesecons_lightstone:lightstone_white_off"}, {["x"] = 12, ["y"] = 5, ["z"] = 47, ["name"] = "moreblocks:copperpatina"}, {["x"] = 12, ["y"] = 5, ["z"] = 48, ["name"] = "moreblocks:copperpatina"}, {["x"] = 12, ["y"] = 5, ["z"] = 49, ["name"] = "wool:black"}, {["x"] = 12, ["y"] = 5, ["z"] = 50, ["name"] = "wool:black"}, {["x"] = 12, ["y"] = 5, ["z"] = 51, ["name"] = "wool:black"}, {["x"] = 12, ["y"] = 5, ["z"] = 52, ["name"] = "wool:black"}, {["x"] = 12, ["y"] = 5, ["z"] = 53, ["name"] = "wool:black"}, {["x"] = 12, ["y"] = 5, ["z"] = 54, ["name"] = "wool:black"}, {["x"] = 12, ["y"] = 5, ["z"] = 55, ["name"] = "wool:black"}, {["x"] = 12, ["y"] = 5, ["z"] = 56, ["name"] = "wool:black"}, {["x"] = 12, ["y"] = 6, ["z"] = 28, ["name"] = "wool:black"}, {["x"] = 12, ["y"] = 6, ["z"] = 35, ["name"] = "wool:dark_grey"}, {["x"] = 12, ["y"] = 6, ["z"] = 36, ["name"] = "default:tinblock"}, {["x"] = 12, ["y"] = 6, ["z"] = 37, ["name"] = "default:tinblock"}, {["x"] = 12, ["y"] = 6, ["z"] = 47, ["name"] = "default:tinblock"}, {["x"] = 12, ["y"] = 6, ["z"] = 48, ["name"] = "default:tinblock"}, {["x"] = 12, ["y"] = 6, ["z"] = 49, ["name"] = "wool:dark_grey"}, {["x"] = 12, ["y"] = 6, ["z"] = 56, ["name"] = "wool:black"}, {["x"] = 12, ["y"] = 7, ["z"] = 28, ["name"] = "wool:black"}, {["x"] = 12, ["y"] = 7, ["param1"] = 68, ["z"] = 35, ["name"] = "default:obsidian_glass"}, {["x"] = 12, ["y"] = 7, ["param1"] = 85, ["z"] = 49, ["name"] = "default:obsidian_glass"}, {["x"] = 12, ["y"] = 7, ["z"] = 56, ["name"] = "wool:black"}, {["x"] = 12, ["y"] = 8, ["z"] = 28, ["name"] = "wool:black"}, {["x"] = 12, ["y"] = 8, ["param1"] = 85, ["z"] = 35, ["name"] = "default:obsidian_glass"}, {["x"] = 12, ["y"] = 8, ["param1"] = 102, ["z"] = 49, ["name"] = "default:obsidian_glass"}, {["x"] = 12, ["y"] = 8, ["z"] = 56, ["name"] = "wool:black"}, {["x"] = 12, ["y"] = 9, ["z"] = 28, ["name"] = "wool:black"}, {["x"] = 12, ["y"] = 9, ["param1"] = 102, ["z"] = 35, ["name"] = "default:obsidian_glass"}, {["x"] = 12, ["y"] = 9, ["param1"] = 119, ["z"] = 49, ["name"] = "default:obsidian_glass"}, {["x"] = 12, ["y"] = 9, ["z"] = 56, ["name"] = "wool:black"}, {["x"] = 12, ["y"] = 10, ["z"] = 28, ["name"] = "wool:black"}, {["x"] = 12, ["y"] = 10, ["z"] = 35, ["name"] = "wool:dark_grey"}, {["x"] = 12, ["y"] = 10, ["z"] = 49, ["name"] = "wool:dark_grey"}, {["x"] = 12, ["y"] = 10, ["z"] = 56, ["name"] = "wool:black"}, {["x"] = 12, ["y"] = 11, ["z"] = 28, ["name"] = "wool:black"}, {["x"] = 12, ["y"] = 11, ["z"] = 29, ["name"] = "wool:black"}, {["x"] = 12, ["y"] = 11, ["z"] = 30, ["name"] = "wool:black"}, {["x"] = 12, ["y"] = 11, ["z"] = 31, ["name"] = "wool:black"}, {["x"] = 12, ["y"] = 11, ["z"] = 32, ["name"] = "wool:black"}, {["x"] = 12, ["y"] = 11, ["z"] = 33, ["name"] = "wool:black"}, {["x"] = 12, ["y"] = 11, ["z"] = 34, ["name"] = "wool:black"}, {["x"] = 12, ["y"] = 11, ["z"] = 35, ["name"] = "wool:dark_grey"}, {["x"] = 12, ["y"] = 11, ["z"] = 36, ["name"] = "mesecons_lightstone:lightstone_gray_off"}, {["x"] = 12, ["y"] = 11, ["z"] = 37, ["name"] = "mesecons_lightstone:lightstone_gray_off"}, {["x"] = 12, ["y"] = 11, ["z"] = 38, ["name"] = "mesecons_lightstone:lightstone_gray_off"}, {["x"] = 12, ["y"] = 11, ["z"] = 39, ["name"] = "mesecons_lightstone:lightstone_gray_off"}, {["x"] = 12, ["y"] = 11, ["z"] = 40, ["name"] = "mesecons_lightstone:lightstone_gray_off"}, {["x"] = 12, ["y"] = 11, ["z"] = 41, ["name"] = "mesecons_lightstone:lightstone_gray_off"}, {["x"] = 12, ["y"] = 11, ["z"] = 42, ["name"] = "mesecons_lightstone:lightstone_gray_off"}, {["x"] = 12, ["y"] = 11, ["z"] = 43, ["name"] = "mesecons_lightstone:lightstone_gray_off"}, {["x"] = 12, ["y"] = 11, ["z"] = 44, ["name"] = "mesecons_lightstone:lightstone_gray_off"}, {["x"] = 12, ["y"] = 11, ["z"] = 45, ["name"] = "mesecons_lightstone:lightstone_gray_off"}, {["x"] = 12, ["y"] = 11, ["z"] = 46, ["name"] = "mesecons_lightstone:lightstone_gray_off"}, {["x"] = 12, ["y"] = 11, ["z"] = 47, ["name"] = "mesecons_lightstone:lightstone_gray_off"}, {["x"] = 12, ["y"] = 11, ["z"] = 48, ["name"] = "mesecons_lightstone:lightstone_gray_off"}, {["x"] = 12, ["y"] = 11, ["z"] = 49, ["name"] = "wool:dark_grey"}, {["x"] = 12, ["y"] = 11, ["z"] = 50, ["name"] = "wool:black"}, {["x"] = 12, ["y"] = 11, ["z"] = 51, ["name"] = "wool:black"}, {["x"] = 12, ["y"] = 11, ["z"] = 52, ["name"] = "wool:black"}, {["x"] = 12, ["y"] = 11, ["z"] = 53, ["name"] = "wool:black"}, {["x"] = 12, ["y"] = 11, ["z"] = 54, ["name"] = "wool:black"}, {["x"] = 12, ["y"] = 11, ["z"] = 55, ["name"] = "wool:black"}, {["x"] = 12, ["y"] = 11, ["z"] = 56, ["name"] = "wool:black"}, {["x"] = 13, ["y"] = 5, ["z"] = 28, ["name"] = "wool:black"}, {["x"] = 13, ["y"] = 5, ["z"] = 29, ["name"] = "wool:black"}, {["x"] = 13, ["y"] = 5, ["z"] = 30, ["name"] = "wool:black"}, {["x"] = 13, ["y"] = 5, ["z"] = 31, ["name"] = "wool:black"}, {["x"] = 13, ["y"] = 5, ["z"] = 32, ["name"] = "wool:black"}, {["x"] = 13, ["y"] = 5, ["z"] = 33, ["name"] = "wool:black"}, {["x"] = 13, ["y"] = 5, ["z"] = 34, ["name"] = "wool:black"}, {["x"] = 13, ["y"] = 5, ["z"] = 35, ["name"] = "moreblocks:copperpatina"}, {["x"] = 13, ["y"] = 5, ["z"] = 36, ["name"] = "mesecons_lightstone:lightstone_white_off"}, {["x"] = 13, ["y"] = 5, ["z"] = 37, ["name"] = "mesecons_lightstone:lightstone_white_off"}, {["x"] = 13, ["y"] = 5, ["z"] = 38, ["name"] = "mesecons_lightstone:lightstone_white_off"}, {["x"] = 13, ["y"] = 5, ["z"] = 39, ["name"] = "mesecons_lightstone:lightstone_white_off"}, {["x"] = 13, ["y"] = 5, ["z"] = 40, ["name"] = "moreblocks:copperpatina"}, {["x"] = 13, ["y"] = 5, ["z"] = 41, ["name"] = "moreblocks:copperpatina"}, {["x"] = 13, ["y"] = 5, ["z"] = 42, ["name"] = "moreblocks:copperpatina"}, {["x"] = 13, ["y"] = 5, ["z"] = 43, ["name"] = "moreblocks:copperpatina"}, {["x"] = 13, ["y"] = 5, ["z"] = 44, ["name"] = "moreblocks:copperpatina"}, {["x"] = 13, ["y"] = 5, ["z"] = 45, ["name"] = "mesecons_lightstone:lightstone_white_off"}, {["x"] = 13, ["y"] = 5, ["z"] = 46, ["name"] = "mesecons_lightstone:lightstone_white_off"}, {["x"] = 13, ["y"] = 5, ["z"] = 47, ["name"] = "mesecons_lightstone:lightstone_white_off"}, {["x"] = 13, ["y"] = 5, ["z"] = 48, ["name"] = "mesecons_lightstone:lightstone_white_off"}, {["x"] = 13, ["y"] = 5, ["z"] = 49, ["name"] = "moreblocks:copperpatina"}, {["x"] = 13, ["y"] = 5, ["z"] = 50, ["name"] = "wool:black"}, {["x"] = 13, ["y"] = 5, ["z"] = 51, ["name"] = "wool:black"}, {["x"] = 13, ["y"] = 5, ["z"] = 52, ["name"] = "wool:black"}, {["x"] = 13, ["y"] = 5, ["z"] = 53, ["name"] = "wool:black"}, {["x"] = 13, ["y"] = 5, ["z"] = 54, ["name"] = "wool:black"}, {["x"] = 13, ["y"] = 5, ["z"] = 55, ["name"] = "wool:black"}, {["x"] = 13, ["y"] = 5, ["z"] = 56, ["name"] = "wool:black"}, {["x"] = 13, ["y"] = 6, ["z"] = 28, ["name"] = "wool:black"}, {["x"] = 13, ["y"] = 6, ["z"] = 34, ["name"] = "wool:dark_grey"}, {["x"] = 13, ["y"] = 6, ["z"] = 35, ["name"] = "default:tinblock"}, {["x"] = 13, ["y"] = 6, ["z"] = 40, ["name"] = "default:tinblock"}, {["x"] = 13, ["y"] = 6, ["z"] = 41, ["name"] = "default:tinblock"}, {["x"] = 13, ["y"] = 6, ["z"] = 42, ["name"] = "default:tinblock"}, {["x"] = 13, ["y"] = 6, ["z"] = 43, ["name"] = "default:tinblock"}, {["x"] = 13, ["y"] = 6, ["z"] = 44, ["name"] = "default:tinblock"}, {["x"] = 13, ["y"] = 6, ["z"] = 49, ["name"] = "default:tinblock"}, {["x"] = 13, ["y"] = 6, ["z"] = 50, ["name"] = "wool:dark_grey"}, {["x"] = 13, ["y"] = 6, ["z"] = 56, ["name"] = "wool:black"}, {["x"] = 13, ["y"] = 7, ["z"] = 28, ["name"] = "wool:black"}, {["x"] = 13, ["y"] = 7, ["param1"] = 68, ["z"] = 34, ["name"] = "default:obsidian_glass"}, {["x"] = 13, ["y"] = 7, ["param1"] = 85, ["z"] = 50, ["name"] = "default:obsidian_glass"}, {["x"] = 13, ["y"] = 7, ["z"] = 56, ["name"] = "wool:black"}, {["x"] = 13, ["y"] = 8, ["z"] = 28, ["name"] = "wool:black"}, {["x"] = 13, ["y"] = 8, ["param1"] = 85, ["z"] = 34, ["name"] = "default:obsidian_glass"}, {["x"] = 13, ["y"] = 8, ["param1"] = 102, ["z"] = 50, ["name"] = "default:obsidian_glass"}, {["x"] = 13, ["y"] = 8, ["z"] = 56, ["name"] = "wool:black"}, {["x"] = 13, ["y"] = 9, ["z"] = 28, ["name"] = "wool:black"}, {["x"] = 13, ["y"] = 9, ["param1"] = 102, ["z"] = 34, ["name"] = "default:obsidian_glass"}, {["x"] = 13, ["y"] = 9, ["param1"] = 119, ["z"] = 50, ["name"] = "default:obsidian_glass"}, {["x"] = 13, ["y"] = 9, ["z"] = 56, ["name"] = "wool:black"}, {["x"] = 13, ["y"] = 10, ["z"] = 28, ["name"] = "wool:black"}, {["x"] = 13, ["y"] = 10, ["z"] = 34, ["name"] = "wool:dark_grey"}, {["x"] = 13, ["y"] = 10, ["z"] = 50, ["name"] = "wool:dark_grey"}, {["x"] = 13, ["y"] = 10, ["z"] = 56, ["name"] = "wool:black"}, {["x"] = 13, ["y"] = 11, ["z"] = 28, ["name"] = "wool:black"}, {["x"] = 13, ["y"] = 11, ["z"] = 29, ["name"] = "wool:black"}, {["x"] = 13, ["y"] = 11, ["z"] = 30, ["name"] = "wool:black"}, {["x"] = 13, ["y"] = 11, ["z"] = 31, ["name"] = "wool:black"}, {["x"] = 13, ["y"] = 11, ["z"] = 32, ["name"] = "wool:black"}, {["x"] = 13, ["y"] = 11, ["z"] = 33, ["name"] = "wool:black"}, {["x"] = 13, ["y"] = 11, ["z"] = 34, ["name"] = "wool:dark_grey"}, {["x"] = 13, ["y"] = 11, ["z"] = 35, ["name"] = "mesecons_lightstone:lightstone_gray_off"}, {["x"] = 13, ["y"] = 11, ["z"] = 36, ["name"] = "mesecons_lightstone:lightstone_gray_off"}, {["x"] = 13, ["y"] = 11, ["z"] = 37, ["name"] = "mesecons_lightstone:lightstone_gray_off"}, {["x"] = 13, ["y"] = 11, ["z"] = 38, ["name"] = "mesecons_lightstone:lightstone_gray_off"}, {["x"] = 13, ["y"] = 11, ["z"] = 39, ["name"] = "mesecons_lightstone:lightstone_gray_off"}, {["x"] = 13, ["y"] = 11, ["z"] = 40, ["name"] = "mesecons_lightstone:lightstone_gray_off"}, {["x"] = 13, ["y"] = 11, ["z"] = 41, ["name"] = "mesecons_lightstone:lightstone_gray_off"}, {["x"] = 13, ["y"] = 11, ["z"] = 42, ["name"] = "mesecons_lightstone:lightstone_gray_off"}, {["x"] = 13, ["y"] = 11, ["z"] = 43, ["name"] = "mesecons_lightstone:lightstone_gray_off"}, {["x"] = 13, ["y"] = 11, ["z"] = 44, ["name"] = "mesecons_lightstone:lightstone_gray_off"}, {["x"] = 13, ["y"] = 11, ["z"] = 45, ["name"] = "mesecons_lightstone:lightstone_gray_off"}, {["x"] = 13, ["y"] = 11, ["z"] = 46, ["name"] = "mesecons_lightstone:lightstone_gray_off"}, {["x"] = 13, ["y"] = 11, ["z"] = 47, ["name"] = "mesecons_lightstone:lightstone_gray_off"}, {["x"] = 13, ["y"] = 11, ["z"] = 48, ["name"] = "mesecons_lightstone:lightstone_gray_off"}, {["x"] = 13, ["y"] = 11, ["z"] = 49, ["name"] = "mesecons_lightstone:lightstone_gray_off"}, {["x"] = 13, ["y"] = 11, ["z"] = 50, ["name"] = "wool:dark_grey"}, {["x"] = 13, ["y"] = 11, ["z"] = 51, ["name"] = "wool:black"}, {["x"] = 13, ["y"] = 11, ["z"] = 52, ["name"] = "wool:black"}, {["x"] = 13, ["y"] = 11, ["z"] = 53, ["name"] = "wool:black"}, {["x"] = 13, ["y"] = 11, ["z"] = 54, ["name"] = "wool:black"}, {["x"] = 13, ["y"] = 11, ["z"] = 55, ["name"] = "wool:black"}, {["x"] = 13, ["y"] = 11, ["z"] = 56, ["name"] = "wool:black"}, {["x"] = 14, ["y"] = 5, ["z"] = 28, ["name"] = "wool:black"}, {["x"] = 14, ["y"] = 5, ["z"] = 29, ["name"] = "wool:black"}, {["x"] = 14, ["y"] = 5, ["z"] = 30, ["name"] = "wool:black"}, {["x"] = 14, ["y"] = 5, ["z"] = 31, ["name"] = "wool:black"}, {["x"] = 14, ["y"] = 5, ["z"] = 32, ["name"] = "wool:black"}, {["x"] = 14, ["y"] = 5, ["z"] = 33, ["name"] = "wool:black"}, {["x"] = 14, ["y"] = 5, ["z"] = 34, ["name"] = "moreblocks:copperpatina"}, {["x"] = 14, ["y"] = 5, ["z"] = 35, ["name"] = "mesecons_lightstone:lightstone_white_off"}, {["x"] = 14, ["y"] = 5, ["z"] = 36, ["name"] = "mesecons_lightstone:lightstone_white_off"}, {["x"] = 14, ["y"] = 5, ["z"] = 37, ["name"] = "mesecons_lightstone:lightstone_white_off"}, {["x"] = 14, ["y"] = 5, ["z"] = 38, ["name"] = "mesecons_lightstone:lightstone_white_off"}, {["x"] = 14, ["y"] = 5, ["z"] = 39, ["name"] = "mesecons_lightstone:lightstone_white_off"}, {["x"] = 14, ["y"] = 5, ["z"] = 40, ["name"] = "moreblocks:copperpatina"}, {["x"] = 14, ["y"] = 5, ["z"] = 41, ["name"] = "mesecons_lightstone:lightstone_white_off"}, {["x"] = 14, ["y"] = 5, ["z"] = 42, ["name"] = "mesecons_lightstone:lightstone_white_off"}, {["x"] = 14, ["y"] = 5, ["z"] = 43, ["name"] = "mesecons_lightstone:lightstone_white_off"}, {["x"] = 14, ["y"] = 5, ["z"] = 44, ["name"] = "moreblocks:copperpatina"}, {["x"] = 14, ["y"] = 5, ["z"] = 45, ["name"] = "mesecons_lightstone:lightstone_white_off"}, {["x"] = 14, ["y"] = 5, ["z"] = 46, ["name"] = "mesecons_lightstone:lightstone_white_off"}, {["x"] = 14, ["y"] = 5, ["z"] = 47, ["name"] = "mesecons_lightstone:lightstone_white_off"}, {["x"] = 14, ["y"] = 5, ["z"] = 48, ["name"] = "mesecons_lightstone:lightstone_white_off"}, {["x"] = 14, ["y"] = 5, ["z"] = 49, ["name"] = "mesecons_lightstone:lightstone_white_off"}, {["x"] = 14, ["y"] = 5, ["z"] = 50, ["name"] = "moreblocks:copperpatina"}, {["x"] = 14, ["y"] = 5, ["z"] = 51, ["name"] = "wool:black"}, {["x"] = 14, ["y"] = 5, ["z"] = 52, ["name"] = "wool:black"}, {["x"] = 14, ["y"] = 5, ["z"] = 53, ["name"] = "wool:black"}, {["x"] = 14, ["y"] = 5, ["z"] = 54, ["name"] = "wool:black"}, {["x"] = 14, ["y"] = 5, ["z"] = 55, ["name"] = "wool:black"}, {["x"] = 14, ["y"] = 5, ["z"] = 56, ["name"] = "wool:black"}, {["x"] = 14, ["y"] = 6, ["z"] = 28, ["name"] = "wool:black"}, {["x"] = 14, ["y"] = 6, ["z"] = 33, ["name"] = "wool:dark_grey"}, {["x"] = 14, ["y"] = 6, ["z"] = 34, ["name"] = "default:tinblock"}, {["x"] = 14, ["y"] = 6, ["z"] = 40, ["name"] = "default:tinblock"}, {["x"] = 14, ["y"] = 6, ["z"] = 44, ["name"] = "default:tinblock"}, {["x"] = 14, ["y"] = 6, ["z"] = 50, ["name"] = "default:tinblock"}, {["x"] = 14, ["y"] = 6, ["z"] = 51, ["name"] = "wool:dark_grey"}, {["x"] = 14, ["y"] = 6, ["z"] = 56, ["name"] = "wool:black"}, {["x"] = 14, ["y"] = 7, ["z"] = 28, ["name"] = "wool:black"}, {["x"] = 14, ["y"] = 7, ["param1"] = 68, ["z"] = 33, ["name"] = "default:obsidian_glass"}, {["x"] = 14, ["y"] = 7, ["param1"] = 85, ["z"] = 51, ["name"] = "default:obsidian_glass"}, {["x"] = 14, ["y"] = 7, ["z"] = 56, ["name"] = "wool:black"}, {["x"] = 14, ["y"] = 8, ["z"] = 28, ["name"] = "wool:black"}, {["x"] = 14, ["y"] = 8, ["param1"] = 85, ["z"] = 33, ["name"] = "default:obsidian_glass"}, {["x"] = 14, ["y"] = 8, ["param1"] = 102, ["z"] = 51, ["name"] = "default:obsidian_glass"}, {["x"] = 14, ["y"] = 8, ["z"] = 56, ["name"] = "wool:black"}, {["x"] = 14, ["y"] = 9, ["z"] = 28, ["name"] = "wool:black"}, {["x"] = 14, ["y"] = 9, ["param1"] = 102, ["z"] = 33, ["name"] = "default:obsidian_glass"}, {["x"] = 14, ["y"] = 9, ["param1"] = 119, ["z"] = 51, ["name"] = "default:obsidian_glass"}, {["x"] = 14, ["y"] = 9, ["z"] = 56, ["name"] = "wool:black"}, {["x"] = 14, ["y"] = 10, ["z"] = 28, ["name"] = "wool:black"}, {["x"] = 14, ["y"] = 10, ["z"] = 33, ["name"] = "wool:dark_grey"}, {["x"] = 14, ["y"] = 10, ["z"] = 51, ["name"] = "wool:dark_grey"}, {["x"] = 14, ["y"] = 10, ["z"] = 56, ["name"] = "wool:black"}, {["x"] = 14, ["y"] = 11, ["z"] = 28, ["name"] = "wool:black"}, {["x"] = 14, ["y"] = 11, ["z"] = 29, ["name"] = "wool:black"}, {["x"] = 14, ["y"] = 11, ["z"] = 30, ["name"] = "wool:black"}, {["x"] = 14, ["y"] = 11, ["z"] = 31, ["name"] = "wool:black"}, {["x"] = 14, ["y"] = 11, ["z"] = 32, ["name"] = "wool:black"}, {["x"] = 14, ["y"] = 11, ["z"] = 33, ["name"] = "wool:dark_grey"}, {["x"] = 14, ["y"] = 11, ["z"] = 34, ["name"] = "mesecons_lightstone:lightstone_gray_off"}, {["x"] = 14, ["y"] = 11, ["z"] = 35, ["name"] = "mesecons_lightstone:lightstone_gray_off"}, {["x"] = 14, ["y"] = 11, ["z"] = 36, ["name"] = "mesecons_lightstone:lightstone_gray_off"}, {["x"] = 14, ["y"] = 11, ["z"] = 37, ["name"] = "mesecons_lightstone:lightstone_gray_off"}, {["x"] = 14, ["y"] = 11, ["z"] = 38, ["name"] = "mesecons_lightstone:lightstone_gray_off"}, {["x"] = 14, ["y"] = 11, ["z"] = 39, ["name"] = "mesecons_lightstone:lightstone_gray_off"}, {["x"] = 14, ["y"] = 11, ["z"] = 40, ["name"] = "mesecons_lightstone:lightstone_gray_off"}, {["x"] = 14, ["y"] = 11, ["z"] = 41, ["name"] = "mesecons_lightstone:lightstone_gray_off"}, {["x"] = 14, ["y"] = 11, ["z"] = 42, ["name"] = "mesecons_lightstone:lightstone_gray_off"}, {["x"] = 14, ["y"] = 11, ["z"] = 43, ["name"] = "mesecons_lightstone:lightstone_gray_off"}, {["x"] = 14, ["y"] = 11, ["z"] = 44, ["name"] = "mesecons_lightstone:lightstone_gray_off"}, {["x"] = 14, ["y"] = 11, ["z"] = 45, ["name"] = "mesecons_lightstone:lightstone_gray_off"}, {["x"] = 14, ["y"] = 11, ["z"] = 46, ["name"] = "mesecons_lightstone:lightstone_gray_off"}, {["x"] = 14, ["y"] = 11, ["z"] = 47, ["name"] = "mesecons_lightstone:lightstone_gray_off"}, {["x"] = 14, ["y"] = 11, ["z"] = 48, ["name"] = "mesecons_lightstone:lightstone_gray_off"}, {["x"] = 14, ["y"] = 11, ["z"] = 49, ["name"] = "mesecons_lightstone:lightstone_gray_off"}, {["x"] = 14, ["y"] = 11, ["z"] = 50, ["name"] = "mesecons_lightstone:lightstone_gray_off"}, {["x"] = 14, ["y"] = 11, ["z"] = 51, ["name"] = "wool:dark_grey"}, {["x"] = 14, ["y"] = 11, ["z"] = 52, ["name"] = "wool:black"}, {["x"] = 14, ["y"] = 11, ["z"] = 53, ["name"] = "wool:black"}, {["x"] = 14, ["y"] = 11, ["z"] = 54, ["name"] = "wool:black"}, {["x"] = 14, ["y"] = 11, ["z"] = 55, ["name"] = "wool:black"}, {["x"] = 14, ["y"] = 11, ["z"] = 56, ["name"] = "wool:black"}, {["x"] = 15, ["y"] = 5, ["z"] = 28, ["name"] = "wool:black"}, {["x"] = 15, ["y"] = 5, ["z"] = 29, ["name"] = "wool:black"}, {["x"] = 15, ["y"] = 5, ["z"] = 30, ["name"] = "wool:black"}, {["x"] = 15, ["y"] = 5, ["z"] = 31, ["name"] = "wool:black"}, {["x"] = 15, ["y"] = 5, ["z"] = 32, ["name"] = "wool:black"}, {["x"] = 15, ["y"] = 5, ["z"] = 33, ["name"] = "mesecons_lightstone:lightstone_white_off"}, {["x"] = 15, ["y"] = 5, ["z"] = 34, ["name"] = "moreblocks:copperpatina"}, {["x"] = 15, ["y"] = 5, ["z"] = 35, ["name"] = "mesecons_lightstone:lightstone_white_off"}, {["x"] = 15, ["y"] = 5, ["z"] = 36, ["name"] = "mesecons_lightstone:lightstone_white_off"}, {["x"] = 15, ["y"] = 5, ["z"] = 37, ["name"] = "mesecons_lightstone:lightstone_white_off"}, {["x"] = 15, ["y"] = 5, ["z"] = 38, ["name"] = "mesecons_lightstone:lightstone_white_off"}, {["x"] = 15, ["y"] = 5, ["z"] = 39, ["name"] = "mesecons_lightstone:lightstone_white_off"}, {["x"] = 15, ["y"] = 5, ["z"] = 40, ["name"] = "mesecons_lightstone:lightstone_white_off"}, {["x"] = 15, ["y"] = 5, ["z"] = 41, ["name"] = "mesecons_lightstone:lightstone_white_off"}, {["x"] = 15, ["y"] = 5, ["z"] = 42, ["name"] = "mesecons_lightstone:lightstone_white_off"}, {["x"] = 15, ["y"] = 5, ["z"] = 43, ["name"] = "mesecons_lightstone:lightstone_white_off"}, {["x"] = 15, ["y"] = 5, ["z"] = 44, ["name"] = "mesecons_lightstone:lightstone_white_off"}, {["x"] = 15, ["y"] = 5, ["z"] = 45, ["name"] = "mesecons_lightstone:lightstone_white_off"}, {["x"] = 15, ["y"] = 5, ["z"] = 46, ["name"] = "mesecons_lightstone:lightstone_white_off"}, {["x"] = 15, ["y"] = 5, ["z"] = 47, ["name"] = "mesecons_lightstone:lightstone_white_off"}, {["x"] = 15, ["y"] = 5, ["z"] = 48, ["name"] = "mesecons_lightstone:lightstone_white_off"}, {["x"] = 15, ["y"] = 5, ["z"] = 49, ["name"] = "mesecons_lightstone:lightstone_white_off"}, {["x"] = 15, ["y"] = 5, ["z"] = 50, ["name"] = "moreblocks:copperpatina"}, {["x"] = 15, ["y"] = 5, ["z"] = 51, ["name"] = "mesecons_lightstone:lightstone_white_off"}, {["x"] = 15, ["y"] = 5, ["z"] = 52, ["name"] = "wool:black"}, {["x"] = 15, ["y"] = 5, ["z"] = 53, ["name"] = "wool:black"}, {["x"] = 15, ["y"] = 5, ["z"] = 54, ["name"] = "wool:black"}, {["x"] = 15, ["y"] = 5, ["z"] = 55, ["name"] = "wool:black"}, {["x"] = 15, ["y"] = 5, ["z"] = 56, ["name"] = "wool:black"}, {["x"] = 15, ["y"] = 6, ["z"] = 28, ["name"] = "wool:black"}, {["x"] = 15, ["y"] = 6, ["z"] = 32, ["name"] = "wool:dark_grey"}, {["x"] = 15, ["y"] = 6, ["z"] = 34, ["name"] = "default:tinblock"}, {["x"] = 15, ["y"] = 6, ["z"] = 50, ["name"] = "default:tinblock"}, {["x"] = 15, ["y"] = 6, ["z"] = 52, ["name"] = "wool:dark_grey"}, {["x"] = 15, ["y"] = 6, ["z"] = 56, ["name"] = "wool:black"}, {["x"] = 15, ["y"] = 7, ["z"] = 28, ["name"] = "wool:black"}, {["x"] = 15, ["y"] = 7, ["z"] = 32, ["name"] = "mesecons_lightstone:lightstone_gray_off"}, {["x"] = 15, ["y"] = 7, ["z"] = 52, ["name"] = "mesecons_lightstone:lightstone_gray_off"}, {["x"] = 15, ["y"] = 7, ["z"] = 56, ["name"] = "wool:black"}, {["x"] = 15, ["y"] = 8, ["z"] = 28, ["name"] = "wool:black"}, {["x"] = 15, ["y"] = 8, ["z"] = 32, ["name"] = "mesecons_lightstone:lightstone_gray_off"}, {["x"] = 15, ["y"] = 8, ["z"] = 52, ["name"] = "mesecons_lightstone:lightstone_gray_off"}, {["x"] = 15, ["y"] = 8, ["z"] = 56, ["name"] = "wool:black"}, {["x"] = 15, ["y"] = 9, ["z"] = 28, ["name"] = "wool:black"}, {["x"] = 15, ["y"] = 9, ["z"] = 32, ["name"] = "mesecons_lightstone:lightstone_gray_off"}, {["x"] = 15, ["y"] = 9, ["z"] = 52, ["name"] = "mesecons_lightstone:lightstone_gray_off"}, {["x"] = 15, ["y"] = 9, ["z"] = 56, ["name"] = "wool:black"}, {["x"] = 15, ["y"] = 10, ["z"] = 28, ["name"] = "wool:black"}, {["x"] = 15, ["y"] = 10, ["z"] = 32, ["name"] = "wool:dark_grey"}, {["x"] = 15, ["y"] = 10, ["param1"] = 238, ["z"] = 42, ["name"] = "morelights_modern:ceilinglight"}, {["x"] = 15, ["y"] = 10, ["z"] = 52, ["name"] = "wool:dark_grey"}, {["x"] = 15, ["y"] = 10, ["z"] = 56, ["name"] = "wool:black"}, {["x"] = 15, ["y"] = 11, ["z"] = 28, ["name"] = "wool:black"}, {["x"] = 15, ["y"] = 11, ["z"] = 29, ["name"] = "wool:black"}, {["x"] = 15, ["y"] = 11, ["z"] = 30, ["name"] = "wool:black"}, {["x"] = 15, ["y"] = 11, ["z"] = 31, ["name"] = "wool:black"}, {["x"] = 15, ["y"] = 11, ["z"] = 32, ["name"] = "wool:dark_grey"}, {["x"] = 15, ["y"] = 11, ["z"] = 33, ["name"] = "mesecons_lightstone:lightstone_gray_off"}, {["x"] = 15, ["y"] = 11, ["z"] = 34, ["name"] = "mesecons_lightstone:lightstone_gray_off"}, {["x"] = 15, ["y"] = 11, ["z"] = 35, ["name"] = "mesecons_lightstone:lightstone_gray_off"}, {["x"] = 15, ["y"] = 11, ["z"] = 36, ["name"] = "mesecons_lightstone:lightstone_gray_off"}, {["x"] = 15, ["y"] = 11, ["z"] = 37, ["name"] = "mesecons_lightstone:lightstone_gray_off"}, {["x"] = 15, ["y"] = 11, ["z"] = 38, ["name"] = "mesecons_lightstone:lightstone_gray_off"}, {["x"] = 15, ["y"] = 11, ["z"] = 39, ["name"] = "mesecons_lightstone:lightstone_gray_off"}, {["x"] = 15, ["y"] = 11, ["z"] = 40, ["name"] = "mesecons_lightstone:lightstone_gray_off"}, {["x"] = 15, ["y"] = 11, ["z"] = 41, ["name"] = "mesecons_lightstone:lightstone_gray_off"}, {["x"] = 15, ["y"] = 11, ["z"] = 42, ["name"] = "mesecons_lightstone:lightstone_gray_off"}, {["x"] = 15, ["y"] = 11, ["z"] = 43, ["name"] = "mesecons_lightstone:lightstone_gray_off"}, {["x"] = 15, ["y"] = 11, ["z"] = 44, ["name"] = "mesecons_lightstone:lightstone_gray_off"}, {["x"] = 15, ["y"] = 11, ["z"] = 45, ["name"] = "mesecons_lightstone:lightstone_gray_off"}, {["x"] = 15, ["y"] = 11, ["z"] = 46, ["name"] = "mesecons_lightstone:lightstone_gray_off"}, {["x"] = 15, ["y"] = 11, ["z"] = 47, ["name"] = "mesecons_lightstone:lightstone_gray_off"}, {["x"] = 15, ["y"] = 11, ["z"] = 48, ["name"] = "mesecons_lightstone:lightstone_gray_off"}, {["x"] = 15, ["y"] = 11, ["z"] = 49, ["name"] = "mesecons_lightstone:lightstone_gray_off"}, {["x"] = 15, ["y"] = 11, ["z"] = 50, ["name"] = "mesecons_lightstone:lightstone_gray_off"}, {["x"] = 15, ["y"] = 11, ["z"] = 51, ["name"] = "mesecons_lightstone:lightstone_gray_off"}, {["x"] = 15, ["y"] = 11, ["z"] = 52, ["name"] = "wool:dark_grey"}, {["x"] = 15, ["y"] = 11, ["z"] = 53, ["name"] = "wool:black"}, {["x"] = 15, ["y"] = 11, ["z"] = 54, ["name"] = "wool:black"}, {["x"] = 15, ["y"] = 11, ["z"] = 55, ["name"] = "wool:black"}, {["x"] = 15, ["y"] = 11, ["z"] = 56, ["name"] = "wool:black"}, {["x"] = 16, ["y"] = 5, ["z"] = 28, ["name"] = "wool:black"}, {["x"] = 16, ["y"] = 5, ["z"] = 29, ["name"] = "wool:black"}, {["x"] = 16, ["y"] = 5, ["z"] = 30, ["name"] = "wool:black"}, {["x"] = 16, ["y"] = 5, ["z"] = 31, ["name"] = "wool:black"}, {["x"] = 16, ["y"] = 5, ["z"] = 32, ["name"] = "wool:black"}, {["x"] = 16, ["y"] = 5, ["z"] = 33, ["name"] = "mesecons_lightstone:lightstone_white_off"}, {["x"] = 16, ["y"] = 5, ["z"] = 34, ["name"] = "mesecons_lightstone:lightstone_white_off"}, {["x"] = 16, ["y"] = 5, ["z"] = 35, ["name"] = "mesecons_lightstone:lightstone_white_off"}, {["x"] = 16, ["y"] = 5, ["z"] = 36, ["name"] = "mesecons_lightstone:lightstone_white_off"}, {["x"] = 16, ["y"] = 5, ["z"] = 37, ["name"] = "mesecons_lightstone:lightstone_white_off"}, {["x"] = 16, ["y"] = 5, ["z"] = 38, ["name"] = "mesecons_lightstone:lightstone_white_off"}, {["x"] = 16, ["y"] = 5, ["z"] = 39, ["name"] = "mesecons_lightstone:lightstone_white_off"}, {["x"] = 16, ["y"] = 5, ["z"] = 40, ["name"] = "mesecons_lightstone:lightstone_white_off"}, {["x"] = 16, ["y"] = 5, ["z"] = 41, ["name"] = "mesecons_lightstone:lightstone_white_off"}, {["x"] = 16, ["y"] = 5, ["z"] = 42, ["name"] = "mesecons_lightstone:lightstone_white_off"}, {["x"] = 16, ["y"] = 5, ["z"] = 43, ["name"] = "mesecons_lightstone:lightstone_white_off"}, {["x"] = 16, ["y"] = 5, ["z"] = 44, ["name"] = "mesecons_lightstone:lightstone_white_off"}, {["x"] = 16, ["y"] = 5, ["z"] = 45, ["name"] = "mesecons_lightstone:lightstone_white_off"}, {["x"] = 16, ["y"] = 5, ["z"] = 46, ["name"] = "mesecons_lightstone:lightstone_white_off"}, {["x"] = 16, ["y"] = 5, ["z"] = 47, ["name"] = "mesecons_lightstone:lightstone_white_off"}, {["x"] = 16, ["y"] = 5, ["z"] = 48, ["name"] = "mesecons_lightstone:lightstone_white_off"}, {["x"] = 16, ["y"] = 5, ["z"] = 49, ["name"] = "mesecons_lightstone:lightstone_white_off"}, {["x"] = 16, ["y"] = 5, ["z"] = 50, ["name"] = "mesecons_lightstone:lightstone_white_off"}, {["x"] = 16, ["y"] = 5, ["z"] = 51, ["name"] = "mesecons_lightstone:lightstone_white_off"}, {["x"] = 16, ["y"] = 5, ["z"] = 52, ["name"] = "wool:black"}, {["x"] = 16, ["y"] = 5, ["z"] = 53, ["name"] = "wool:black"}, {["x"] = 16, ["y"] = 5, ["z"] = 54, ["name"] = "wool:black"}, {["x"] = 16, ["y"] = 5, ["z"] = 55, ["name"] = "wool:black"}, {["x"] = 16, ["y"] = 5, ["z"] = 56, ["name"] = "wool:black"}, {["x"] = 16, ["y"] = 6, ["z"] = 28, ["name"] = "wool:black"}, {["x"] = 16, ["y"] = 6, ["z"] = 29, ["name"] = "wool:black"}, {["x"] = 16, ["y"] = 6, ["z"] = 30, ["name"] = "wool:black"}, {["x"] = 16, ["y"] = 6, ["z"] = 31, ["name"] = "wool:black"}, {["x"] = 16, ["y"] = 6, ["z"] = 32, ["name"] = "wool:dark_grey"}, {["x"] = 16, ["y"] = 6, ["z"] = 52, ["name"] = "wool:dark_grey"}, {["x"] = 16, ["y"] = 6, ["z"] = 53, ["name"] = "wool:black"}, {["x"] = 16, ["y"] = 6, ["z"] = 54, ["name"] = "wool:black"}, {["x"] = 16, ["y"] = 6, ["z"] = 55, ["name"] = "wool:black"}, {["x"] = 16, ["y"] = 6, ["z"] = 56, ["name"] = "wool:black"}, {["x"] = 16, ["y"] = 7, ["z"] = 28, ["name"] = "wool:black"}, {["x"] = 16, ["y"] = 7, ["z"] = 29, ["name"] = "wool:black"}, {["x"] = 16, ["y"] = 7, ["z"] = 30, ["name"] = "wool:black"}, {["x"] = 16, ["y"] = 7, ["z"] = 31, ["name"] = "wool:black"}, {["x"] = 16, ["meta"] = {["fields"] = {["infotext"] = "Bell Sprint", ["laptop_appdata"] = "return {[\"os\"] = {[\"theme\"] = \"Snow Pines\"}, [\"stickynote:files\"] = {[\"NAV_INFO\"] = {[\"owner\"] = \"singleplayer\", [\"content\"] = \"NAV_DATA GOOD\\\
NAV_COURSE GOOD\", [\"ctime\"] = 1606470059}}, [\"stickynote\"] = {[\"selected_file_name\"] = \"NAV_INFO\", [\"fileslist_sorted\"] = {}, [\"selected_disk_name\"] = \"removable\", [\"files\"] = {}, [\"text\"] = \"NAV_DATA GOOD\\\
NAV_COURSE GOOD\"}}", ["laptop_ram"] = "return {[\"os\"] = {[\"booted_from\"] = \"hdd\", [\"current_player\"] = \"dove1234\", [\"stack\"] = {}, [\"app_timer\"] = {}, [\"last_player\"] = \"dove1234\", [\"current_app\"] = \"launcher\"}, [\"os:select_file\"] = {}, [\"realchess\"] = {[\"castlingBlackL\"] = 1, [\"winner\"] = \"\", [\"lastMove\"] = \"white\", [\"castlingWhiteR\"] = 1, [\"castlingBlackR\"] = 1, [\"playerWhite\"] = \"dove1234\", [\"messageOther\"] = \"[!] You can't reset the chessboard, a game has been started.\\\
If you are not a current player, try again in 4 min. 57 sec.\", [\"init_done\"] = true, [\"castlingWhiteL\"] = 1, [\"lastMoveTime\"] = 85288, [\"playerBlack\"] = \"dove1234\"}}", ["formspec"] = "size[15,10]background[15,10;0,0;laptop_theme_snowpines_desktop_background.png;true]image_button[1,1;1,1;blank.png^laptop_browser.png;browser;\27(c@#000000)\27(c@#ffffff)]tooltip[browser;Web Browser]image_button[0.5,2.08;2,.5;laptop_theme_desktop_icon_label_button_black.png;browser;\27(c@#FFFFFF)MineBrowse\27(c@#ffffff)]image_button[1,3;1,1;blank.png^laptop_calculator.png;calculator;\27(c@#000000)\27(c@#ffffff)]tooltip[calculator;Perform Mathematical Calculations]image_button[0.5,4.08;2,.5;laptop_theme_desktop_icon_label_button_black.png;calculator;\27(c@#FFFFFF)Calculator\27(c@#ffffff)]image_button[1,5;1,1;blank.png^laptop_cs_bos.png;cs-bos_launcher;\27(c@#000000)\27(c@#ffffff)]tooltip[cs-bos_launcher;Command Line Interface]image_button[0.5,6.08;2,.5;laptop_theme_desktop_icon_label_button_black.png;cs-bos_launcher;\27(c@#FFFFFF)CS-BOS Prompt\27(c@#ffffff)]image_button[1,7;1,1;blank.png^laptop_setting_wrench.png;launcher_settings;\27(c@#000000)\27(c@#ffffff)]tooltip[launcher_settings;Desktop settings.]image_button[0.5,8.08;2,.5;laptop_theme_desktop_icon_label_button_black.png;launcher_settings;\27(c@#FFFFFF)Settings\27(c@#ffffff)]image_button[3,1;1,1;blank.png^laptop_email_letter.png;mail;\27(c@#000000)\27(c@#ffffff)]tooltip[mail;Send Electronic Mail]image_button[2.5,2.08;2,.5;laptop_theme_desktop_icon_label_button_black.png;mail;\27(c@#FFFFFF)Mail\27(c@#ffffff)]image_button[3,3;1,1;blank.png^laptop_realchess_chessboard_icon.png;realchess;\27(c@#000000)\27(c@#ffffff)]tooltip[realchess;A Chess game]image_button[2.5,4.08;2,.5;laptop_theme_desktop_icon_label_button_black.png;realchess;\27(c@#FFFFFF)Realchess\27(c@#ffffff)]image_button[3,5;1,1;blank.png^laptop_removable.png;removable;\27(c@#000000)\27(c@#ffffff)]tooltip[removable;Interface with Removable Media]image_button[2.5,6.08;2,.5;laptop_theme_desktop_icon_label_button_black.png;removable;\27(c@#FFFFFF)Removable Storage\27(c@#ffffff)]image_button[3,7;1,1;blank.png^laptop_notes_pad.png;stickynote;\27(c@#000000)\27(c@#ffffff)]tooltip[stickynote;Write Text Documents]image_button[2.5,8.08;2,.5;laptop_theme_desktop_icon_label_button_black.png;stickynote;\27(c@#FFFFFF)Notepad\27(c@#ffffff)]image_button[5,1;1,1;blank.png^laptop_tetris_icon.png;tetris;\27(c@#000000)\27(c@#ffffff)]tooltip[tetris;Falling Tile Game]image_button[4.5,2.08;2,.5;laptop_theme_desktop_icon_label_button_black.png;tetris;\27(c@#FFFFFF)Tetris\27(c@#ffffff)]image_button[5,3;1,1;blank.png^laptop_tnt.png;tntsweeper;\27(c@#000000)\27(c@#ffffff)]tooltip[tntsweeper;Avoid hitting TNT]image_button[4.5,4.08;2,.5;laptop_theme_desktop_icon_label_button_black.png;tntsweeper;\27(c@#FFFFFF)TNT Sweeper\27(c@#ffffff)]image_button[5.5,-.31;4,0.7;laptop_theme_snowpines_major_button.png;os_clock;\27(c@#FFFFFF)1/21/2021 6:13:33 PM\27(c@#ffffff)]"}, ["inventory"] = {["main"] = {""}, ["board"] = {"laptop:realchess_rook_black_1", "laptop:realchess_knight_black_1", "laptop:realchess_bishop_black_1", "laptop:realchess_queen_black", "laptop:realchess_king_black", "laptop:realchess_bishop_black_2", "laptop:realchess_knight_black_2", "laptop:realchess_rook_black_2", "laptop:realchess_pawn_black_1", "laptop:realchess_pawn_black_2", "laptop:realchess_pawn_black_3", "laptop:realchess_pawn_black_4", "laptop:realchess_pawn_black_5", "laptop:realchess_pawn_black_6", "laptop:realchess_pawn_black_7", "", "", "", "", "", "", "", "", "laptop:realchess_pawn_black_8", "", "", "", "", "", "", "", "", "", "", "", "", "", "", "", "", "", "", "", "", "", "", "", "laptop:realchess_pawn_white_8", "laptop:realchess_pawn_white_1", "laptop:realchess_pawn_white_2", "laptop:realchess_pawn_white_3", "laptop:realchess_pawn_white_4", "laptop:realchess_pawn_white_5", "laptop:realchess_pawn_white_6", "laptop:realchess_pawn_white_7", "", "laptop:realchess_rook_white_1", "laptop:realchess_knight_white_1", "laptop:realchess_bishop_white_1", "laptop:realchess_queen_white", "laptop:realchess_king_white", "laptop:realchess_bishop_white_2", "laptop:realchess_knight_white_2", "laptop:realchess_rook_white_2"}}}, ["param2"] = 2, ["y"] = 7, ["param1"] = 85, ["z"] = 32, ["name"] = "laptop_extend_pack_2:bell_sprint_on"}, {["x"] = 16, ["y"] = 7, ["z"] = 52, ["name"] = "mesecons_lightstone:lightstone_gray_off"}, {["x"] = 16, ["y"] = 7, ["z"] = 53, ["name"] = "wool:black"}, {["x"] = 16, ["y"] = 7, ["z"] = 54, ["name"] = "wool:black"}, {["x"] = 16, ["y"] = 7, ["z"] = 55, ["name"] = "wool:black"}, {["x"] = 16, ["y"] = 7, ["z"] = 56, ["name"] = "wool:black"}, {["x"] = 16, ["y"] = 8, ["z"] = 28, ["name"] = "wool:black"}, {["x"] = 16, ["y"] = 8, ["z"] = 29, ["name"] = "wool:black"}, {["x"] = 16, ["y"] = 8, ["z"] = 30, ["name"] = "wool:black"}, {["x"] = 16, ["y"] = 8, ["z"] = 31, ["name"] = "wool:black"}, {["x"] = 16, ["y"] = 8, ["z"] = 32, ["name"] = "mesecons_lightstone:lightstone_gray_off"}, {["x"] = 16, ["y"] = 8, ["z"] = 52, ["name"] = "mesecons_lightstone:lightstone_gray_off"}, {["x"] = 16, ["y"] = 8, ["z"] = 53, ["name"] = "wool:black"}, {["x"] = 16, ["y"] = 8, ["z"] = 54, ["name"] = "wool:black"}, {["x"] = 16, ["y"] = 8, ["z"] = 55, ["name"] = "wool:black"}, {["x"] = 16, ["y"] = 8, ["z"] = 56, ["name"] = "wool:black"}, {["x"] = 16, ["y"] = 9, ["z"] = 28, ["name"] = "wool:black"}, {["x"] = 16, ["y"] = 9, ["z"] = 29, ["name"] = "wool:black"}, {["x"] = 16, ["y"] = 9, ["z"] = 30, ["name"] = "wool:black"}, {["x"] = 16, ["y"] = 9, ["z"] = 31, ["name"] = "wool:black"}, {["x"] = 16, ["y"] = 9, ["z"] = 32, ["name"] = "mesecons_lightstone:lightstone_gray_off"}, {["x"] = 16, ["y"] = 9, ["z"] = 52, ["name"] = "mesecons_lightstone:lightstone_gray_off"}, {["x"] = 16, ["y"] = 9, ["z"] = 53, ["name"] = "wool:black"}, {["x"] = 16, ["y"] = 9, ["z"] = 54, ["name"] = "wool:black"}, {["x"] = 16, ["y"] = 9, ["z"] = 55, ["name"] = "wool:black"}, {["x"] = 16, ["y"] = 9, ["z"] = 56, ["name"] = "wool:black"}, {["x"] = 16, ["y"] = 10, ["z"] = 28, ["name"] = "wool:black"}, {["x"] = 16, ["y"] = 10, ["z"] = 29, ["name"] = "wool:black"}, {["x"] = 16, ["y"] = 10, ["z"] = 30, ["name"] = "wool:black"}, {["x"] = 16, ["y"] = 10, ["z"] = 31, ["name"] = "wool:black"}, {["x"] = 16, ["y"] = 10, ["z"] = 32, ["name"] = "wool:dark_grey"}, {["x"] = 16, ["y"] = 10, ["param1"] = 238, ["z"] = 42, ["name"] = "morelights_modern:ceilinglight"}, {["x"] = 16, ["y"] = 10, ["z"] = 52, ["name"] = "wool:dark_grey"}, {["x"] = 16, ["y"] = 10, ["z"] = 53, ["name"] = "wool:black"}, {["x"] = 16, ["y"] = 10, ["z"] = 54, ["name"] = "wool:black"}, {["x"] = 16, ["y"] = 10, ["z"] = 55, ["name"] = "wool:black"}, {["x"] = 16, ["y"] = 10, ["z"] = 56, ["name"] = "wool:black"}, {["x"] = 16, ["y"] = 11, ["z"] = 28, ["name"] = "wool:black"}, {["x"] = 16, ["y"] = 11, ["z"] = 29, ["name"] = "wool:black"}, {["x"] = 16, ["y"] = 11, ["z"] = 30, ["name"] = "wool:black"}, {["x"] = 16, ["y"] = 11, ["z"] = 31, ["name"] = "wool:black"}, {["x"] = 16, ["y"] = 11, ["z"] = 32, ["name"] = "wool:dark_grey"}, {["x"] = 16, ["y"] = 11, ["z"] = 33, ["name"] = "mesecons_lightstone:lightstone_gray_off"}, {["x"] = 16, ["y"] = 11, ["z"] = 34, ["name"] = "mesecons_lightstone:lightstone_gray_off"}, {["x"] = 16, ["y"] = 11, ["z"] = 35, ["name"] = "mesecons_lightstone:lightstone_gray_off"}, {["x"] = 16, ["y"] = 11, ["z"] = 36, ["name"] = "mesecons_lightstone:lightstone_gray_off"}, {["x"] = 16, ["y"] = 11, ["z"] = 37, ["name"] = "mesecons_lightstone:lightstone_gray_off"}, {["x"] = 16, ["y"] = 11, ["z"] = 38, ["name"] = "mesecons_lightstone:lightstone_gray_off"}, {["x"] = 16, ["y"] = 11, ["z"] = 39, ["name"] = "mesecons_lightstone:lightstone_gray_off"}, {["x"] = 16, ["y"] = 11, ["z"] = 40, ["name"] = "mesecons_lightstone:lightstone_gray_off"}, {["x"] = 16, ["y"] = 11, ["z"] = 41, ["name"] = "mesecons_lightstone:lightstone_gray_off"}, {["x"] = 16, ["y"] = 11, ["z"] = 42, ["name"] = "mesecons_lightstone:lightstone_gray_off"}, {["x"] = 16, ["y"] = 11, ["z"] = 43, ["name"] = "mesecons_lightstone:lightstone_gray_off"}, {["x"] = 16, ["y"] = 11, ["z"] = 44, ["name"] = "mesecons_lightstone:lightstone_gray_off"}, {["x"] = 16, ["y"] = 11, ["z"] = 45, ["name"] = "mesecons_lightstone:lightstone_gray_off"}, {["x"] = 16, ["y"] = 11, ["z"] = 46, ["name"] = "mesecons_lightstone:lightstone_gray_off"}, {["x"] = 16, ["y"] = 11, ["z"] = 47, ["name"] = "mesecons_lightstone:lightstone_gray_off"}, {["x"] = 16, ["y"] = 11, ["z"] = 48, ["name"] = "mesecons_lightstone:lightstone_gray_off"}, {["x"] = 16, ["y"] = 11, ["z"] = 49, ["name"] = "mesecons_lightstone:lightstone_gray_off"}, {["x"] = 16, ["y"] = 11, ["z"] = 50, ["name"] = "mesecons_lightstone:lightstone_gray_off"}, {["x"] = 16, ["y"] = 11, ["z"] = 51, ["name"] = "mesecons_lightstone:lightstone_gray_off"}, {["x"] = 16, ["y"] = 11, ["z"] = 52, ["name"] = "wool:dark_grey"}, {["x"] = 16, ["y"] = 11, ["z"] = 53, ["name"] = "wool:black"}, {["x"] = 16, ["y"] = 11, ["z"] = 54, ["name"] = "wool:black"}, {["x"] = 16, ["y"] = 11, ["z"] = 55, ["name"] = "wool:black"}, {["x"] = 16, ["y"] = 11, ["z"] = 56, ["name"] = "wool:black"}, {["x"] = 17, ["y"] = 5, ["z"] = 33, ["name"] = "mesecons_lightstone:lightstone_white_off"}, {["x"] = 17, ["y"] = 5, ["z"] = 34, ["name"] = "mesecons_lightstone:lightstone_white_off"}, {["x"] = 17, ["y"] = 5, ["z"] = 35, ["name"] = "mesecons_lightstone:lightstone_white_off"}, {["x"] = 17, ["y"] = 5, ["z"] = 36, ["name"] = "mesecons_lightstone:lightstone_white_off"}, {["x"] = 17, ["y"] = 5, ["z"] = 37, ["name"] = "mesecons_lightstone:lightstone_white_off"}, {["x"] = 17, ["y"] = 5, ["z"] = 38, ["name"] = "mesecons_lightstone:lightstone_white_off"}, {["x"] = 17, ["y"] = 5, ["z"] = 39, ["name"] = "mesecons_lightstone:lightstone_white_off"}, {["x"] = 17, ["y"] = 5, ["z"] = 40, ["name"] = "mesecons_lightstone:lightstone_white_off"}, {["x"] = 17, ["y"] = 5, ["z"] = 41, ["name"] = "mesecons_lightstone:lightstone_white_off"}, {["x"] = 17, ["y"] = 5, ["z"] = 42, ["name"] = "mesecons_lightstone:lightstone_blue_off"}, {["x"] = 17, ["y"] = 5, ["z"] = 43, ["name"] = "mesecons_lightstone:lightstone_white_off"}, {["x"] = 17, ["y"] = 5, ["z"] = 44, ["name"] = "mesecons_lightstone:lightstone_white_off"}, {["x"] = 17, ["y"] = 5, ["z"] = 45, ["name"] = "mesecons_lightstone:lightstone_white_off"}, {["x"] = 17, ["y"] = 5, ["z"] = 46, ["name"] = "mesecons_lightstone:lightstone_white_off"}, {["x"] = 17, ["y"] = 5, ["z"] = 47, ["name"] = "mesecons_lightstone:lightstone_white_off"}, {["x"] = 17, ["y"] = 5, ["z"] = 48, ["name"] = "mesecons_lightstone:lightstone_white_off"}, {["x"] = 17, ["y"] = 5, ["z"] = 49, ["name"] = "mesecons_lightstone:lightstone_white_off"}, {["x"] = 17, ["y"] = 5, ["z"] = 50, ["name"] = "mesecons_lightstone:lightstone_white_off"}, {["x"] = 17, ["y"] = 5, ["z"] = 51, ["name"] = "mesecons_lightstone:lightstone_white_off"}, {["x"] = 17, ["y"] = 6, ["z"] = 32, ["name"] = "wool:dark_grey"}, {["x"] = 17, ["y"] = 6, ["z"] = 52, ["name"] = "wool:dark_grey"}, {["x"] = 17, ["y"] = 7, ["z"] = 32, ["name"] = "mesecons_lightstone:lightstone_gray_off"}, {["x"] = 17, ["y"] = 7, ["z"] = 52, ["name"] = "mesecons_lightstone:lightstone_gray_off"}, {["x"] = 17, ["y"] = 8, ["z"] = 32, ["name"] = "mesecons_lightstone:lightstone_gray_off"}, {["x"] = 17, ["y"] = 8, ["z"] = 52, ["name"] = "mesecons_lightstone:lightstone_gray_off"}, {["x"] = 17, ["y"] = 9, ["z"] = 32, ["name"] = "mesecons_lightstone:lightstone_gray_off"}, {["x"] = 17, ["y"] = 9, ["z"] = 52, ["name"] = "mesecons_lightstone:lightstone_gray_off"}, {["x"] = 17, ["y"] = 10, ["z"] = 32, ["name"] = "wool:dark_grey"}, {["x"] = 17, ["y"] = 10, ["param1"] = 238, ["z"] = 37, ["name"] = "morelights_modern:ceilinglight"}, {["x"] = 17, ["y"] = 10, ["param1"] = 238, ["z"] = 38, ["name"] = "morelights_modern:ceilinglight"}, {["x"] = 17, ["y"] = 10, ["param1"] = 238, ["z"] = 39, ["name"] = "morelights_modern:ceilinglight"}, {["x"] = 17, ["y"] = 10, ["param1"] = 238, ["z"] = 40, ["name"] = "morelights_modern:ceilinglight"}, {["x"] = 17, ["y"] = 10, ["param1"] = 238, ["z"] = 41, ["name"] = "morelights_modern:ceilinglight"}, {["x"] = 17, ["y"] = 10, ["param1"] = 238, ["z"] = 42, ["name"] = "morelights_modern:ceilinglight"}, {["x"] = 17, ["y"] = 10, ["param1"] = 238, ["z"] = 43, ["name"] = "morelights_modern:ceilinglight"}, {["x"] = 17, ["y"] = 10, ["param1"] = 238, ["z"] = 44, ["name"] = "morelights_modern:ceilinglight"}, {["x"] = 17, ["y"] = 10, ["param1"] = 238, ["z"] = 45, ["name"] = "morelights_modern:ceilinglight"}, {["x"] = 17, ["y"] = 10, ["param1"] = 238, ["z"] = 46, ["name"] = "morelights_modern:ceilinglight"}, {["x"] = 17, ["y"] = 10, ["param1"] = 238, ["z"] = 47, ["name"] = "morelights_modern:ceilinglight"}, {["x"] = 17, ["y"] = 10, ["param1"] = 238, ["z"] = 48, ["name"] = "morelights_modern:ceilinglight"}, {["x"] = 17, ["y"] = 10, ["z"] = 52, ["name"] = "wool:dark_grey"}, {["x"] = 17, ["y"] = 11, ["z"] = 32, ["name"] = "wool:dark_grey"}, {["x"] = 17, ["y"] = 11, ["z"] = 33, ["name"] = "mesecons_lightstone:lightstone_gray_off"}, {["x"] = 17, ["y"] = 11, ["z"] = 34, ["name"] = "mesecons_lightstone:lightstone_gray_off"}, {["x"] = 17, ["y"] = 11, ["z"] = 35, ["name"] = "mesecons_lightstone:lightstone_gray_off"}, {["x"] = 17, ["y"] = 11, ["z"] = 36, ["name"] = "mesecons_lightstone:lightstone_gray_off"}, {["x"] = 17, ["y"] = 11, ["z"] = 37, ["name"] = "mesecons_lightstone:lightstone_gray_off"}, {["x"] = 17, ["y"] = 11, ["z"] = 38, ["name"] = "mesecons_lightstone:lightstone_gray_off"}, {["x"] = 17, ["y"] = 11, ["z"] = 39, ["name"] = "mesecons_lightstone:lightstone_gray_off"}, {["x"] = 17, ["y"] = 11, ["z"] = 40, ["name"] = "mesecons_lightstone:lightstone_gray_off"}, {["x"] = 17, ["y"] = 11, ["z"] = 41, ["name"] = "mesecons_lightstone:lightstone_gray_off"}, {["x"] = 17, ["y"] = 11, ["z"] = 42, ["name"] = "mesecons_lightstone:lightstone_gray_off"}, {["x"] = 17, ["y"] = 11, ["z"] = 43, ["name"] = "mesecons_lightstone:lightstone_gray_off"}, {["x"] = 17, ["y"] = 11, ["z"] = 44, ["name"] = "mesecons_lightstone:lightstone_gray_off"}, {["x"] = 17, ["y"] = 11, ["z"] = 45, ["name"] = "mesecons_lightstone:lightstone_gray_off"}, {["x"] = 17, ["y"] = 11, ["z"] = 46, ["name"] = "mesecons_lightstone:lightstone_gray_off"}, {["x"] = 17, ["y"] = 11, ["z"] = 47, ["name"] = "mesecons_lightstone:lightstone_gray_off"}, {["x"] = 17, ["y"] = 11, ["z"] = 48, ["name"] = "mesecons_lightstone:lightstone_gray_off"}, {["x"] = 17, ["y"] = 11, ["z"] = 49, ["name"] = "mesecons_lightstone:lightstone_gray_off"}, {["x"] = 17, ["y"] = 11, ["z"] = 50, ["name"] = "mesecons_lightstone:lightstone_gray_off"}, {["x"] = 17, ["y"] = 11, ["z"] = 51, ["name"] = "mesecons_lightstone:lightstone_gray_off"}, {["x"] = 17, ["y"] = 11, ["z"] = 52, ["name"] = "wool:dark_grey"}, {["x"] = 18, ["y"] = 5, ["z"] = 33, ["name"] = "mesecons_lightstone:lightstone_white_off"}, {["x"] = 18, ["y"] = 5, ["z"] = 34, ["name"] = "mesecons_lightstone:lightstone_white_off"}, {["x"] = 18, ["y"] = 5, ["z"] = 35, ["name"] = "mesecons_lightstone:lightstone_white_off"}, {["x"] = 18, ["y"] = 5, ["z"] = 36, ["name"] = "mesecons_lightstone:lightstone_white_off"}, {["x"] = 18, ["y"] = 5, ["z"] = 37, ["name"] = "mesecons_lightstone:lightstone_white_off"}, {["x"] = 18, ["y"] = 5, ["z"] = 38, ["name"] = "mesecons_lightstone:lightstone_white_off"}, {["x"] = 18, ["y"] = 5, ["z"] = 39, ["name"] = "mesecons_lightstone:lightstone_white_off"}, {["x"] = 18, ["y"] = 5, ["z"] = 40, ["name"] = "mesecons_lightstone:lightstone_white_off"}, {["x"] = 18, ["y"] = 5, ["z"] = 41, ["name"] = "mesecons_lightstone:lightstone_blue_off"}, {["x"] = 18, ["y"] = 5, ["z"] = 42, ["name"] = "mesecons_lightstone:lightstone_blue_off"}, {["x"] = 18, ["y"] = 5, ["z"] = 43, ["name"] = "mesecons_lightstone:lightstone_blue_off"}, {["x"] = 18, ["y"] = 5, ["z"] = 44, ["name"] = "mesecons_lightstone:lightstone_white_off"}, {["x"] = 18, ["y"] = 5, ["z"] = 45, ["name"] = "mesecons_lightstone:lightstone_white_off"}, {["x"] = 18, ["y"] = 5, ["z"] = 46, ["name"] = "mesecons_lightstone:lightstone_white_off"}, {["x"] = 18, ["y"] = 5, ["z"] = 47, ["name"] = "mesecons_lightstone:lightstone_white_off"}, {["x"] = 18, ["y"] = 5, ["z"] = 48, ["name"] = "mesecons_lightstone:lightstone_white_off"}, {["x"] = 18, ["y"] = 5, ["z"] = 49, ["name"] = "mesecons_lightstone:lightstone_white_off"}, {["x"] = 18, ["y"] = 5, ["z"] = 50, ["name"] = "mesecons_lightstone:lightstone_white_off"}, {["x"] = 18, ["y"] = 5, ["z"] = 51, ["name"] = "mesecons_lightstone:lightstone_white_off"}, {["x"] = 18, ["y"] = 6, ["z"] = 32, ["name"] = "wool:dark_grey"}, {["x"] = 18, ["y"] = 6, ["z"] = 52, ["name"] = "wool:dark_grey"}, {["x"] = 18, ["y"] = 7, ["z"] = 32, ["name"] = "mesecons_lightstone:lightstone_gray_off"}, {["x"] = 18, ["y"] = 7, ["z"] = 52, ["name"] = "mesecons_lightstone:lightstone_gray_off"}, {["x"] = 18, ["y"] = 8, ["z"] = 32, ["name"] = "mesecons_lightstone:lightstone_gray_off"}, {["x"] = 18, ["y"] = 8, ["z"] = 52, ["name"] = "mesecons_lightstone:lightstone_gray_off"}, {["x"] = 18, ["y"] = 9, ["z"] = 32, ["name"] = "mesecons_lightstone:lightstone_gray_off"}, {["x"] = 18, ["y"] = 9, ["z"] = 52, ["name"] = "mesecons_lightstone:lightstone_gray_off"}, {["x"] = 18, ["y"] = 10, ["z"] = 32, ["name"] = "wool:dark_grey"}, {["x"] = 18, ["y"] = 10, ["param1"] = 238, ["z"] = 42, ["name"] = "morelights_modern:ceilinglight"}, {["x"] = 18, ["y"] = 10, ["z"] = 52, ["name"] = "wool:dark_grey"}, {["x"] = 18, ["y"] = 11, ["z"] = 32, ["name"] = "wool:dark_grey"}, {["x"] = 18, ["y"] = 11, ["z"] = 33, ["name"] = "mesecons_lightstone:lightstone_gray_off"}, {["x"] = 18, ["y"] = 11, ["z"] = 34, ["name"] = "mesecons_lightstone:lightstone_gray_off"}, {["x"] = 18, ["y"] = 11, ["z"] = 35, ["name"] = "mesecons_lightstone:lightstone_gray_off"}, {["x"] = 18, ["y"] = 11, ["z"] = 36, ["name"] = "mesecons_lightstone:lightstone_gray_off"}, {["x"] = 18, ["y"] = 11, ["z"] = 37, ["name"] = "mesecons_lightstone:lightstone_gray_off"}, {["x"] = 18, ["y"] = 11, ["z"] = 38, ["name"] = "mesecons_lightstone:lightstone_gray_off"}, {["x"] = 18, ["y"] = 11, ["z"] = 39, ["name"] = "mesecons_lightstone:lightstone_gray_off"}, {["x"] = 18, ["y"] = 11, ["z"] = 40, ["name"] = "mesecons_lightstone:lightstone_gray_off"}, {["x"] = 18, ["y"] = 11, ["z"] = 41, ["name"] = "mesecons_lightstone:lightstone_gray_off"}, {["x"] = 18, ["y"] = 11, ["z"] = 42, ["name"] = "mesecons_lightstone:lightstone_gray_off"}, {["x"] = 18, ["y"] = 11, ["z"] = 43, ["name"] = "mesecons_lightstone:lightstone_gray_off"}, {["x"] = 18, ["y"] = 11, ["z"] = 44, ["name"] = "mesecons_lightstone:lightstone_gray_off"}, {["x"] = 18, ["y"] = 11, ["z"] = 45, ["name"] = "mesecons_lightstone:lightstone_gray_off"}, {["x"] = 18, ["y"] = 11, ["z"] = 46, ["name"] = "mesecons_lightstone:lightstone_gray_off"}, {["x"] = 18, ["y"] = 11, ["z"] = 47, ["name"] = "mesecons_lightstone:lightstone_gray_off"}, {["x"] = 18, ["y"] = 11, ["z"] = 48, ["name"] = "mesecons_lightstone:lightstone_gray_off"}, {["x"] = 18, ["y"] = 11, ["z"] = 49, ["name"] = "mesecons_lightstone:lightstone_gray_off"}, {["x"] = 18, ["y"] = 11, ["z"] = 50, ["name"] = "mesecons_lightstone:lightstone_gray_off"}, {["x"] = 18, ["y"] = 11, ["z"] = 51, ["name"] = "mesecons_lightstone:lightstone_gray_off"}, {["x"] = 18, ["y"] = 11, ["z"] = 52, ["name"] = "wool:dark_grey"}, {["x"] = 19, ["y"] = 3, ["z"] = 26, ["name"] = "default:tinblock"}, {["x"] = 19, ["y"] = 3, ["z"] = 27, ["name"] = "default:tinblock"}, {["x"] = 19, ["y"] = 3, ["z"] = 28, ["name"] = "default:tinblock"}, {["x"] = 19, ["y"] = 3, ["z"] = 29, ["name"] = "default:tinblock"}, {["x"] = 19, ["y"] = 3, ["z"] = 30, ["name"] = "default:tinblock"}, {["x"] = 19, ["y"] = 3, ["z"] = 31, ["name"] = "default:tinblock"}, {["x"] = 19, ["y"] = 3, ["z"] = 32, ["name"] = "default:tinblock"}, {["x"] = 19, ["y"] = 3, ["z"] = 33, ["name"] = "default:tinblock"}, {["x"] = 19, ["y"] = 3, ["z"] = 34, ["name"] = "default:tinblock"}, {["x"] = 19, ["y"] = 3, ["z"] = 50, ["name"] = "default:tinblock"}, {["x"] = 19, ["y"] = 3, ["z"] = 51, ["name"] = "default:tinblock"}, {["x"] = 19, ["y"] = 3, ["z"] = 52, ["name"] = "default:tinblock"}, {["x"] = 19, ["y"] = 3, ["z"] = 53, ["name"] = "default:tinblock"}, {["x"] = 19, ["y"] = 3, ["z"] = 54, ["name"] = "default:tinblock"}, {["x"] = 19, ["y"] = 3, ["z"] = 55, ["name"] = "default:tinblock"}, {["x"] = 19, ["y"] = 3, ["z"] = 56, ["name"] = "default:tinblock"}, {["x"] = 19, ["y"] = 3, ["z"] = 57, ["name"] = "default:tinblock"}, {["x"] = 19, ["y"] = 3, ["z"] = 58, ["name"] = "default:tinblock"}, {["x"] = 19, ["y"] = 3, ["z"] = 59, ["name"] = "default:tinblock"}, {["x"] = 19, ["y"] = 3, ["z"] = 60, ["name"] = "default:tinblock"}, {["x"] = 19, ["y"] = 3, ["z"] = 61, ["name"] = "default:tinblock"}, {["x"] = 19, ["y"] = 4, ["z"] = 26, ["name"] = "default:tinblock"}, {["x"] = 19, ["y"] = 4, ["z"] = 27, ["name"] = "default:tinblock"}, {["x"] = 19, ["y"] = 4, ["z"] = 28, ["name"] = "default:tinblock"}, {["x"] = 19, ["y"] = 4, ["z"] = 29, ["name"] = "default:tinblock"}, {["x"] = 19, ["y"] = 4, ["z"] = 30, ["name"] = "default:tinblock"}, {["x"] = 19, ["y"] = 4, ["z"] = 31, ["name"] = "default:tinblock"}, {["x"] = 19, ["y"] = 4, ["z"] = 32, ["name"] = "default:tinblock"}, {["x"] = 19, ["y"] = 4, ["z"] = 33, ["name"] = "default:tinblock"}, {["x"] = 19, ["y"] = 4, ["z"] = 34, ["name"] = "default:tinblock"}, {["x"] = 19, ["y"] = 4, ["z"] = 50, ["name"] = "default:tinblock"}, {["x"] = 19, ["y"] = 4, ["z"] = 51, ["name"] = "default:tinblock"}, {["x"] = 19, ["y"] = 4, ["z"] = 52, ["name"] = "default:tinblock"}, {["x"] = 19, ["y"] = 4, ["z"] = 53, ["name"] = "default:tinblock"}, {["x"] = 19, ["y"] = 4, ["z"] = 54, ["name"] = "default:tinblock"}, {["x"] = 19, ["y"] = 4, ["z"] = 55, ["name"] = "default:tinblock"}, {["x"] = 19, ["y"] = 4, ["z"] = 56, ["name"] = "default:tinblock"}, {["x"] = 19, ["y"] = 4, ["z"] = 57, ["name"] = "default:tinblock"}, {["x"] = 19, ["y"] = 4, ["z"] = 58, ["name"] = "default:tinblock"}, {["x"] = 19, ["y"] = 4, ["z"] = 59, ["name"] = "default:tinblock"}, {["x"] = 19, ["y"] = 4, ["z"] = 60, ["name"] = "default:tinblock"}, {["x"] = 19, ["y"] = 4, ["z"] = 61, ["name"] = "default:tinblock"}, {["x"] = 19, ["y"] = 5, ["z"] = 33, ["name"] = "mesecons_lightstone:lightstone_white_off"}, {["x"] = 19, ["y"] = 5, ["z"] = 34, ["name"] = "mesecons_lightstone:lightstone_white_off"}, {["x"] = 19, ["y"] = 5, ["z"] = 35, ["name"] = "mesecons_lightstone:lightstone_white_off"}, {["x"] = 19, ["y"] = 5, ["z"] = 36, ["name"] = "mesecons_lightstone:lightstone_white_off"}, {["x"] = 19, ["y"] = 5, ["z"] = 37, ["name"] = "mesecons_lightstone:lightstone_white_off"}, {["x"] = 19, ["y"] = 5, ["z"] = 38, ["name"] = "mesecons_lightstone:lightstone_white_off"}, {["x"] = 19, ["y"] = 5, ["z"] = 39, ["name"] = "mesecons_lightstone:lightstone_white_off"}, {["x"] = 19, ["y"] = 5, ["z"] = 40, ["name"] = "mesecons_lightstone:lightstone_white_off"}, {["x"] = 19, ["y"] = 5, ["z"] = 41, ["name"] = "mesecons_lightstone:lightstone_blue_off"}, {["x"] = 19, ["y"] = 5, ["z"] = 42, ["name"] = "mesecons_lightstone:lightstone_blue_off"}, {["x"] = 19, ["y"] = 5, ["z"] = 43, ["name"] = "mesecons_lightstone:lightstone_blue_off"}, {["x"] = 19, ["y"] = 5, ["z"] = 44, ["name"] = "mesecons_lightstone:lightstone_white_off"}, {["x"] = 19, ["y"] = 5, ["z"] = 45, ["name"] = "mesecons_lightstone:lightstone_white_off"}, {["x"] = 19, ["y"] = 5, ["z"] = 46, ["name"] = "mesecons_lightstone:lightstone_white_off"}, {["x"] = 19, ["y"] = 5, ["z"] = 47, ["name"] = "mesecons_lightstone:lightstone_white_off"}, {["x"] = 19, ["y"] = 5, ["z"] = 48, ["name"] = "mesecons_lightstone:lightstone_white_off"}, {["x"] = 19, ["y"] = 5, ["z"] = 49, ["name"] = "mesecons_lightstone:lightstone_white_off"}, {["x"] = 19, ["y"] = 5, ["z"] = 50, ["name"] = "mesecons_lightstone:lightstone_white_off"}, {["x"] = 19, ["y"] = 5, ["z"] = 51, ["name"] = "mesecons_lightstone:lightstone_white_off"}, {["x"] = 19, ["y"] = 6, ["z"] = 32, ["name"] = "wool:dark_grey"}, {["x"] = 19, ["y"] = 6, ["z"] = 52, ["name"] = "wool:dark_grey"}, {["x"] = 19, ["y"] = 7, ["z"] = 32, ["name"] = "mesecons_lightstone:lightstone_gray_off"}, {["x"] = 19, ["y"] = 7, ["z"] = 52, ["name"] = "mesecons_lightstone:lightstone_gray_off"}, {["x"] = 19, ["y"] = 8, ["z"] = 32, ["name"] = "mesecons_lightstone:lightstone_gray_off"}, {["x"] = 19, ["y"] = 8, ["z"] = 52, ["name"] = "mesecons_lightstone:lightstone_gray_off"}, {["x"] = 19, ["y"] = 9, ["z"] = 32, ["name"] = "mesecons_lightstone:lightstone_gray_off"}, {["x"] = 19, ["y"] = 9, ["z"] = 52, ["name"] = "mesecons_lightstone:lightstone_gray_off"}, {["x"] = 19, ["y"] = 10, ["z"] = 32, ["name"] = "wool:dark_grey"}, {["x"] = 19, ["y"] = 10, ["param1"] = 238, ["z"] = 42, ["name"] = "morelights_modern:ceilinglight"}, {["x"] = 19, ["y"] = 10, ["z"] = 52, ["name"] = "wool:dark_grey"}, {["x"] = 19, ["y"] = 11, ["z"] = 32, ["name"] = "wool:dark_grey"}, {["x"] = 19, ["y"] = 11, ["z"] = 33, ["name"] = "mesecons_lightstone:lightstone_gray_off"}, {["x"] = 19, ["y"] = 11, ["z"] = 34, ["name"] = "mesecons_lightstone:lightstone_gray_off"}, {["x"] = 19, ["y"] = 11, ["z"] = 35, ["name"] = "mesecons_lightstone:lightstone_gray_off"}, {["x"] = 19, ["y"] = 11, ["z"] = 36, ["name"] = "mesecons_lightstone:lightstone_gray_off"}, {["x"] = 19, ["y"] = 11, ["z"] = 37, ["name"] = "mesecons_lightstone:lightstone_gray_off"}, {["x"] = 19, ["y"] = 11, ["z"] = 38, ["name"] = "mesecons_lightstone:lightstone_gray_off"}, {["x"] = 19, ["y"] = 11, ["z"] = 39, ["name"] = "mesecons_lightstone:lightstone_gray_off"}, {["x"] = 19, ["y"] = 11, ["z"] = 40, ["name"] = "mesecons_lightstone:lightstone_gray_off"}, {["x"] = 19, ["y"] = 11, ["z"] = 41, ["name"] = "mesecons_lightstone:lightstone_gray_off"}, {["x"] = 19, ["y"] = 11, ["z"] = 42, ["name"] = "mesecons_lightstone:lightstone_gray_off"}, {["x"] = 19, ["y"] = 11, ["z"] = 43, ["name"] = "mesecons_lightstone:lightstone_gray_off"}, {["x"] = 19, ["y"] = 11, ["z"] = 44, ["name"] = "mesecons_lightstone:lightstone_gray_off"}, {["x"] = 19, ["y"] = 11, ["z"] = 45, ["name"] = "mesecons_lightstone:lightstone_gray_off"}, {["x"] = 19, ["y"] = 11, ["z"] = 46, ["name"] = "mesecons_lightstone:lightstone_gray_off"}, {["x"] = 19, ["y"] = 11, ["z"] = 47, ["name"] = "mesecons_lightstone:lightstone_gray_off"}, {["x"] = 19, ["y"] = 11, ["z"] = 48, ["name"] = "mesecons_lightstone:lightstone_gray_off"}, {["x"] = 19, ["y"] = 11, ["z"] = 49, ["name"] = "mesecons_lightstone:lightstone_gray_off"}, {["x"] = 19, ["y"] = 11, ["z"] = 50, ["name"] = "mesecons_lightstone:lightstone_gray_off"}, {["x"] = 19, ["y"] = 11, ["z"] = 51, ["name"] = "mesecons_lightstone:lightstone_gray_off"}, {["x"] = 19, ["y"] = 11, ["z"] = 52, ["name"] = "wool:dark_grey"}, {["x"] = 20, ["y"] = 2, ["z"] = 27, ["name"] = "default:tinblock"}, {["x"] = 20, ["y"] = 2, ["z"] = 28, ["name"] = "default:tinblock"}, {["x"] = 20, ["y"] = 2, ["z"] = 29, ["name"] = "default:tinblock"}, {["x"] = 20, ["y"] = 2, ["z"] = 30, ["name"] = "default:tinblock"}, {["x"] = 20, ["y"] = 2, ["z"] = 31, ["name"] = "default:tinblock"}, {["x"] = 20, ["y"] = 2, ["z"] = 32, ["name"] = "default:tinblock"}, {["x"] = 20, ["y"] = 2, ["z"] = 33, ["name"] = "default:tinblock"}, {["x"] = 20, ["y"] = 2, ["z"] = 34, ["name"] = "default:tinblock"}, {["x"] = 20, ["y"] = 2, ["z"] = 35, ["name"] = "default:tinblock"}, {["x"] = 20, ["y"] = 2, ["z"] = 49, ["name"] = "default:tinblock"},