5:return {{["x"] = 0, ["y"] = 0, ["param1"] = 26, ["z"] = 0, ["name"] = "default:silver_sandstone"}, {["x"] = 0, ["y"] = 0, ["param1"] = 26, ["z"] = 1, ["name"] = "default:silver_sandstone"}, {["x"] = 0, ["y"] = 0, ["param1"] = 26, ["z"] = 2, ["name"] = "default:silver_sandstone"}, {["x"] = 0, ["y"] = 0, ["param1"] = 26, ["z"] = 3, ["name"] = "default:silver_sandstone"}, {["x"] = 0, ["y"] = 0, ["param1"] = 19, ["z"] = 4, ["name"] = "default:silver_sandstone"}, {["x"] = 0, ["y"] = 0, ["param1"] = 19, ["z"] = 5, ["name"] = "default:silver_sandstone"}, {["x"] = 0, ["y"] = 0, ["param1"] = 19, ["z"] = 6, ["name"] = "default:silver_sandstone"}, {["x"] = 0, ["y"] = 0, ["param1"] = 19, ["z"] = 7, ["name"] = "default:silver_sandstone"}, {["x"] = 0, ["y"] = 0, ["param1"] = 19, ["z"] = 8, ["name"] = "default:silver_sandstone"}, {["x"] = 0, ["y"] = 0, ["param1"] = 19, ["z"] = 9, ["name"] = "default:silver_sandstone"}, {["x"] = 0, ["y"] = 0, ["param1"] = 19, ["z"] = 10, ["name"] = "default:silver_sandstone"}, {["x"] = 0, ["y"] = 0, ["param1"] = 19, ["z"] = 11, ["name"] = "default:silver_sandstone"}, {["x"] = 0, ["y"] = 0, ["param1"] = 19, ["z"] = 12, ["name"] = "default:silver_sandstone"}, {["x"] = 0, ["y"] = 0, ["param1"] = 19, ["z"] = 13, ["name"] = "default:silver_sandstone"}, {["x"] = 0, ["y"] = 0, ["param1"] = 19, ["z"] = 14, ["name"] = "default:silver_sandstone"}, {["x"] = 0, ["y"] = 0, ["param1"] = 19, ["z"] = 15, ["name"] = "default:silver_sandstone"}, {["x"] = 0, ["y"] = 0, ["param1"] = 19, ["z"] = 16, ["name"] = "default:silver_sandstone"}, {["x"] = 0, ["y"] = 0, ["param1"] = 19, ["z"] = 17, ["name"] = "default:silver_sandstone"}, {["x"] = 0, ["y"] = 0, ["param1"] = 19, ["z"] = 18, ["name"] = "default:silver_sandstone"}, {["x"] = 0, ["y"] = 0, ["param1"] = 19, ["z"] = 19, ["name"] = "default:silver_sandstone"}, {["x"] = 0, ["y"] = 0, ["param1"] = 19, ["z"] = 20, ["name"] = "default:silver_sandstone"}, {["x"] = 0, ["y"] = 0, ["param1"] = 19, ["z"] = 21, ["name"] = "default:silver_sandstone"}, {["x"] = 0, ["y"] = 0, ["param1"] = 19, ["z"] = 22, ["name"] = "default:silver_sandstone"}, {["x"] = 0, ["y"] = 0, ["param1"] = 19, ["z"] = 23, ["name"] = "default:silver_sandstone"}, {["x"] = 0, ["y"] = 0, ["param1"] = 19, ["z"] = 24, ["name"] = "default:silver_sandstone"}, {["x"] = 0, ["y"] = 0, ["param1"] = 19, ["z"] = 25, ["name"] = "default:silver_sandstone"}, {["x"] = 0, ["y"] = 0, ["param1"] = 19, ["z"] = 26, ["name"] = "default:silver_sandstone"}, {["x"] = 0, ["y"] = 0, ["param1"] = 19, ["z"] = 27, ["name"] = "default:silver_sandstone"}, {["x"] = 0, ["y"] = 0, ["param1"] = 19, ["z"] = 28, ["name"] = "default:silver_sandstone"}, {["x"] = 0, ["y"] = 0, ["param1"] = 19, ["z"] = 29, ["name"] = "default:silver_sandstone"}, {["x"] = 0, ["y"] = 0, ["param1"] = 19, ["z"] = 30, ["name"] = "default:silver_sandstone"}, {["x"] = 0, ["y"] = 0, ["param1"] = 19, ["z"] = 31, ["name"] = "default:silver_sandstone"}, {["x"] = 0, ["y"] = 0, ["param1"] = 19, ["z"] = 32, ["name"] = "default:silver_sandstone"}, {["x"] = 0, ["y"] = 0, ["param1"] = 19, ["z"] = 33, ["name"] = "default:silver_sandstone"}, {["x"] = 0, ["y"] = 0, ["param1"] = 19, ["z"] = 34, ["name"] = "default:silver_sandstone"}, {["x"] = 0, ["y"] = 0, ["param1"] = 19, ["z"] = 35, ["name"] = "default:silver_sandstone"}, {["x"] = 0, ["y"] = 0, ["param1"] = 19, ["z"] = 36, ["name"] = "default:silver_sandstone"}, {["x"] = 0, ["y"] = 0, ["param1"] = 19, ["z"] = 37, ["name"] = "default:silver_sandstone"}, {["x"] = 0, ["y"] = 0, ["param1"] = 19, ["z"] = 38, ["name"] = "default:silver_sandstone"}, {["x"] = 0, ["y"] = 0, ["param1"] = 19, ["z"] = 39, ["name"] = "default:silver_sandstone"}, {["x"] = 0, ["y"] = 0, ["param1"] = 19, ["z"] = 40, ["name"] = "default:silver_sandstone"}, {["x"] = 0, ["y"] = 0, ["param1"] = 19, ["z"] = 41, ["name"] = "default:silver_sandstone"}, {["x"] = 0, ["y"] = 0, ["param1"] = 19, ["z"] = 42, ["name"] = "default:silver_sandstone"}, {["x"] = 0, ["y"] = 0, ["param1"] = 19, ["z"] = 43, ["name"] = "default:silver_sandstone"}, {["x"] = 0, ["y"] = 0, ["param1"] = 19, ["z"] = 44, ["name"] = "default:silver_sandstone"}, {["x"] = 0, ["y"] = 0, ["param1"] = 19, ["z"] = 45, ["name"] = "default:silver_sandstone"}, {["x"] = 0, ["y"] = 1, ["param1"] = 15, ["z"] = 0, ["name"] = "default:silver_sandstone"}, {["x"] = 0, ["y"] = 1, ["param1"] = 15, ["z"] = 1, ["name"] = "default:silver_sandstone"}, {["x"] = 0, ["y"] = 1, ["param1"] = 15, ["z"] = 2, ["name"] = "default:silver_sandstone"}, {["x"] = 0, ["y"] = 1, ["param1"] = 14, ["z"] = 3, ["name"] = "default:silver_sandstone"}, {["x"] = 0, ["y"] = 1, ["param1"] = 15, ["z"] = 4, ["name"] = "default:silver_sandstone"}, {["x"] = 0, ["y"] = 1, ["param1"] = 20, ["z"] = 5, ["name"] = "default:silver_sandstone"}, {["x"] = 0, ["y"] = 1, ["param1"] = 15, ["z"] = 6, ["name"] = "default:silver_sandstone"}, {["x"] = 0, ["y"] = 1, ["param1"] = 15, ["z"] = 7, ["name"] = "default:silver_sandstone"}, {["x"] = 0, ["y"] = 1, ["param1"] = 15, ["z"] = 8, ["name"] = "default:silver_sandstone"}, {["x"] = 0, ["y"] = 1, ["param1"] = 15, ["z"] = 9, ["name"] = "default:silver_sandstone"}, {["x"] = 0, ["y"] = 1, ["param1"] = 15, ["z"] = 10, ["name"] = "default:silver_sandstone"}, {["x"] = 0, ["y"] = 1, ["param1"] = 15, ["z"] = 11, ["name"] = "default:silver_sandstone"}, {["x"] = 0, ["y"] = 1, ["param1"] = 15, ["z"] = 12, ["name"] = "default:silver_sandstone"}, {["x"] = 0, ["y"] = 1, ["param1"] = 20, ["z"] = 13, ["name"] = "default:silver_sandstone"}, {["x"] = 0, ["y"] = 1, ["param1"] = 15, ["z"] = 14, ["name"] = "default:silver_sandstone"}, {["x"] = 0, ["y"] = 1, ["param1"] = 15, ["z"] = 15, ["name"] = "default:silver_sandstone"}, {["x"] = 0, ["y"] = 1, ["param1"] = 15, ["z"] = 16, ["name"] = "default:silver_sandstone"}, {["x"] = 0, ["y"] = 1, ["param1"] = 15, ["z"] = 17, ["name"] = "default:silver_sandstone"}, {["x"] = 0, ["y"] = 1, ["param1"] = 15, ["z"] = 18, ["name"] = "default:silver_sandstone"}, {["x"] = 0, ["y"] = 1, ["param1"] = 15, ["z"] = 19, ["name"] = "default:silver_sandstone"}, {["x"] = 0, ["y"] = 1, ["param1"] = 15, ["z"] = 20, ["name"] = "default:silver_sandstone"}, {["x"] = 0, ["y"] = 1, ["param1"] = 20, ["z"] = 21, ["name"] = "default:silver_sandstone"}, {["x"] = 0, ["y"] = 1, ["param1"] = 15, ["z"] = 22, ["name"] = "default:silver_sandstone"}, {["x"] = 0, ["y"] = 1, ["param1"] = 15, ["z"] = 23, ["name"] = "default:silver_sandstone"}, {["x"] = 0, ["y"] = 1, ["param1"] = 15, ["z"] = 24, ["name"] = "default:silver_sandstone"}, {["x"] = 0, ["y"] = 1, ["param1"] = 15, ["z"] = 25, ["name"] = "default:silver_sandstone"}, {["x"] = 0, ["y"] = 1, ["param1"] = 15, ["z"] = 26, ["name"] = "default:silver_sandstone"}, {["x"] = 0, ["y"] = 1, ["param1"] = 15, ["z"] = 27, ["name"] = "default:silver_sandstone"}, {["x"] = 0, ["y"] = 1, ["param1"] = 15, ["z"] = 28, ["name"] = "default:silver_sandstone"}, {["x"] = 0, ["y"] = 1, ["param1"] = 20, ["z"] = 29, ["name"] = "default:silver_sandstone"}, {["x"] = 0, ["y"] = 1, ["param1"] = 15, ["z"] = 30, ["name"] = "default:silver_sandstone"}, {["x"] = 0, ["y"] = 1, ["param1"] = 15, ["z"] = 31, ["name"] = "default:silver_sandstone"}, {["x"] = 0, ["y"] = 1, ["param1"] = 15, ["z"] = 32, ["name"] = "default:silver_sandstone"}, {["x"] = 0, ["y"] = 1, ["param1"] = 15, ["z"] = 33, ["name"] = "default:silver_sandstone"}, {["x"] = 0, ["y"] = 1, ["param1"] = 15, ["z"] = 34, ["name"] = "default:silver_sandstone"}, {["x"] = 0, ["y"] = 1, ["param1"] = 15, ["z"] = 35, ["name"] = "default:silver_sandstone"}, {["x"] = 0, ["y"] = 1, ["param1"] = 15, ["z"] = 36, ["name"] = "default:silver_sandstone"}, {["x"] = 0, ["y"] = 1, ["param1"] = 20, ["z"] = 37, ["name"] = "default:silver_sandstone"}, {["x"] = 0, ["y"] = 1, ["param1"] = 15, ["z"] = 38, ["name"] = "default:silver_sandstone"}, {["x"] = 0, ["y"] = 1, ["param1"] = 15, ["z"] = 39, ["name"] = "default:silver_sandstone"}, {["x"] = 0, ["y"] = 1, ["param1"] = 15, ["z"] = 40, ["name"] = "default:silver_sandstone"}, {["x"] = 0, ["y"] = 1, ["param1"] = 15, ["z"] = 41, ["name"] = "default:silver_sandstone"}, {["x"] = 0, ["y"] = 1, ["param1"] = 15, ["z"] = 42, ["name"] = "default:silver_sandstone"}, {["x"] = 0, ["y"] = 1, ["param1"] = 15, ["z"] = 43, ["name"] = "default:silver_sandstone"}, {["x"] = 0, ["y"] = 1, ["param1"] = 15, ["z"] = 44, ["name"] = "default:silver_sandstone"}, {["x"] = 0, ["y"] = 1, ["param1"] = 19, ["z"] = 45, ["name"] = "default:silver_sandstone"}, {["x"] = 0, ["y"] = 2, ["param1"] = 15, ["z"] = 0, ["name"] = "default:silver_sandstone"}, {["x"] = 0, ["y"] = 2, ["param1"] = 15, ["z"] = 1, ["name"] = "default:silver_sandstone"}, {["x"] = 0, ["y"] = 2, ["param1"] = 15, ["z"] = 2, ["name"] = "default:silver_sandstone"}, {["x"] = 0, ["y"] = 2, ["param1"] = 14, ["z"] = 3, ["name"] = "default:silver_sandstone"}, {["x"] = 0, ["y"] = 2, ["param1"] = 15, ["z"] = 4, ["name"] = "default:silver_sandstone"}, {["x"] = 0, ["y"] = 2, ["param1"] = 20, ["z"] = 5, ["name"] = "default:silver_sandstone"}, {["x"] = 0, ["y"] = 2, ["param1"] = 15, ["z"] = 6, ["name"] = "default:silver_sandstone"}, {["x"] = 0, ["y"] = 2, ["param1"] = 15, ["z"] = 7, ["name"] = "default:silver_sandstone"}, {["x"] = 0, ["y"] = 2, ["param1"] = 15, ["z"] = 8, ["name"] = "default:silver_sandstone"}, {["x"] = 0, ["y"] = 2, ["param1"] = 15, ["z"] = 9, ["name"] = "default:silver_sandstone"}, {["x"] = 0, ["y"] = 2, ["param1"] = 15, ["z"] = 10, ["name"] = "default:silver_sandstone"}, {["x"] = 0, ["y"] = 2, ["param1"] = 15, ["z"] = 11, ["name"] = "default:silver_sandstone"}, {["x"] = 0, ["y"] = 2, ["param1"] = 15, ["z"] = 12, ["name"] = "default:silver_sandstone"}, {["x"] = 0, ["y"] = 2, ["param1"] = 20, ["z"] = 13, ["name"] = "default:silver_sandstone"}, {["x"] = 0, ["y"] = 2, ["param1"] = 15, ["z"] = 14, ["name"] = "default:silver_sandstone"}, {["x"] = 0, ["y"] = 2, ["param1"] = 15, ["z"] = 15, ["name"] = "default:silver_sandstone"}, {["x"] = 0, ["y"] = 2, ["param1"] = 15, ["z"] = 16, ["name"] = "default:silver_sandstone"}, {["x"] = 0, ["y"] = 2, ["param1"] = 15, ["z"] = 17, ["name"] = "default:silver_sandstone"}, {["x"] = 0, ["y"] = 2, ["param1"] = 15, ["z"] = 18, ["name"] = "default:silver_sandstone"}, {["x"] = 0, ["y"] = 2, ["param1"] = 15, ["z"] = 19, ["name"] = "default:silver_sandstone"}, {["x"] = 0, ["y"] = 2, ["param1"] = 15, ["z"] = 20, ["name"] = "default:silver_sandstone"}, {["x"] = 0, ["y"] = 2, ["param1"] = 20, ["z"] = 21, ["name"] = "default:silver_sandstone"}, {["x"] = 0, ["y"] = 2, ["param1"] = 15, ["z"] = 22, ["name"] = "default:silver_sandstone"}, {["x"] = 0, ["y"] = 2, ["param1"] = 15, ["z"] = 23, ["name"] = "default:silver_sandstone"}, {["x"] = 0, ["y"] = 2, ["param1"] = 15, ["z"] = 24, ["name"] = "default:silver_sandstone"}, {["x"] = 0, ["y"] = 2, ["param1"] = 15, ["z"] = 25, ["name"] = "default:silver_sandstone"}, {["x"] = 0, ["y"] = 2, ["param1"] = 15, ["z"] = 26, ["name"] = "default:silver_sandstone"}, {["x"] = 0, ["y"] = 2, ["param1"] = 15, ["z"] = 27, ["name"] = "default:silver_sandstone"}, {["x"] = 0, ["y"] = 2, ["param1"] = 15, ["z"] = 28, ["name"] = "default:silver_sandstone"}, {["x"] = 0, ["y"] = 2, ["param1"] = 20, ["z"] = 29, ["name"] = "default:silver_sandstone"}, {["x"] = 0, ["y"] = 2, ["param1"] = 15, ["z"] = 30, ["name"] = "default:silver_sandstone"}, {["x"] = 0, ["y"] = 2, ["param1"] = 15, ["z"] = 31, ["name"] = "default:silver_sandstone"}, {["x"] = 0, ["y"] = 2, ["param1"] = 15, ["z"] = 32, ["name"] = "default:silver_sandstone"}, {["x"] = 0, ["y"] = 2, ["param1"] = 15, ["z"] = 33, ["name"] = "default:silver_sandstone"}, {["x"] = 0, ["y"] = 2, ["param1"] = 15, ["z"] = 34, ["name"] = "default:silver_sandstone"}, {["x"] = 0, ["y"] = 2, ["param1"] = 15, ["z"] = 35, ["name"] = "default:silver_sandstone"}, {["x"] = 0, ["y"] = 2, ["param1"] = 15, ["z"] = 36, ["name"] = "default:silver_sandstone"}, {["x"] = 0, ["y"] = 2, ["param1"] = 20, ["z"] = 37, ["name"] = "default:silver_sandstone"}, {["x"] = 0, ["y"] = 2, ["param1"] = 15, ["z"] = 38, ["name"] = "default:silver_sandstone"}, {["x"] = 0, ["y"] = 2, ["param1"] = 15, ["z"] = 39, ["name"] = "default:silver_sandstone"}, {["x"] = 0, ["y"] = 2, ["param1"] = 15, ["z"] = 40, ["name"] = "default:silver_sandstone"}, {["x"] = 0, ["y"] = 2, ["param1"] = 15, ["z"] = 41, ["name"] = "default:silver_sandstone"}, {["x"] = 0, ["y"] = 2, ["param1"] = 15, ["z"] = 42, ["name"] = "default:silver_sandstone"}, {["x"] = 0, ["y"] = 2, ["param1"] = 15, ["z"] = 43, ["name"] = "default:silver_sandstone"}, {["x"] = 0, ["y"] = 2, ["param1"] = 15, ["z"] = 44, ["name"] = "default:silver_sandstone"}, {["x"] = 0, ["y"] = 2, ["param1"] = 19, ["z"] = 45, ["name"] = "default:silver_sandstone"}, {["x"] = 0, ["y"] = 3, ["param1"] = 15, ["z"] = 0, ["name"] = "default:silver_sandstone"}, {["x"] = 0, ["y"] = 3, ["param1"] = 15, ["z"] = 1, ["name"] = "default:silver_sandstone"}, {["x"] = 0, ["y"] = 3, ["param1"] = 15, ["z"] = 2, ["name"] = "default:silver_sandstone"}, {["x"] = 0, ["y"] = 3, ["param1"] = 14, ["z"] = 3, ["name"] = "default:silver_sandstone"}, {["x"] = 0, ["y"] = 3, ["param1"] = 15, ["z"] = 4, ["name"] = "default:silver_sandstone"}, {["x"] = 0, ["y"] = 3, ["param1"] = 20, ["z"] = 5, ["name"] = "default:silver_sandstone"}, {["x"] = 0, ["y"] = 3, ["param1"] = 15, ["z"] = 6, ["name"] = "default:silver_sandstone"}, {["x"] = 0, ["y"] = 3, ["param1"] = 15, ["z"] = 7, ["name"] = "default:silver_sandstone"}, {["x"] = 0, ["y"] = 3, ["param1"] = 15, ["z"] = 8, ["name"] = "default:silver_sandstone"}, {["x"] = 0, ["y"] = 3, ["param1"] = 15, ["z"] = 9, ["name"] = "default:silver_sandstone"}, {["x"] = 0, ["y"] = 3, ["param1"] = 15, ["z"] = 10, ["name"] = "default:silver_sandstone"}, {["x"] = 0, ["y"] = 3, ["param1"] = 15, ["z"] = 11, ["name"] = "default:silver_sandstone"}, {["x"] = 0, ["y"] = 3, ["param1"] = 15, ["z"] = 12, ["name"] = "default:silver_sandstone"}, {["x"] = 0, ["y"] = 3, ["param1"] = 20, ["z"] = 13, ["name"] = "default:silver_sandstone"}, {["x"] = 0, ["y"] = 3, ["param1"] = 15, ["z"] = 14, ["name"] = "default:silver_sandstone"}, {["x"] = 0, ["y"] = 3, ["param1"] = 15, ["z"] = 15, ["name"] = "default:silver_sandstone"}, {["x"] = 0, ["y"] = 3, ["param1"] = 15, ["z"] = 16, ["name"] = "default:silver_sandstone"}, {["x"] = 0, ["y"] = 3, ["param1"] = 15, ["z"] = 17, ["name"] = "default:silver_sandstone"}, {["x"] = 0, ["y"] = 3, ["param1"] = 15, ["z"] = 18, ["name"] = "default:silver_sandstone"}, {["x"] = 0, ["y"] = 3, ["param1"] = 15, ["z"] = 19, ["name"] = "default:silver_sandstone"}, {["x"] = 0, ["y"] = 3, ["param1"] = 15, ["z"] = 20, ["name"] = "default:silver_sandstone"}, {["x"] = 0, ["y"] = 3, ["param1"] = 20, ["z"] = 21, ["name"] = "default:silver_sandstone"}, {["x"] = 0, ["y"] = 3, ["param1"] = 15, ["z"] = 22, ["name"] = "default:silver_sandstone"}, {["x"] = 0, ["y"] = 3, ["param1"] = 15, ["z"] = 23, ["name"] = "default:silver_sandstone"}, {["x"] = 0, ["y"] = 3, ["param1"] = 15, ["z"] = 24, ["name"] = "default:silver_sandstone"}, {["x"] = 0, ["y"] = 3, ["param1"] = 15, ["z"] = 25, ["name"] = "default:silver_sandstone"}, {["x"] = 0, ["y"] = 3, ["param1"] = 15, ["z"] = 26, ["name"] = "default:silver_sandstone"}, {["x"] = 0, ["y"] = 3, ["param1"] = 15, ["z"] = 27, ["name"] = "default:silver_sandstone"}, {["x"] = 0, ["y"] = 3, ["param1"] = 15, ["z"] = 28, ["name"] = "default:silver_sandstone"}, {["x"] = 0, ["y"] = 3, ["param1"] = 20, ["z"] = 29, ["name"] = "default:silver_sandstone"}, {["x"] = 0, ["y"] = 3, ["param1"] = 15, ["z"] = 30, ["name"] = "default:silver_sandstone"}, {["x"] = 0, ["y"] = 3, ["param1"] = 15, ["z"] = 31, ["name"] = "default:silver_sandstone"}, {["x"] = 0, ["y"] = 3, ["param1"] = 15, ["z"] = 32, ["name"] = "default:silver_sandstone"}, {["x"] = 0, ["y"] = 3, ["param1"] = 15, ["z"] = 33, ["name"] = "default:silver_sandstone"}, {["x"] = 0, ["y"] = 3, ["param1"] = 15, ["z"] = 34, ["name"] = "default:silver_sandstone"}, {["x"] = 0, ["y"] = 3, ["param1"] = 15, ["z"] = 35, ["name"] = "default:silver_sandstone"}, {["x"] = 0, ["y"] = 3, ["param1"] = 15, ["z"] = 36, ["name"] = "default:silver_sandstone"}, {["x"] = 0, ["y"] = 3, ["param1"] = 20, ["z"] = 37, ["name"] = "default:silver_sandstone"}, {["x"] = 0, ["y"] = 3, ["param1"] = 15, ["z"] = 38, ["name"] = "default:silver_sandstone"}, {["x"] = 0, ["y"] = 3, ["param1"] = 15, ["z"] = 39, ["name"] = "default:silver_sandstone"}, {["x"] = 0, ["y"] = 3, ["param1"] = 15, ["z"] = 40, ["name"] = "default:silver_sandstone"}, {["x"] = 0, ["y"] = 3, ["param1"] = 15, ["z"] = 41, ["name"] = "default:silver_sandstone"}, {["x"] = 0, ["y"] = 3, ["param1"] = 15, ["z"] = 42, ["name"] = "default:silver_sandstone"}, {["x"] = 0, ["y"] = 3, ["param1"] = 15, ["z"] = 43, ["name"] = "default:silver_sandstone"}, {["x"] = 0, ["y"] = 3, ["param1"] = 15, ["z"] = 44, ["name"] = "default:silver_sandstone"}, {["x"] = 0, ["y"] = 3, ["param1"] = 19, ["z"] = 45, ["name"] = "default:silver_sandstone"}, {["x"] = 0, ["y"] = 4, ["param1"] = 15, ["z"] = 0, ["name"] = "default:silver_sandstone"}, {["x"] = 0, ["y"] = 4, ["param1"] = 15, ["z"] = 1, ["name"] = "default:silver_sandstone"}, {["x"] = 0, ["y"] = 4, ["param1"] = 15, ["z"] = 2, ["name"] = "default:silver_sandstone"}, {["x"] = 0, ["y"] = 4, ["param1"] = 14, ["z"] = 3, ["name"] = "default:silver_sandstone"}, {["x"] = 0, ["y"] = 4, ["param1"] = 15, ["z"] = 4, ["name"] = "default:silver_sandstone"}, {["x"] = 0, ["y"] = 4, ["param1"] = 20, ["z"] = 5, ["name"] = "default:silver_sandstone"}, {["x"] = 0, ["y"] = 4, ["param1"] = 15, ["z"] = 6, ["name"] = "default:silver_sandstone"}, {["x"] = 0, ["y"] = 4, ["param1"] = 15, ["z"] = 7, ["name"] = "default:silver_sandstone"}, {["x"] = 0, ["y"] = 4, ["param1"] = 15, ["z"] = 8, ["name"] = "default:silver_sandstone"}, {["x"] = 0, ["y"] = 4, ["param1"] = 15, ["z"] = 9, ["name"] = "default:silver_sandstone"}, {["x"] = 0, ["y"] = 4, ["param1"] = 15, ["z"] = 10, ["name"] = "default:silver_sandstone"}, {["x"] = 0, ["y"] = 4, ["param1"] = 15, ["z"] = 11, ["name"] = "default:silver_sandstone"}, {["x"] = 0, ["y"] = 4, ["param1"] = 15, ["z"] = 12, ["name"] = "default:silver_sandstone"}, {["x"] = 0, ["y"] = 4, ["param1"] = 20, ["z"] = 13, ["name"] = "default:silver_sandstone"}, {["x"] = 0, ["y"] = 4, ["param1"] = 15, ["z"] = 14, ["name"] = "default:silver_sandstone"}, {["x"] = 0, ["y"] = 4, ["param1"] = 15, ["z"] = 15, ["name"] = "default:silver_sandstone"}, {["x"] = 0, ["y"] = 4, ["param1"] = 15, ["z"] = 16, ["name"] = "default:silver_sandstone"}, {["x"] = 0, ["y"] = 4, ["param1"] = 15, ["z"] = 17, ["name"] = "default:silver_sandstone"}, {["x"] = 0, ["y"] = 4, ["param1"] = 15, ["z"] = 18, ["name"] = "default:silver_sandstone"}, {["x"] = 0, ["y"] = 4, ["param1"] = 15, ["z"] = 19, ["name"] = "default:silver_sandstone"}, {["x"] = 0, ["y"] = 4, ["param1"] = 15, ["z"] = 20, ["name"] = "default:silver_sandstone"}, {["x"] = 0, ["y"] = 4, ["param1"] = 20, ["z"] = 21, ["name"] = "default:silver_sandstone"}, {["x"] = 0, ["y"] = 4, ["param1"] = 15, ["z"] = 22, ["name"] = "default:silver_sandstone"}, {["x"] = 0, ["y"] = 4, ["param1"] = 15, ["z"] = 23, ["name"] = "default:silver_sandstone"}, {["x"] = 0, ["y"] = 4, ["param1"] = 15, ["z"] = 24, ["name"] = "default:silver_sandstone"}, {["x"] = 0, ["y"] = 4, ["param1"] = 15, ["z"] = 25, ["name"] = "default:silver_sandstone"}, {["x"] = 0, ["y"] = 4, ["param1"] = 15, ["z"] = 26, ["name"] = "default:silver_sandstone"}, {["x"] = 0, ["y"] = 4, ["param1"] = 15, ["z"] = 27, ["name"] = "default:silver_sandstone"}, {["x"] = 0, ["y"] = 4, ["param1"] = 15, ["z"] = 28, ["name"] = "default:silver_sandstone"}, {["x"] = 0, ["y"] = 4, ["param1"] = 20, ["z"] = 29, ["name"] = "default:silver_sandstone"}, {["x"] = 0, ["y"] = 4, ["param1"] = 15, ["z"] = 30, ["name"] = "default:silver_sandstone"}, {["x"] = 0, ["y"] = 4, ["param1"] = 15, ["z"] = 31, ["name"] = "default:silver_sandstone"}, {["x"] = 0, ["y"] = 4, ["param1"] = 15, ["z"] = 32, ["name"] = "default:silver_sandstone"}, {["x"] = 0, ["y"] = 4, ["param1"] = 15, ["z"] = 33, ["name"] = "default:silver_sandstone"}, {["x"] = 0, ["y"] = 4, ["param1"] = 15, ["z"] = 34, ["name"] = "default:silver_sandstone"}, {["x"] = 0, ["y"] = 4, ["param1"] = 15, ["z"] = 35, ["name"] = "default:silver_sandstone"}, {["x"] = 0, ["y"] = 4, ["param1"] = 15, ["z"] = 36, ["name"] = "default:silver_sandstone"}, {["x"] = 0, ["y"] = 4, ["param1"] = 20, ["z"] = 37, ["name"] = "default:silver_sandstone"}, {["x"] = 0, ["y"] = 4, ["param1"] = 15, ["z"] = 38, ["name"] = "default:silver_sandstone"}, {["x"] = 0, ["y"] = 4, ["param1"] = 15, ["z"] = 39, ["name"] = "default:silver_sandstone"}, {["x"] = 0, ["y"] = 4, ["param1"] = 15, ["z"] = 40, ["name"] = "default:silver_sandstone"}, {["x"] = 0, ["y"] = 4, ["param1"] = 15, ["z"] = 41, ["name"] = "default:silver_sandstone"}, {["x"] = 0, ["y"] = 4, ["param1"] = 15, ["z"] = 42, ["name"] = "default:silver_sandstone"}, {["x"] = 0, ["y"] = 4, ["param1"] = 15, ["z"] = 43, ["name"] = "default:silver_sandstone"}, {["x"] = 0, ["y"] = 4, ["param1"] = 15, ["z"] = 44, ["name"] = "default:silver_sandstone"}, {["x"] = 0, ["y"] = 4, ["param1"] = 19, ["z"] = 45, ["name"] = "default:silver_sandstone"}, {["x"] = 1, ["y"] = 0, ["param1"] = 26, ["z"] = 0, ["name"] = "default:silver_sandstone"}, {["x"] = 1, ["y"] = 0, ["param1"] = 26, ["z"] = 1, ["name"] = "default:silver_sandstone"}, {["x"] = 1, ["y"] = 0, ["param1"] = 26, ["z"] = 2, ["name"] = "maptools:grass"}, {["x"] = 1, ["y"] = 0, ["param1"] = 26, ["z"] = 3, ["name"] = "maptools:grass"}, {["x"] = 1, ["y"] = 0, ["param1"] = 255, ["z"] = 4, ["name"] = "default:silver_sandstone"}, {["x"] = 1, ["y"] = 0, ["param1"] = 255, ["z"] = 5, ["name"] = "default:silver_sandstone"}, {["x"] = 1, ["y"] = 0, ["param1"] = 111, ["z"] = 6, ["name"] = "default:silver_sandstone"}, {["x"] = 1, ["y"] = 0, ["param1"] = 255, ["z"] = 7, ["name"] = "maptools:grass"}, {["x"] = 1, ["y"] = 0, ["param1"] = 255, ["z"] = 8, ["name"] = "maptools:grass"}, {["x"] = 1, ["y"] = 0, ["param1"] = 255, ["z"] = 9, ["name"] = "maptools:grass"}, {["x"] = 1, ["y"] = 0, ["param1"] = 255, ["z"] = 10, ["name"] = "maptools:grass"}, {["x"] = 1, ["y"] = 0, ["param1"] = 255, ["z"] = 11, ["name"] = "maptools:grass"}, {["x"] = 1, ["y"] = 0, ["param1"] = 255, ["z"] = 12, ["name"] = "default:silver_sandstone"}, {["x"] = 1, ["y"] = 0, ["param1"] = 255, ["z"] = 13, ["name"] = "maptools:grass"}, {["x"] = 1, ["y"] = 0, ["param1"] = 255, ["z"] = 14, ["name"] = "default:silver_sandstone"}, {["x"] = 1, ["y"] = 0, ["param1"] = 255, ["z"] = 15, ["name"] = "maptools:grass"}, {["x"] = 1, ["y"] = 0, ["param1"] = 255, ["z"] = 16, ["name"] = "maptools:grass"}, {["x"] = 1, ["y"] = 0, ["param1"] = 255, ["z"] = 17, ["name"] = "maptools:grass"}, {["x"] = 1, ["y"] = 0, ["param1"] = 255, ["z"] = 18, ["name"] = "maptools:grass"}, {["x"] = 1, ["y"] = 0, ["param1"] = 255, ["z"] = 19, ["name"] = "maptools:grass"}, {["x"] = 1, ["y"] = 0, ["param1"] = 255, ["z"] = 20, ["name"] = "default:silver_sandstone"}, {["x"] = 1, ["y"] = 0, ["param1"] = 255, ["z"] = 21, ["name"] = "maptools:grass"}, {["x"] = 1, ["y"] = 0, ["param1"] = 255, ["z"] = 22, ["name"] = "default:silver_sandstone"}, {["x"] = 1, ["y"] = 0, ["param1"] = 255, ["z"] = 23, ["name"] = "maptools:grass"}, {["x"] = 1, ["y"] = 0, ["param1"] = 255, ["z"] = 24, ["name"] = "maptools:grass"}, {["x"] = 1, ["y"] = 0, ["param1"] = 255, ["z"] = 25, ["name"] = "maptools:grass"}, {["x"] = 1, ["y"] = 0, ["param1"] = 255, ["z"] = 26, ["name"] = "maptools:grass"}, {["x"] = 1, ["y"] = 0, ["param1"] = 255, ["z"] = 27, ["name"] = "maptools:grass"}, {["x"] = 1, ["y"] = 0, ["param1"] = 255, ["z"] = 28, ["name"] = "default:silver_sandstone"}, {["x"] = 1, ["y"] = 0, ["param1"] = 255, ["z"] = 29, ["name"] = "maptools:grass"}, {["x"] = 1, ["y"] = 0, ["z"] = 30, ["name"] = "default:silver_sandstone"}, {["x"] = 1, ["y"] = 0, ["param1"] = 255, ["z"] = 31, ["name"] = "maptools:grass"}, {["x"] = 1, ["y"] = 0, ["param1"] = 255, ["z"] = 32, ["name"] = "maptools:grass"}, {["x"] = 1, ["y"] = 0, ["param1"] = 255, ["z"] = 33, ["name"] = "maptools:grass"}, {["x"] = 1, ["y"] = 0, ["param1"] = 255, ["z"] = 34, ["name"] = "maptools:grass"}, {["x"] = 1, ["y"] = 0, ["param1"] = 255, ["z"] = 35, ["name"] = "maptools:grass"}, {["x"] = 1, ["y"] = 0, ["param1"] = 255, ["z"] = 36, ["name"] = "default:silver_sandstone"}, {["x"] = 1, ["y"] = 0, ["param1"] = 255, ["z"] = 37, ["name"] = "maptools:grass"}, {["x"] = 1, ["y"] = 0, ["param1"] = 255, ["z"] = 38, ["name"] = "default:silver_sandstone"}, {["x"] = 1, ["y"] = 0, ["param1"] = 255, ["z"] = 39, ["name"] = "maptools:grass"}, {["x"] = 1, ["y"] = 0, ["param1"] = 255, ["z"] = 40, ["name"] = "maptools:grass"}, {["x"] = 1, ["y"] = 0, ["param1"] = 255, ["z"] = 41, ["name"] = "maptools:grass"}, {["x"] = 1, ["y"] = 0, ["param1"] = 255, ["z"] = 42, ["name"] = "maptools:grass"}, {["x"] = 1, ["y"] = 0, ["param1"] = 255, ["z"] = 43, ["name"] = "maptools:grass"}, {["x"] = 1, ["y"] = 0, ["param1"] = 255, ["z"] = 44, ["name"] = "default:silver_sandstone"}, {["x"] = 1, ["y"] = 0, ["param1"] = 19, ["z"] = 45, ["name"] = "default:silver_sandstone"}, {["x"] = 1, ["y"] = 1, ["param1"] = 15, ["z"] = 0, ["name"] = "default:silver_sandstone"}, {["x"] = 1, ["y"] = 1, ["param1"] = 20, ["z"] = 5, ["name"] = "default:silver_sandstone"}, {["x"] = 1, ["y"] = 1, ["param1"] = 20, ["z"] = 13, ["name"] = "default:silver_sandstone"}, {["x"] = 1, ["y"] = 1, ["param1"] = 20, ["z"] = 21, ["name"] = "default:silver_sandstone"}, {["x"] = 1, ["y"] = 1, ["param1"] = 20, ["z"] = 29, ["name"] = "default:silver_sandstone"}, {["x"] = 1, ["y"] = 1, ["param1"] = 20, ["z"] = 37, ["name"] = "default:silver_sandstone"}, {["x"] = 1, ["y"] = 1, ["param1"] = 19, ["z"] = 45, ["name"] = "default:silver_sandstone"}, {["x"] = 1, ["y"] = 2, ["param1"] = 15, ["z"] = 0, ["name"] = "default:silver_sandstone"}, {["x"] = 1, ["y"] = 2, ["param1"] = 20, ["z"] = 5, ["name"] = "default:silver_sandstone"}, {["x"] = 1, ["y"] = 2, ["param1"] = 20, ["z"] = 13, ["name"] = "default:silver_sandstone"}, {["x"] = 1, ["y"] = 2, ["param1"] = 20, ["z"] = 21, ["name"] = "default:silver_sandstone"}, {["x"] = 1, ["y"] = 2, ["param1"] = 20, ["z"] = 29, ["name"] = "default:silver_sandstone"}, {["x"] = 1, ["y"] = 2, ["param1"] = 20, ["z"] = 37, ["name"] = "default:silver_sandstone"}, {["x"] = 1, ["y"] = 2, ["param1"] = 19, ["z"] = 45, ["name"] = "default:silver_sandstone"}, {["x"] = 1, ["y"] = 3, ["param1"] = 15, ["z"] = 0, ["name"] = "default:silver_sandstone"}, {["x"] = 1, ["y"] = 3, ["param1"] = 15, ["z"] = 1, ["name"] = "default:silver_sandstone"}, {["x"] = 1, ["y"] = 3, ["param1"] = 15, ["z"] = 2, ["name"] = "default:silver_sandstone"}, {["x"] = 1, ["y"] = 3, ["param1"] = 14, ["z"] = 3, ["name"] = "default:silver_sandstone"}, {["x"] = 1, ["y"] = 3, ["param1"] = 13, ["z"] = 4, ["name"] = "default:silver_sandstone"}, {["x"] = 1, ["y"] = 3, ["param1"] = 20, ["z"] = 5, ["name"] = "default:silver_sandstone"}, {["x"] = 1, ["y"] = 3, ["param1"] = 15, ["z"] = 6, ["name"] = "default:silver_sandstone"}, {["x"] = 1, ["y"] = 3, ["param1"] = 15, ["z"] = 12, ["name"] = "default:silver_sandstone"}, {["x"] = 1, ["y"] = 3, ["param1"] = 20, ["z"] = 13, ["name"] = "default:silver_sandstone"}, {["x"] = 1, ["y"] = 3, ["z"] = 14, ["name"] = "default:silver_sandstone"}, {["x"] = 1, ["y"] = 3, ["param1"] = 15, ["z"] = 20, ["name"] = "default:silver_sandstone"}, {["x"] = 1, ["y"] = 3, ["param1"] = 20, ["z"] = 21, ["name"] = "default:silver_sandstone"}, {["x"] = 1, ["y"] = 3, ["param1"] = 15, ["z"] = 22, ["name"] = "default:silver_sandstone"}, {["x"] = 1, ["y"] = 3, ["param1"] = 15, ["z"] = 28, ["name"] = "default:silver_sandstone"}, {["x"] = 1, ["y"] = 3, ["param1"] = 20, ["z"] = 29, ["name"] = "default:silver_sandstone"}, {["x"] = 1, ["y"] = 3, ["param1"] = 15, ["z"] = 30, ["name"] = "default:silver_sandstone"}, {["x"] = 1, ["y"] = 3, ["param1"] = 15, ["z"] = 36, ["name"] = "default:silver_sandstone"}, {["x"] = 1, ["y"] = 3, ["param1"] = 20, ["z"] = 37, ["name"] = "default:silver_sandstone"}, {["x"] = 1, ["y"] = 3, ["z"] = 38, ["name"] = "default:silver_sandstone"}, {["x"] = 1, ["y"] = 3, ["param1"] = 15, ["z"] = 44, ["name"] = "default:silver_sandstone"}, {["x"] = 1, ["y"] = 3, ["param1"] = 19, ["z"] = 45, ["name"] = "default:silver_sandstone"}, {["x"] = 1, ["y"] = 4, ["param1"] = 15, ["z"] = 0, ["name"] = "default:silver_sandstone"}, {["x"] = 1, ["y"] = 4, ["param1"] = 20, ["z"] = 5, ["name"] = "default:silver_sandstone"}, {["x"] = 1, ["y"] = 4, ["param1"] = 20, ["z"] = 13, ["name"] = "default:silver_sandstone"}, {["x"] = 1, ["y"] = 4, ["param1"] = 20, ["z"] = 21, ["name"] = "default:silver_sandstone"}, {["x"] = 1, ["y"] = 4, ["param1"] = 20, ["z"] = 29, ["name"] = "default:silver_sandstone"}, {["x"] = 1, ["y"] = 4, ["param1"] = 20, ["z"] = 37, ["name"] = "default:silver_sandstone"}, {["x"] = 1, ["y"] = 4, ["param1"] = 19, ["z"] = 45, ["name"] = "default:silver_sandstone"}, {["x"] = 2, ["y"] = 0, ["param1"] = 26, ["z"] = 0, ["name"] = "default:silver_sandstone"}, {["x"] = 2, ["y"] = 0, ["param1"] = 26, ["z"] = 1, ["name"] = "default:silver_sandstone"}, {["x"] = 2, ["y"] = 0, ["param1"] = 26, ["z"] = 2, ["name"] = "maptools:grass"}, {["x"] = 2, ["y"] = 0, ["param1"] = 26, ["z"] = 3, ["name"] = "maptools:grass"}, {["x"] = 2, ["y"] = 0, ["param1"] = 255, ["z"] = 4, ["name"] = "default:silver_sandstone"}, {["x"] = 2, ["y"] = 0, ["param1"] = 255, ["z"] = 5, ["name"] = "default:silver_sandstone"}, {["x"] = 2, ["y"] = 0, ["param1"] = 111, ["z"] = 6, ["name"] = "default:silver_sandstone"}, {["x"] = 2, ["y"] = 0, ["param1"] = 255, ["z"] = 7, ["name"] = "maptools:grass"}, {["x"] = 2, ["y"] = 0, ["param1"] = 255, ["z"] = 8, ["name"] = "maptools:grass"}, {["x"] = 2, ["y"] = 0, ["param1"] = 255, ["z"] = 9, ["name"] = "maptools:grass"}, {["x"] = 2, ["y"] = 0, ["param1"] = 255, ["z"] = 10, ["name"] = "maptools:grass"}, {["x"] = 2, ["y"] = 0, ["param1"] = 255, ["z"] = 11, ["name"] = "maptools:grass"}, {["x"] = 2, ["y"] = 0, ["param1"] = 255, ["z"] = 12, ["name"] = "default:silver_sandstone"}, {["x"] = 2, ["y"] = 0, ["param1"] = 255, ["z"] = 13, ["name"] = "maptools:grass"}, {["x"] = 2, ["y"] = 0, ["param1"] = 255, ["z"] = 14, ["name"] = "default:silver_sandstone"}, {["x"] = 2, ["y"] = 0, ["param1"] = 255, ["z"] = 15, ["name"] = "maptools:grass"}, {["x"] = 2, ["y"] = 0, ["param1"] = 255, ["z"] = 16, ["name"] = "maptools:grass"}, {["x"] = 2, ["y"] = 0, ["param1"] = 255, ["z"] = 17, ["name"] = "maptools:grass"}, {["x"] = 2, ["y"] = 0, ["param1"] = 255, ["z"] = 18, ["name"] = "maptools:grass"}, {["x"] = 2, ["y"] = 0, ["param1"] = 255, ["z"] = 19, ["name"] = "maptools:grass"}, {["x"] = 2, ["y"] = 0, ["param1"] = 255, ["z"] = 20, ["name"] = "default:silver_sandstone"}, {["x"] = 2, ["y"] = 0, ["param1"] = 255, ["z"] = 21, ["name"] = "maptools:grass"}, {["x"] = 2, ["y"] = 0, ["param1"] = 255, ["z"] = 22, ["name"] = "default:silver_sandstone"}, {["x"] = 2, ["y"] = 0, ["param1"] = 255, ["z"] = 23, ["name"] = "maptools:grass"}, {["x"] = 2, ["y"] = 0, ["param1"] = 255, ["z"] = 24, ["name"] = "maptools:grass"}, {["x"] = 2, ["y"] = 0, ["param1"] = 255, ["z"] = 25, ["name"] = "maptools:grass"}, {["x"] = 2, ["y"] = 0, ["param1"] = 255, ["z"] = 26, ["name"] = "maptools:grass"}, {["x"] = 2, ["y"] = 0, ["param1"] = 255, ["z"] = 27, ["name"] = "maptools:grass"}, {["x"] = 2, ["y"] = 0, ["param1"] = 255, ["z"] = 28, ["name"] = "default:silver_sandstone"}, {["x"] = 2, ["y"] = 0, ["param1"] = 255, ["z"] = 29, ["name"] = "maptools:grass"}, {["x"] = 2, ["y"] = 0, ["z"] = 30, ["name"] = "default:silver_sandstone"}, {["x"] = 2, ["y"] = 0, ["param1"] = 255, ["z"] = 31, ["name"] = "maptools:grass"}, {["x"] = 2, ["y"] = 0, ["param1"] = 255, ["z"] = 32, ["name"] = "maptools:grass"}, {["x"] = 2, ["y"] = 0, ["param1"] = 255, ["z"] = 33, ["name"] = "maptools:grass"}, {["x"] = 2, ["y"] = 0, ["param1"] = 255, ["z"] = 34, ["name"] = "maptools:grass"}, {["x"] = 2, ["y"] = 0, ["param1"] = 255, ["z"] = 35, ["name"] = "maptools:grass"}, {["x"] = 2, ["y"] = 0, ["param1"] = 255, ["z"] = 36, ["name"] = "default:silver_sandstone"}, {["x"] = 2, ["y"] = 0, ["param1"] = 255, ["z"] = 37, ["name"] = "maptools:grass"}, {["x"] = 2, ["y"] = 0, ["param1"] = 255, ["z"] = 38, ["name"] = "default:silver_sandstone"}, {["x"] = 2, ["y"] = 0, ["param1"] = 255, ["z"] = 39, ["name"] = "maptools:grass"}, {["x"] = 2, ["y"] = 0, ["param1"] = 255, ["z"] = 40, ["name"] = "maptools:grass"}, {["x"] = 2, ["y"] = 0, ["param1"] = 255, ["z"] = 41, ["name"] = "maptools:grass"}, {["x"] = 2, ["y"] = 0, ["param1"] = 255, ["z"] = 42, ["name"] = "maptools:grass"}, {["x"] = 2, ["y"] = 0, ["param1"] = 255, ["z"] = 43, ["name"] = "maptools:grass"}, {["x"] = 2, ["y"] = 0, ["param1"] = 255, ["z"] = 44, ["name"] = "default:silver_sandstone"}, {["x"] = 2, ["y"] = 0, ["param1"] = 19, ["z"] = 45, ["name"] = "default:silver_sandstone"}, {["x"] = 2, ["y"] = 1, ["param1"] = 15, ["z"] = 0, ["name"] = "default:silver_sandstone"}, {["x"] = 2, ["y"] = 1, ["param1"] = 20, ["z"] = 5, ["name"] = "default:silver_sandstone"}, {["x"] = 2, ["y"] = 1, ["param1"] = 20, ["z"] = 13, ["name"] = "default:silver_sandstone"}, {["x"] = 2, ["y"] = 1, ["param1"] = 20, ["z"] = 21, ["name"] = "default:silver_sandstone"}, {["x"] = 2, ["y"] = 1, ["param1"] = 20, ["z"] = 29, ["name"] = "default:silver_sandstone"}, {["x"] = 2, ["y"] = 1, ["param1"] = 20, ["z"] = 37, ["name"] = "default:silver_sandstone"}, {["x"] = 2, ["y"] = 1, ["param1"] = 19, ["z"] = 45, ["name"] = "default:silver_sandstone"}, {["x"] = 2, ["y"] = 2, ["param1"] = 15, ["z"] = 0, ["name"] = "default:silver_sandstone"}, {["x"] = 2, ["y"] = 2, ["param1"] = 20, ["z"] = 5, ["name"] = "default:silver_sandstone"}, {["x"] = 2, ["y"] = 2, ["param1"] = 20, ["z"] = 13, ["name"] = "default:silver_sandstone"}, {["x"] = 2, ["y"] = 2, ["param1"] = 20, ["z"] = 21, ["name"] = "default:silver_sandstone"}, {["x"] = 2, ["y"] = 2, ["param1"] = 20, ["z"] = 29, ["name"] = "default:silver_sandstone"}, {["x"] = 2, ["y"] = 2, ["param1"] = 20, ["z"] = 37, ["name"] = "default:silver_sandstone"}, {["x"] = 2, ["y"] = 2, ["param1"] = 19, ["z"] = 45, ["name"] = "default:silver_sandstone"}, {["x"] = 2, ["y"] = 3, ["param1"] = 15, ["z"] = 0, ["name"] = "default:silver_sandstone"}, {["x"] = 2, ["y"] = 3, ["param1"] = 15, ["z"] = 1, ["name"] = "default:silver_sandstone"}, {["x"] = 2, ["y"] = 3, ["param1"] = 15, ["z"] = 2, ["name"] = "default:silver_sandstone"}, {["x"] = 2, ["y"] = 3, ["param1"] = 14, ["z"] = 3, ["name"] = "default:silver_sandstone"}, {["x"] = 2, ["y"] = 3, ["param1"] = 14, ["z"] = 4, ["name"] = "default:silver_sandstone"}, {["x"] = 2, ["y"] = 3, ["param1"] = 20, ["z"] = 5, ["name"] = "default:silver_sandstone"}, {["x"] = 2, ["y"] = 3, ["param1"] = 15, ["z"] = 6, ["name"] = "default:silver_sandstone"}, {["x"] = 2, ["y"] = 3, ["param1"] = 15, ["z"] = 12, ["name"] = "default:silver_sandstone"}, {["x"] = 2, ["y"] = 3, ["param1"] = 20, ["z"] = 13, ["name"] = "default:silver_sandstone"}, {["x"] = 2, ["y"] = 3, ["z"] = 14, ["name"] = "default:silver_sandstone"}, {["x"] = 2, ["y"] = 3, ["param1"] = 15, ["z"] = 20, ["name"] = "default:silver_sandstone"}, {["x"] = 2, ["y"] = 3, ["param1"] = 20, ["z"] = 21, ["name"] = "default:silver_sandstone"}, {["x"] = 2, ["y"] = 3, ["param1"] = 15, ["z"] = 22, ["name"] = "default:silver_sandstone"}, {["x"] = 2, ["y"] = 3, ["param1"] = 15, ["z"] = 28, ["name"] = "default:silver_sandstone"}, {["x"] = 2, ["y"] = 3, ["param1"] = 20, ["z"] = 29, ["name"] = "default:silver_sandstone"}, {["x"] = 2, ["y"] = 3, ["param1"] = 15, ["z"] = 30, ["name"] = "default:silver_sandstone"}, {["x"] = 2, ["y"] = 3, ["param1"] = 15, ["z"] = 36, ["name"] = "default:silver_sandstone"}, {["x"] = 2, ["y"] = 3, ["param1"] = 20, ["z"] = 37, ["name"] = "default:silver_sandstone"}, {["x"] = 2, ["y"] = 3, ["z"] = 38, ["name"] = "default:silver_sandstone"}, {["x"] = 2, ["y"] = 3, ["param1"] = 15, ["z"] = 44, ["name"] = "default:silver_sandstone"}, {["x"] = 2, ["y"] = 3, ["param1"] = 19, ["z"] = 45, ["name"] = "default:silver_sandstone"}, {["x"] = 2, ["y"] = 4, ["param1"] = 15, ["z"] = 0, ["name"] = "default:silver_sandstone"}, {["x"] = 2, ["y"] = 4, ["param1"] = 20, ["z"] = 5, ["name"] = "default:silver_sandstone"}, {["x"] = 2, ["y"] = 4, ["param1"] = 20, ["z"] = 13, ["name"] = "default:silver_sandstone"}, {["x"] = 2, ["y"] = 4, ["param1"] = 20, ["z"] = 21, ["name"] = "default:silver_sandstone"}, {["x"] = 2, ["y"] = 4, ["param1"] = 20, ["z"] = 29, ["name"] = "default:silver_sandstone"}, {["x"] = 2, ["y"] = 4, ["param1"] = 20, ["z"] = 37, ["name"] = "default:silver_sandstone"}, {["x"] = 2, ["y"] = 4, ["param1"] = 19, ["z"] = 45, ["name"] = "default:silver_sandstone"}, {["x"] = 3, ["y"] = 0, ["param1"] = 26, ["z"] = 0, ["name"] = "default:silver_sandstone"}, {["x"] = 3, ["y"] = 0, ["param1"] = 26, ["z"] = 1, ["name"] = "default:silver_sandstone"}, {["x"] = 3, ["y"] = 0, ["param1"] = 26, ["z"] = 2, ["name"] = "maptools:grass"}, {["x"] = 3, ["y"] = 0, ["param1"] = 26, ["z"] = 3, ["name"] = "maptools:grass"}, {["x"] = 3, ["y"] = 0, ["param1"] = 255, ["z"] = 4, ["name"] = "default:silver_sandstone"}, {["x"] = 3, ["y"] = 0, ["param1"] = 255, ["z"] = 5, ["name"] = "default:silver_sandstone"}, {["x"] = 3, ["y"] = 0, ["param1"] = 111, ["z"] = 6, ["name"] = "default:silver_sandstone"}, {["x"] = 3, ["y"] = 0, ["param1"] = 255, ["z"] = 7, ["name"] = "maptools:grass"}, {["x"] = 3, ["y"] = 0, ["param1"] = 255, ["z"] = 8, ["name"] = "maptools:grass"}, {["x"] = 3, ["y"] = 0, ["param1"] = 255, ["z"] = 9, ["name"] = "maptools:grass"}, {["x"] = 3, ["y"] = 0, ["param1"] = 255, ["z"] = 10, ["name"] = "maptools:grass"}, {["x"] = 3, ["y"] = 0, ["param1"] = 255, ["z"] = 11, ["name"] = "maptools:grass"}, {["x"] = 3, ["y"] = 0, ["param1"] = 255, ["z"] = 12, ["name"] = "default:silver_sandstone"}, {["x"] = 3, ["y"] = 0, ["param1"] = 255, ["z"] = 13, ["name"] = "maptools:grass"}, {["x"] = 3, ["y"] = 0, ["param1"] = 255, ["z"] = 14, ["name"] = "default:silver_sandstone"}, {["x"] = 3, ["y"] = 0, ["param1"] = 255, ["z"] = 15, ["name"] = "maptools:grass"}, {["x"] = 3, ["y"] = 0, ["param1"] = 255, ["z"] = 16, ["name"] = "maptools:grass"}, {["x"] = 3, ["y"] = 0, ["param1"] = 255, ["z"] = 17, ["name"] = "maptools:grass"}, {["x"] = 3, ["y"] = 0, ["param1"] = 255, ["z"] = 18, ["name"] = "maptools:grass"}, {["x"] = 3, ["y"] = 0, ["param1"] = 255, ["z"] = 19, ["name"] = "maptools:grass"}, {["x"] = 3, ["y"] = 0, ["param1"] = 255, ["z"] = 20, ["name"] = "default:silver_sandstone"}, {["x"] = 3, ["y"] = 0, ["param1"] = 255, ["z"] = 21, ["name"] = "maptools:grass"}, {["x"] = 3, ["y"] = 0, ["param1"] = 255, ["z"] = 22, ["name"] = "default:silver_sandstone"}, {["x"] = 3, ["y"] = 0, ["param1"] = 255, ["z"] = 23, ["name"] = "maptools:grass"}, {["x"] = 3, ["y"] = 0, ["param1"] = 255, ["z"] = 24, ["name"] = "maptools:grass"}, {["x"] = 3, ["y"] = 0, ["param1"] = 255, ["z"] = 25, ["name"] = "maptools:grass"}, {["x"] = 3, ["y"] = 0, ["param1"] = 255, ["z"] = 26, ["name"] = "maptools:grass"}, {["x"] = 3, ["y"] = 0, ["param1"] = 255, ["z"] = 27, ["name"] = "maptools:grass"}, {["x"] = 3, ["y"] = 0, ["param1"] = 255, ["z"] = 28, ["name"] = "default:silver_sandstone"}, {["x"] = 3, ["y"] = 0, ["param1"] = 255, ["z"] = 29, ["name"] = "maptools:grass"}, {["x"] = 3, ["y"] = 0, ["z"] = 30, ["name"] = "default:silver_sandstone"}, {["x"] = 3, ["y"] = 0, ["param1"] = 255, ["z"] = 31, ["name"] = "maptools:grass"}, {["x"] = 3, ["y"] = 0, ["param1"] = 255, ["z"] = 32, ["name"] = "maptools:grass"}, {["x"] = 3, ["y"] = 0, ["param1"] = 255, ["z"] = 33, ["name"] = "maptools:grass"}, {["x"] = 3, ["y"] = 0, ["param1"] = 255, ["z"] = 34, ["name"] = "maptools:grass"}, {["x"] = 3, ["y"] = 0, ["param1"] = 255, ["z"] = 35, ["name"] = "maptools:grass"}, {["x"] = 3, ["y"] = 0, ["param1"] = 255, ["z"] = 36, ["name"] = "default:silver_sandstone"}, {["x"] = 3, ["y"] = 0, ["param1"] = 255, ["z"] = 37, ["name"] = "maptools:grass"}, {["x"] = 3, ["y"] = 0, ["param1"] = 255, ["z"] = 38, ["name"] = "default:silver_sandstone"}, {["x"] = 3, ["y"] = 0, ["param1"] = 255, ["z"] = 39, ["name"] = "maptools:grass"}, {["x"] = 3, ["y"] = 0, ["param1"] = 255, ["z"] = 40, ["name"] = "maptools:grass"}, {["x"] = 3, ["y"] = 0, ["param1"] = 255, ["z"] = 41, ["name"] = "maptools:grass"}, {["x"] = 3, ["y"] = 0, ["param1"] = 255, ["z"] = 42, ["name"] = "maptools:grass"}, {["x"] = 3, ["y"] = 0, ["param1"] = 255, ["z"] = 43, ["name"] = "maptools:grass"}, {["x"] = 3, ["y"] = 0, ["param1"] = 255, ["z"] = 44, ["name"] = "default:silver_sandstone"}, {["x"] = 3, ["y"] = 0, ["param1"] = 19, ["z"] = 45, ["name"] = "default:silver_sandstone"}, {["x"] = 3, ["y"] = 1, ["param1"] = 15, ["z"] = 0, ["name"] = "default:silver_sandstone"}, {["x"] = 3, ["y"] = 1, ["param1"] = 20, ["z"] = 5, ["name"] = "default:silver_sandstone"}, {["x"] = 3, ["y"] = 1, ["param1"] = 20, ["z"] = 13, ["name"] = "default:silver_sandstone"}, {["x"] = 3, ["y"] = 1, ["param1"] = 20, ["z"] = 21, ["name"] = "default:silver_sandstone"}, {["x"] = 3, ["y"] = 1, ["param1"] = 20, ["z"] = 29, ["name"] = "default:silver_sandstone"}, {["x"] = 3, ["y"] = 1, ["param1"] = 20, ["z"] = 37, ["name"] = "default:silver_sandstone"}, {["x"] = 3, ["y"] = 1, ["param1"] = 19, ["z"] = 45, ["name"] = "default:silver_sandstone"}, {["x"] = 3, ["y"] = 2, ["param1"] = 15, ["z"] = 0, ["name"] = "default:silver_sandstone"}, {["x"] = 3, ["y"] = 2, ["param1"] = 20, ["z"] = 5, ["name"] = "default:silver_sandstone"}, {["x"] = 3, ["y"] = 2, ["param1"] = 20, ["z"] = 13, ["name"] = "default:silver_sandstone"}, {["x"] = 3, ["y"] = 2, ["param1"] = 20, ["z"] = 21, ["name"] = "default:silver_sandstone"}, {["x"] = 3, ["y"] = 2, ["param1"] = 20, ["z"] = 29, ["name"] = "default:silver_sandstone"}, {["x"] = 3, ["y"] = 2, ["param1"] = 20, ["z"] = 37, ["name"] = "default:silver_sandstone"}, {["x"] = 3, ["y"] = 2, ["param1"] = 19, ["z"] = 45, ["name"] = "default:silver_sandstone"}, {["x"] = 3, ["y"] = 3, ["param1"] = 15, ["z"] = 0, ["name"] = "default:silver_sandstone"}, {["x"] = 3, ["y"] = 3, ["param1"] = 15, ["z"] = 1, ["name"] = "default:silver_sandstone"}, {["x"] = 3, ["y"] = 3, ["param1"] = 15, ["z"] = 2, ["name"] = "default:silver_sandstone"}, {["x"] = 3, ["y"] = 3, ["param1"] = 14, ["z"] = 3, ["name"] = "default:silver_sandstone"}, {["x"] = 3, ["y"] = 3, ["param1"] = 14, ["z"] = 4, ["name"] = "default:silver_sandstone"}, {["x"] = 3, ["y"] = 3, ["param1"] = 20, ["z"] = 5, ["name"] = "default:silver_sandstone"}, {["x"] = 3, ["y"] = 3, ["param1"] = 15, ["z"] = 6, ["name"] = "default:silver_sandstone"}, {["x"] = 3, ["y"] = 3, ["param1"] = 15, ["z"] = 12, ["name"] = "default:silver_sandstone"}, {["x"] = 3, ["y"] = 3, ["param1"] = 20, ["z"] = 13, ["name"] = "default:silver_sandstone"}, {["x"] = 3, ["y"] = 3, ["z"] = 14, ["name"] = "default:silver_sandstone"}, {["x"] = 3, ["y"] = 3, ["param1"] = 15, ["z"] = 20, ["name"] = "default:silver_sandstone"}, {["x"] = 3, ["y"] = 3, ["param1"] = 20, ["z"] = 21, ["name"] = "default:silver_sandstone"}, {["x"] = 3, ["y"] = 3, ["param1"] = 15, ["z"] = 22, ["name"] = "default:silver_sandstone"}, {["x"] = 3, ["y"] = 3, ["param1"] = 15, ["z"] = 28, ["name"] = "default:silver_sandstone"}, {["x"] = 3, ["y"] = 3, ["param1"] = 20, ["z"] = 29, ["name"] = "default:silver_sandstone"}, {["x"] = 3, ["y"] = 3, ["param1"] = 15, ["z"] = 30, ["name"] = "default:silver_sandstone"}, {["x"] = 3, ["y"] = 3, ["param1"] = 15, ["z"] = 36, ["name"] = "default:silver_sandstone"}, {["x"] = 3, ["y"] = 3, ["param1"] = 20, ["z"] = 37, ["name"] = "default:silver_sandstone"}, {["x"] = 3, ["y"] = 3, ["z"] = 38, ["name"] = "default:silver_sandstone"}, {["x"] = 3, ["y"] = 3, ["param1"] = 15, ["z"] = 44, ["name"] = "default:silver_sandstone"}, {["x"] = 3, ["y"] = 3, ["param1"] = 19, ["z"] = 45, ["name"] = "default:silver_sandstone"}, {["x"] = 3, ["y"] = 4, ["param1"] = 15, ["z"] = 0, ["name"] = "default:silver_sandstone"}, {["x"] = 3, ["y"] = 4, ["param1"] = 20, ["z"] = 5, ["name"] = "default:silver_sandstone"}, {["x"] = 3, ["y"] = 4, ["param1"] = 20, ["z"] = 13, ["name"] = "default:silver_sandstone"}, {["x"] = 3, ["y"] = 4, ["param1"] = 20, ["z"] = 21, ["name"] = "default:silver_sandstone"}, {["x"] = 3, ["y"] = 4, ["param1"] = 20, ["z"] = 29, ["name"] = "default:silver_sandstone"}, {["x"] = 3, ["y"] = 4, ["param1"] = 20, ["z"] = 37, ["name"] = "default:silver_sandstone"}, {["x"] = 3, ["y"] = 4, ["param1"] = 19, ["z"] = 45, ["name"] = "default:silver_sandstone"}, {["x"] = 4, ["y"] = 0, ["param1"] = 26, ["z"] = 0, ["name"] = "default:silver_sandstone"}, {["x"] = 4, ["y"] = 0, ["param1"] = 26, ["z"] = 1, ["name"] = "default:silver_sandstone"}, {["x"] = 4, ["y"] = 0, ["param1"] = 26, ["z"] = 2, ["name"] = "maptools:grass"}, {["x"] = 4, ["y"] = 0, ["param1"] = 26, ["z"] = 3, ["name"] = "maptools:grass"}, {["x"] = 4, ["y"] = 0, ["param1"] = 255, ["z"] = 4, ["name"] = "default:silver_sandstone"}, {["x"] = 4, ["y"] = 0, ["param1"] = 255, ["z"] = 5, ["name"] = "default:silver_sandstone"}, {["x"] = 4, ["y"] = 0, ["param1"] = 111, ["z"] = 6, ["name"] = "default:silver_sandstone"}, {["x"] = 4, ["y"] = 0, ["param1"] = 255, ["z"] = 7, ["name"] = "maptools:grass"}, {["x"] = 4, ["y"] = 0, ["param1"] = 255, ["z"] = 8, ["name"] = "maptools:grass"}, {["x"] = 4, ["y"] = 0, ["param1"] = 255, ["z"] = 9, ["name"] = "maptools:grass"}, {["x"] = 4, ["y"] = 0, ["param1"] = 255, ["z"] = 10, ["name"] = "maptools:grass"}, {["x"] = 4, ["y"] = 0, ["param1"] = 255, ["z"] = 11, ["name"] = "maptools:grass"}, {["x"] = 4, ["y"] = 0, ["param1"] = 255, ["z"] = 12, ["name"] = "default:silver_sandstone"}, {["x"] = 4, ["y"] = 0, ["param1"] = 255, ["z"] = 13, ["name"] = "maptools:grass"}, {["x"] = 4, ["y"] = 0, ["param1"] = 255, ["z"] = 14, ["name"] = "default:silver_sandstone"}, {["x"] = 4, ["y"] = 0, ["param1"] = 255, ["z"] = 15, ["name"] = "maptools:grass"}, {["x"] = 4, ["y"] = 0, ["param1"] = 255, ["z"] = 16, ["name"] = "maptools:grass"}, {["x"] = 4, ["y"] = 0, ["param1"] = 255, ["z"] = 17, ["name"] = "maptools:grass"}, {["x"] = 4, ["y"] = 0, ["param1"] = 255, ["z"] = 18, ["name"] = "maptools:grass"}, {["x"] = 4, ["y"] = 0, ["param1"] = 255, ["z"] = 19, ["name"] = "maptools:grass"}, {["x"] = 4, ["y"] = 0, ["param1"] = 255, ["z"] = 20, ["name"] = "default:silver_sandstone"}, {["x"] = 4, ["y"] = 0, ["param1"] = 255, ["z"] = 21, ["name"] = "maptools:grass"}, {["x"] = 4, ["y"] = 0, ["param1"] = 255, ["z"] = 22, ["name"] = "default:silver_sandstone"}, {["x"] = 4, ["y"] = 0, ["param1"] = 255, ["z"] = 23, ["name"] = "maptools:grass"}, {["x"] = 4, ["y"] = 0, ["param1"] = 255, ["z"] = 24, ["name"] = "maptools:grass"}, {["x"] = 4, ["y"] = 0, ["param1"] = 255, ["z"] = 25, ["name"] = "maptools:grass"}, {["x"] = 4, ["y"] = 0, ["param1"] = 255, ["z"] = 26, ["name"] = "maptools:grass"}, {["x"] = 4, ["y"] = 0, ["param1"] = 255, ["z"] = 27, ["name"] = "maptools:grass"}, {["x"] = 4, ["y"] = 0, ["param1"] = 255, ["z"] = 28, ["name"] = "default:silver_sandstone"}, {["x"] = 4, ["y"] = 0, ["param1"] = 255, ["z"] = 29, ["name"] = "maptools:grass"}, {["x"] = 4, ["y"] = 0, ["z"] = 30, ["name"] = "default:silver_sandstone"}, {["x"] = 4, ["y"] = 0, ["param1"] = 255, ["z"] = 31, ["name"] = "maptools:grass"}, {["x"] = 4, ["y"] = 0, ["param1"] = 255, ["z"] = 32, ["name"] = "maptools:grass"}, {["x"] = 4, ["y"] = 0, ["param1"] = 255, ["z"] = 33, ["name"] = "maptools:grass"}, {["x"] = 4, ["y"] = 0, ["param1"] = 255, ["z"] = 34, ["name"] = "maptools:grass"}, {["x"] = 4, ["y"] = 0, ["param1"] = 255, ["z"] = 35, ["name"] = "maptools:grass"}, {["x"] = 4, ["y"] = 0, ["param1"] = 255, ["z"] = 36, ["name"] = "default:silver_sandstone"}, {["x"] = 4, ["y"] = 0, ["param1"] = 255, ["z"] = 37, ["name"] = "maptools:grass"}, {["x"] = 4, ["y"] = 0, ["param1"] = 255, ["z"] = 38, ["name"] = "default:silver_sandstone"}, {["x"] = 4, ["y"] = 0, ["param1"] = 255, ["z"] = 39, ["name"] = "maptools:grass"}, {["x"] = 4, ["y"] = 0, ["param1"] = 255, ["z"] = 40, ["name"] = "maptools:grass"}, {["x"] = 4, ["y"] = 0, ["param1"] = 255, ["z"] = 41, ["name"] = "maptools:grass"}, {["x"] = 4, ["y"] = 0, ["param1"] = 255, ["z"] = 42, ["name"] = "maptools:grass"}, {["x"] = 4, ["y"] = 0, ["param1"] = 255, ["z"] = 43, ["name"] = "maptools:grass"}, {["x"] = 4, ["y"] = 0, ["param1"] = 255, ["z"] = 44, ["name"] = "default:silver_sandstone"}, {["x"] = 4, ["y"] = 0, ["param1"] = 19, ["z"] = 45, ["name"] = "default:silver_sandstone"}, {["x"] = 4, ["y"] = 1, ["param1"] = 15, ["z"] = 0, ["name"] = "default:silver_sandstone"}, {["x"] = 4, ["y"] = 1, ["param1"] = 20, ["z"] = 5, ["name"] = "default:silver_sandstone"}, {["x"] = 4, ["y"] = 1, ["param1"] = 20, ["z"] = 13, ["name"] = "default:silver_sandstone"}, {["x"] = 4, ["y"] = 1, ["param1"] = 20, ["z"] = 21, ["name"] = "default:silver_sandstone"}, {["x"] = 4, ["y"] = 1, ["param1"] = 20, ["z"] = 29, ["name"] = "default:silver_sandstone"}, {["x"] = 4, ["y"] = 1, ["param1"] = 20, ["z"] = 37, ["name"] = "default:silver_sandstone"}, {["x"] = 4, ["y"] = 1, ["param1"] = 19, ["z"] = 45, ["name"] = "default:silver_sandstone"}, {["x"] = 4, ["y"] = 2, ["param1"] = 15, ["z"] = 0, ["name"] = "default:silver_sandstone"}, {["x"] = 4, ["y"] = 2, ["param1"] = 20, ["z"] = 5, ["name"] = "default:silver_sandstone"}, {["x"] = 4, ["y"] = 2, ["param1"] = 20, ["z"] = 13, ["name"] = "default:silver_sandstone"}, {["x"] = 4, ["y"] = 2, ["param1"] = 20, ["z"] = 21, ["name"] = "default:silver_sandstone"}, {["x"] = 4, ["y"] = 2, ["param1"] = 20, ["z"] = 29, ["name"] = "default:silver_sandstone"}, {["x"] = 4, ["y"] = 2, ["param1"] = 20, ["z"] = 37, ["name"] = "default:silver_sandstone"}, {["x"] = 4, ["y"] = 2, ["param1"] = 19, ["z"] = 45, ["name"] = "default:silver_sandstone"}, {["x"] = 4, ["y"] = 3, ["param1"] = 15, ["z"] = 0, ["name"] = "default:silver_sandstone"}, {["x"] = 4, ["y"] = 3, ["param1"] = 15, ["z"] = 1, ["name"] = "default:silver_sandstone"}, {["x"] = 4, ["y"] = 3, ["param1"] = 15, ["z"] = 2, ["name"] = "default:silver_sandstone"}, {["x"] = 4, ["y"] = 3, ["param1"] = 14, ["z"] = 3, ["name"] = "default:silver_sandstone"}, {["x"] = 4, ["y"] = 3, ["param1"] = 14, ["z"] = 4, ["name"] = "default:silver_sandstone"}, {["x"] = 4, ["y"] = 3, ["param1"] = 20, ["z"] = 5, ["name"] = "default:silver_sandstone"}, {["x"] = 4, ["y"] = 3, ["param1"] = 15, ["z"] = 6, ["name"] = "default:silver_sandstone"}, {["x"] = 4, ["y"] = 3, ["param1"] = 15, ["z"] = 12, ["name"] = "default:silver_sandstone"}, {["x"] = 4, ["y"] = 3, ["param1"] = 20, ["z"] = 13, ["name"] = "default:silver_sandstone"}, {["x"] = 4, ["y"] = 3, ["z"] = 14, ["name"] = "default:silver_sandstone"}, {["x"] = 4, ["y"] = 3, ["param1"] = 15, ["z"] = 20, ["name"] = "default:silver_sandstone"}, {["x"] = 4, ["y"] = 3, ["param1"] = 20, ["z"] = 21, ["name"] = "default:silver_sandstone"}, {["x"] = 4, ["y"] = 3, ["param1"] = 15, ["z"] = 22, ["name"] = "default:silver_sandstone"}, {["x"] = 4, ["y"] = 3, ["param1"] = 15, ["z"] = 28, ["name"] = "default:silver_sandstone"}, {["x"] = 4, ["y"] = 3, ["param1"] = 20, ["z"] = 29, ["name"] = "default:silver_sandstone"}, {["x"] = 4, ["y"] = 3, ["param1"] = 15, ["z"] = 30, ["name"] = "default:silver_sandstone"}, {["x"] = 4, ["y"] = 3, ["param1"] = 15, ["z"] = 36, ["name"] = "default:silver_sandstone"}, {["x"] = 4, ["y"] = 3, ["param1"] = 20, ["z"] = 37, ["name"] = "default:silver_sandstone"}, {["x"] = 4, ["y"] = 3, ["z"] = 38, ["name"] = "default:silver_sandstone"}, {["x"] = 4, ["y"] = 3, ["param1"] = 15, ["z"] = 44, ["name"] = "default:silver_sandstone"}, {["x"] = 4, ["y"] = 3, ["param1"] = 19, ["z"] = 45, ["name"] = "default:silver_sandstone"}, {["x"] = 4, ["y"] = 4, ["param1"] = 15, ["z"] = 0, ["name"] = "default:silver_sandstone"}, {["x"] = 4, ["y"] = 4, ["param1"] = 20, ["z"] = 5, ["name"] = "default:silver_sandstone"}, {["x"] = 4, ["y"] = 4, ["param1"] = 20, ["z"] = 13, ["name"] = "default:silver_sandstone"}, {["x"] = 4, ["y"] = 4, ["param1"] = 20, ["z"] = 21, ["name"] = "default:silver_sandstone"}, {["x"] = 4, ["y"] = 4, ["param1"] = 20, ["z"] = 29, ["name"] = "default:silver_sandstone"}, {["x"] = 4, ["y"] = 4, ["param1"] = 20, ["z"] = 37, ["name"] = "default:silver_sandstone"}, {["x"] = 4, ["y"] = 4, ["param1"] = 19, ["z"] = 45, ["name"] = "default:silver_sandstone"}, {["x"] = 5, ["y"] = 0, ["param1"] = 26, ["z"] = 0, ["name"] = "default:silver_sandstone"}, {["x"] = 5, ["y"] = 0, ["param1"] = 26, ["z"] = 1, ["name"] = "default:silver_sandstone"}, {["x"] = 5, ["y"] = 0, ["param1"] = 26, ["z"] = 2, ["name"] = "maptools:grass"}, {["x"] = 5, ["y"] = 0, ["param1"] = 26, ["z"] = 3, ["name"] = "maptools:grass"}, {["x"] = 5, ["y"] = 0, ["param1"] = 255, ["z"] = 4, ["name"] = "default:silver_sandstone"}, {["x"] = 5, ["y"] = 0, ["param1"] = 255, ["z"] = 5, ["name"] = "default:silver_sandstone"}, {["x"] = 5, ["y"] = 0, ["param1"] = 111, ["z"] = 6, ["name"] = "default:silver_sandstone"}, {["x"] = 5, ["y"] = 0, ["param1"] = 255, ["z"] = 7, ["name"] = "maptools:grass"}, {["x"] = 5, ["y"] = 0, ["param1"] = 255, ["z"] = 8, ["name"] = "maptools:grass"}, {["x"] = 5, ["y"] = 0, ["param1"] = 255, ["z"] = 9, ["name"] = "maptools:grass"}, {["x"] = 5, ["y"] = 0, ["param1"] = 255, ["z"] = 10, ["name"] = "maptools:grass"}, {["x"] = 5, ["y"] = 0, ["param1"] = 255, ["z"] = 11, ["name"] = "maptools:grass"}, {["x"] = 5, ["y"] = 0, ["param1"] = 255, ["z"] = 12, ["name"] = "default:silver_sandstone"}, {["x"] = 5, ["y"] = 0, ["param1"] = 255, ["z"] = 13, ["name"] = "maptools:grass"}, {["x"] = 5, ["y"] = 0, ["param1"] = 255, ["z"] = 14, ["name"] = "default:silver_sandstone"}, {["x"] = 5, ["y"] = 0, ["param1"] = 255, ["z"] = 15, ["name"] = "maptools:grass"}, {["x"] = 5, ["y"] = 0, ["param1"] = 255, ["z"] = 16, ["name"] = "maptools:grass"}, {["x"] = 5, ["y"] = 0, ["param1"] = 255, ["z"] = 17, ["name"] = "maptools:grass"}, {["x"] = 5, ["y"] = 0, ["param1"] = 255, ["z"] = 18, ["name"] = "maptools:grass"}, {["x"] = 5, ["y"] = 0, ["param1"] = 255, ["z"] = 19, ["name"] = "maptools:grass"}, {["x"] = 5, ["y"] = 0, ["param1"] = 255, ["z"] = 20, ["name"] = "default:silver_sandstone"}, {["x"] = 5, ["y"] = 0, ["param1"] = 255, ["z"] = 21, ["name"] = "maptools:grass"}, {["x"] = 5, ["y"] = 0, ["param1"] = 255, ["z"] = 22, ["name"] = "default:silver_sandstone"}, {["x"] = 5, ["y"] = 0, ["param1"] = 255, ["z"] = 23, ["name"] = "maptools:grass"}, {["x"] = 5, ["y"] = 0, ["param1"] = 255, ["z"] = 24, ["name"] = "maptools:grass"}, {["x"] = 5, ["y"] = 0, ["param1"] = 255, ["z"] = 25, ["name"] = "maptools:grass"}, {["x"] = 5, ["y"] = 0, ["param1"] = 255, ["z"] = 26, ["name"] = "maptools:grass"}, {["x"] = 5, ["y"] = 0, ["param1"] = 255, ["z"] = 27, ["name"] = "maptools:grass"}, {["x"] = 5, ["y"] = 0, ["param1"] = 255, ["z"] = 28, ["name"] = "default:silver_sandstone"}, {["x"] = 5, ["y"] = 0, ["param1"] = 255, ["z"] = 29, ["name"] = "maptools:grass"}, {["x"] = 5, ["y"] = 0, ["z"] = 30, ["name"] = "default:silver_sandstone"}, {["x"] = 5, ["y"] = 0, ["param1"] = 255, ["z"] = 31, ["name"] = "maptools:grass"}, {["x"] = 5, ["y"] = 0, ["param1"] = 255, ["z"] = 32, ["name"] = "maptools:grass"}, {["x"] = 5, ["y"] = 0, ["param1"] = 255, ["z"] = 33, ["name"] = "maptools:grass"}, {["x"] = 5, ["y"] = 0, ["param1"] = 255, ["z"] = 34, ["name"] = "maptools:grass"}, {["x"] = 5, ["y"] = 0, ["param1"] = 255, ["z"] = 35, ["name"] = "maptools:grass"}, {["x"] = 5, ["y"] = 0, ["param1"] = 255, ["z"] = 36, ["name"] = "default:silver_sandstone"}, {["x"] = 5, ["y"] = 0, ["param1"] = 255, ["z"] = 37, ["name"] = "maptools:grass"}, {["x"] = 5, ["y"] = 0, ["param1"] = 255, ["z"] = 38, ["name"] = "default:silver_sandstone"}, {["x"] = 5, ["y"] = 0, ["param1"] = 255, ["z"] = 39, ["name"] = "maptools:grass"}, {["x"] = 5, ["y"] = 0, ["param1"] = 255, ["z"] = 40, ["name"] = "maptools:grass"}, {["x"] = 5, ["y"] = 0, ["param1"] = 255, ["z"] = 41, ["name"] = "maptools:grass"}, {["x"] = 5, ["y"] = 0, ["param1"] = 255, ["z"] = 42, ["name"] = "maptools:grass"}, {["x"] = 5, ["y"] = 0, ["param1"] = 255, ["z"] = 43, ["name"] = "maptools:grass"}, {["x"] = 5, ["y"] = 0, ["param1"] = 255, ["z"] = 44, ["name"] = "default:silver_sandstone"}, {["x"] = 5, ["y"] = 0, ["param1"] = 19, ["z"] = 45, ["name"] = "default:silver_sandstone"}, {["x"] = 5, ["y"] = 1, ["param1"] = 15, ["z"] = 0, ["name"] = "default:silver_sandstone"}, {["x"] = 5, ["y"] = 1, ["param1"] = 20, ["z"] = 5, ["name"] = "default:silver_sandstone"}, {["x"] = 5, ["y"] = 1, ["param1"] = 20, ["z"] = 13, ["name"] = "default:silver_sandstone"}, {["x"] = 5, ["y"] = 1, ["param1"] = 20, ["z"] = 21, ["name"] = "default:silver_sandstone"}, {["x"] = 5, ["y"] = 1, ["param1"] = 20, ["z"] = 29, ["name"] = "default:silver_sandstone"}, {["x"] = 5, ["y"] = 1, ["param1"] = 20, ["z"] = 37, ["name"] = "default:silver_sandstone"}, {["x"] = 5, ["y"] = 1, ["param1"] = 19, ["z"] = 45, ["name"] = "default:silver_sandstone"}, {["x"] = 5, ["y"] = 2, ["param1"] = 15, ["z"] = 0, ["name"] = "default:silver_sandstone"}, {["x"] = 5, ["y"] = 2, ["param1"] = 20, ["z"] = 5, ["name"] = "default:silver_sandstone"}, {["x"] = 5, ["y"] = 2, ["param1"] = 20, ["z"] = 13, ["name"] = "default:silver_sandstone"}, {["x"] = 5, ["y"] = 2, ["param1"] = 20, ["z"] = 21, ["name"] = "default:silver_sandstone"}, {["x"] = 5, ["y"] = 2, ["param1"] = 20, ["z"] = 29, ["name"] = "default:silver_sandstone"}, {["x"] = 5, ["y"] = 2, ["param1"] = 20, ["z"] = 37, ["name"] = "default:silver_sandstone"}, {["x"] = 5, ["y"] = 2, ["param1"] = 19, ["z"] = 45, ["name"] = "default:silver_sandstone"}, {["x"] = 5, ["y"] = 3, ["param1"] = 15, ["z"] = 0, ["name"] = "default:silver_sandstone"}, {["x"] = 5, ["y"] = 3, ["param1"] = 15, ["z"] = 1, ["name"] = "default:silver_sandstone"}, {["x"] = 5, ["y"] = 3, ["param1"] = 15, ["z"] = 2, ["name"] = "default:silver_sandstone"}, {["x"] = 5, ["y"] = 3, ["param1"] = 14, ["z"] = 3, ["name"] = "default:silver_sandstone"}, {["x"] = 5, ["y"] = 3, ["param1"] = 14, ["z"] = 4, ["name"] = "default:silver_sandstone"}, {["x"] = 5, ["y"] = 3, ["param1"] = 20, ["z"] = 5, ["name"] = "default:silver_sandstone"}, {["x"] = 5, ["y"] = 3, ["param1"] = 15, ["z"] = 6, ["name"] = "default:silver_sandstone"}, {["x"] = 5, ["y"] = 3, ["param1"] = 15, ["z"] = 12, ["name"] = "default:silver_sandstone"}, {["x"] = 5, ["y"] = 3, ["param1"] = 20, ["z"] = 13, ["name"] = "default:silver_sandstone"}, {["x"] = 5, ["y"] = 3, ["z"] = 14, ["name"] = "default:silver_sandstone"}, {["x"] = 5, ["y"] = 3, ["param1"] = 15, ["z"] = 20, ["name"] = "default:silver_sandstone"}, {["x"] = 5, ["y"] = 3, ["param1"] = 20, ["z"] = 21, ["name"] = "default:silver_sandstone"}, {["x"] = 5, ["y"] = 3, ["param1"] = 15, ["z"] = 22, ["name"] = "default:silver_sandstone"}, {["x"] = 5, ["y"] = 3, ["param1"] = 15, ["z"] = 28, ["name"] = "default:silver_sandstone"}, {["x"] = 5, ["y"] = 3, ["param1"] = 20, ["z"] = 29, ["name"] = "default:silver_sandstone"}, {["x"] = 5, ["y"] = 3, ["param1"] = 15, ["z"] = 30, ["name"] = "default:silver_sandstone"}, {["x"] = 5, ["y"] = 3, ["param1"] = 15, ["z"] = 36, ["name"] = "default:silver_sandstone"}, {["x"] = 5, ["y"] = 3, ["param1"] = 20, ["z"] = 37, ["name"] = "default:silver_sandstone"}, {["x"] = 5, ["y"] = 3, ["z"] = 38, ["name"] = "default:silver_sandstone"}, {["x"] = 5, ["y"] = 3, ["param1"] = 15, ["z"] = 44, ["name"] = "default:silver_sandstone"}, {["x"] = 5, ["y"] = 3, ["param1"] = 19, ["z"] = 45, ["name"] = "default:silver_sandstone"}, {["x"] = 5, ["y"] = 4, ["param1"] = 15, ["z"] = 0, ["name"] = "default:silver_sandstone"}, {["x"] = 5, ["y"] = 4, ["param1"] = 20, ["z"] = 5, ["name"] = "default:silver_sandstone"}, {["x"] = 5, ["y"] = 4, ["param1"] = 20, ["z"] = 13, ["name"] = "default:silver_sandstone"}, {["x"] = 5, ["y"] = 4, ["param1"] = 20, ["z"] = 21, ["name"] = "default:silver_sandstone"}, {["x"] = 5, ["y"] = 4, ["param1"] = 20, ["z"] = 29, ["name"] = "default:silver_sandstone"}, {["x"] = 5, ["y"] = 4, ["param1"] = 20, ["z"] = 37, ["name"] = "default:silver_sandstone"}, {["x"] = 5, ["y"] = 4, ["param1"] = 19, ["z"] = 45, ["name"] = "default:silver_sandstone"}, {["x"] = 6, ["y"] = 0, ["param1"] = 26, ["z"] = 0, ["name"] = "default:silver_sandstone"}, {["x"] = 6, ["y"] = 0, ["param1"] = 26, ["z"] = 1, ["name"] = "default:silver_sandstone"}, {["x"] = 6, ["y"] = 0, ["param1"] = 26, ["z"] = 2, ["name"] = "maptools:grass"}, {["x"] = 6, ["y"] = 0, ["param1"] = 26, ["z"] = 3, ["name"] = "maptools:grass"}, {["x"] = 6, ["y"] = 0, ["param1"] = 255, ["z"] = 4, ["name"] = "default:silver_sandstone"}, {["x"] = 6, ["y"] = 0, ["param1"] = 255, ["z"] = 5, ["name"] = "default:silver_sandstone"}, {["x"] = 6, ["y"] = 0, ["param1"] = 111, ["z"] = 6, ["name"] = "default:silver_sandstone"}, {["x"] = 6, ["y"] = 0, ["param1"] = 255, ["z"] = 7, ["name"] = "maptools:grass"}, {["x"] = 6, ["y"] = 0, ["param1"] = 255, ["z"] = 8, ["name"] = "maptools:grass"}, {["x"] = 6, ["y"] = 0, ["param1"] = 255, ["z"] = 9, ["name"] = "maptools:grass"}, {["x"] = 6, ["y"] = 0, ["param1"] = 255, ["z"] = 10, ["name"] = "maptools:grass"}, {["x"] = 6, ["y"] = 0, ["param1"] = 255, ["z"] = 11, ["name"] = "maptools:grass"}, {["x"] = 6, ["y"] = 0, ["param1"] = 255, ["z"] = 12, ["name"] = "default:silver_sandstone"}, {["x"] = 6, ["y"] = 0, ["param1"] = 255, ["z"] = 13, ["name"] = "maptools:grass"}, {["x"] = 6, ["y"] = 0, ["param1"] = 255, ["z"] = 14, ["name"] = "default:silver_sandstone"}, {["x"] = 6, ["y"] = 0, ["param1"] = 255, ["z"] = 15, ["name"] = "maptools:grass"}, {["x"] = 6, ["y"] = 0, ["param1"] = 255, ["z"] = 16, ["name"] = "maptools:grass"}, {["x"] = 6, ["y"] = 0, ["param1"] = 255, ["z"] = 17, ["name"] = "maptools:grass"}, {["x"] = 6, ["y"] = 0, ["param1"] = 255, ["z"] = 18, ["name"] = "maptools:grass"}, {["x"] = 6, ["y"] = 0, ["param1"] = 255, ["z"] = 19, ["name"] = "maptools:grass"}, {["x"] = 6, ["y"] = 0, ["param1"] = 255, ["z"] = 20, ["name"] = "default:silver_sandstone"}, {["x"] = 6, ["y"] = 0, ["param1"] = 255, ["z"] = 21, ["name"] = "maptools:grass"}, {["x"] = 6, ["y"] = 0, ["param1"] = 255, ["z"] = 22, ["name"] = "default:silver_sandstone"}, {["x"] = 6, ["y"] = 0, ["param1"] = 255, ["z"] = 23, ["name"] = "maptools:grass"}, {["x"] = 6, ["y"] = 0, ["param1"] = 255, ["z"] = 24, ["name"] = "maptools:grass"}, {["x"] = 6, ["y"] = 0, ["param1"] = 255, ["z"] = 25, ["name"] = "maptools:grass"}, {["x"] = 6, ["y"] = 0, ["param1"] = 255, ["z"] = 26, ["name"] = "maptools:grass"}, {["x"] = 6, ["y"] = 0, ["param1"] = 255, ["z"] = 27, ["name"] = "maptools:grass"}, {["x"] = 6, ["y"] = 0, ["param1"] = 255, ["z"] = 28, ["name"] = "default:silver_sandstone"}, {["x"] = 6, ["y"] = 0, ["param1"] = 255, ["z"] = 29, ["name"] = "maptools:grass"}, {["x"] = 6, ["y"] = 0, ["z"] = 30, ["name"] = "default:silver_sandstone"}, {["x"] = 6, ["y"] = 0, ["param1"] = 255, ["z"] = 31, ["name"] = "maptools:grass"}, {["x"] = 6, ["y"] = 0, ["param1"] = 255, ["z"] = 32, ["name"] = "maptools:grass"}, {["x"] = 6, ["y"] = 0, ["param1"] = 255, ["z"] = 33, ["name"] = "maptools:grass"}, {["x"] = 6, ["y"] = 0, ["param1"] = 255, ["z"] = 34, ["name"] = "maptools:grass"}, {["x"] = 6, ["y"] = 0, ["param1"] = 255, ["z"] = 35, ["name"] = "maptools:grass"}, {["x"] = 6, ["y"] = 0, ["param1"] = 255, ["z"] = 36, ["name"] = "default:silver_sandstone"}, {["x"] = 6, ["y"] = 0, ["param1"] = 255, ["z"] = 37, ["name"] = "maptools:grass"}, {["x"] = 6, ["y"] = 0, ["param1"] = 255, ["z"] = 38, ["name"] = "default:silver_sandstone"}, {["x"] = 6, ["y"] = 0, ["param1"] = 255, ["z"] = 39, ["name"] = "maptools:grass"}, {["x"] = 6, ["y"] = 0, ["param1"] = 255, ["z"] = 40, ["name"] = "maptools:grass"}, {["x"] = 6, ["y"] = 0, ["param1"] = 255, ["z"] = 41, ["name"] = "maptools:grass"}, {["x"] = 6, ["y"] = 0, ["param1"] = 255, ["z"] = 42, ["name"] = "maptools:grass"}, {["x"] = 6, ["y"] = 0, ["param1"] = 255, ["z"] = 43, ["name"] = "maptools:grass"}, {["x"] = 6, ["y"] = 0, ["param1"] = 255, ["z"] = 44, ["name"] = "default:silver_sandstone"}, {["x"] = 6, ["y"] = 0, ["param1"] = 19, ["z"] = 45, ["name"] = "default:silver_sandstone"}, {["x"] = 6, ["y"] = 1, ["param1"] = 15, ["z"] = 0, ["name"] = "default:silver_sandstone"}, {["x"] = 6, ["y"] = 1, ["param1"] = 20, ["z"] = 5, ["name"] = "default:silver_sandstone"}, {["x"] = 6, ["y"] = 1, ["param1"] = 20, ["z"] = 13, ["name"] = "default:silver_sandstone"}, {["x"] = 6, ["y"] = 1, ["param1"] = 20, ["z"] = 21, ["name"] = "default:silver_sandstone"}, {["x"] = 6, ["y"] = 1, ["param1"] = 20, ["z"] = 29, ["name"] = "default:silver_sandstone"}, {["x"] = 6, ["y"] = 1, ["param1"] = 20, ["z"] = 37, ["name"] = "default:silver_sandstone"}, {["x"] = 6, ["y"] = 1, ["param1"] = 19, ["z"] = 45, ["name"] = "default:silver_sandstone"}, {["x"] = 6, ["y"] = 2, ["param1"] = 15, ["z"] = 0, ["name"] = "default:silver_sandstone"}, {["x"] = 6, ["y"] = 2, ["param1"] = 20, ["z"] = 5, ["name"] = "default:silver_sandstone"}, {["x"] = 6, ["y"] = 2, ["param1"] = 20, ["z"] = 13, ["name"] = "default:silver_sandstone"}, {["x"] = 6, ["y"] = 2, ["param1"] = 20, ["z"] = 21, ["name"] = "default:silver_sandstone"}, {["x"] = 6, ["y"] = 2, ["param1"] = 20, ["z"] = 29, ["name"] = "default:silver_sandstone"}, {["x"] = 6, ["y"] = 2, ["param1"] = 20, ["z"] = 37, ["name"] = "default:silver_sandstone"}, {["x"] = 6, ["y"] = 2, ["param1"] = 19, ["z"] = 45, ["name"] = "default:silver_sandstone"}, {["x"] = 6, ["y"] = 3, ["param1"] = 15, ["z"] = 0, ["name"] = "default:silver_sandstone"}, {["x"] = 6, ["y"] = 3, ["param1"] = 15, ["z"] = 1, ["name"] = "default:silver_sandstone"}, {["x"] = 6, ["y"] = 3, ["param1"] = 15, ["z"] = 2, ["name"] = "default:silver_sandstone"}, {["x"] = 6, ["y"] = 3, ["param1"] = 14, ["z"] = 3, ["name"] = "default:silver_sandstone"}, {["x"] = 6, ["y"] = 3, ["param1"] = 14, ["z"] = 4, ["name"] = "default:silver_sandstone"}, {["x"] = 6, ["y"] = 3, ["param1"] = 20, ["z"] = 5, ["name"] = "default:silver_sandstone"}, {["x"] = 6, ["y"] = 3, ["param1"] = 15, ["z"] = 6, ["name"] = "default:silver_sandstone"}, {["x"] = 6, ["y"] = 3, ["param1"] = 15, ["z"] = 12, ["name"] = "default:silver_sandstone"}, {["x"] = 6, ["y"] = 3, ["param1"] = 20, ["z"] = 13, ["name"] = "default:silver_sandstone"}, {["x"] = 6, ["y"] = 3, ["z"] = 14, ["name"] = "default:silver_sandstone"}, {["x"] = 6, ["y"] = 3, ["param1"] = 15, ["z"] = 20, ["name"] = "default:silver_sandstone"}, {["x"] = 6, ["y"] = 3, ["param1"] = 20, ["z"] = 21, ["name"] = "default:silver_sandstone"}, {["x"] = 6, ["y"] = 3, ["param1"] = 15, ["z"] = 22, ["name"] = "default:silver_sandstone"}, {["x"] = 6, ["y"] = 3, ["param1"] = 15, ["z"] = 28, ["name"] = "default:silver_sandstone"}, {["x"] = 6, ["y"] = 3, ["param1"] = 20, ["z"] = 29, ["name"] = "default:silver_sandstone"}, {["x"] = 6, ["y"] = 3, ["param1"] = 15, ["z"] = 30, ["name"] = "default:silver_sandstone"}, {["x"] = 6, ["y"] = 3, ["param1"] = 15, ["z"] = 36, ["name"] = "default:silver_sandstone"}, {["x"] = 6, ["y"] = 3, ["param1"] = 20, ["z"] = 37, ["name"] = "default:silver_sandstone"}, {["x"] = 6, ["y"] = 3, ["z"] = 38, ["name"] = "default:silver_sandstone"}, {["x"] = 6, ["y"] = 3, ["param1"] = 15, ["z"] = 44, ["name"] = "default:silver_sandstone"}, {["x"] = 6, ["y"] = 3, ["param1"] = 19, ["z"] = 45, ["name"] = "default:silver_sandstone"}, {["x"] = 6, ["y"] = 4, ["param1"] = 15, ["z"] = 0, ["name"] = "default:silver_sandstone"}, {["x"] = 6, ["y"] = 4, ["param1"] = 20, ["z"] = 5, ["name"] = "default:silver_sandstone"}, {["x"] = 6, ["y"] = 4, ["param1"] = 20, ["z"] = 13, ["name"] = "default:silver_sandstone"}, {["x"] = 6, ["y"] = 4, ["param1"] = 20, ["z"] = 21, ["name"] = "default:silver_sandstone"}, {["x"] = 6, ["y"] = 4, ["param1"] = 20, ["z"] = 29, ["name"] = "default:silver_sandstone"}, {["x"] = 6, ["y"] = 4, ["param1"] = 20, ["z"] = 37, ["name"] = "default:silver_sandstone"}, {["x"] = 6, ["y"] = 4, ["param1"] = 19, ["z"] = 45, ["name"] = "default:silver_sandstone"}, {["x"] = 7, ["y"] = 0, ["param1"] = 26, ["z"] = 0, ["name"] = "default:silver_sandstone"}, {["x"] = 7, ["y"] = 0, ["param1"] = 26, ["z"] = 1, ["name"] = "default:silver_sandstone"}, {["x"] = 7, ["y"] = 0, ["param1"] = 26, ["z"] = 2, ["name"] = "maptools:grass"}, {["x"] = 7, ["y"] = 0, ["param1"] = 26, ["z"] = 3, ["name"] = "maptools:grass"}, {["x"] = 7, ["y"] = 0, ["param1"] = 255, ["z"] = 4, ["name"] = "default:silver_sandstone"}, {["x"] = 7, ["y"] = 0, ["param1"] = 255, ["z"] = 5, ["name"] = "default:silver_sandstone"}, {["x"] = 7, ["y"] = 0, ["param1"] = 111, ["z"] = 6, ["name"] = "default:silver_sandstone"}, {["x"] = 7, ["y"] = 0, ["param1"] = 255, ["z"] = 7, ["name"] = "maptools:grass"}, {["x"] = 7, ["y"] = 0, ["param1"] = 255, ["z"] = 8, ["name"] = "maptools:grass"}, {["x"] = 7, ["y"] = 0, ["param1"] = 255, ["z"] = 9, ["name"] = "maptools:grass"}, {["x"] = 7, ["y"] = 0, ["param1"] = 255, ["z"] = 10, ["name"] = "maptools:grass"}, {["x"] = 7, ["y"] = 0, ["param1"] = 255, ["z"] = 11, ["name"] = "maptools:grass"}, {["x"] = 7, ["y"] = 0, ["param1"] = 255, ["z"] = 12, ["name"] = "default:silver_sandstone"}, {["x"] = 7, ["y"] = 0, ["param1"] = 255, ["z"] = 13, ["name"] = "maptools:grass"}, {["x"] = 7, ["y"] = 0, ["param1"] = 255, ["z"] = 14, ["name"] = "default:silver_sandstone"}, {["x"] = 7, ["y"] = 0, ["param1"] = 255, ["z"] = 15, ["name"] = "maptools:grass"}, {["x"] = 7, ["y"] = 0, ["param1"] = 255, ["z"] = 16, ["name"] = "maptools:grass"}, {["x"] = 7, ["y"] = 0, ["param1"] = 255, ["z"] = 17, ["name"] = "maptools:grass"}, {["x"] = 7, ["y"] = 0, ["param1"] = 255, ["z"] = 18, ["name"] = "maptools:grass"}, {["x"] = 7, ["y"] = 0, ["param1"] = 255, ["z"] = 19, ["name"] = "maptools:grass"}, {["x"] = 7, ["y"] = 0, ["param1"] = 255, ["z"] = 20, ["name"] = "default:silver_sandstone"}, {["x"] = 7, ["y"] = 0, ["param1"] = 255, ["z"] = 21, ["name"] = "maptools:grass"}, {["x"] = 7, ["y"] = 0, ["param1"] = 255, ["z"] = 22, ["name"] = "default:silver_sandstone"}, {["x"] = 7, ["y"] = 0, ["param1"] = 255, ["z"] = 23, ["name"] = "maptools:grass"}, {["x"] = 7, ["y"] = 0, ["param1"] = 255, ["z"] = 24, ["name"] = "maptools:grass"}, {["x"] = 7, ["y"] = 0, ["param1"] = 255, ["z"] = 25, ["name"] = "maptools:grass"}, {["x"] = 7, ["y"] = 0, ["param1"] = 255, ["z"] = 26, ["name"] = "maptools:grass"}, {["x"] = 7, ["y"] = 0, ["param1"] = 255, ["z"] = 27, ["name"] = "maptools:grass"}, {["x"] = 7, ["y"] = 0, ["param1"] = 255, ["z"] = 28, ["name"] = "default:silver_sandstone"}, {["x"] = 7, ["y"] = 0, ["param1"] = 255, ["z"] = 29, ["name"] = "maptools:grass"}, {["x"] = 7, ["y"] = 0, ["z"] = 30, ["name"] = "default:silver_sandstone"}, {["x"] = 7, ["y"] = 0, ["param1"] = 255, ["z"] = 31, ["name"] = "maptools:grass"}, {["x"] = 7, ["y"] = 0, ["param1"] = 255, ["z"] = 32, ["name"] = "maptools:grass"}, {["x"] = 7, ["y"] = 0, ["param1"] = 255, ["z"] = 33, ["name"] = "maptools:grass"}, {["x"] = 7, ["y"] = 0, ["param1"] = 255, ["z"] = 34, ["name"] = "maptools:grass"}, {["x"] = 7, ["y"] = 0, ["param1"] = 255, ["z"] = 35, ["name"] = "maptools:grass"}, {["x"] = 7, ["y"] = 0, ["param1"] = 255, ["z"] = 36, ["name"] = "default:silver_sandstone"}, {["x"] = 7, ["y"] = 0, ["param1"] = 255, ["z"] = 37, ["name"] = "maptools:grass"}, {["x"] = 7, ["y"] = 0, ["param1"] = 255, ["z"] = 38, ["name"] = "default:silver_sandstone"}, {["x"] = 7, ["y"] = 0, ["param1"] = 255, ["z"] = 39, ["name"] = "maptools:grass"}, {["x"] = 7, ["y"] = 0, ["param1"] = 255, ["z"] = 40, ["name"] = "maptools:grass"}, {["x"] = 7, ["y"] = 0, ["param1"] = 255, ["z"] = 41, ["name"] = "maptools:grass"}, {["x"] = 7, ["y"] = 0, ["param1"] = 255, ["z"] = 42, ["name"] = "maptools:grass"}, {["x"] = 7, ["y"] = 0, ["param1"] = 255, ["z"] = 43, ["name"] = "maptools:grass"}, {["x"] = 7, ["y"] = 0, ["param1"] = 255, ["z"] = 44, ["name"] = "default:silver_sandstone"}, {["x"] = 7, ["y"] = 0, ["param1"] = 19, ["z"] = 45, ["name"] = "default:silver_sandstone"}, {["x"] = 7, ["y"] = 1, ["param1"] = 15, ["z"] = 0, ["name"] = "default:silver_sandstone"}, {["x"] = 7, ["y"] = 1, ["param1"] = 20, ["z"] = 5, ["name"] = "default:silver_sandstone"}, {["x"] = 7, ["y"] = 1, ["param1"] = 20, ["z"] = 13, ["name"] = "default:silver_sandstone"}, {["x"] = 7, ["y"] = 1, ["param1"] = 20, ["z"] = 21, ["name"] = "default:silver_sandstone"}, {["x"] = 7, ["y"] = 1, ["param1"] = 20, ["z"] = 29, ["name"] = "default:silver_sandstone"}, {["x"] = 7, ["y"] = 1, ["param1"] = 20, ["z"] = 37, ["name"] = "default:silver_sandstone"}, {["x"] = 7, ["y"] = 1, ["param1"] = 19, ["z"] = 45, ["name"] = "default:silver_sandstone"}, {["x"] = 7, ["y"] = 2, ["param1"] = 15, ["z"] = 0, ["name"] = "default:silver_sandstone"}, {["x"] = 7, ["y"] = 2, ["param1"] = 20, ["z"] = 5, ["name"] = "default:silver_sandstone"}, {["x"] = 7, ["y"] = 2, ["param1"] = 20, ["z"] = 13, ["name"] = "default:silver_sandstone"}, {["x"] = 7, ["y"] = 2, ["param1"] = 20, ["z"] = 21, ["name"] = "default:silver_sandstone"}, {["x"] = 7, ["y"] = 2, ["param1"] = 20, ["z"] = 29, ["name"] = "default:silver_sandstone"}, {["x"] = 7, ["y"] = 2, ["param1"] = 20, ["z"] = 37, ["name"] = "default:silver_sandstone"}, {["x"] = 7, ["y"] = 2, ["param1"] = 19, ["z"] = 45, ["name"] = "default:silver_sandstone"}, {["x"] = 7, ["y"] = 3, ["param1"] = 15, ["z"] = 0, ["name"] = "default:silver_sandstone"}, {["x"] = 7, ["y"] = 3, ["param1"] = 15, ["z"] = 1, ["name"] = "default:silver_sandstone"}, {["x"] = 7, ["y"] = 3, ["param1"] = 15, ["z"] = 2, ["name"] = "default:silver_sandstone"}, {["x"] = 7, ["y"] = 3, ["param1"] = 14, ["z"] = 3, ["name"] = "default:silver_sandstone"}, {["x"] = 7, ["y"] = 3, ["param1"] = 14, ["z"] = 4, ["name"] = "default:silver_sandstone"}, {["x"] = 7, ["y"] = 3, ["param1"] = 20, ["z"] = 5, ["name"] = "default:silver_sandstone"}, {["x"] = 7, ["y"] = 3, ["param1"] = 15, ["z"] = 6, ["name"] = "default:silver_sandstone"}, {["x"] = 7, ["y"] = 3, ["param1"] = 15, ["z"] = 12, ["name"] = "default:silver_sandstone"}, {["x"] = 7, ["y"] = 3, ["param1"] = 20, ["z"] = 13, ["name"] = "default:silver_sandstone"}, {["x"] = 7, ["y"] = 3, ["z"] = 14, ["name"] = "default:silver_sandstone"}, {["x"] = 7, ["y"] = 3, ["param1"] = 15, ["z"] = 20, ["name"] = "default:silver_sandstone"}, {["x"] = 7, ["y"] = 3, ["param1"] = 20, ["z"] = 21, ["name"] = "default:silver_sandstone"}, {["x"] = 7, ["y"] = 3, ["param1"] = 15, ["z"] = 22, ["name"] = "default:silver_sandstone"}, {["x"] = 7, ["y"] = 3, ["param1"] = 15, ["z"] = 28, ["name"] = "default:silver_sandstone"}, {["x"] = 7, ["y"] = 3, ["param1"] = 20, ["z"] = 29, ["name"] = "default:silver_sandstone"}, {["x"] = 7, ["y"] = 3, ["param1"] = 15, ["z"] = 30, ["name"] = "default:silver_sandstone"}, {["x"] = 7, ["y"] = 3, ["param1"] = 15, ["z"] = 36, ["name"] = "default:silver_sandstone"}, {["x"] = 7, ["y"] = 3, ["param1"] = 20, ["z"] = 37, ["name"] = "default:silver_sandstone"}, {["x"] = 7, ["y"] = 3, ["z"] = 38, ["name"] = "default:silver_sandstone"}, {["x"] = 7, ["y"] = 3, ["param1"] = 15, ["z"] = 44, ["name"] = "default:silver_sandstone"}, {["x"] = 7, ["y"] = 3, ["param1"] = 19, ["z"] = 45, ["name"] = "default:silver_sandstone"}, {["x"] = 7, ["y"] = 4, ["param1"] = 15, ["z"] = 0, ["name"] = "default:silver_sandstone"}, {["x"] = 7, ["y"] = 4, ["param1"] = 20, ["z"] = 5, ["name"] = "default:silver_sandstone"}, {["x"] = 7, ["y"] = 4, ["param1"] = 20, ["z"] = 13, ["name"] = "default:silver_sandstone"}, {["x"] = 7, ["y"] = 4, ["param1"] = 20, ["z"] = 21, ["name"] = "default:silver_sandstone"}, {["x"] = 7, ["y"] = 4, ["param1"] = 20, ["z"] = 29, ["name"] = "default:silver_sandstone"}, {["x"] = 7, ["y"] = 4, ["param1"] = 20, ["z"] = 37, ["name"] = "default:silver_sandstone"}, {["x"] = 7, ["y"] = 4, ["param1"] = 19, ["z"] = 45, ["name"] = "default:silver_sandstone"}, {["x"] = 8, ["y"] = 0, ["param1"] = 26, ["z"] = 0, ["name"] = "default:silver_sandstone"}, {["x"] = 8, ["y"] = 0, ["param1"] = 26, ["z"] = 1, ["name"] = "default:silver_sandstone"}, {["x"] = 8, ["y"] = 0, ["param1"] = 26, ["z"] = 2, ["name"] = "maptools:grass"}, {["x"] = 8, ["y"] = 0, ["param1"] = 26, ["z"] = 3, ["name"] = "maptools:grass"}, {["x"] = 8, ["y"] = 0, ["param1"] = 255, ["z"] = 4, ["name"] = "default:silver_sandstone"}, {["x"] = 8, ["y"] = 0, ["param1"] = 255, ["z"] = 5, ["name"] = "default:silver_sandstone"}, {["x"] = 8, ["y"] = 0, ["param1"] = 111, ["z"] = 6, ["name"] = "default:silver_sandstone"}, {["x"] = 8, ["y"] = 0, ["param1"] = 255, ["z"] = 7, ["name"] = "maptools:grass"}, {["x"] = 8, ["y"] = 0, ["param1"] = 255, ["z"] = 8, ["name"] = "maptools:grass"}, {["x"] = 8, ["y"] = 0, ["param1"] = 255, ["z"] = 9, ["name"] = "maptools:grass"}, {["x"] = 8, ["y"] = 0, ["param1"] = 255, ["z"] = 10, ["name"] = "maptools:grass"}, {["x"] = 8, ["y"] = 0, ["param1"] = 255, ["z"] = 11, ["name"] = "maptools:grass"}, {["x"] = 8, ["y"] = 0, ["param1"] = 255, ["z"] = 12, ["name"] = "default:silver_sandstone"}, {["x"] = 8, ["y"] = 0, ["param1"] = 255, ["z"] = 13, ["name"] = "maptools:grass"}, {["x"] = 8, ["y"] = 0, ["param1"] = 255, ["z"] = 14, ["name"] = "default:silver_sandstone"}, {["x"] = 8, ["y"] = 0, ["param1"] = 255, ["z"] = 15, ["name"] = "maptools:grass"}, {["x"] = 8, ["y"] = 0, ["param1"] = 255, ["z"] = 16, ["name"] = "maptools:grass"}, {["x"] = 8, ["y"] = 0, ["param1"] = 255, ["z"] = 17, ["name"] = "maptools:grass"}, {["x"] = 8, ["y"] = 0, ["param1"] = 255, ["z"] = 18, ["name"] = "maptools:grass"}, {["x"] = 8, ["y"] = 0, ["param1"] = 255, ["z"] = 19, ["name"] = "maptools:grass"}, {["x"] = 8, ["y"] = 0, ["param1"] = 255, ["z"] = 20, ["name"] = "default:silver_sandstone"}, {["x"] = 8, ["y"] = 0, ["param1"] = 255, ["z"] = 21, ["name"] = "maptools:grass"}, {["x"] = 8, ["y"] = 0, ["param1"] = 255, ["z"] = 22, ["name"] = "default:silver_sandstone"}, {["x"] = 8, ["y"] = 0, ["param1"] = 255, ["z"] = 23, ["name"] = "maptools:grass"}, {["x"] = 8, ["y"] = 0, ["param1"] = 255, ["z"] = 24, ["name"] = "maptools:grass"}, {["x"] = 8, ["y"] = 0, ["param1"] = 255, ["z"] = 25, ["name"] = "maptools:grass"}, {["x"] = 8, ["y"] = 0, ["param1"] = 255, ["z"] = 26, ["name"] = "maptools:grass"}, {["x"] = 8, ["y"] = 0, ["param1"] = 255, ["z"] = 27, ["name"] = "maptools:grass"}, {["x"] = 8, ["y"] = 0, ["param1"] = 255, ["z"] = 28, ["name"] = "default:silver_sandstone"}, {["x"] = 8, ["y"] = 0, ["param1"] = 255, ["z"] = 29, ["name"] = "maptools:grass"}, {["x"] = 8, ["y"] = 0, ["z"] = 30, ["name"] = "default:silver_sandstone"}, {["x"] = 8, ["y"] = 0, ["param1"] = 255, ["z"] = 31, ["name"] = "maptools:grass"}, {["x"] = 8, ["y"] = 0, ["param1"] = 255, ["z"] = 32, ["name"] = "maptools:grass"}, {["x"] = 8, ["y"] = 0, ["param1"] = 255, ["z"] = 33, ["name"] = "maptools:grass"}, {["x"] = 8, ["y"] = 0, ["param1"] = 255, ["z"] = 34, ["name"] = "maptools:grass"}, {["x"] = 8, ["y"] = 0, ["param1"] = 255, ["z"] = 35, ["name"] = "maptools:grass"}, {["x"] = 8, ["y"] = 0, ["param1"] = 255, ["z"] = 36, ["name"] = "default:silver_sandstone"}, {["x"] = 8, ["y"] = 0, ["param1"] = 255, ["z"] = 37, ["name"] = "maptools:grass"}, {["x"] = 8, ["y"] = 0, ["param1"] = 255, ["z"] = 38, ["name"] = "default:silver_sandstone"}, {["x"] = 8, ["y"] = 0, ["param1"] = 255, ["z"] = 39, ["name"] = "maptools:grass"}, {["x"] = 8, ["y"] = 0, ["param1"] = 255, ["z"] = 40, ["name"] = "maptools:grass"}, {["x"] = 8, ["y"] = 0, ["param1"] = 255, ["z"] = 41, ["name"] = "maptools:grass"}, {["x"] = 8, ["y"] = 0, ["param1"] = 255, ["z"] = 42, ["name"] = "maptools:grass"}, {["x"] = 8, ["y"] = 0, ["param1"] = 255, ["z"] = 43, ["name"] = "maptools:grass"}, {["x"] = 8, ["y"] = 0, ["param1"] = 255, ["z"] = 44, ["name"] = "default:silver_sandstone"}, {["x"] = 8, ["y"] = 0, ["param1"] = 19, ["z"] = 45, ["name"] = "default:silver_sandstone"}, {["x"] = 8, ["y"] = 1, ["param1"] = 15, ["z"] = 0, ["name"] = "default:silver_sandstone"}, {["x"] = 8, ["y"] = 1, ["param1"] = 20, ["z"] = 5, ["name"] = "default:silver_sandstone"}, {["x"] = 8, ["y"] = 1, ["param1"] = 20, ["z"] = 13, ["name"] = "default:silver_sandstone"}, {["x"] = 8, ["y"] = 1, ["param1"] = 20, ["z"] = 21, ["name"] = "default:silver_sandstone"}, {["x"] = 8, ["y"] = 1, ["param1"] = 20, ["z"] = 29, ["name"] = "default:silver_sandstone"}, {["x"] = 8, ["y"] = 1, ["param1"] = 20, ["z"] = 37, ["name"] = "default:silver_sandstone"}, {["x"] = 8, ["y"] = 1, ["param1"] = 19, ["z"] = 45, ["name"] = "default:silver_sandstone"}, {["x"] = 8, ["y"] = 2, ["param1"] = 15, ["z"] = 0, ["name"] = "default:silver_sandstone"}, {["x"] = 8, ["y"] = 2, ["param1"] = 20, ["z"] = 5, ["name"] = "default:silver_sandstone"}, {["x"] = 8, ["y"] = 2, ["param1"] = 20, ["z"] = 13, ["name"] = "default:silver_sandstone"}, {["x"] = 8, ["y"] = 2, ["param1"] = 20, ["z"] = 21, ["name"] = "default:silver_sandstone"}, {["x"] = 8, ["y"] = 2, ["param1"] = 20, ["z"] = 29, ["name"] = "default:silver_sandstone"}, {["x"] = 8, ["y"] = 2, ["param1"] = 20, ["z"] = 37, ["name"] = "default:silver_sandstone"}, {["x"] = 8, ["y"] = 2, ["param1"] = 19, ["z"] = 45, ["name"] = "default:silver_sandstone"}, {["x"] = 8, ["y"] = 3, ["param1"] = 15, ["z"] = 0, ["name"] = "default:silver_sandstone"}, {["x"] = 8, ["y"] = 3, ["param1"] = 15, ["z"] = 1, ["name"] = "default:silver_sandstone"}, {["x"] = 8, ["y"] = 3, ["param1"] = 15, ["z"] = 2, ["name"] = "default:silver_sandstone"}, {["x"] = 8, ["y"] = 3, ["param1"] = 14, ["z"] = 3, ["name"] = "default:silver_sandstone"}, {["x"] = 8, ["y"] = 3, ["param1"] = 14, ["z"] = 4, ["name"] = "default:silver_sandstone"}, {["x"] = 8, ["y"] = 3, ["param1"] = 20, ["z"] = 5, ["name"] = "default:silver_sandstone"}, {["x"] = 8, ["y"] = 3, ["param1"] = 15, ["z"] = 6, ["name"] = "default:silver_sandstone"}, {["x"] = 8, ["y"] = 3, ["param1"] = 15, ["z"] = 12, ["name"] = "default:silver_sandstone"}, {["x"] = 8, ["y"] = 3, ["param1"] = 20, ["z"] = 13, ["name"] = "default:silver_sandstone"}, {["x"] = 8, ["y"] = 3, ["z"] = 14, ["name"] = "default:silver_sandstone"}, {["x"] = 8, ["y"] = 3, ["param1"] = 15, ["z"] = 20, ["name"] = "default:silver_sandstone"}, {["x"] = 8, ["y"] = 3, ["param1"] = 20, ["z"] = 21, ["name"] = "default:silver_sandstone"}, {["x"] = 8, ["y"] = 3, ["param1"] = 15, ["z"] = 22, ["name"] = "default:silver_sandstone"}, {["x"] = 8, ["y"] = 3, ["param1"] = 15, ["z"] = 28, ["name"] = "default:silver_sandstone"}, {["x"] = 8, ["y"] = 3, ["param1"] = 20, ["z"] = 29, ["name"] = "default:silver_sandstone"}, {["x"] = 8, ["y"] = 3, ["param1"] = 15, ["z"] = 30, ["name"] = "default:silver_sandstone"}, {["x"] = 8, ["y"] = 3, ["param1"] = 15, ["z"] = 36, ["name"] = "default:silver_sandstone"}, {["x"] = 8, ["y"] = 3, ["param1"] = 20, ["z"] = 37, ["name"] = "default:silver_sandstone"}, {["x"] = 8, ["y"] = 3, ["z"] = 38, ["name"] = "default:silver_sandstone"}, {["x"] = 8, ["y"] = 3, ["param1"] = 15, ["z"] = 44, ["name"] = "default:silver_sandstone"}, {["x"] = 8, ["y"] = 3, ["param1"] = 19, ["z"] = 45, ["name"] = "default:silver_sandstone"}, {["x"] = 8, ["y"] = 4, ["param1"] = 15, ["z"] = 0, ["name"] = "default:silver_sandstone"}, {["x"] = 8, ["y"] = 4, ["param1"] = 20, ["z"] = 5, ["name"] = "default:silver_sandstone"}, {["x"] = 8, ["y"] = 4, ["param1"] = 20, ["z"] = 13, ["name"] = "default:silver_sandstone"}, {["x"] = 8, ["y"] = 4, ["param1"] = 20, ["z"] = 21, ["name"] = "default:silver_sandstone"}, {["x"] = 8, ["y"] = 4, ["param1"] = 20, ["z"] = 29, ["name"] = "default:silver_sandstone"}, {["x"] = 8, ["y"] = 4, ["param1"] = 20, ["z"] = 37, ["name"] = "default:silver_sandstone"}, {["x"] = 8, ["y"] = 4, ["param1"] = 19, ["z"] = 45, ["name"] = "default:silver_sandstone"}, {["x"] = 9, ["y"] = 0, ["param1"] = 26, ["z"] = 0, ["name"] = "default:silver_sandstone"}, {["x"] = 9, ["y"] = 0, ["param1"] = 26, ["z"] = 1, ["name"] = "default:silver_sandstone"}, {["x"] = 9, ["y"] = 0, ["param1"] = 26, ["z"] = 2, ["name"] = "maptools:grass"}, {["x"] = 9, ["y"] = 0, ["param1"] = 26, ["z"] = 3, ["name"] = "maptools:grass"}, {["x"] = 9, ["y"] = 0, ["param1"] = 255, ["z"] = 4, ["name"] = "default:silver_sandstone"}, {["x"] = 9, ["y"] = 0, ["param1"] = 255, ["z"] = 5, ["name"] = "default:silver_sandstone"}, {["x"] = 9, ["y"] = 0, ["param1"] = 95, ["z"] = 6, ["name"] = "default:silver_sandstone"}, {["x"] = 9, ["y"] = 0, ["param1"] = 255, ["z"] = 7, ["name"] = "maptools:grass"}, {["x"] = 9, ["y"] = 0, ["param1"] = 255, ["z"] = 8, ["name"] = "maptools:grass"}, {["x"] = 9, ["y"] = 0, ["param1"] = 255, ["z"] = 9, ["name"] = "maptools:grass"}, {["x"] = 9, ["y"] = 0, ["param1"] = 255, ["z"] = 10, ["name"] = "maptools:grass"}, {["x"] = 9, ["y"] = 0, ["param1"] = 255, ["z"] = 11, ["name"] = "maptools:grass"}, {["x"] = 9, ["y"] = 0, ["param1"] = 255, ["z"] = 12, ["name"] = "default:silver_sandstone"}, {["x"] = 9, ["y"] = 0, ["param1"] = 255, ["z"] = 13, ["name"] = "maptools:grass"}, {["x"] = 9, ["y"] = 0, ["param1"] = 255, ["z"] = 14, ["name"] = "default:silver_sandstone"}, {["x"] = 9, ["y"] = 0, ["param1"] = 255, ["z"] = 15, ["name"] = "maptools:grass"}, {["x"] = 9, ["y"] = 0, ["param1"] = 255, ["z"] = 16, ["name"] = "maptools:grass"}, {["x"] = 9, ["y"] = 0, ["param1"] = 255, ["z"] = 17, ["name"] = "maptools:grass"}, {["x"] = 9, ["y"] = 0, ["param1"] = 255, ["z"] = 18, ["name"] = "maptools:grass"}, {["x"] = 9, ["y"] = 0, ["param1"] = 255, ["z"] = 19, ["name"] = "maptools:grass"}, {["x"] = 9, ["y"] = 0, ["param1"] = 255, ["z"] = 20, ["name"] = "default:silver_sandstone"}, {["x"] = 9, ["y"] = 0, ["param1"] = 255, ["z"] = 21, ["name"] = "maptools:grass"}, {["x"] = 9, ["y"] = 0, ["param1"] = 255, ["z"] = 22, ["name"] = "default:silver_sandstone"}, {["x"] = 9, ["y"] = 0, ["param1"] = 255, ["z"] = 23, ["name"] = "maptools:grass"}, {["x"] = 9, ["y"] = 0, ["param1"] = 255, ["z"] = 24, ["name"] = "maptools:grass"}, {["x"] = 9, ["y"] = 0, ["param1"] = 255, ["z"] = 25, ["name"] = "maptools:grass"}, {["x"] = 9, ["y"] = 0, ["param1"] = 255, ["z"] = 26, ["name"] = "maptools:grass"}, {["x"] = 9, ["y"] = 0, ["param1"] = 255, ["z"] = 27, ["name"] = "maptools:grass"}, {["x"] = 9, ["y"] = 0, ["param1"] = 255, ["z"] = 28, ["name"] = "default:silver_sandstone"}, {["x"] = 9, ["y"] = 0, ["param1"] = 255, ["z"] = 29, ["name"] = "maptools:grass"}, {["x"] = 9, ["y"] = 0, ["z"] = 30, ["name"] = "default:silver_sandstone"}, {["x"] = 9, ["y"] = 0, ["param1"] = 255, ["z"] = 31, ["name"] = "maptools:grass"}, {["x"] = 9, ["y"] = 0, ["param1"] = 255, ["z"] = 32, ["name"] = "maptools:grass"}, {["x"] = 9, ["y"] = 0, ["param1"] = 255, ["z"] = 33, ["name"] = "maptools:grass"}, {["x"] = 9, ["y"] = 0, ["param1"] = 255, ["z"] = 34, ["name"] = "maptools:grass"}, {["x"] = 9, ["y"] = 0, ["param1"] = 255, ["z"] = 35, ["name"] = "maptools:grass"}, {["x"] = 9, ["y"] = 0, ["param1"] = 255, ["z"] = 36, ["name"] = "default:silver_sandstone"}, {["x"] = 9, ["y"] = 0, ["param1"] = 255, ["z"] = 37, ["name"] = "maptools:grass"}, {["x"] = 9, ["y"] = 0, ["param1"] = 255, ["z"] = 38, ["name"] = "default:silver_sandstone"}, {["x"] = 9, ["y"] = 0, ["param1"] = 255, ["z"] = 39, ["name"] = "maptools:grass"}, {["x"] = 9, ["y"] = 0, ["param1"] = 255, ["z"] = 40, ["name"] = "maptools:grass"}, {["x"] = 9, ["y"] = 0, ["param1"] = 255, ["z"] = 41, ["name"] = "maptools:grass"}, {["x"] = 9, ["y"] = 0, ["param1"] = 255, ["z"] = 42, ["name"] = "maptools:grass"}, {["x"] = 9, ["y"] = 0, ["param1"] = 255, ["z"] = 43, ["name"] = "maptools:grass"}, {["x"] = 9, ["y"] = 0, ["param1"] = 255, ["z"] = 44, ["name"] = "default:silver_sandstone"}, {["x"] = 9, ["y"] = 0, ["param1"] = 19, ["z"] = 45, ["name"] = "default:silver_sandstone"}, {["x"] = 9, ["y"] = 1, ["param1"] = 14, ["z"] = 0, ["name"] = "default:silver_sandstone"}, {["x"] = 9, ["y"] = 1, ["param1"] = 20, ["z"] = 5, ["name"] = "default:silver_sandstone"}, {["x"] = 9, ["y"] = 1, ["param1"] = 20, ["z"] = 13, ["name"] = "default:silver_sandstone"}, {["x"] = 9, ["y"] = 1, ["param1"] = 20, ["z"] = 21, ["name"] = "default:silver_sandstone"}, {["x"] = 9, ["y"] = 1, ["param1"] = 20, ["z"] = 29, ["name"] = "default:silver_sandstone"}, {["x"] = 9, ["y"] = 1, ["param1"] = 20, ["z"] = 37, ["name"] = "default:silver_sandstone"}, {["x"] = 9, ["y"] = 1, ["param1"] = 19, ["z"] = 45, ["name"] = "default:silver_sandstone"}, {["x"] = 9, ["y"] = 2, ["param1"] = 14, ["z"] = 0, ["name"] = "default:silver_sandstone"}, {["x"] = 9, ["y"] = 2, ["param1"] = 20, ["z"] = 5, ["name"] = "default:silver_sandstone"}, {["x"] = 9, ["y"] = 2, ["param1"] = 20, ["z"] = 13, ["name"] = "default:silver_sandstone"}, {["x"] = 9, ["y"] = 2, ["param1"] = 20, ["z"] = 21, ["name"] = "default:silver_sandstone"}, {["x"] = 9, ["y"] = 2, ["param1"] = 20, ["z"] = 29, ["name"] = "default:silver_sandstone"}, {["x"] = 9, ["y"] = 2, ["param1"] = 20, ["z"] = 37, ["name"] = "default:silver_sandstone"}, {["x"] = 9, ["y"] = 2, ["param1"] = 19, ["z"] = 45, ["name"] = "default:silver_sandstone"}, {["x"] = 9, ["y"] = 3, ["param1"] = 14, ["z"] = 0, ["name"] = "default:silver_sandstone"}, {["x"] = 9, ["y"] = 3, ["param1"] = 14, ["z"] = 1, ["name"] = "default:silver_sandstone"}, {["x"] = 9, ["y"] = 3, ["param1"] = 14, ["z"] = 2, ["name"] = "default:silver_sandstone"}, {["x"] = 9, ["y"] = 3, ["param1"] = 14, ["z"] = 3, ["name"] = "default:silver_sandstone"}, {["x"] = 9, ["y"] = 3, ["param1"] = 13, ["z"] = 4, ["name"] = "default:silver_sandstone"}, {["x"] = 9, ["y"] = 3, ["param1"] = 20, ["z"] = 5, ["name"] = "default:silver_sandstone"}, {["x"] = 9, ["y"] = 3, ["param1"] = 15, ["z"] = 6, ["name"] = "default:silver_sandstone"}, {["x"] = 9, ["y"] = 3, ["param1"] = 14, ["z"] = 12, ["name"] = "default:silver_sandstone"}, {["x"] = 9, ["y"] = 3, ["param1"] = 20, ["z"] = 13, ["name"] = "default:silver_sandstone"}, {["x"] = 9, ["y"] = 3, ["z"] = 14, ["name"] = "default:silver_sandstone"}, {["x"] = 9, ["y"] = 3, ["param1"] = 15, ["z"] = 20, ["name"] = "default:silver_sandstone"}, {["x"] = 9, ["y"] = 3, ["param1"] = 20, ["z"] = 21, ["name"] = "default:silver_sandstone"}, {["x"] = 9, ["y"] = 3, ["param1"] = 15, ["z"] = 22, ["name"] = "default:silver_sandstone"}, {["x"] = 9, ["y"] = 3, ["param1"] = 15, ["z"] = 28, ["name"] = "default:silver_sandstone"}, {["x"] = 9, ["y"] = 3, ["param1"] = 20, ["z"] = 29, ["name"] = "default:silver_sandstone"}, {["x"] = 9, ["y"] = 3, ["param1"] = 15, ["z"] = 30, ["name"] = "default:silver_sandstone"}, {["x"] = 9, ["y"] = 3, ["param1"] = 15, ["z"] = 36, ["name"] = "default:silver_sandstone"}, {["x"] = 9, ["y"] = 3, ["param1"] = 20, ["z"] = 37, ["name"] = "default:silver_sandstone"}, {["x"] = 9, ["y"] = 3, ["z"] = 38, ["name"] = "default:silver_sandstone"}, {["x"] = 9, ["y"] = 3, ["param1"] = 15, ["z"] = 44, ["name"] = "default:silver_sandstone"}, {["x"] = 9, ["y"] = 3, ["param1"] = 19, ["z"] = 45, ["name"] = "default:silver_sandstone"}, {["x"] = 9, ["y"] = 4, ["param1"] = 14, ["z"] = 0, ["name"] = "default:silver_sandstone"}, {["x"] = 9, ["y"] = 4, ["param1"] = 20, ["z"] = 5, ["name"] = "default:silver_sandstone"}, {["x"] = 9, ["y"] = 4, ["param1"] = 20, ["z"] = 13, ["name"] = "default:silver_sandstone"}, {["x"] = 9, ["y"] = 4, ["param1"] = 20, ["z"] = 21, ["name"] = "default:silver_sandstone"}, {["x"] = 9, ["y"] = 4, ["param1"] = 20, ["z"] = 29, ["name"] = "default:silver_sandstone"}, {["x"] = 9, ["y"] = 4, ["param1"] = 20, ["z"] = 37, ["name"] = "default:silver_sandstone"}, {["x"] = 9, ["y"] = 4, ["param1"] = 19, ["z"] = 45, ["name"] = "default:silver_sandstone"}, {["x"] = 10, ["y"] = 0, ["param1"] = 26, ["z"] = 0, ["name"] = "default:silver_sandstone"}, {["x"] = 10, ["y"] = 0, ["param1"] = 26, ["z"] = 1, ["name"] = "default:silver_sandstone"}, {["x"] = 10, ["y"] = 0, ["param1"] = 26, ["z"] = 2, ["name"] = "maptools:grass"}, {["x"] = 10, ["y"] = 0, ["param1"] = 26, ["z"] = 3, ["name"] = "maptools:grass"}, {["x"] = 10, ["y"] = 0, ["param1"] = 255, ["z"] = 4, ["name"] = "default:silver_sandstone"}, {["x"] = 10, ["y"] = 0, ["param1"] = 255, ["z"] = 5, ["name"] = "default:silver_sandstone"}, {["x"] = 10, ["y"] = 0, ["param1"] = 95, ["z"] = 6, ["name"] = "default:silver_sandstone"}, {["x"] = 10, ["y"] = 0, ["param1"] = 255, ["z"] = 7, ["name"] = "maptools:grass"}, {["x"] = 10, ["y"] = 0, ["param1"] = 255, ["z"] = 8, ["name"] = "maptools:grass"}, {["x"] = 10, ["y"] = 0, ["param1"] = 255, ["z"] = 9, ["name"] = "maptools:grass"}, {["x"] = 10, ["y"] = 0, ["param1"] = 255, ["z"] = 10, ["name"] = "maptools:grass"}, {["x"] = 10, ["y"] = 0, ["param1"] = 255, ["z"] = 11, ["name"] = "maptools:grass"}, {["x"] = 10, ["y"] = 0, ["param1"] = 255, ["z"] = 12, ["name"] = "default:silver_sandstone"}, {["x"] = 10, ["y"] = 0, ["param1"] = 255, ["z"] = 13, ["name"] = "maptools:grass"}, {["x"] = 10, ["y"] = 0, ["param1"] = 255, ["z"] = 14, ["name"] = "default:silver_sandstone"}, {["x"] = 10, ["y"] = 0, ["param1"] = 255, ["z"] = 15, ["name"] = "maptools:grass"}, {["x"] = 10, ["y"] = 0, ["param1"] = 255, ["z"] = 16, ["name"] = "maptools:grass"}, {["x"] = 10, ["y"] = 0, ["param1"] = 255, ["z"] = 17, ["name"] = "maptools:grass"}, {["x"] = 10, ["y"] = 0, ["param1"] = 255, ["z"] = 18, ["name"] = "maptools:grass"}, {["x"] = 10, ["y"] = 0, ["param1"] = 255, ["z"] = 19, ["name"] = "maptools:grass"}, {["x"] = 10, ["y"] = 0, ["param1"] = 255, ["z"] = 20, ["name"] = "default:silver_sandstone"}, {["x"] = 10, ["y"] = 0, ["param1"] = 255, ["z"] = 21, ["name"] = "maptools:grass"}, {["x"] = 10, ["y"] = 0, ["param1"] = 255, ["z"] = 22, ["name"] = "default:silver_sandstone"}, {["x"] = 10, ["y"] = 0, ["param1"] = 255, ["z"] = 23, ["name"] = "maptools:grass"}, {["x"] = 10, ["y"] = 0, ["param1"] = 255, ["z"] = 24, ["name"] = "maptools:grass"}, {["x"] = 10, ["y"] = 0, ["param1"] = 255, ["z"] = 25, ["name"] = "maptools:grass"}, {["x"] = 10, ["y"] = 0, ["param1"] = 255, ["z"] = 26, ["name"] = "maptools:grass"}, {["x"] = 10, ["y"] = 0, ["param1"] = 255, ["z"] = 27, ["name"] = "maptools:grass"}, {["x"] = 10, ["y"] = 0, ["param1"] = 255, ["z"] = 28, ["name"] = "default:silver_sandstone"}, {["x"] = 10, ["y"] = 0, ["param1"] = 255, ["z"] = 29, ["name"] = "maptools:grass"}, {["x"] = 10, ["y"] = 0, ["z"] = 30, ["name"] = "default:silver_sandstone"}, {["x"] = 10, ["y"] = 0, ["param1"] = 255, ["z"] = 31, ["name"] = "maptools:grass"}, {["x"] = 10, ["y"] = 0, ["param1"] = 255, ["z"] = 32, ["name"] = "maptools:grass"}, {["x"] = 10, ["y"] = 0, ["param1"] = 255, ["z"] = 33, ["name"] = "maptools:grass"}, {["x"] = 10, ["y"] = 0, ["param1"] = 255, ["z"] = 34, ["name"] = "maptools:grass"}, {["x"] = 10, ["y"] = 0, ["param1"] = 255, ["z"] = 35, ["name"] = "maptools:grass"}, {["x"] = 10, ["y"] = 0, ["param1"] = 255, ["z"] = 36, ["name"] = "default:silver_sandstone"}, {["x"] = 10, ["y"] = 0, ["param1"] = 255, ["z"] = 37, ["name"] = "maptools:grass"}, {["x"] = 10, ["y"] = 0, ["param1"] = 255, ["z"] = 38, ["name"] = "default:silver_sandstone"}, {["x"] = 10, ["y"] = 0, ["param1"] = 255, ["z"] = 39, ["name"] = "maptools:grass"}, {["x"] = 10, ["y"] = 0, ["param1"] = 255, ["z"] = 40, ["name"] = "maptools:grass"}, {["x"] = 10, ["y"] = 0, ["param1"] = 255, ["z"] = 41, ["name"] = "maptools:grass"}, {["x"] = 10, ["y"] = 0, ["param1"] = 255, ["z"] = 42, ["name"] = "maptools:grass"}, {["x"] = 10, ["y"] = 0, ["param1"] = 255, ["z"] = 43, ["name"] = "maptools:grass"}, {["x"] = 10, ["y"] = 0, ["param1"] = 255, ["z"] = 44, ["name"] = "default:silver_sandstone"}, {["x"] = 10, ["y"] = 0, ["param1"] = 19, ["z"] = 45, ["name"] = "default:silver_sandstone"}, {["x"] = 10, ["y"] = 1, ["param1"] = 14, ["z"] = 0, ["name"] = "default:silver_sandstone"}, {["x"] = 10, ["y"] = 1, ["param1"] = 20, ["z"] = 5, ["name"] = "default:silver_sandstone"}, {["x"] = 10, ["y"] = 1, ["param1"] = 20, ["z"] = 13, ["name"] = "default:silver_sandstone"}, {["x"] = 10, ["y"] = 1, ["param1"] = 20, ["z"] = 21, ["name"] = "default:silver_sandstone"}, {["x"] = 10, ["y"] = 1, ["param1"] = 20, ["z"] = 29, ["name"] = "default:silver_sandstone"}, {["x"] = 10, ["y"] = 1, ["param1"] = 20, ["z"] = 37, ["name"] = "default:silver_sandstone"}, {["x"] = 10, ["y"] = 1, ["param1"] = 19, ["z"] = 45, ["name"] = "default:silver_sandstone"}, {["x"] = 10, ["y"] = 2, ["param1"] = 14, ["z"] = 0, ["name"] = "default:silver_sandstone"}, {["x"] = 10, ["y"] = 2, ["param1"] = 20, ["z"] = 5, ["name"] = "default:silver_sandstone"}, {["x"] = 10, ["y"] = 2, ["param1"] = 20, ["z"] = 13, ["name"] = "default:silver_sandstone"}, {["x"] = 10, ["y"] = 2, ["param1"] = 20, ["z"] = 21, ["name"] = "default:silver_sandstone"}, {["x"] = 10, ["y"] = 2, ["param1"] = 20, ["z"] = 29, ["name"] = "default:silver_sandstone"}, {["x"] = 10, ["y"] = 2, ["param1"] = 20, ["z"] = 37, ["name"] = "default:silver_sandstone"}, {["x"] = 10, ["y"] = 2, ["param1"] = 19, ["z"] = 45, ["name"] = "default:silver_sandstone"}, {["x"] = 10, ["y"] = 3, ["param1"] = 14, ["z"] = 0, ["name"] = "default:silver_sandstone"}, {["x"] = 10, ["y"] = 3, ["param1"] = 14, ["z"] = 1, ["name"] = "default:silver_sandstone"}, {["x"] = 10, ["y"] = 3, ["param1"] = 14, ["z"] = 2, ["name"] = "default:silver_sandstone"}, {["x"] = 10, ["y"] = 3, ["param1"] = 14, ["z"] = 3, ["name"] = "default:silver_sandstone"}, {["x"] = 10, ["y"] = 3, ["param1"] = 13, ["z"] = 4, ["name"] = "default:silver_sandstone"}, {["x"] = 10, ["y"] = 3, ["param1"] = 20, ["z"] = 5, ["name"] = "default:silver_sandstone"}, {["x"] = 10, ["y"] = 3, ["param1"] = 15, ["z"] = 6, ["name"] = "default:silver_sandstone"}, {["x"] = 10, ["y"] = 3, ["param1"] = 14, ["z"] = 12, ["name"] = "default:silver_sandstone"}, {["x"] = 10, ["y"] = 3, ["param1"] = 20, ["z"] = 13, ["name"] = "default:silver_sandstone"}, {["x"] = 10, ["y"] = 3, ["z"] = 14, ["name"] = "default:silver_sandstone"}, {["x"] = 10, ["y"] = 3, ["param1"] = 15, ["z"] = 20, ["name"] = "default:silver_sandstone"}, {["x"] = 10, ["y"] = 3, ["param1"] = 20, ["z"] = 21, ["name"] = "default:silver_sandstone"}, {["x"] = 10, ["y"] = 3, ["param1"] = 15, ["z"] = 22, ["name"] = "default:silver_sandstone"}, {["x"] = 10, ["y"] = 3, ["param1"] = 15, ["z"] = 28, ["name"] = "default:silver_sandstone"}, {["x"] = 10, ["y"] = 3, ["param1"] = 20, ["z"] = 29, ["name"] = "default:silver_sandstone"}, {["x"] = 10, ["y"] = 3, ["param1"] = 15, ["z"] = 30, ["name"] = "default:silver_sandstone"}, {["x"] = 10, ["y"] = 3, ["param1"] = 15, ["z"] = 36, ["name"] = "default:silver_sandstone"}, {["x"] = 10, ["y"] = 3, ["param1"] = 20, ["z"] = 37, ["name"] = "default:silver_sandstone"}, {["x"] = 10, ["y"] = 3, ["z"] = 38, ["name"] = "default:silver_sandstone"}, {["x"] = 10, ["y"] = 3, ["param1"] = 15, ["z"] = 44, ["name"] = "default:silver_sandstone"}, {["x"] = 10, ["y"] = 3, ["param1"] = 19, ["z"] = 45, ["name"] = "default:silver_sandstone"}, {["x"] = 10, ["y"] = 4, ["param1"] = 14, ["z"] = 0, ["name"] = "default:silver_sandstone"}, {["x"] = 10, ["y"] = 4, ["param1"] = 20, ["z"] = 5, ["name"] = "default:silver_sandstone"}, {["x"] = 10, ["y"] = 4, ["param1"] = 20, ["z"] = 13, ["name"] = "default:silver_sandstone"}, {["x"] = 10, ["y"] = 4, ["param1"] = 20, ["z"] = 21, ["name"] = "default:silver_sandstone"}, {["x"] = 10, ["y"] = 4, ["param1"] = 20, ["z"] = 29, ["name"] = "default:silver_sandstone"}, {["x"] = 10, ["y"] = 4, ["param1"] = 20, ["z"] = 37, ["name"] = "default:silver_sandstone"}, {["x"] = 10, ["y"] = 4, ["param1"] = 19, ["z"] = 45, ["name"] = "default:silver_sandstone"}, {["x"] = 11, ["y"] = 0, ["param1"] = 26, ["z"] = 0, ["name"] = "default:silver_sandstone"}, {["x"] = 11, ["y"] = 0, ["param1"] = 26, ["z"] = 1, ["name"] = "default:silver_sandstone"}, {["x"] = 11, ["y"] = 0, ["param1"] = 26, ["z"] = 2, ["name"] = "maptools:grass"}, {["x"] = 11, ["y"] = 0, ["param1"] = 26, ["z"] = 3, ["name"] = "maptools:grass"}, {["x"] = 11, ["y"] = 0, ["param1"] = 255, ["z"] = 4, ["name"] = "default:silver_sandstone"}, {["x"] = 11, ["y"] = 0, ["param1"] = 255, ["z"] = 5, ["name"] = "default:silver_sandstone"}, {["x"] = 11, ["y"] = 0, ["param1"] = 111, ["z"] = 6, ["name"] = "default:silver_sandstone"}, {["x"] = 11, ["y"] = 0, ["param1"] = 255, ["z"] = 7, ["name"] = "maptools:grass"}, {["x"] = 11, ["y"] = 0, ["param1"] = 255, ["z"] = 8, ["name"] = "maptools:grass"}, {["x"] = 11, ["y"] = 0, ["param1"] = 255, ["z"] = 9, ["name"] = "maptools:grass"}, {["x"] = 11, ["y"] = 0, ["param1"] = 255, ["z"] = 10, ["name"] = "maptools:grass"}, {["x"] = 11, ["y"] = 0, ["param1"] = 255, ["z"] = 11, ["name"] = "maptools:grass"}, {["x"] = 11, ["y"] = 0, ["param1"] = 255, ["z"] = 12, ["name"] = "default:silver_sandstone"}, {["x"] = 11, ["y"] = 0, ["param1"] = 255, ["z"] = 13, ["name"] = "maptools:grass"},